Workbook

Sheet 00_README
A1: README - Warehouse Ledger + Configuration + Deployment Tracker
A2: Use this sheet as the quick operating guide. Enter data only in the non-AUTO columns. For pallet moves, log the move once in 03_Warehouse_Movements and 01_Warehouse_Ledger updates itself.
A4: Task | B4: Go to tab | C4: Edit these columns | D4: Notes / outcome
A5: Add / update a pallet | B5: 01_Warehouse_Ledger | C5: A,B,C,E,F,G,I,J,K,L | D5: One row per pallet. Do NOT type in CurrentLocationCode / LastMove fields (AUTO).
A6: Move a pallet | B6: 03_Warehouse_Movements | C6: A,B,C,E,H,I,J (F,G optional) | D6: Add one movement row (MOVE / RECEIVE / SHIP / RETURN / etc). Ledger CurrentLocationCode + LastMoveTS update automatically.
A7: Add / update a location | B7: 02_Warehouse_Locations | C7: A–G,I | D7: One row per warehouse slot. QR_Payload auto = LocationCode.
A8: Print QR labels | B8: 04_Label_Export | C8: Nothing (auto list) | D8: Print LOCATION labels (top section) and PALLET labels (starts at row 505). QR payload stays minimal (LocationCode / PalletID).
A9: Find where a pallet is | B9: 05_Scan_Lookup | C9: Scan into B3 | D9: Scan Pallet QR -> see CurrentLocationCode + map fields instantly.
A10: Tie a device to a pallet | B10: 12 - Device_Configuration | C10: BL (PalletID (Manual)) | D10: Enter PalletID on the device row -> BM/BN/BO auto-fill Warehouse Location + Pallet Status + Last Move TS.
A13: Pallet moves - the 30-second routine
A14: 1) | B14: Go to 03_Warehouse_Movements and add a NEW row at the top of the data (first blank row).
A15: 2) | B15: Fill: Timestamp (A), Action (B)=MOVE, PalletID (C)=scan or type, ToLocation (E)=scan location code, ByWho (H), Ref (I) if relevant, Notes (J) if needed. Optional: Item (F) + Qty (G) if you are tracking contents.
A16: 3) | B16: Do NOT edit FromLocation (D). It auto-fills from the pallet’s prior state (based on 01_Warehouse_Ledger).
A17: 4) | B17: Sanity check: open 01_Warehouse_Ledger -> CurrentLocationCode (AUTO) and LastMoveTS (AUTO) should update for that PalletID.
A18: 5) | B18: Optional: if the move changed the pallet’s lifecycle (STAGED/DEPLOYED/RETURNED), update PalletStatus (E) on 01_Warehouse_Ledger.
A20: Data rules (don’t break the tracker)
A21: • Only type into columns that are NOT labeled (AUTO) or (deprecated).
A22: • PalletIDs must exist in 01_Warehouse_Ledger before you reference them anywhere else (moves, device config, contents, labels).
A23: • PalletID format enforced by the ledger CF: PAL-0000001 (PAL- + 7 digits). Duplicates highlight.
A24: • LocationCode: pick from 02_Warehouse_Locations (use dropdowns where present).
A25: • If a cell looks formula-driven, leave it alone. Don’t paste over formulas.
A26: • If you must paste, paste VALUES only (not formatting) into input columns.
A27: • When in doubt: use 05_Scan_Lookup to verify the pallet’s current location before moving anything.
A29: Quick troubleshooting
A30: • 05_Scan_Lookup shows blanks -> confirm you scanned a valid PalletID that exists in 01_Warehouse_Ledger column A.
A31: • Move row highlights -> check required fields in 03_Warehouse_Movements: Timestamp (A), Action (B), PalletID (C), ToLocation (E).
A32: • FromLocation (AUTO) stays blank -> the pallet is unknown to the ledger or has no prior location. Add the pallet to 01_Warehouse_Ledger, set HomeLocationCode (C), then re-enter the move row.
... A43: • 05_Scan_Lookup is the fast verify panel: scan PalletID -> read CurrentLocationCode + location display info.

Sheet 01_Warehouse_Ledger
A1: PalletID | B1: PalletCallSign | C1: HomeLocationCode | D1: CurrentLocationCode (AUTO) | E1: PalletStatus | F1: Compliance | G1: TTL_Days | H1: Expires (AUTO) | I1: ContentsSummary | J1: Notes | K1: CreatedDate | L1: CreatedBy | M1: LastMoveTS (AUTO) | N1: LastMovedBy (AUTO) | O1: QR_Payload_Pallet (deprecated) | P1: ReceiptDate (deprecated) | Q1: Ref (deprecated) | R1: Item (deprecated) | S1: QtyReceived (deprecated) | T1: Serials (deprecated) | U1: EnteredBy_RAW (deprecated) | V1: Legacy_RawInputs (deprecated) | W1: StockLines (AUTO) | X1: StockQtyTotal (AUTO) | Y1: StockUniquePN (AUTO) | Z1: StockHasPN (AUTO)
A2: PAL-0000001 | B2: OVERFLOW-RICH-CYBERNETS-CFAM-CCMC | C2: CHRIS_OVERFLOW_A_ZONE3 | D2: =IF($C2="","",IFERROR(LOOKUP(2,1/('03_Warehouse_Movements'!$C$2:$C$500=$A2),'03_Warehouse_Movements'!$E$2:$E$500),$C2)) -> CHRIS_OVERFLOW_A_ZONE3 | E2: ACTIVE | F2: STANDARD | G2: 7 | H2: =IF(AND($F2="TEMP",$G2>0,$M2<>""),$M2+$G2,"") | I2: CYBERNETS CFAM/CCMC QTY:15 | J2: NORTHWELL NUERON PROJECT | K2: 46053 | L2: Alejandro Perales | M2: =IF($C2="","",IFERROR(LOOKUP(2,1/('03_Warehouse_Movements'!$C$2:$C$500=$A2),'03_Warehouse_Movements'!$A$2:$A$500),"")) | N2: =IF($C2="","",IFERROR(LOOKUP(2,1/('03_Warehouse_Movements'!$C$2:$C$500=$A2),'03_Warehouse_Movements'!$H$2:$H$500),"")) | O2: =A2 -> PAL-0000001 | P2: 46284 | Q2: 144180 | V2: B:WH-Z1-A01-AISLE-FLOOR-02 F:OVERFLOW-<ClientLastName>-PO<PO>-<Category>-<Seq> D:WH-Z1-A01-AISLE-FLOOR-02 | W2: =IF($A2="","",COUNTIF('07_Pallet_Contents'!$A$2:$A$3000,$A2)) -> 0 | X2: =IF($A2="","",SUMIF('07_Pallet_Contents'!$A$2:$A$3000,$A2,'07_Pallet_Contents'!$D$2:$D$3000)) -> 0 | Y2: =IF($A2="","",SUMIF('07_Pallet_Contents'!$A$2:$A$3000,$A2,'07_Pallet_Contents'!$I$2:$I$3000)) -> 0 | Z2: =IF($A2="","",IF(COUNTIF('07_Pallet_Contents'!$A$2:$A$3000,$A2)>0,"Yes",""))
A3: PAL-0000002 | C3: WH-STAGE-IN | D3: =IF($C3="","",IFERROR(LOOKUP(2,1/('03_Warehouse_Movements'!$C$2:$C$500=$A3),'03_Warehouse_Movements'!$E$2:$E$500),$C3)) -> WH-STAGE-IN | E3: STAGED | F3: SAFE | H3: =IF(AND($F3="TEMP",$G3>0,$M3<>""),$M3+$G3,"") | I3: SAMPLE: Monitors 24-40 | J3: SAMPLE: replace with real notes / serials / constraints | K3: 46052 | L3: SAMPLE-TECH | M3: =IF($C3="","",IFERROR(LOOKUP(2,1/('03_Warehouse_Movements'!$C$2:$C$500=$A3),'03_Warehouse_Movements'!$A$2:$A$500),"")) | N3: =IF($C3="","",IFERROR(LOOKUP(2,1/('03_Warehouse_Movements'!$C$2:$C$500=$A3),'03_Warehouse_Movements'!$H$2:$H$500),"")) | O3: =A3 -> PAL-0000002 | V3: B:OVERFLOW-<ClientLastName>-PO<PO>-<Category>-<Seq> | W3: =IF($A2="","",COUNTIF('07_Pallet_Contents'!$A$2:$A$3000,$A2)) -> 0 | X3: =IF($A2="","",SUMIF('07_Pallet_Contents'!$A$2:$A$3000,$A2,'07_Pallet_Contents'!$D$2:$D$3000)) -> 0 | Y3: =IF($A2="","",SUMIF('07_Pallet_Contents'!$A$2:$A$3000,$A2,'07_Pallet_Contents'!$I$2:$I$3000)) -> 0 | Z3: =IF($A2="","",IF(COUNTIF('07_Pallet_Contents'!$A$2:$A$3000,$A2)>0,"Yes",""))
A4: PAL-0000003 | B4: OVERFLOW-CHRIS-UMAIR_TICKETS- | C4: CHRIS_OVERFLOW_A_ZONE1 | D4: =IF($C4="","",IFERROR(LOOKUP(2,1/('03_Warehouse_Movements'!$C$2:$C$500=$A4),'03_Warehouse_Movements'!$E$2:$E$500),$C4)) -> CHRIS_OVERFLOW_A_ZONE1 | E4: ACTIVE | F4: UNSAFE | H4: =IF(AND($F4="TEMP",$G4>0,$M4<>""),$M4+$G4,"") | I4: Monitors T24-40 | J4: 24 Day Ticket | K4: 46046 | L4: Alejandro Perales | M4: =IF($C4="","",IFERROR(LOOKUP(2,1/('03_Warehouse_Movements'!$C$2:$C$500=$A4),'03_Warehouse_Movements'!$A$2:$A$500),"")) | N4: =IF($C4="","",IFERROR(LOOKUP(2,1/('03_Warehouse_Movements'!$C$2:$C$500=$A4),'03_Warehouse_Movements'!$H$2:$H$500),"")) | O4: =A4 -> PAL-0000003 | U4: 46046 | V4: B:OVERFLOW-CHRIS-UMAIR_TICKETS- D:CHRIS_OVERFLOW_A_ZONE1 | W4: =IF($A2="","",COUNTIF('07_Pallet_Contents'!$A$2:$A$3000,$A2)) -> 0 | X4: =IF($A2="","",SUMIF('07_Pallet_Contents'!$A$2:$A$3000,$A2,'07_Pallet_Contents'!$D$2:$D$3000)) -> 0 | Y4: =IF($A2="","",SUMIF('07_Pallet_Contents'!$A$2:$A$3000,$A2,'07_Pallet_Contents'!$I$2:$I$3000)) -> 0 | Z4: =IF($A2="","",IF(COUNTIF('07_Pallet_Contents'!$A$2:$A$3000,$A2)>0,"Yes",""))
A5: PAL-0000004 | B5: WH-Z1-AisleO-Bay10-Level1 | C5: WH-Z1-AisleO-Bay10-Level1 | D5: =IF($C5="","",IFERROR(LOOKUP(2,1/('03_Warehouse_Movements'!$C$2:$C$500=$A5),'03_Warehouse_Movements'!$E$2:$E$500),$C5)) -> WH-Z1-AisleO-Bay10-Level1 | E5: ACTIVE | F5: SAFE | H5: =IF(AND($F5="TEMP",$G5>0,$M5<>""),$M5+$G5,"") | I5: 48x T24i-30 | J5: SAMPLE: replace with real notes / serials / constraints | K5: 46051 | L5: Geoff Gerber | M5: =IF($C5="","",IFERROR(LOOKUP(2,1/('03_Warehouse_Movements'!$C$2:$C$500=$A5),'03_Warehouse_Movements'!$A$2:$A$500),"")) | N5: =IF($C5="","",IFERROR(LOOKUP(2,1/('03_Warehouse_Movements'!$C$2:$C$500=$A5),'03_Warehouse_Movements'!$H$2:$H$500),"")) | O5: =A5 -> PAL-0000004 | U5: 46051 | V5: B:OVERFLOW-CHRIS- D:CHRIS_OVERFLOW_A_ZONE1 | W5: =IF($A2="","",COUNTIF('07_Pallet_Contents'!$A$2:$A$3000,$A2)) -> 0 | X5: =IF($A2="","",SUMIF('07_Pallet_Contents'!$A$2:$A$3000,$A2,'07_Pallet_Contents'!$D$2:$D$3000)) -> 0 | Y5: =IF($A2="","",SUMIF('07_Pallet_Contents'!$A$2:$A$3000,$A2,'07_Pallet_Contents'!$I$2:$I$3000)) -> 0 | Z5: =IF($A2="","",IF(COUNTIF('07_Pallet_Contents'!$A$2:$A$3000,$A2)>0,"Yes",""))
A6: PAL-0000005 | B6: Northwell Capsule & GCX | C6: WH-ZR-AisleM-Bay1-Level3 | D6: =IF($C6="","",IFERROR(LOOKUP(2,1/('03_Warehouse_Movements'!$C$2:$C$500=$A6),'03_Warehouse_Movements'!$E$2:$E$500),$C6)) -> WH-ZR-AisleM-Bay1-Level3 | E6: ACTIVE | F6: SAFE | H6: =IF(AND($F6="TEMP",$G6>0,$M6<>""),$M6+$G6,"") | I6: capsule & GCX | J6: crate looks broken, contents are tightly wrapped / unable to 100% verify actually contents of boxes | K6: 46059 | L6: Khadejah Harrison | M6: =IF($C6="","",IFERROR(LOOKUP(2,1/('03_Warehouse_Movements'!$C$2:$C$500=$A6),'03_Warehouse_Movements'!$A$2:$A$500),"")) | N6: =IF($C6="","",IFERROR(LOOKUP(2,1/('03_Warehouse_Movements'!$C$2:$C$500=$A6),'03_Warehouse_Movements'!$H$2:$H$500),"")) | O6: =A6 -> PAL-0000005 | W6: =IF($A2="","",COUNTIF('07_Pallet_Contents'!$A$2:$A$3000,$A2)) -> 0 | X6: =IF($A2="","",SUMIF('07_Pallet_Contents'!$A$2:$A$3000,$A2,'07_Pallet_Contents'!$D$2:$D$3000)) -> 0 | Y6: =IF($A2="","",SUMIF('07_Pallet_Contents'!$A$2:$A$3000,$A2,'07_Pallet_Contents'!$I$2:$I$3000)) -> 0 | Z6: =IF($A2="","",IF(COUNTIF('07_Pallet_Contents'!$A$2:$A$3000,$A2)>0,"Yes",""))
A7: PAL-0000006 | C7: WH-Z1-NOOverflow | D7: =IF($C7="","",IFERROR(LOOKUP(2,1/('03_Warehouse_Movements'!$C$2:$C$500=$A7),'03_Warehouse_Movements'!$E$2:$E$500),$C7)) -> WH-Z1-NOOverflow | E7: STAGED | F7: SAFE | H7: =IF(AND($F7="TEMP",$G7>0,$M7<>""),$M7+$G7,"") | I7: 19x T24 Thinkvision Monitor 63CFMAR1US | K7: 46052 | L7: Geoff Gerber | M7: =IF($C7="","",IFERROR(LOOKUP(2,1/('03_Warehouse_Movements'!$C$2:$C$500=$A7),'03_Warehouse_Movements'!$A$2:$A$500),"")) | N7: =IF($C7="","",IFERROR(LOOKUP(2,1/('03_Warehouse_Movements'!$C$2:$C$500=$A7),'03_Warehouse_Movements'!$H$2:$H$500),"")) | O7: =A7 -> PAL-0000006 | W7: =IF($A2="","",COUNTIF('07_Pallet_Contents'!$A$2:$A$3000,$A2)) -> 0 | X7: =IF($A2="","",SUMIF('07_Pallet_Contents'!$A$2:$A$3000,$A2,'07_Pallet_Contents'!$D$2:$D$3000)) -> 0 | Y7: =IF($A2="","",SUMIF('07_Pallet_Contents'!$A$2:$A$3000,$A2,'07_Pallet_Contents'!$I$2:$I$3000)) -> 0 | Z7: =IF($A2="","",IF(COUNTIF('07_Pallet_Contents'!$A$2:$A$3000,$A2)>0,"Yes",""))
A8: PAL-0000007 | C8: WH-Z1-AisleO-Bay7-Level1 | D8: =IF($C8="","",IFERROR(LOOKUP(2,1/('03_Warehouse_Movements'!$C$2:$C$500=$A8),'03_Warehouse_Movements'!$E$2:$E$500),$C8)) -> WH-Z1-AisleO-Bay7-Level1 | E8: STAGED | F8: TEMP | G8: 14 | H8: =IF(AND($F8="TEMP",$G8>0,$M8<>""),$M8+$G8,"") | I8: 48x T24i-30 | J8: SAMPLE: replace with real notes / serials / constraints | K8: 46052 | L8: Geoff Gerber | M8: =IF($C8="","",IFERROR(LOOKUP(2,1/('03_Warehouse_Movements'!$C$2:$C$500=$A8),'03_Warehouse_Movements'!$A$2:$A$500),"")) | N8: =IF($C8="","",IFERROR(LOOKUP(2,1/('03_Warehouse_Movements'!$C$2:$C$500=$A8),'03_Warehouse_Movements'!$H$2:$H$500),"")) | O8: =A8 -> PAL-0000007 | W8: =IF($A2="","",COUNTIF('07_Pallet_Contents'!$A$2:$A$3000,$A2)) -> 0 | X8: =IF($A2="","",SUMIF('07_Pallet_Contents'!$A$2:$A$3000,$A2,'07_Pallet_Contents'!$D$2:$D$3000)) -> 0 | Y8: =IF($A2="","",SUMIF('07_Pallet_Contents'!$A$2:$A$3000,$A2,'07_Pallet_Contents'!$I$2:$I$3000)) -> 0 | Z8: =IF($A2="","",IF(COUNTIF('07_Pallet_Contents'!$A$2:$A$3000,$A2)>0,"Yes",""))
A9: PAL-0000008 | B9: OVERFLOW-SAMPLE-PO1007-CAT3-PAL008 | C9: WH-Z1-AisleA-Bay1-Level5 | D9: =IF($C9="","",IFERROR(LOOKUP(2,1/('03_Warehouse_Movements'!$C$2:$C$500=$A9),'03_Warehouse_Movements'!$E$2:$E$500),$C9)) -> WH-Z1-AisleA-Bay1-Level5 | E9: ACTIVE | F9: SAFE | H9: =IF(AND($F9="TEMP",$G9>0,$M9<>""),$M9+$G9,"") | I9: SAMPLE: Power Supplies | J9: SAMPLE: replace with real notes / serials / constraints | K9: 46052 | L9: SAMPLE-TECH | M9: =IF($C9="","",IFERROR(LOOKUP(2,1/('03_Warehouse_Movements'!$C$2:$C$500=$A9),'03_Warehouse_Movements'!$A$2:$A$500),"")) | N9: =IF($C9="","",IFERROR(LOOKUP(2,1/('03_Warehouse_Movements'!$C$2:$C$500=$A9),'03_Warehouse_Movements'!$H$2:$H$500),"")) | O9: =A9 -> PAL-0000008 | W9: =IF($A2="","",COUNTIF('07_Pallet_Contents'!$A$2:$A$3000,$A2)) -> 0 | X9: =IF($A2="","",SUMIF('07_Pallet_Contents'!$A$2:$A$3000,$A2,'07_Pallet_Contents'!$D$2:$D$3000)) -> 0 | Y9: =IF($A2="","",SUMIF('07_Pallet_Contents'!$A$2:$A$3000,$A2,'07_Pallet_Contents'!$I$2:$I$3000)) -> 0 | Z9: =IF($A2="","",IF(COUNTIF('07_Pallet_Contents'!$A$2:$A$3000,$A2)>0,"Yes",""))
A10: PAL-0000009 | C10: WH-Z1-AisleA-Bay1-Level6 | D10: =IF($C10="","",IFERROR(LOOKUP(2,1/('03_Warehouse_Movements'!$C$2:$C$500=$A10),'03_Warehouse_Movements'!$E$2:$E$500),$C10)) -> WH-Z1-AisleA-Bay1-Level6 | E10: ACTIVE | F10: SAFE | H10: =IF(AND($F10="TEMP",$G10>0,$M10<>""),$M10+$G10,"") | I10: SAMPLE: Imaging Equipment | J10: SAMPLE: replace with real notes / serials / constraints | K10: 46052 | L10: SAMPLE-TECH | M10: =IF($C10="","",IFERROR(LOOKUP(2,1/('03_Warehouse_Movements'!$C$2:$C$500=$A10),'03_Warehouse_Movements'!$A$2:$A$500),"")) | N10: =IF($C10="","",IFERROR(LOOKUP(2,1/('03_Warehouse_Movements'!$C$2:$C$500=$A10),'03_Warehouse_Movements'!$H$2:$H$500),"")) | O10: =A10 -> PAL-0000009 | W10: =IF($A2="","",COUNTIF('07_Pallet_Contents'!$A$2:$A$3000,$A2)) -> 0 | X10: =IF($A2="","",SUMIF('07_Pallet_Contents'!$A$2:$A$3000,$A2,'07_Pallet_Contents'!$D$2:$D$3000)) -> 0 | Y10: =IF($A2="","",SUMIF('07_Pallet_Contents'!$A$2:$A$3000,$A2,'07_Pallet_Contents'!$I$2:$I$3000)) -> 0 | Z10: =IF($A2="","",IF(COUNTIF('07_Pallet_Contents'!$A$2:$A$3000,$A2)>0,"Yes",""))
A11: PAL-0000010 | C11: WH-Z1-AisleA-Bay1-Level7 | D11: =IF($C11="","",IFERROR(LOOKUP(2,1/('03_Warehouse_Movements'!$C$2:$C$500=$A11),'03_Warehouse_Movements'!$E$2:$E$500),$C11)) -> WH-Z1-AisleA-Bay1-Level7 | E11: ACTIVE | F11: SAFE | H11: =IF(AND($F11="TEMP",$G11>0,$M11<>""),$M11+$G11,"") | I11: SAMPLE: Misc Hardware | J11: SAMPLE: replace with real notes / serials / constraints | K11: 46052 | L11: SAMPLE-TECH | M11: =IF($C11="","",IFERROR(LOOKUP(2,1/('03_Warehouse_Movements'!$C$2:$C$500=$A11),'03_Warehouse_Movements'!$A$2:$A$500),"")) | N11: =IF($C11="","",IFERROR(LOOKUP(2,1/('03_Warehouse_Movements'!$C$2:$C$500=$A11),'03_Warehouse_Movements'!$H$2:$H$500),"")) | O11: =A11 -> PAL-0000010 | Q11: B | W11: =IF($A2="","",COUNTIF('07_Pallet_Contents'!$A$2:$A$3000,$A2)) -> 0 | X11: =IF($A2="","",SUMIF('07_Pallet_Contents'!$A$2:$A$3000,$A2,'07_Pallet_Contents'!$D$2:$D$3000)) -> 0 | Y11: =IF($A2="","",SUMIF('07_Pallet_Contents'!$A$2:$A$3000,$A2,'07_Pallet_Contents'!$I$2:$I$3000)) -> 0 | Z11: =IF($A2="","",IF(COUNTIF('07_Pallet_Contents'!$A$2:$A$3000,$A2)>0,"Yes",""))
A12: PAL-0000011 | C12: WH-Z1-AisleA-Bay1-Level8 | D12: =IF($C12="","",IFERROR(LOOKUP(2,1/('03_Warehouse_Movements'!$C$2:$C$500=$A12),'03_Warehouse_Movements'!$E$2:$E$500),$C12)) -> WH-Z1-AisleA-Bay1-Level8 | E12: ACTIVE | F12: SAFE | H12: =IF(AND($F12="TEMP",$G12>0,$M12<>""),$M12+$G12,"") | I12: SAMPLE: Dell Devices | J12: SAMPLE: replace with real notes / serials / constraints | K12: 46052 | L12: SAMPLE-TECH | M12: =IF($C12="","",IFERROR(LOOKUP(2,1/('03_Warehouse_Movements'!$C$2:$C$500=$A12),'03_Warehouse_Movements'!$A$2:$A$500),"")) | N12: =IF($C12="","",IFERROR(LOOKUP(2,1/('03_Warehouse_Movements'!$C$2:$C$500=$A12),'03_Warehouse_Movements'!$H$2:$H$500),"")) | O12: =A12 -> PAL-0000011 | W12: =IF($A2="","",COUNTIF('07_Pallet_Contents'!$A$2:$A$3000,$A2)) -> 0 | X12: =IF($A2="","",SUMIF('07_Pallet_Contents'!$A$2:$A$3000,$A2,'07_Pallet_Contents'!$D$2:$D$3000)) -> 0 | Y12: =IF($A2="","",SUMIF('07_Pallet_Contents'!$A$2:$A$3000,$A2,'07_Pallet_Contents'!$I$2:$I$3000)) -> 0 | Z12: =IF($A2="","",IF(COUNTIF('07_Pallet_Contents'!$A$2:$A$3000,$A2)>0,"Yes",""))
A13: PAL-0000012 | C13: WH-Z1-AisleA-Bay1-Level9 | D13: =IF($C13="","",IFERROR(LOOKUP(2,1/('03_Warehouse_Movements'!$C$2:$C$500=$A13),'03_Warehouse_Movements'!$E$2:$E$500),$C13)) -> WH-Z1-AisleA-Bay1-Level9 | E13: ACTIVE | F13: SAFE | H13: =IF(AND($F13="TEMP",$G13>0,$M13<>""),$M13+$G13,"") | I13: SAMPLE: Monitors 24-40 | J13: SAMPLE: replace with real notes / serials / constraints | K13: 46052 | L13: SAMPLE-TECH | M13: =IF($C13="","",IFERROR(LOOKUP(2,1/('03_Warehouse_Movements'!$C$2:$C$500=$A13),'03_Warehouse_Movements'!$A$2:$A$500),"")) | N13: =IF($C13="","",IFERROR(LOOKUP(2,1/('03_Warehouse_Movements'!$C$2:$C$500=$A13),'03_Warehouse_Movements'!$H$2:$H$500),"")) | O13: =A13 -> PAL-0000012 | W13: =IF($A2="","",COUNTIF('07_Pallet_Contents'!$A$2:$A$3000,$A2)) -> 0 | X13: =IF($A2="","",SUMIF('07_Pallet_Contents'!$A$2:$A$3000,$A2,'07_Pallet_Contents'!$D$2:$D$3000)) -> 0 | Y13: =IF($A2="","",SUMIF('07_Pallet_Contents'!$A$2:$A$3000,$A2,'07_Pallet_Contents'!$I$2:$I$3000)) -> 0 | Z13: =IF($A2="","",IF(COUNTIF('07_Pallet_Contents'!$A$2:$A$3000,$A2)>0,"Yes",""))
A14: PAL-0000013 | C14: WH-Z1-AisleA-Bay1-Level10 | D14: =IF($C14="","",IFERROR(LOOKUP(2,1/('03_Warehouse_Movements'!$C$2:$C$500=$A14),'03_Warehouse_Movements'!$E$2:$E$500),$C14)) -> WH-Z1-AisleA-Bay1-Level10 | E14: ACTIVE | F14: TEMP | G14: 14 | H14: =IF(AND($F14="TEMP",$G14>0,$M14<>""),$M14+$G14,"") | I14: SAMPLE: Cables & Adapters | J14: SAMPLE: replace with real notes / serials / constraints | K14: 46052 | L14: SAMPLE-TECH | M14: =IF($C14="","",IFERROR(LOOKUP(2,1/('03_Warehouse_Movements'!$C$2:$C$500=$A14),'03_Warehouse_Movements'!$A$2:$A$500),"")) | N14: =IF($C14="","",IFERROR(LOOKUP(2,1/('03_Warehouse_Movements'!$C$2:$C$500=$A14),'03_Warehouse_Movements'!$H$2:$H$500),"")) | O14: =A14 -> PAL-0000013 | W14: =IF($A2="","",COUNTIF('07_Pallet_Contents'!$A$2:$A$3000,$A2)) -> 0 | X14: =IF($A2="","",SUMIF('07_Pallet_Contents'!$A$2:$A$3000,$A2,'07_Pallet_Contents'!$D$2:$D$3000)) -> 0 | Y14: =IF($A2="","",SUMIF('07_Pallet_Contents'!$A$2:$A$3000,$A2,'07_Pallet_Contents'!$I$2:$I$3000)) -> 0 | Z14: =IF($A2="","",IF(COUNTIF('07_Pallet_Contents'!$A$2:$A$3000,$A2)>0,"Yes",""))
A15: PAL-0000014 | C15: WH-Z1-AisleA-Bay1-Level11 | D15: =IF($C15="","",IFERROR(LOOKUP(2,1/('03_Warehouse_Movements'!$C$2:$C$500=$A15),'03_Warehouse_Movements'!$E$2:$E$500),$C15)) -> WH-Z1-AisleA-Bay1-Level11 | E15: ACTIVE | F15: SAFE | H15: =IF(AND($F15="TEMP",$G15>0,$M15<>""),$M15+$G15,"") | I15: SAMPLE: Racks & Rails | J15: SAMPLE: replace with real notes / serials / constraints | K15: 46052 | L15: SAMPLE-TECH | M15: =IF($C15="","",IFERROR(LOOKUP(2,1/('03_Warehouse_Movements'!$C$2:$C$500=$A15),'03_Warehouse_Movements'!$A$2:$A$500),"")) | N15: =IF($C15="","",IFERROR(LOOKUP(2,1/('03_Warehouse_Movements'!$C$2:$C$500=$A15),'03_Warehouse_Movements'!$H$2:$H$500),"")) | O15: =A15 -> PAL-0000014 | W15: =IF($A2="","",COUNTIF('07_Pallet_Contents'!$A$2:$A$3000,$A2)) -> 0 | X15: =IF($A2="","",SUMIF('07_Pallet_Contents'!$A$2:$A$3000,$A2,'07_Pallet_Contents'!$D$2:$D$3000)) -> 0 | Y15: =IF($A2="","",SUMIF('07_Pallet_Contents'!$A$2:$A$3000,$A2,'07_Pallet_Contents'!$I$2:$I$3000)) -> 0 | Z15: =IF($A2="","",IF(COUNTIF('07_Pallet_Contents'!$A$2:$A$3000,$A2)>0,"Yes",""))
A16: PAL-0000015 | B16: OVERFLOW-SAMPLE-PO1014-CAT5-PAL015 | C16: WH-Z1-AisleA-Bay1-Level12 | D16: =IF($C16="","",IFERROR(LOOKUP(2,1/('03_Warehouse_Movements'!$C$2:$C$500=$A16),'03_Warehouse_Movements'!$E$2:$E$500),$C16)) -> WH-Z1-AisleA-Bay1-Level12 | E16: ACTIVE | F16: SAFE | H16: =IF(AND($F16="TEMP",$G16>0,$M16<>""),$M16+$G16,"") | I16: SAMPLE: Networking Gear | J16: SAMPLE: replace with real notes / serials / constraints | K16: 46052 | L16: SAMPLE-TECH | M16: =IF($C16="","",IFERROR(LOOKUP(2,1/('03_Warehouse_Movements'!$C$2:$C$500=$A16),'03_Warehouse_Movements'!$A$2:$A$500),"")) | N16: =IF($C16="","",IFERROR(LOOKUP(2,1/('03_Warehouse_Movements'!$C$2:$C$500=$A16),'03_Warehouse_Movements'!$H$2:$H$500),"")) | O16: =A16 -> PAL-0000015 | W16: =IF($A2="","",COUNTIF('07_Pallet_Contents'!$A$2:$A$3000,$A2)) -> 0 | X16: =IF($A2="","",SUMIF('07_Pallet_Contents'!$A$2:$A$3000,$A2,'07_Pallet_Contents'!$D$2:$D$3000)) -> 0 | Y16: =IF($A2="","",SUMIF('07_Pallet_Contents'!$A$2:$A$3000,$A2,'07_Pallet_Contents'!$I$2:$I$3000)) -> 0 | Z16: =IF($A2="","",IF(COUNTIF('07_Pallet_Contents'!$A$2:$A$3000,$A2)>0,"Yes",""))
A17: PAL-0000016 | C17: WH-Z1-AisleA-Bay1-Level13 | D17: =IF($C17="","",IFERROR(LOOKUP(2,1/('03_Warehouse_Movements'!$C$2:$C$500=$A17),'03_Warehouse_Movements'!$E$2:$E$500),$C17)) -> WH-Z1-AisleA-Bay1-Level13 | E17: ACTIVE | F17: SAFE | H17: =IF(AND($F17="TEMP",$G17>0,$M17<>""),$M17+$G17,"") | I17: SAMPLE: Keyboards & Mice | J17: SAMPLE: replace with real notes / serials / constraints | K17: 46052 | L17: SAMPLE-TECH | M17: =IF($C17="","",IFERROR(LOOKUP(2,1/('03_Warehouse_Movements'!$C$2:$C$500=$A17),'03_Warehouse_Movements'!$A$2:$A$500),"")) | N17: =IF($C17="","",IFERROR(LOOKUP(2,1/('03_Warehouse_Movements'!$C$2:$C$500=$A17),'03_Warehouse_Movements'!$H$2:$H$500),"")) | O17: =A17 -> PAL-0000016 | W17: =IF($A2="","",COUNTIF('07_Pallet_Contents'!$A$2:$A$3000,$A2)) -> 0 | X17: =IF($A2="","",SUMIF('07_Pallet_Contents'!$A$2:$A$3000,$A2,'07_Pallet_Contents'!$D$2:$D$3000)) -> 0 | Y17: =IF($A2="","",SUMIF('07_Pallet_Contents'!$A$2:$A$3000,$A2,'07_Pallet_Contents'!$I$2:$I$3000)) -> 0 | Z17: =IF($A2="","",IF(COUNTIF('07_Pallet_Contents'!$A$2:$A$3000,$A2)>0,"Yes",""))
A18: PAL-0000017 | C18: WH-Z1-AisleA-Bay1-Level14 | D18: =IF($C18="","",IFERROR(LOOKUP(2,1/('03_Warehouse_Movements'!$C$2:$C$500=$A18),'03_Warehouse_Movements'!$E$2:$E$500),$C18)) -> WH-Z1-AisleA-Bay1-Level14 | E18: ACTIVE | F18: SAFE | H18: =IF(AND($F18="TEMP",$G18>0,$M18<>""),$M18+$G18,"") | I18: SAMPLE: Spare Parts | J18: SAMPLE: replace with real notes / serials / constraints | K18: 46052 | L18: SAMPLE-TECH | M18: =IF($C18="","",IFERROR(LOOKUP(2,1/('03_Warehouse_Movements'!$C$2:$C$500=$A18),'03_Warehouse_Movements'!$A$2:$A$500),"")) | N18: =IF($C18="","",IFERROR(LOOKUP(2,1/('03_Warehouse_Movements'!$C$2:$C$500=$A18),'03_Warehouse_Movements'!$H$2:$H$500),"")) | O18: =A18 -> PAL-0000017 | W18: =IF($A2="","",COUNTIF('07_Pallet_Contents'!$A$2:$A$3000,$A2)) -> 0 | X18: =IF($A2="","",SUMIF('07_Pallet_Contents'!$A$2:$A$3000,$A2,'07_Pallet_Contents'!$D$2:$D$3000)) -> 0 | Y18: =IF($A2="","",SUMIF('07_Pallet_Contents'!$A$2:$A$3000,$A2,'07_Pallet_Contents'!$I$2:$I$3000)) -> 0 | Z18: =IF($A2="","",IF(COUNTIF('07_Pallet_Contents'!$A$2:$A$3000,$A2)>0,"Yes",""))
A19: PAL-0000018 | C19: WH-Z1-AisleA-Bay1-Level15 | D19: =IF($C19="","",IFERROR(LOOKUP(2,1/('03_Warehouse_Movements'!$C$2:$C$500=$A19),'03_Warehouse_Movements'!$E$2:$E$500),$C19)) -> WH-Z1-AisleA-Bay1-Level15 | E19: ACTIVE | F19: SAFE | H19: =IF(AND($F19="TEMP",$G19>0,$M19<>""),$M19+$G19,"") | I19: SAMPLE: Power Supplies | J19: SAMPLE: replace with real notes / serials / constraints | K19: 46052 | L19: SAMPLE-TECH | M19: =IF($C19="","",IFERROR(LOOKUP(2,1/('03_Warehouse_Movements'!$C$2:$C$500=$A19),'03_Warehouse_Movements'!$A$2:$A$500),"")) | N19: =IF($C19="","",IFERROR(LOOKUP(2,1/('03_Warehouse_Movements'!$C$2:$C$500=$A19),'03_Warehouse_Movements'!$H$2:$H$500),"")) | O19: =A19 -> PAL-0000018 | W19: =IF($A2="","",COUNTIF('07_Pallet_Contents'!$A$2:$A$3000,$A2)) -> 0 | X19: =IF($A2="","",SUMIF('07_Pallet_Contents'!$A$2:$A$3000,$A2,'07_Pallet_Contents'!$D$2:$D$3000)) -> 0 | Y19: =IF($A2="","",SUMIF('07_Pallet_Contents'!$A$2:$A$3000,$A2,'07_Pallet_Contents'!$I$2:$I$3000)) -> 0 | Z19: =IF($A2="","",IF(COUNTIF('07_Pallet_Contents'!$A$2:$A$3000,$A2)>0,"Yes",""))
A20: PAL-0000019 | C20: WH-Z1-AisleA-Bay1-Level16 | D20: =IF($C20="","",IFERROR(LOOKUP(2,1/('03_Warehouse_Movements'!$C$2:$C$500=$A20),'03_Warehouse_Movements'!$E$2:$E$500),$C20)) -> WH-Z1-AisleA-Bay1-Level16 | E20: ACTIVE | F20: TEMP | G20: 14 | H20: =IF(AND($F20="TEMP",$G20>0,$M20<>""),$M20+$G20,"") | I20: SAMPLE: Imaging Equipment | J20: SAMPLE: replace with real notes / serials / constraints | K20: 46052 | L20: SAMPLE-TECH | M20: =IF($C20="","",IFERROR(LOOKUP(2,1/('03_Warehouse_Movements'!$C$2:$C$500=$A20),'03_Warehouse_Movements'!$A$2:$A$500),"")) | N20: =IF($C20="","",IFERROR(LOOKUP(2,1/('03_Warehouse_Movements'!$C$2:$C$500=$A20),'03_Warehouse_Movements'!$H$2:$H$500),"")) | O20: =A20 -> PAL-0000019 | W20: =IF($A2="","",COUNTIF('07_Pallet_Contents'!$A$2:$A$3000,$A2)) -> 0 | X20: =IF($A2="","",SUMIF('07_Pallet_Contents'!$A$2:$A$3000,$A2,'07_Pallet_Contents'!$D$2:$D$3000)) -> 0 | Y20: =IF($A2="","",SUMIF('07_Pallet_Contents'!$A$2:$A$3000,$A2,'07_Pallet_Contents'!$I$2:$I$3000)) -> 0 | Z20: =IF($A2="","",IF(COUNTIF('07_Pallet_Contents'!$A$2:$A$3000,$A2)>0,"Yes",""))
A21: PAL-0000020 | C21: WH-Z1-AisleA-Bay1-Level17 | D21: =IF($C21="","",IFERROR(LOOKUP(2,1/('03_Warehouse_Movements'!$C$2:$C$500=$A21),'03_Warehouse_Movements'!$E$2:$E$500),$C21)) -> WH-Z1-AisleA-Bay1-Level17 | E21: ACTIVE | F21: SAFE | H21: =IF(AND($F21="TEMP",$G21>0,$M21<>""),$M21+$G21,"") | I21: SAMPLE: Misc Hardware | J21: SAMPLE: replace with real notes / serials / constraints | K21: 46052 | L21: SAMPLE-TECH | M21: =IF($C21="","",IFERROR(LOOKUP(2,1/('03_Warehouse_Movements'!$C$2:$C$500=$A21),'03_Warehouse_Movements'!$A$2:$A$500),"")) | N21: =IF($C21="","",IFERROR(LOOKUP(2,1/('03_Warehouse_Movements'!$C$2:$C$500=$A21),'03_Warehouse_Movements'!$H$2:$H$500),"")) | O21: =A21 -> PAL-0000020 | W21: =IF($A2="","",COUNTIF('07_Pallet_Contents'!$A$2:$A$3000,$A2)) -> 0 | X21: =IF($A2="","",SUMIF('07_Pallet_Contents'!$A$2:$A$3000,$A2,'07_Pallet_Contents'!$D$2:$D$3000)) -> 0 | Y21: =IF($A2="","",SUMIF('07_Pallet_Contents'!$A$2:$A$3000,$A2,'07_Pallet_Contents'!$I$2:$I$3000)) -> 0 | Z21: =IF($A2="","",IF(COUNTIF('07_Pallet_Contents'!$A$2:$A$3000,$A2)>0,"Yes",""))
A22: PAL-0000021 | C22: WH-Z1-AisleA-Bay1-Level18 | D22: =IF($C22="","",IFERROR(LOOKUP(2,1/('03_Warehouse_Movements'!$C$2:$C$500=$A22),'03_Warehouse_Movements'!$E$2:$E$500),$C22)) -> WH-Z1-AisleA-Bay1-Level18 | E22: ACTIVE | F22: SAFE | H22: =IF(AND($F22="TEMP",$G22>0,$M22<>""),$M22+$G22,"") | I22: SAMPLE: Dell Devices | J22: SAMPLE: replace with real notes / serials / constraints | K22: 46052 | L22: SAMPLE-TECH | M22: =IF($C22="","",IFERROR(LOOKUP(2,1/('03_Warehouse_Movements'!$C$2:$C$500=$A22),'03_Warehouse_Movements'!$A$2:$A$500),"")) | N22: =IF($C22="","",IFERROR(LOOKUP(2,1/('03_Warehouse_Movements'!$C$2:$C$500=$A22),'03_Warehouse_Movements'!$H$2:$H$500),"")) | O22: =A22 -> PAL-0000021 | W22: =IF($A2="","",COUNTIF('07_Pallet_Contents'!$A$2:$A$3000,$A2)) -> 0 | X22: =IF($A2="","",SUMIF('07_Pallet_Contents'!$A$2:$A$3000,$A2,'07_Pallet_Contents'!$D$2:$D$3000)) -> 0 | Y22: =IF($A2="","",SUMIF('07_Pallet_Contents'!$A$2:$A$3000,$A2,'07_Pallet_Contents'!$I$2:$I$3000)) -> 0 | Z22: =IF($A2="","",IF(COUNTIF('07_Pallet_Contents'!$A$2:$A$3000,$A2)>0,"Yes",""))
A23: PAL-0000022 | B23: OVERFLOW-SAMPLE-PO1021-CAT2-PAL022 | C23: WH-Z1-AisleA-Bay1-Level19 | D23: =IF($C23="","",IFERROR(LOOKUP(2,1/('03_Warehouse_Movements'!$C$2:$C$500=$A23),'03_Warehouse_Movements'!$E$2:$E$500),$C23)) -> WH-Z1-AisleA-Bay1-Level19 | E23: ACTIVE | F23: SAFE | H23: =IF(AND($F23="TEMP",$G23>0,$M23<>""),$M23+$G23,"") | I23: SAMPLE: Monitors 24-40 | J23: SAMPLE: replace with real notes / serials / constraints | K23: 46052 | L23: SAMPLE-TECH | M23: =IF($C23="","",IFERROR(LOOKUP(2,1/('03_Warehouse_Movements'!$C$2:$C$500=$A23),'03_Warehouse_Movements'!$A$2:$A$500),"")) | N23: =IF($C23="","",IFERROR(LOOKUP(2,1/('03_Warehouse_Movements'!$C$2:$C$500=$A23),'03_Warehouse_Movements'!$H$2:$H$500),"")) | O23: =A23 -> PAL-0000022 | W23: =IF($A2="","",COUNTIF('07_Pallet_Contents'!$A$2:$A$3000,$A2)) -> 0 | X23: =IF($A2="","",SUMIF('07_Pallet_Contents'!$A$2:$A$3000,$A2,'07_Pallet_Contents'!$D$2:$D$3000)) -> 0 | Y23: =IF($A2="","",SUMIF('07_Pallet_Contents'!$A$2:$A$3000,$A2,'07_Pallet_Contents'!$I$2:$I$3000)) -> 0 | Z23: =IF($A2="","",IF(COUNTIF('07_Pallet_Contents'!$A$2:$A$3000,$A2)>0,"Yes",""))
A24: PAL-0000023 | C24: WH-Z1-AisleA-Bay1-Level20 | D24: =IF($C24="","",IFERROR(LOOKUP(2,1/('03_Warehouse_Movements'!$C$2:$C$500=$A24),'03_Warehouse_Movements'!$E$2:$E$500),$C24)) -> WH-Z1-AisleA-Bay1-Level20 | E24: ACTIVE | F24: SAFE | H24: =IF(AND($F24="TEMP",$G24>0,$M24<>""),$M24+$G24,"") | I24: SAMPLE: Cables & Adapters | J24: SAMPLE: replace with real notes / serials / constraints | K24: 46052 | L24: SAMPLE-TECH | M24: =IF($C24="","",IFERROR(LOOKUP(2,1/('03_Warehouse_Movements'!$C$2:$C$500=$A24),'03_Warehouse_Movements'!$A$2:$A$500),"")) | N24: =IF($C24="","",IFERROR(LOOKUP(2,1/('03_Warehouse_Movements'!$C$2:$C$500=$A24),'03_Warehouse_Movements'!$H$2:$H$500),"")) | O24: =A24 -> PAL-0000023 | W24: =IF($A2="","",COUNTIF('07_Pallet_Contents'!$A$2:$A$3000,$A2)) -> 0 | X24: =IF($A2="","",SUMIF('07_Pallet_Contents'!$A$2:$A$3000,$A2,'07_Pallet_Contents'!$D$2:$D$3000)) -> 0 | Y24: =IF($A2="","",SUMIF('07_Pallet_Contents'!$A$2:$A$3000,$A2,'07_Pallet_Contents'!$I$2:$I$3000)) -> 0 | Z24: =IF($A2="","",IF(COUNTIF('07_Pallet_Contents'!$A$2:$A$3000,$A2)>0,"Yes",""))
A25: PAL-0000024 | C25: WH-Z1-AisleB-Bay1-Level1 | D25: =IF($C25="","",IFERROR(LOOKUP(2,1/('03_Warehouse_Movements'!$C$2:$C$500=$A25),'03_Warehouse_Movements'!$E$2:$E$500),$C25)) -> WH-Z1-AisleB-Bay1-Level1 | E25: ACTIVE | F25: SAFE | H25: =IF(AND($F25="TEMP",$G25>0,$M25<>""),$M25+$G25,"") | I25: SAMPLE: Racks & Rails | J25: SAMPLE: replace with real notes / serials / constraints | K25: 46052 | L25: SAMPLE-TECH | M25: =IF($C25="","",IFERROR(LOOKUP(2,1/('03_Warehouse_Movements'!$C$2:$C$500=$A25),'03_Warehouse_Movements'!$A$2:$A$500),"")) | N25: =IF($C25="","",IFERROR(LOOKUP(2,1/('03_Warehouse_Movements'!$C$2:$C$500=$A25),'03_Warehouse_Movements'!$H$2:$H$500),"")) | O25: =A25 -> PAL-0000024 | W25: =IF($A2="","",COUNTIF('07_Pallet_Contents'!$A$2:$A$3000,$A2)) -> 0 | X25: =IF($A2="","",SUMIF('07_Pallet_Contents'!$A$2:$A$3000,$A2,'07_Pallet_Contents'!$D$2:$D$3000)) -> 0 | Y25: =IF($A2="","",SUMIF('07_Pallet_Contents'!$A$2:$A$3000,$A2,'07_Pallet_Contents'!$I$2:$I$3000)) -> 0 | Z25: =IF($A2="","",IF(COUNTIF('07_Pallet_Contents'!$A$2:$A$3000,$A2)>0,"Yes",""))
A26: PAL-0000025 | C26: WH-Z1-AisleB-Bay1-Level2 | D26: =IF($C26="","",IFERROR(LOOKUP(2,1/('03_Warehouse_Movements'!$C$2:$C$500=$A26),'03_Warehouse_Movements'!$E$2:$E$500),$C26)) -> WH-Z1-AisleB-Bay1-Level2 | E26: ACTIVE | F26: TEMP | G26: 14 | H26: =IF(AND($F26="TEMP",$G26>0,$M26<>""),$M26+$G26,"") | I26: SAMPLE: Networking Gear | J26: SAMPLE: replace with real notes / serials / constraints | K26: 46052 | L26: SAMPLE-TECH | M26: =IF($C26="","",IFERROR(LOOKUP(2,1/('03_Warehouse_Movements'!$C$2:$C$500=$A26),'03_Warehouse_Movements'!$A$2:$A$500),"")) | N26: =IF($C26="","",IFERROR(LOOKUP(2,1/('03_Warehouse_Movements'!$C$2:$C$500=$A26),'03_Warehouse_Movements'!$H$2:$H$500),"")) | O26: =A26 -> PAL-0000025 | W26: =IF($A2="","",COUNTIF('07_Pallet_Contents'!$A$2:$A$3000,$A2)) -> 0 | X26: =IF($A2="","",SUMIF('07_Pallet_Contents'!$A$2:$A$3000,$A2,'07_Pallet_Contents'!$D$2:$D$3000)) -> 0 | Y26: =IF($A2="","",SUMIF('07_Pallet_Contents'!$A$2:$A$3000,$A2,'07_Pallet_Contents'!$I$2:$I$3000)) -> 0 | Z26: =IF($A2="","",IF(COUNTIF('07_Pallet_Contents'!$A$2:$A$3000,$A2)>0,"Yes",""))
A27: PAL-0000026 | C27: WH-Z1-AisleB-Bay1-Level3 | D27: =IF($C27="","",IFERROR(LOOKUP(2,1/('03_Warehouse_Movements'!$C$2:$C$500=$A27),'03_Warehouse_Movements'!$E$2:$E$500),$C27)) -> WH-Z1-AisleB-Bay1-Level3 | E27: ACTIVE | F27: SAFE | H27: =IF(AND($F27="TEMP",$G27>0,$M27<>""),$M27+$G27,"") | I27: SAMPLE: Keyboards & Mice | J27: SAMPLE: replace with real notes / serials / constraints | K27: 46052 | L27: SAMPLE-TECH | M27: =IF($C27="","",IFERROR(LOOKUP(2,1/('03_Warehouse_Movements'!$C$2:$C$500=$A27),'03_Warehouse_Movements'!$A$2:$A$500),"")) | N27: =IF($C27="","",IFERROR(LOOKUP(2,1/('03_Warehouse_Movements'!$C$2:$C$500=$A27),'03_Warehouse_Movements'!$H$2:$H$500),"")) | O27: =A27 -> PAL-0000026 | W27: =IF($A2="","",COUNTIF('07_Pallet_Contents'!$A$2:$A$3000,$A2)) -> 0 | X27: =IF($A2="","",SUMIF('07_Pallet_Contents'!$A$2:$A$3000,$A2,'07_Pallet_Contents'!$D$2:$D$3000)) -> 0 | Y27: =IF($A2="","",SUMIF('07_Pallet_Contents'!$A$2:$A$3000,$A2,'07_Pallet_Contents'!$I$2:$I$3000)) -> 0 | Z27: =IF($A2="","",IF(COUNTIF('07_Pallet_Contents'!$A$2:$A$3000,$A2)>0,"Yes",""))
A28: PAL-0000027 | C28: WH-Z1-AisleB-Bay1-Level4 | D28: =IF($C28="","",IFERROR(LOOKUP(2,1/('03_Warehouse_Movements'!$C$2:$C$500=$A28),'03_Warehouse_Movements'!$E$2:$E$500),$C28)) -> WH-Z1-AisleB-Bay1-Level4 | E28: ACTIVE | F28: SAFE | H28: =IF(AND($F28="TEMP",$G28>0,$M28<>""),$M28+$G28,"") | I28: SAMPLE: Spare Parts | J28: SAMPLE: replace with real notes / serials / constraints | K28: 46052 | L28: SAMPLE-TECH | M28: =IF($C28="","",IFERROR(LOOKUP(2,1/('03_Warehouse_Movements'!$C$2:$C$500=$A28),'03_Warehouse_Movements'!$A$2:$A$500),"")) | N28: =IF($C28="","",IFERROR(LOOKUP(2,1/('03_Warehouse_Movements'!$C$2:$C$500=$A28),'03_Warehouse_Movements'!$H$2:$H$500),"")) | O28: =A28 -> PAL-0000027 | W28: =IF($A2="","",COUNTIF('07_Pallet_Contents'!$A$2:$A$3000,$A2)) -> 0 | X28: =IF($A2="","",SUMIF('07_Pallet_Contents'!$A$2:$A$3000,$A2,'07_Pallet_Contents'!$D$2:$D$3000)) -> 0 | Y28: =IF($A2="","",SUMIF('07_Pallet_Contents'!$A$2:$A$3000,$A2,'07_Pallet_Contents'!$I$2:$I$3000)) -> 0 | Z28: =IF($A2="","",IF(COUNTIF('07_Pallet_Contents'!$A$2:$A$3000,$A2)>0,"Yes",""))
A29: PAL-0000028 | C29: WH-Z1-AisleB-Bay1-Level5 | D29: =IF($C29="","",IFERROR(LOOKUP(2,1/('03_Warehouse_Movements'!$C$2:$C$500=$A29),'03_Warehouse_Movements'!$E$2:$E$500),$C29)) -> WH-Z1-AisleB-Bay1-Level5 | E29: ACTIVE | F29: SAFE | H29: =IF(AND($F29="TEMP",$G29>0,$M29<>""),$M29+$G29,"") | I29: SAMPLE: Power Supplies | J29: SAMPLE: replace with real notes / serials / constraints | K29: 46052 | L29: SAMPLE-TECH | M29: =IF($C29="","",IFERROR(LOOKUP(2,1/('03_Warehouse_Movements'!$C$2:$C$500=$A29),'03_Warehouse_Movements'!$A$2:$A$500),"")) | N29: =IF($C29="","",IFERROR(LOOKUP(2,1/('03_Warehouse_Movements'!$C$2:$C$500=$A29),'03_Warehouse_Movements'!$H$2:$H$500),"")) | O29: =A29 -> PAL-0000028 | W29: =IF($A2="","",COUNTIF('07_Pallet_Contents'!$A$2:$A$3000,$A2)) -> 0 | X29: =IF($A2="","",SUMIF('07_Pallet_Contents'!$A$2:$A$3000,$A2,'07_Pallet_Contents'!$D$2:$D$3000)) -> 0 | Y29: =IF($A2="","",SUMIF('07_Pallet_Contents'!$A$2:$A$3000,$A2,'07_Pallet_Contents'!$I$2:$I$3000)) -> 0 | Z29: =IF($A2="","",IF(COUNTIF('07_Pallet_Contents'!$A$2:$A$3000,$A2)>0,"Yes",""))
A30: PAL-0000029 | B30: OVERFLOW-SAMPLE-PO1028-CAT4-PAL029 | C30: WH-Z1-AisleB-Bay1-Level6 | D30: =IF($C30="","",IFERROR(LOOKUP(2,1/('03_Warehouse_Movements'!$C$2:$C$500=$A30),'03_Warehouse_Movements'!$E$2:$E$500),$C30)) -> WH-Z1-AisleB-Bay1-Level6 | E30: ACTIVE | F30: SAFE | H30: =IF(AND($F30="TEMP",$G30>0,$M30<>""),$M30+$G30,"") | I30: SAMPLE: Imaging Equipment | J30: SAMPLE: replace with real notes / serials / constraints | K30: 46052 | L30: SAMPLE-TECH | M30: =IF($C30="","",IFERROR(LOOKUP(2,1/('03_Warehouse_Movements'!$C$2:$C$500=$A30),'03_Warehouse_Movements'!$A$2:$A$500),"")) | N30: =IF($C30="","",IFERROR(LOOKUP(2,1/('03_Warehouse_Movements'!$C$2:$C$500=$A30),'03_Warehouse_Movements'!$H$2:$H$500),"")) | O30: =A30 -> PAL-0000029 | W30: =IF($A2="","",COUNTIF('07_Pallet_Contents'!$A$2:$A$3000,$A2)) -> 0 | X30: =IF($A2="","",SUMIF('07_Pallet_Contents'!$A$2:$A$3000,$A2,'07_Pallet_Contents'!$D$2:$D$3000)) -> 0 | Y30: =IF($A2="","",SUMIF('07_Pallet_Contents'!$A$2:$A$3000,$A2,'07_Pallet_Contents'!$I$2:$I$3000)) -> 0 | Z30: =IF($A2="","",IF(COUNTIF('07_Pallet_Contents'!$A$2:$A$3000,$A2)>0,"Yes",""))
A31: PAL-0000030 | C31: WH-Z1-AisleB-Bay1-Level7 | D31: =IF($C31="","",IFERROR(LOOKUP(2,1/('03_Warehouse_Movements'!$C$2:$C$500=$A31),'03_Warehouse_Movements'!$E$2:$E$500),$C31)) -> WH-Z1-AisleB-Bay1-Level7 | E31: ACTIVE | F31: SAFE | H31: =IF(AND($F31="TEMP",$G31>0,$M31<>""),$M31+$G31,"") | I31: SAMPLE: Misc Hardware | J31: SAMPLE: replace with real notes / serials / constraints | K31: 46052 | L31: SAMPLE-TECH | M31: =IF($C31="","",IFERROR(LOOKUP(2,1/('03_Warehouse_Movements'!$C$2:$C$500=$A31),'03_Warehouse_Movements'!$A$2:$A$500),"")) | N31: =IF($C31="","",IFERROR(LOOKUP(2,1/('03_Warehouse_Movements'!$C$2:$C$500=$A31),'03_Warehouse_Movements'!$H$2:$H$500),"")) | O31: =A31 -> PAL-0000030 | W31: =IF($A2="","",COUNTIF('07_Pallet_Contents'!$A$2:$A$3000,$A2)) -> 0 | X31: =IF($A2="","",SUMIF('07_Pallet_Contents'!$A$2:$A$3000,$A2,'07_Pallet_Contents'!$D$2:$D$3000)) -> 0 | Y31: =IF($A2="","",SUMIF('07_Pallet_Contents'!$A$2:$A$3000,$A2,'07_Pallet_Contents'!$I$2:$I$3000)) -> 0 | Z31: =IF($A2="","",IF(COUNTIF('07_Pallet_Contents'!$A$2:$A$3000,$A2)>0,"Yes",""))
A32: PAL-0000031 | C32: WH-Z1-AisleB-Bay1-Level8 | D32: =IF($C32="","",IFERROR(LOOKUP(2,1/('03_Warehouse_Movements'!$C$2:$C$500=$A32),'03_Warehouse_Movements'!$E$2:$E$500),$C32)) -> WH-Z1-AisleB-Bay1-Level8 | E32: ACTIVE | F32: TEMP | G32: 14 | H32: =IF(AND($F32="TEMP",$G32>0,$M32<>""),$M32+$G32,"") | I32: SAMPLE: Dell Devices | J32: SAMPLE: replace with real notes / serials / constraints | K32: 46052 | L32: SAMPLE-TECH | M32: =IF($C32="","",IFERROR(LOOKUP(2,1/('03_Warehouse_Movements'!$C$2:$C$500=$A32),'03_Warehouse_Movements'!$A$2:$A$500),"")) | N32: =IF($C32="","",IFERROR(LOOKUP(2,1/('03_Warehouse_Movements'!$C$2:$C$500=$A32),'03_Warehouse_Movements'!$H$2:$H$500),"")) | O32: =A32 -> PAL-0000031 | W32: =IF($A2="","",COUNTIF('07_Pallet_Contents'!$A$2:$A$3000,$A2)) -> 0 | X32: =IF($A2="","",SUMIF('07_Pallet_Contents'!$A$2:$A$3000,$A2,'07_Pallet_Contents'!$D$2:$D$3000)) -> 0 | Y32: =IF($A2="","",SUMIF('07_Pallet_Contents'!$A$2:$A$3000,$A2,'07_Pallet_Contents'!$I$2:$I$3000)) -> 0 | Z32: =IF($A2="","",IF(COUNTIF('07_Pallet_Contents'!$A$2:$A$3000,$A2)>0,"Yes",""))
A33: PAL-0000032 | C33: WH-Z1-AisleB-Bay1-Level9 | D33: =IF($C33="","",IFERROR(LOOKUP(2,1/('03_Warehouse_Movements'!$C$2:$C$500=$A33),'03_Warehouse_Movements'!$E$2:$E$500),$C33)) -> WH-Z1-AisleB-Bay1-Level9 | E33: ACTIVE | F33: SAFE | H33: =IF(AND($F33="TEMP",$G33>0,$M33<>""),$M33+$G33,"") | I33: SAMPLE: Monitors 24-40 | J33: SAMPLE: replace with real notes / serials / constraints | K33: 46052 | L33: SAMPLE-TECH | M33: =IF($C33="","",IFERROR(LOOKUP(2,1/('03_Warehouse_Movements'!$C$2:$C$500=$A33),'03_Warehouse_Movements'!$A$2:$A$500),"")) | N33: =IF($C33="","",IFERROR(LOOKUP(2,1/('03_Warehouse_Movements'!$C$2:$C$500=$A33),'03_Warehouse_Movements'!$H$2:$H$500),"")) | O33: =A33 -> PAL-0000032 | W33: =IF($A2="","",COUNTIF('07_Pallet_Contents'!$A$2:$A$3000,$A2)) -> 0 | X33: =IF($A2="","",SUMIF('07_Pallet_Contents'!$A$2:$A$3000,$A2,'07_Pallet_Contents'!$D$2:$D$3000)) -> 0 | Y33: =IF($A2="","",SUMIF('07_Pallet_Contents'!$A$2:$A$3000,$A2,'07_Pallet_Contents'!$I$2:$I$3000)) -> 0 | Z33: =IF($A2="","",IF(COUNTIF('07_Pallet_Contents'!$A$2:$A$3000,$A2)>0,"Yes",""))
A34: PAL-0000033 | C34: WH-Z1-AisleB-Bay1-Level10 | D34: =IF($C34="","",IFERROR(LOOKUP(2,1/('03_Warehouse_Movements'!$C$2:$C$500=$A34),'03_Warehouse_Movements'!$E$2:$E$500),$C34)) -> WH-Z1-AisleB-Bay1-Level10 | E34: ACTIVE | F34: SAFE | H34: =IF(AND($F34="TEMP",$G34>0,$M34<>""),$M34+$G34,"") | I34: SAMPLE: Cables & Adapters | J34: SAMPLE: replace with real notes / serials / constraints | K34: 46052 | L34: SAMPLE-TECH | M34: =IF($C34="","",IFERROR(LOOKUP(2,1/('03_Warehouse_Movements'!$C$2:$C$500=$A34),'03_Warehouse_Movements'!$A$2:$A$500),"")) | N34: =IF($C34="","",IFERROR(LOOKUP(2,1/('03_Warehouse_Movements'!$C$2:$C$500=$A34),'03_Warehouse_Movements'!$H$2:$H$500),"")) | O34: =A34 -> PAL-0000033 | W34: =IF($A2="","",COUNTIF('07_Pallet_Contents'!$A$2:$A$3000,$A2)) -> 0 | X34: =IF($A2="","",SUMIF('07_Pallet_Contents'!$A$2:$A$3000,$A2,'07_Pallet_Contents'!$D$2:$D$3000)) -> 0 | Y34: =IF($A2="","",SUMIF('07_Pallet_Contents'!$A$2:$A$3000,$A2,'07_Pallet_Contents'!$I$2:$I$3000)) -> 0 | Z34: =IF($A2="","",IF(COUNTIF('07_Pallet_Contents'!$A$2:$A$3000,$A2)>0,"Yes",""))
A35: PAL-0000034 | C35: WH-Z1-AisleB-Bay1-Level11 | D35: =IF($C35="","",IFERROR(LOOKUP(2,1/('03_Warehouse_Movements'!$C$2:$C$500=$A35),'03_Warehouse_Movements'!$E$2:$E$500),$C35)) -> WH-Z1-AisleB-Bay1-Level11 | E35: ACTIVE | F35: SAFE | H35: =IF(AND($F35="TEMP",$G35>0,$M35<>""),$M35+$G35,"") | I35: SAMPLE: Racks & Rails | J35: SAMPLE: replace with real notes / serials / constraints | K35: 46052 | L35: SAMPLE-TECH | M35: =IF($C35="","",IFERROR(LOOKUP(2,1/('03_Warehouse_Movements'!$C$2:$C$500=$A35),'03_Warehouse_Movements'!$A$2:$A$500),"")) | N35: =IF($C35="","",IFERROR(LOOKUP(2,1/('03_Warehouse_Movements'!$C$2:$C$500=$A35),'03_Warehouse_Movements'!$H$2:$H$500),"")) | O35: =A35 -> PAL-0000034 | W35: =IF($A2="","",COUNTIF('07_Pallet_Contents'!$A$2:$A$3000,$A2)) -> 0 | X35: =IF($A2="","",SUMIF('07_Pallet_Contents'!$A$2:$A$3000,$A2,'07_Pallet_Contents'!$D$2:$D$3000)) -> 0 | Y35: =IF($A2="","",SUMIF('07_Pallet_Contents'!$A$2:$A$3000,$A2,'07_Pallet_Contents'!$I$2:$I$3000)) -> 0 | Z35: =IF($A2="","",IF(COUNTIF('07_Pallet_Contents'!$A$2:$A$3000,$A2)>0,"Yes",""))
A36: PAL-0000035 | C36: WH-Z1-AisleB-Bay1-Level12 | D36: =IF($C36="","",IFERROR(LOOKUP(2,1/('03_Warehouse_Movements'!$C$2:$C$500=$A36),'03_Warehouse_Movements'!$E$2:$E$500),$C36)) -> WH-Z1-AisleB-Bay1-Level12 | E36: ACTIVE | F36: SAFE | H36: =IF(AND($F36="TEMP",$G36>0,$M36<>""),$M36+$G36,"") | I36: SAMPLE: Networking Gear | J36: SAMPLE: replace with real notes / serials / constraints | K36: 46052 | L36: SAMPLE-TECH | M36: =IF($C36="","",IFERROR(LOOKUP(2,1/('03_Warehouse_Movements'!$C$2:$C$500=$A36),'03_Warehouse_Movements'!$A$2:$A$500),"")) | N36: =IF($C36="","",IFERROR(LOOKUP(2,1/('03_Warehouse_Movements'!$C$2:$C$500=$A36),'03_Warehouse_Movements'!$H$2:$H$500),"")) | O36: =A36 -> PAL-0000035 | W36: =IF($A2="","",COUNTIF('07_Pallet_Contents'!$A$2:$A$3000,$A2)) -> 0 | X36: =IF($A2="","",SUMIF('07_Pallet_Contents'!$A$2:$A$3000,$A2,'07_Pallet_Contents'!$D$2:$D$3000)) -> 0 | Y36: =IF($A2="","",SUMIF('07_Pallet_Contents'!$A$2:$A$3000,$A2,'07_Pallet_Contents'!$I$2:$I$3000)) -> 0 | Z36: =IF($A2="","",IF(COUNTIF('07_Pallet_Contents'!$A$2:$A$3000,$A2)>0,"Yes",""))
A37: PAL-0000036 | B37: OVERFLOW-SAMPLE-PO1035-CAT1-PAL036 | C37: WH-Z1-AisleB-Bay1-Level13 | D37: =IF($C37="","",IFERROR(LOOKUP(2,1/('03_Warehouse_Movements'!$C$2:$C$500=$A37),'03_Warehouse_Movements'!$E$2:$E$500),$C37)) -> WH-Z1-AisleB-Bay1-Level13 | E37: ACTIVE | F37: SAFE | H37: =IF(AND($F37="TEMP",$G37>0,$M37<>""),$M37+$G37,"") | I37: SAMPLE: Keyboards & Mice | J37: SAMPLE: replace with real notes / serials / constraints | K37: 46052 | L37: SAMPLE-TECH | M37: =IF($C37="","",IFERROR(LOOKUP(2,1/('03_Warehouse_Movements'!$C$2:$C$500=$A37),'03_Warehouse_Movements'!$A$2:$A$500),"")) | N37: =IF($C37="","",IFERROR(LOOKUP(2,1/('03_Warehouse_Movements'!$C$2:$C$500=$A37),'03_Warehouse_Movements'!$H$2:$H$500),"")) | O37: =A37 -> PAL-0000036 | W37: =IF($A2="","",COUNTIF('07_Pallet_Contents'!$A$2:$A$3000,$A2)) -> 0 | X37: =IF($A2="","",SUMIF('07_Pallet_Contents'!$A$2:$A$3000,$A2,'07_Pallet_Contents'!$D$2:$D$3000)) -> 0 | Y37: =IF($A2="","",SUMIF('07_Pallet_Contents'!$A$2:$A$3000,$A2,'07_Pallet_Contents'!$I$2:$I$3000)) -> 0 | Z37: =IF($A2="","",IF(COUNTIF('07_Pallet_Contents'!$A$2:$A$3000,$A2)>0,"Yes",""))
A38: PAL-0000037 | C38: WH-Z1-AisleB-Bay1-Level14 | D38: =IF($C38="","",IFERROR(LOOKUP(2,1/('03_Warehouse_Movements'!$C$2:$C$500=$A38),'03_Warehouse_Movements'!$E$2:$E$500),$C38)) -> WH-Z1-AisleB-Bay1-Level14 | E38: ACTIVE | F38: TEMP | G38: 14 | H38: =IF(AND($F38="TEMP",$G38>0,$M38<>""),$M38+$G38,"") | I38: SAMPLE: Spare Parts | J38: SAMPLE: replace with real notes / serials / constraints | K38: 46052 | L38: SAMPLE-TECH | M38: =IF($C38="","",IFERROR(LOOKUP(2,1/('03_Warehouse_Movements'!$C$2:$C$500=$A38),'03_Warehouse_Movements'!$A$2:$A$500),"")) | N38: =IF($C38="","",IFERROR(LOOKUP(2,1/('03_Warehouse_Movements'!$C$2:$C$500=$A38),'03_Warehouse_Movements'!$H$2:$H$500),"")) | O38: =A38 -> PAL-0000037 | W38: =IF($A2="","",COUNTIF('07_Pallet_Contents'!$A$2:$A$3000,$A2)) -> 0 | X38: =IF($A2="","",SUMIF('07_Pallet_Contents'!$A$2:$A$3000,$A2,'07_Pallet_Contents'!$D$2:$D$3000)) -> 0 | Y38: =IF($A2="","",SUMIF('07_Pallet_Contents'!$A$2:$A$3000,$A2,'07_Pallet_Contents'!$I$2:$I$3000)) -> 0 | Z38: =IF($A2="","",IF(COUNTIF('07_Pallet_Contents'!$A$2:$A$3000,$A2)>0,"Yes",""))
A39: PAL-0000038 | C39: WH-Z1-AisleB-Bay1-Level15 | D39: =IF($C39="","",IFERROR(LOOKUP(2,1/('03_Warehouse_Movements'!$C$2:$C$500=$A39),'03_Warehouse_Movements'!$E$2:$E$500),$C39)) -> WH-Z1-AisleB-Bay1-Level15 | E39: ACTIVE | F39: SAFE | H39: =IF(AND($F39="TEMP",$G39>0,$M39<>""),$M39+$G39,"") | I39: SAMPLE: Power Supplies | J39: SAMPLE: replace with real notes / serials / constraints | K39: 46052 | L39: SAMPLE-TECH | M39: =IF($C39="","",IFERROR(LOOKUP(2,1/('03_Warehouse_Movements'!$C$2:$C$500=$A39),'03_Warehouse_Movements'!$A$2:$A$500),"")) | N39: =IF($C39="","",IFERROR(LOOKUP(2,1/('03_Warehouse_Movements'!$C$2:$C$500=$A39),'03_Warehouse_Movements'!$H$2:$H$500),"")) | O39: =A39 -> PAL-0000038 | W39: =IF($A2="","",COUNTIF('07_Pallet_Contents'!$A$2:$A$3000,$A2)) -> 0 | X39: =IF($A2="","",SUMIF('07_Pallet_Contents'!$A$2:$A$3000,$A2,'07_Pallet_Contents'!$D$2:$D$3000)) -> 0 | Y39: =IF($A2="","",SUMIF('07_Pallet_Contents'!$A$2:$A$3000,$A2,'07_Pallet_Contents'!$I$2:$I$3000)) -> 0 | Z39: =IF($A2="","",IF(COUNTIF('07_Pallet_Contents'!$A$2:$A$3000,$A2)>0,"Yes",""))
A40: PAL-0000039 | C40: WH-Z1-AisleB-Bay1-Level16 | D40: =IF($C40="","",IFERROR(LOOKUP(2,1/('03_Warehouse_Movements'!$C$2:$C$500=$A40),'03_Warehouse_Movements'!$E$2:$E$500),$C40)) -> WH-Z1-AisleB-Bay1-Level16 | E40: ACTIVE | F40: SAFE | H40: =IF(AND($F40="TEMP",$G40>0,$M40<>""),$M40+$G40,"") | I40: SAMPLE: Imaging Equipment | J40: SAMPLE: replace with real notes / serials / constraints | K40: 46052 | L40: SAMPLE-TECH | M40: =IF($C40="","",IFERROR(LOOKUP(2,1/('03_Warehouse_Movements'!$C$2:$C$500=$A40),'03_Warehouse_Movements'!$A$2:$A$500),"")) | N40: =IF($C40="","",IFERROR(LOOKUP(2,1/('03_Warehouse_Movements'!$C$2:$C$500=$A40),'03_Warehouse_Movements'!$H$2:$H$500),"")) | O40: =A40 -> PAL-0000039 | W40: =IF($A2="","",COUNTIF('07_Pallet_Contents'!$A$2:$A$3000,$A2)) -> 0 | X40: =IF($A2="","",SUMIF('07_Pallet_Contents'!$A$2:$A$3000,$A2,'07_Pallet_Contents'!$D$2:$D$3000)) -> 0 | Y40: =IF($A2="","",SUMIF('07_Pallet_Contents'!$A$2:$A$3000,$A2,'07_Pallet_Contents'!$I$2:$I$3000)) -> 0 | Z40: =IF($A2="","",IF(COUNTIF('07_Pallet_Contents'!$A$2:$A$3000,$A2)>0,"Yes",""))
...

Sheet 02_Warehouse_Locations
A1: LocationCode | B1: Zone | C1: Aisle | D1: Position/Slot | E1: LocationType | F1: AccessRating(1-5) | G1: TTL_Days | H1: QR_Payload | I1: Notes | J1: DisplayLabel (AUTO) | K1: AisleNum (AUTO) | L1: SlotNum (AUTO) | M1: LevelNum (AUTO) | N1: PrismNode (AUTO) | O1: GridCol (AUTO) | P1: GridRow (AUTO) | Q1: GridNode (AUTO)
A2: WH-STAGE-IN | B2: WH | E2: STAGE_IN | F2: 1 | G2: 0 | H2: =A2 -> WH-STAGE-IN | I2: Inbound staging | J2: =IF($I2<>"",$I2,$A2) -> Inbound staging | K2: =IF($C2="","",IF(LEN($C2)=1,CODE(UPPER($C2))-64,IFERROR(VALUE(MID($C2,2,99)),""))) | L2: =IF($D2="","",IFERROR(VALUE($D2),"")) | M2: =IFERROR(VALUE(MID($A2,FIND("Level",$A2)+5,99)),IF($E2="AISLE_FLOOR",0,IF($E2="OVERFLOW",0,IF($E2="ENDCAP",0,"")))) | N2: =IF(AND($B2<>"",$C2<>"",ISNUMBER(--$D2)), $B2&": "&LEFT($C2,1)&TEXT(--$D2,"00"), IF($I2<>"",$I2,$A2)) -> Inbound staging | O2: =IF(AND($C2<>"",ISNUMBER(--$D2)),LEFT($C2,1),"") | P2: =IF(ISNUMBER(--$D2),--$D2,"") -> 0 | Q2: =IF(AND($O2<>"",$P2<>""),$O2&TEXT($P2,"00"),"")
A3: WH-STAGE-OUT | B3: WH | E3: STAGE_OUT | F3: 1 | G3: 0 | H3: =A3 -> WH-STAGE-OUT | I3: Outbound / ship staging | J3: =IF($I3<>"",$I3,$A3) -> Outbound / ship staging | K3: =IF($C3="","",IF(LEN($C3)=1,CODE(UPPER($C3))-64,IFERROR(VALUE(MID($C3,2,99)),""))) | L3: =IF($D3="","",IFERROR(VALUE($D3),"")) | M3: =IFERROR(VALUE(MID($A3,FIND("Level",$A3)+5,99)),IF($E3="AISLE_FLOOR",0,IF($E3="OVERFLOW",0,IF($E3="ENDCAP",0,"")))) | N3: =IF(AND($B3<>"",$C3<>"",ISNUMBER(--$D3)), $B3&": "&LEFT($C3,1)&TEXT(--$D3,"00"), IF($I3<>"",$I3,$A3)) -> Outbound / ship staging | O3: =IF(AND($C3<>"",ISNUMBER(--$D3)),LEFT($C3,1),"") | P3: =IF(ISNUMBER(--$D3),--$D3,"") -> 0 | Q3: =IF(AND($O3<>"",$P3<>""),$O3&TEXT($P3,"00"),"")
A4: WH-QUARANTINE | B4: WH | E4: QUARANTINE | F4: 2 | G4: 0 | H4: =A4 -> WH-QUARANTINE | I4: Damaged/unknown hold | J4: =IF($I4<>"",$I4,$A4) -> Damaged/unknown hold | K4: =IF($C4="","",IF(LEN($C4)=1,CODE(UPPER($C4))-64,IFERROR(VALUE(MID($C4,2,99)),""))) | L4: =IF($D4="","",IFERROR(VALUE($D4),"")) | M4: =IFERROR(VALUE(MID($A4,FIND("Level",$A4)+5,99)),IF($E4="AISLE_FLOOR",0,IF($E4="OVERFLOW",0,IF($E4="ENDCAP",0,"")))) | N4: =IF(AND($B4<>"",$C4<>"",ISNUMBER(--$D4)), $B4&": "&LEFT($C4,1)&TEXT(--$D4,"00"), IF($I4<>"",$I4,$A4)) -> Damaged/unknown hold | O4: =IF(AND($C4<>"",ISNUMBER(--$D4)),LEFT($C4,1),"") | P4: =IF(ISNUMBER(--$D4),--$D4,"") -> 0 | Q4: =IF(AND($O4<>"",$P4<>""),$O4&TEXT($P4,"00"),"")
A5: WH-Z1-A01-ENDCAP-L | B5: Z1 | C5: A01 | D5: L | E5: ENDCAP | F5: 1 | G5: 2 | H5: =A5 -> WH-Z1-A01-ENDCAP-L | I5: Endcap left | J5: =IF($I5<>"",$I5,$A5) -> Endcap left | K5: =IF($C5="","",IF(LEN($C5)=1,CODE(UPPER($C5))-64,IFERROR(VALUE(MID($C5,2,99)),""))) -> 1 | L5: =IF($D5="","",IFERROR(VALUE($D5),"")) | M5: =IFERROR(VALUE(MID($A5,FIND("Level",$A5)+5,99)),IF($E5="AISLE_FLOOR",0,IF($E5="OVERFLOW",0,IF($E5="ENDCAP",0,"")))) -> 0 | N5: =IF(AND($B5<>"",$C5<>"",ISNUMBER(--$D5)), $B5&": "&LEFT($C5,1)&TEXT(--$D5,"00"), IF($I5<>"",$I5,$A5)) -> Endcap left | O5: =IF(AND($C5<>"",ISNUMBER(--$D5)),LEFT($C5,1),"") | P5: =IF(ISNUMBER(--$D5),--$D5,"") | Q5: =IF(AND($O5<>"",$P5<>""),$O5&TEXT($P5,"00"),"")
A6: WH-Z1-AisleA-Bay1-Level1 | B6: Z1 | C6: A | D6: 1 | E6: AISLE_FLOOR | F6: 4 | G6: 2 | H6: =A6 -> WH-Z1-AisleA-Bay1-Level1 | I6: Between rows segment 01 | J6: =IF($I6<>"",$I6,$A6) -> Between rows segment 01 | K6: =IF($C6="","",IF(LEN($C6)=1,CODE(UPPER($C6))-64,IFERROR(VALUE(MID($C6,2,99)),""))) -> 1 | L6: =IF($D6="","",IFERROR(VALUE($D6),"")) -> 1 | M6: =IFERROR(VALUE(MID($A6,FIND("Level",$A6)+5,99)),IF($E6="AISLE_FLOOR",0,IF($E6="OVERFLOW",0,IF($E6="ENDCAP",0,"")))) -> 1 | N6: =IF(AND($B6<>"",$C6<>"",ISNUMBER(--$D6)), $B6&": "&LEFT($C6,1)&TEXT(--$D6,"00"), IF($I6<>"",$I6,$A6)) -> Z1: A01 | O6: =IF(AND($C6<>"",ISNUMBER(--$D6)),LEFT($C6,1),"") -> A | P6: =IF(ISNUMBER(--$D6),--$D6,"") -> 1 | Q6: =IF(AND($O6<>"",$P6<>""),$O6&TEXT($P6,"00"),"") -> A01
A7: WH-Z1-AisleA-Bay1-Level2 | B7: Z1 | C7: A | D7: 1 | E7: AISLE_FLOOR | F7: 4 | G7: 2 | H7: =A7 -> WH-Z1-AisleA-Bay1-Level2 | I7: Between rows segment 02 | J7: =IF($I7<>"",$I7,$A7) -> Between rows segment 02 | K7: =IF($C7="","",IF(LEN($C7)=1,CODE(UPPER($C7))-64,IFERROR(VALUE(MID($C7,2,99)),""))) -> 1 | L7: =IF($D7="","",IFERROR(VALUE($D7),"")) -> 1 | M7: =IFERROR(VALUE(MID($A7,FIND("Level",$A7)+5,99)),IF($E7="AISLE_FLOOR",0,IF($E7="OVERFLOW",0,IF($E7="ENDCAP",0,"")))) -> 2 | N7: =IF(AND($B7<>"",$C7<>"",ISNUMBER(--$D7)), $B7&": "&LEFT($C7,1)&TEXT(--$D7,"00"), IF($I7<>"",$I7,$A7)) -> Z1: A01 | O7: =IF(AND($C7<>"",ISNUMBER(--$D7)),LEFT($C7,1),"") -> A | P7: =IF(ISNUMBER(--$D7),--$D7,"") -> 1 | Q7: =IF(AND($O7<>"",$P7<>""),$O7&TEXT($P7,"00"),"") -> A01
A8: WH-Z1-A01-OVERFLOW-01 | B8: Z1 | C8: A01 | D8: 01 | E8: OVERFLOW | F8: 3 | G8: 7 | H8: =A8 -> WH-Z1-A01-OVERFLOW-01 | I8: Overflow slot 01 | J8: =IF($I8<>"",$I8,$A8) -> Overflow slot 01 | K8: =IF($C8="","",IF(LEN($C8)=1,CODE(UPPER($C8))-64,IFERROR(VALUE(MID($C8,2,99)),""))) -> 1 | L8: =IF($D8="","",IFERROR(VALUE($D8),"")) -> 1 | M8: =IFERROR(VALUE(MID($A8,FIND("Level",$A8)+5,99)),IF($E8="AISLE_FLOOR",0,IF($E8="OVERFLOW",0,IF($E8="ENDCAP",0,"")))) -> 0 | N8: =IF(AND($B8<>"",$C8<>"",ISNUMBER(--$D8)), $B8&": "&LEFT($C8,1)&TEXT(--$D8,"00"), IF($I8<>"",$I8,$A8)) -> Z1: A01 | O8: =IF(AND($C8<>"",ISNUMBER(--$D8)),LEFT($C8,1),"") -> A | P8: =IF(ISNUMBER(--$D8),--$D8,"") -> 1 | Q8: =IF(AND($O8<>"",$P8<>""),$O8&TEXT($P8,"00"),"") -> A01
A9: CHRIS_OVERFLOW_A_ZONE1 | B9: CHRIS | E9: OVERFLOW | F9: 3 | G9: 0 | H9: =A9 -> CHRIS_OVERFLOW_A_ZONE1 | I9: Custom location code from Warehouse Ledger (details TBD). | J9: =IF($I9<>"",$I9,$A9) -> Custom location code from Warehouse Ledger (details TBD). | K9: =IF($C9="","",IF(LEN($C9)=1,CODE(UPPER($C9))-64,IFERROR(VALUE(MID($C9,2,99)),""))) | L9: =IF($D9="","",IFERROR(VALUE($D9),"")) | M9: =IFERROR(VALUE(MID($A9,FIND("Level",$A9)+5,99)),IF($E9="AISLE_FLOOR",0,IF($E9="OVERFLOW",0,IF($E9="ENDCAP",0,"")))) -> 0 | N9: =IF(AND($B9<>"",$C9<>"",ISNUMBER(--$D9)), $B9&": "&LEFT($C9,1)&TEXT(--$D9,"00"), IF($I9<>"",$I9,$A9)) -> Custom location code from Warehouse Ledger (details TBD). | O9: =IF(AND($C9<>"",ISNUMBER(--$D9)),LEFT($C9,1),"") | P9: =IF(ISNUMBER(--$D9),--$D9,"") -> 0 | Q9: =IF(AND($O9<>"",$P9<>""),$O9&TEXT($P9,"00"),"")
A10: WH-Z1-AisleA-Bay1-Level3 | B10: Z1 | C10: A | D10: 1 | E10: AISLE_FLOOR | F10: 4 | G10: 2 | H10: =A10 -> WH-Z1-AisleA-Bay1-Level3 | I10: SAMPLE: Grid A03 | J10: =IF($I10<>"",$I10,$A10) -> SAMPLE: Grid A03 | K10: =IF($C10="","",IF(LEN($C10)=1,CODE(UPPER($C10))-64,IFERROR(VALUE(MID($C10,2,99)),""))) -> 1 | L10: =IF($D10="","",IFERROR(VALUE($D10),"")) -> 1 | M10: =IFERROR(VALUE(MID($A10,FIND("Level",$A10)+5,99)),IF($E10="AISLE_FLOOR",0,IF($E10="OVERFLOW",0,IF($E10="ENDCAP",0,"")))) -> 3 | N10: =IF(AND($B10<>"",$C10<>"",ISNUMBER(--$D10)), $B10&": "&LEFT($C10,1)&TEXT(--$D10,"00"), IF($I10<>"",$I10,$A10)) -> Z1: A01 | O10: =IF(AND($C10<>"",ISNUMBER(--$D10)),LEFT($C10,1),"") -> A | P10: =IF(ISNUMBER(--$D10),--$D10,"") -> 1 | Q10: =IF(AND($O10<>"",$P10<>""),$O10&TEXT($P10,"00"),"") -> A01
A11: WH-Z1-AisleA-Bay1-Level4 | B11: Z1 | C11: A | D11: 1 | E11: AISLE_FLOOR | F11: 4 | G11: 2 | H11: =A11 -> WH-Z1-AisleA-Bay1-Level4 | I11: SAMPLE: Grid A04 | J11: =IF($I11<>"",$I11,$A11) -> SAMPLE: Grid A04 | K11: =IF($C11="","",IF(LEN($C11)=1,CODE(UPPER($C11))-64,IFERROR(VALUE(MID($C11,2,99)),""))) -> 1 | L11: =IF($D11="","",IFERROR(VALUE($D11),"")) -> 1 | M11: =IFERROR(VALUE(MID($A11,FIND("Level",$A11)+5,99)),IF($E11="AISLE_FLOOR",0,IF($E11="OVERFLOW",0,IF($E11="ENDCAP",0,"")))) -> 4 | N11: =IF(AND($B11<>"",$C11<>"",ISNUMBER(--$D11)), $B11&": "&LEFT($C11,1)&TEXT(--$D11,"00"), IF($I11<>"",$I11,$A11)) -> Z1: A01 | O11: =IF(AND($C11<>"",ISNUMBER(--$D11)),LEFT($C11,1),"") -> A | P11: =IF(ISNUMBER(--$D11),--$D11,"") -> 1 | Q11: =IF(AND($O11<>"",$P11<>""),$O11&TEXT($P11,"00"),"") -> A01
A12: WH-Z1-AisleA-Bay1-Level5 | B12: Z1 | C12: A | D12: 1 | E12: AISLE_FLOOR | F12: 4 | G12: 2 | H12: =A12 -> WH-Z1-AisleA-Bay1-Level5 | I12: SAMPLE: Grid A05 | J12: =IF($I12<>"",$I12,$A12) -> SAMPLE: Grid A05 | K12: =IF($C12="","",IF(LEN($C12)=1,CODE(UPPER($C12))-64,IFERROR(VALUE(MID($C12,2,99)),""))) -> 1 | L12: =IF($D12="","",IFERROR(VALUE($D12),"")) -> 1 | M12: =IFERROR(VALUE(MID($A12,FIND("Level",$A12)+5,99)),IF($E12="AISLE_FLOOR",0,IF($E12="OVERFLOW",0,IF($E12="ENDCAP",0,"")))) -> 5 | N12: =IF(AND($B12<>"",$C12<>"",ISNUMBER(--$D12)), $B12&": "&LEFT($C12,1)&TEXT(--$D12,"00"), IF($I12<>"",$I12,$A12)) -> Z1: A01 | O12: =IF(AND($C12<>"",ISNUMBER(--$D12)),LEFT($C12,1),"") -> A | P12: =IF(ISNUMBER(--$D12),--$D12,"") -> 1 | Q12: =IF(AND($O12<>"",$P12<>""),$O12&TEXT($P12,"00"),"") -> A01
A13: WH-Z1-AisleA-Bay1-Level6 | B13: Z1 | C13: A | D13: 1 | E13: AISLE_FLOOR | F13: 4 | G13: 2 | H13: =A13 -> WH-Z1-AisleA-Bay1-Level6 | I13: SAMPLE: Grid A06 | J13: =IF($I13<>"",$I13,$A13) -> SAMPLE: Grid A06 | K13: =IF($C13="","",IF(LEN($C13)=1,CODE(UPPER($C13))-64,IFERROR(VALUE(MID($C13,2,99)),""))) -> 1 | L13: =IF($D13="","",IFERROR(VALUE($D13),"")) -> 1 | M13: =IFERROR(VALUE(MID($A13,FIND("Level",$A13)+5,99)),IF($E13="AISLE_FLOOR",0,IF($E13="OVERFLOW",0,IF($E13="ENDCAP",0,"")))) -> 6 | N13: =IF(AND($B13<>"",$C13<>"",ISNUMBER(--$D13)), $B13&": "&LEFT($C13,1)&TEXT(--$D13,"00"), IF($I13<>"",$I13,$A13)) -> Z1: A01 | O13: =IF(AND($C13<>"",ISNUMBER(--$D13)),LEFT($C13,1),"") -> A | P13: =IF(ISNUMBER(--$D13),--$D13,"") -> 1 | Q13: =IF(AND($O13<>"",$P13<>""),$O13&TEXT($P13,"00"),"") -> A01
A14: WH-Z1-AisleA-Bay1-Level7 | B14: Z1 | C14: A | D14: 1 | E14: AISLE_FLOOR | F14: 4 | G14: 2 | H14: =A14 -> WH-Z1-AisleA-Bay1-Level7 | I14: SAMPLE: Grid A07 | J14: =IF($I14<>"",$I14,$A14) -> SAMPLE: Grid A07 | K14: =IF($C14="","",IF(LEN($C14)=1,CODE(UPPER($C14))-64,IFERROR(VALUE(MID($C14,2,99)),""))) -> 1 | L14: =IF($D14="","",IFERROR(VALUE($D14),"")) -> 1 | M14: =IFERROR(VALUE(MID($A14,FIND("Level",$A14)+5,99)),IF($E14="AISLE_FLOOR",0,IF($E14="OVERFLOW",0,IF($E14="ENDCAP",0,"")))) -> 7 | N14: =IF(AND($B14<>"",$C14<>"",ISNUMBER(--$D14)), $B14&": "&LEFT($C14,1)&TEXT(--$D14,"00"), IF($I14<>"",$I14,$A14)) -> Z1: A01 | O14: =IF(AND($C14<>"",ISNUMBER(--$D14)),LEFT($C14,1),"") -> A | P14: =IF(ISNUMBER(--$D14),--$D14,"") -> 1 | Q14: =IF(AND($O14<>"",$P14<>""),$O14&TEXT($P14,"00"),"") -> A01
A15: WH-Z1-AisleA-Bay1-Level8 | B15: Z1 | C15: A | D15: 1 | E15: AISLE_FLOOR | F15: 4 | G15: 2 | H15: =A15 -> WH-Z1-AisleA-Bay1-Level8 | I15: SAMPLE: Grid A08 | J15: =IF($I15<>"",$I15,$A15) -> SAMPLE: Grid A08 | K15: =IF($C15="","",IF(LEN($C15)=1,CODE(UPPER($C15))-64,IFERROR(VALUE(MID($C15,2,99)),""))) -> 1 | L15: =IF($D15="","",IFERROR(VALUE($D15),"")) -> 1 | M15: =IFERROR(VALUE(MID($A15,FIND("Level",$A15)+5,99)),IF($E15="AISLE_FLOOR",0,IF($E15="OVERFLOW",0,IF($E15="ENDCAP",0,"")))) -> 8 | N15: =IF(AND($B15<>"",$C15<>"",ISNUMBER(--$D15)), $B15&": "&LEFT($C15,1)&TEXT(--$D15,"00"), IF($I15<>"",$I15,$A15)) -> Z1: A01 | O15: =IF(AND($C15<>"",ISNUMBER(--$D15)),LEFT($C15,1),"") -> A | P15: =IF(ISNUMBER(--$D15),--$D15,"") -> 1 | Q15: =IF(AND($O15<>"",$P15<>""),$O15&TEXT($P15,"00"),"") -> A01
A16: WH-Z1-AisleA-Bay1-Level9 | B16: Z1 | C16: A | D16: 1 | E16: AISLE_FLOOR | F16: 4 | G16: 2 | H16: =A16 -> WH-Z1-AisleA-Bay1-Level9 | I16: SAMPLE: Grid A09 | J16: =IF($I16<>"",$I16,$A16) -> SAMPLE: Grid A09 | K16: =IF($C16="","",IF(LEN($C16)=1,CODE(UPPER($C16))-64,IFERROR(VALUE(MID($C16,2,99)),""))) -> 1 | L16: =IF($D16="","",IFERROR(VALUE($D16),"")) -> 1 | M16: =IFERROR(VALUE(MID($A16,FIND("Level",$A16)+5,99)),IF($E16="AISLE_FLOOR",0,IF($E16="OVERFLOW",0,IF($E16="ENDCAP",0,"")))) -> 9 | N16: =IF(AND($B16<>"",$C16<>"",ISNUMBER(--$D16)), $B16&": "&LEFT($C16,1)&TEXT(--$D16,"00"), IF($I16<>"",$I16,$A16)) -> Z1: A01 | O16: =IF(AND($C16<>"",ISNUMBER(--$D16)),LEFT($C16,1),"") -> A | P16: =IF(ISNUMBER(--$D16),--$D16,"") -> 1 | Q16: =IF(AND($O16<>"",$P16<>""),$O16&TEXT($P16,"00"),"") -> A01
A17: WH-Z1-AisleA-Bay1-Level10 | B17: Z1 | C17: A | D17: 1 | E17: AISLE_FLOOR | F17: 4 | G17: 2 | H17: =A17 -> WH-Z1-AisleA-Bay1-Level10 | I17: SAMPLE: Grid A10 | J17: =IF($I17<>"",$I17,$A17) -> SAMPLE: Grid A10 | K17: =IF($C17="","",IF(LEN($C17)=1,CODE(UPPER($C17))-64,IFERROR(VALUE(MID($C17,2,99)),""))) -> 1 | L17: =IF($D17="","",IFERROR(VALUE($D17),"")) -> 1 | M17: =IFERROR(VALUE(MID($A17,FIND("Level",$A17)+5,99)),IF($E17="AISLE_FLOOR",0,IF($E17="OVERFLOW",0,IF($E17="ENDCAP",0,"")))) -> 10 | N17: =IF(AND($B17<>"",$C17<>"",ISNUMBER(--$D17)), $B17&": "&LEFT($C17,1)&TEXT(--$D17,"00"), IF($I17<>"",$I17,$A17)) -> Z1: A01 | O17: =IF(AND($C17<>"",ISNUMBER(--$D17)),LEFT($C17,1),"") -> A | P17: =IF(ISNUMBER(--$D17),--$D17,"") -> 1 | Q17: =IF(AND($O17<>"",$P17<>""),$O17&TEXT($P17,"00"),"") -> A01
A18: WH-Z1-AisleA-Bay1-Level11 | B18: Z1 | C18: A | D18: 1 | E18: AISLE_FLOOR | F18: 4 | G18: 2 | H18: =A18 -> WH-Z1-AisleA-Bay1-Level11 | I18: SAMPLE: Grid A11 | J18: =IF($I18<>"",$I18,$A18) -> SAMPLE: Grid A11 | K18: =IF($C18="","",IF(LEN($C18)=1,CODE(UPPER($C18))-64,IFERROR(VALUE(MID($C18,2,99)),""))) -> 1 | L18: =IF($D18="","",IFERROR(VALUE($D18),"")) -> 1 | M18: =IFERROR(VALUE(MID($A18,FIND("Level",$A18)+5,99)),IF($E18="AISLE_FLOOR",0,IF($E18="OVERFLOW",0,IF($E18="ENDCAP",0,"")))) -> 11 | N18: =IF(AND($B18<>"",$C18<>"",ISNUMBER(--$D18)), $B18&": "&LEFT($C18,1)&TEXT(--$D18,"00"), IF($I18<>"",$I18,$A18)) -> Z1: A01 | O18: =IF(AND($C18<>"",ISNUMBER(--$D18)),LEFT($C18,1),"") -> A | P18: =IF(ISNUMBER(--$D18),--$D18,"") -> 1 | Q18: =IF(AND($O18<>"",$P18<>""),$O18&TEXT($P18,"00"),"") -> A01
