Workbook
Name ReminderMinutesList: Picklists!$C$2:$C$20
Name ShowAsList: Picklists!$A$2:$A$20
Name StatusList: Picklists!$B$2:$B$20
Name TimeZoneList: Picklists!$D$2:$D$20

Sheet PM Showcase
A1: Teams Invites Tracker — Tech Quick View + PM Showcase
A2: Use the left table to scan operations. Use the dropdown on the right to instantly generate a copy/paste Teams invite body.
A3: Tech Quick View — Operations Index | K3: Copy/Paste Generator — Teams Invite Body
A4: Event ID | B4: Date | C4: Start | D4: End | E4: Title | F4: Location | G4: Required | H4: Optional | I4: Status | K4: Event ID | L4: AP-2026-02-22
A5: =IFERROR(INDEX('Invite Builder'!$A:$A,ROW()-3),"") | B5: =IFERROR(INDEX('Invite Builder'!$C:$C,ROW()-3),"") | C5: =IFERROR(INDEX('Invite Builder'!$D:$D,ROW()-3),"") | D5: =IFERROR(INDEX('Invite Builder'!$E:$E,ROW()-3),"") | E5: =IFERROR(INDEX('Invite Builder'!$B:$B,ROW()-3),"") | F5: =IFERROR(INDEX('Invite Builder'!$I:$I,ROW()-3),"") | G5: =IFERROR(INDEX('Invite Builder'!$G:$G,ROW()-3),"") | H5: =IFERROR(INDEX('Invite Builder'!$H:$H,ROW()-3),"") | I5: =IFERROR(INDEX('Invite Builder'!$T:$T,ROW()-3),"") | K5: Title | L5: =IFERROR(VLOOKUP($L$4,'Invite Builder'!$A:$U,2,FALSE),"")
A6: =IFERROR(INDEX('Invite Builder'!$A:$A,ROW()-3),"") | B6: =IFERROR(INDEX('Invite Builder'!$C:$C,ROW()-3),"") | C6: =IFERROR(INDEX('Invite Builder'!$D:$D,ROW()-3),"") | D6: =IFERROR(INDEX('Invite Builder'!$E:$E,ROW()-3),"") | E6: =IFERROR(INDEX('Invite Builder'!$B:$B,ROW()-3),"") | F6: =IFERROR(INDEX('Invite Builder'!$I:$I,ROW()-3),"") | G6: =IFERROR(INDEX('Invite Builder'!$G:$G,ROW()-3),"") | H6: =IFERROR(INDEX('Invite Builder'!$H:$H,ROW()-3),"") | I6: =IFERROR(INDEX('Invite Builder'!$T:$T,ROW()-3),"") | K6: Date | L6: =IFERROR(VLOOKUP($L$4,'Invite Builder'!$A:$U,3,FALSE),"")
A7: =IFERROR(INDEX('Invite Builder'!$A:$A,ROW()-3),"") | B7: =IFERROR(INDEX('Invite Builder'!$C:$C,ROW()-3),"") | C7: =IFERROR(INDEX('Invite Builder'!$D:$D,ROW()-3),"") | D7: =IFERROR(INDEX('Invite Builder'!$E:$E,ROW()-3),"") | E7: =IFERROR(INDEX('Invite Builder'!$B:$B,ROW()-3),"") | F7: =IFERROR(INDEX('Invite Builder'!$I:$I,ROW()-3),"") | G7: =IFERROR(INDEX('Invite Builder'!$G:$G,ROW()-3),"") | H7: =IFERROR(INDEX('Invite Builder'!$H:$H,ROW()-3),"") | I7: =IFERROR(INDEX('Invite Builder'!$T:$T,ROW()-3),"") | K7: Time | L7: =IFERROR(TEXT(VLOOKUP($L$4,'Invite Builder'!$A:$U,4,FALSE),"h:mm AM/PM"),"")&" - "&IFERROR(TEXT(VLOOKUP($L$4,'Invite Builder'!$A:$U,5,FALSE),"h:mm AM/PM"),"")&" "&IFERROR(VLOOKUP($L$4,'Invite Builder'!$A:$U,6,FALSE),"")
A8: =IFERROR(INDEX('Invite Builder'!$A:$A,ROW()-3),"") | B8: =IFERROR(INDEX('Invite Builder'!$C:$C,ROW()-3),"") | C8: =IFERROR(INDEX('Invite Builder'!$D:$D,ROW()-3),"") | D8: =IFERROR(INDEX('Invite Builder'!$E:$E,ROW()-3),"") | E8: =IFERROR(INDEX('Invite Builder'!$B:$B,ROW()-3),"") | F8: =IFERROR(INDEX('Invite Builder'!$I:$I,ROW()-3),"") | G8: =IFERROR(INDEX('Invite Builder'!$G:$G,ROW()-3),"") | H8: =IFERROR(INDEX('Invite Builder'!$H:$H,ROW()-3),"") | I8: =IFERROR(INDEX('Invite Builder'!$T:$T,ROW()-3),"") | K8: Location | L8: =IFERROR(VLOOKUP($L$4,'Invite Builder'!$A:$U,9,FALSE),"")
A9: =IFERROR(INDEX('Invite Builder'!$A:$A,ROW()-3),"") | B9: =IFERROR(INDEX('Invite Builder'!$C:$C,ROW()-3),"") | C9: =IFERROR(INDEX('Invite Builder'!$D:$D,ROW()-3),"") | D9: =IFERROR(INDEX('Invite Builder'!$E:$E,ROW()-3),"") | E9: =IFERROR(INDEX('Invite Builder'!$B:$B,ROW()-3),"") | F9: =IFERROR(INDEX('Invite Builder'!$I:$I,ROW()-3),"") | G9: =IFERROR(INDEX('Invite Builder'!$G:$G,ROW()-3),"") | H9: =IFERROR(INDEX('Invite Builder'!$H:$H,ROW()-3),"") | I9: =IFERROR(INDEX('Invite Builder'!$T:$T,ROW()-3),"") | K9: Invite QA | L9: =IFERROR(VLOOKUP($L$4,'Invite Builder'!$A:$V,22,FALSE),"")
A10: =IFERROR(INDEX('Invite Builder'!$A:$A,ROW()-3),"") | B10: =IFERROR(INDEX('Invite Builder'!$C:$C,ROW()-3),"") | C10: =IFERROR(INDEX('Invite Builder'!$D:$D,ROW()-3),"") | D10: =IFERROR(INDEX('Invite Builder'!$E:$E,ROW()-3),"") | E10: =IFERROR(INDEX('Invite Builder'!$B:$B,ROW()-3),"") | F10: =IFERROR(INDEX('Invite Builder'!$I:$I,ROW()-3),"") | G10: =IFERROR(INDEX('Invite Builder'!$G:$G,ROW()-3),"") | H10: =IFERROR(INDEX('Invite Builder'!$H:$H,ROW()-3),"") | I10: =IFERROR(INDEX('Invite Builder'!$T:$T,ROW()-3),"") | K10: Teams Body (copy/paste) | L10: (click cell below, Ctrl+A, Ctrl+C)
A11: =IFERROR(INDEX('Invite Builder'!$A:$A,ROW()-3),"") | B11: =IFERROR(INDEX('Invite Builder'!$C:$C,ROW()-3),"") | C11: =IFERROR(INDEX('Invite Builder'!$D:$D,ROW()-3),"") | D11: =IFERROR(INDEX('Invite Builder'!$E:$E,ROW()-3),"") | E11: =IFERROR(INDEX('Invite Builder'!$B:$B,ROW()-3),"") | F11: =IFERROR(INDEX('Invite Builder'!$I:$I,ROW()-3),"") | G11: =IFERROR(INDEX('Invite Builder'!$G:$G,ROW()-3),"") | H11: =IFERROR(INDEX('Invite Builder'!$H:$H,ROW()-3),"") | I11: =IFERROR(INDEX('Invite Builder'!$T:$T,ROW()-3),"") | K11: =IFERROR(IF(OR(VLOOKUP($L$4,'Invite Builder'!$A:$U,18,FALSE)="",LEN(VLOOKUP($L$4,'Invite Builder'!$A:$U,18,FALSE))<60,ISNUMBER(MATCH(TRIM(VLOOKUP($L$4,'Invite Builder'!$A:$U,18,FALSE)),StatusList,0))),"⚠️ Teams body looks overwritten/short. Check Invite Builder col R (Body) and restore the formula.",VLOOKUP($L$4,'Invite Builder'!$A:$U,18,FALSE)),"")
A12: =IFERROR(INDEX('Invite Builder'!$A:$A,ROW()-3),"") | B12: =IFERROR(INDEX('Invite Builder'!$C:$C,ROW()-3),"") | C12: =IFERROR(INDEX('Invite Builder'!$D:$D,ROW()-3),"") | D12: =IFERROR(INDEX('Invite Builder'!$E:$E,ROW()-3),"") | E12: =IFERROR(INDEX('Invite Builder'!$B:$B,ROW()-3),"") | F12: =IFERROR(INDEX('Invite Builder'!$I:$I,ROW()-3),"") | G12: =IFERROR(INDEX('Invite Builder'!$G:$G,ROW()-3),"") | H12: =IFERROR(INDEX('Invite Builder'!$H:$H,ROW()-3),"") | I12: =IFERROR(INDEX('Invite Builder'!$T:$T,ROW()-3),"")
A13: =IFERROR(INDEX('Invite Builder'!$A:$A,ROW()-3),"") | B13: =IFERROR(INDEX('Invite Builder'!$C:$C,ROW()-3),"") | C13: =IFERROR(INDEX('Invite Builder'!$D:$D,ROW()-3),"") | D13: =IFERROR(INDEX('Invite Builder'!$E:$E,ROW()-3),"") | E13: =IFERROR(INDEX('Invite Builder'!$B:$B,ROW()-3),"") | F13: =IFERROR(INDEX('Invite Builder'!$I:$I,ROW()-3),"") | G13: =IFERROR(INDEX('Invite Builder'!$G:$G,ROW()-3),"") | H13: =IFERROR(INDEX('Invite Builder'!$H:$H,ROW()-3),"") | I13: =IFERROR(INDEX('Invite Builder'!$T:$T,ROW()-3),"")
A14: =IFERROR(INDEX('Invite Builder'!$A:$A,ROW()-3),"") | B14: =IFERROR(INDEX('Invite Builder'!$C:$C,ROW()-3),"") | C14: =IFERROR(INDEX('Invite Builder'!$D:$D,ROW()-3),"") | D14: =IFERROR(INDEX('Invite Builder'!$E:$E,ROW()-3),"") | E14: =IFERROR(INDEX('Invite Builder'!$B:$B,ROW()-3),"") | F14: =IFERROR(INDEX('Invite Builder'!$I:$I,ROW()-3),"") | G14: =IFERROR(INDEX('Invite Builder'!$G:$G,ROW()-3),"") | H14: =IFERROR(INDEX('Invite Builder'!$H:$H,ROW()-3),"") | I14: =IFERROR(INDEX('Invite Builder'!$T:$T,ROW()-3),"")
A15: =IFERROR(INDEX('Invite Builder'!$A:$A,ROW()-3),"") | B15: =IFERROR(INDEX('Invite Builder'!$C:$C,ROW()-3),"") | C15: =IFERROR(INDEX('Invite Builder'!$D:$D,ROW()-3),"") | D15: =IFERROR(INDEX('Invite Builder'!$E:$E,ROW()-3),"") | E15: =IFERROR(INDEX('Invite Builder'!$B:$B,ROW()-3),"") | F15: =IFERROR(INDEX('Invite Builder'!$I:$I,ROW()-3),"") | G15: =IFERROR(INDEX('Invite Builder'!$G:$G,ROW()-3),"") | H15: =IFERROR(INDEX('Invite Builder'!$H:$H,ROW()-3),"") | I15: =IFERROR(INDEX('Invite Builder'!$T:$T,ROW()-3),"")
A16: =IFERROR(INDEX('Invite Builder'!$A:$A,ROW()-3),"") | B16: =IFERROR(INDEX('Invite Builder'!$C:$C,ROW()-3),"") | C16: =IFERROR(INDEX('Invite Builder'!$D:$D,ROW()-3),"") | D16: =IFERROR(INDEX('Invite Builder'!$E:$E,ROW()-3),"") | E16: =IFERROR(INDEX('Invite Builder'!$B:$B,ROW()-3),"") | F16: =IFERROR(INDEX('Invite Builder'!$I:$I,ROW()-3),"") | G16: =IFERROR(INDEX('Invite Builder'!$G:$G,ROW()-3),"") | H16: =IFERROR(INDEX('Invite Builder'!$H:$H,ROW()-3),"") | I16: =IFERROR(INDEX('Invite Builder'!$T:$T,ROW()-3),"")
A17: =IFERROR(INDEX('Invite Builder'!$A:$A,ROW()-3),"") | B17: =IFERROR(INDEX('Invite Builder'!$C:$C,ROW()-3),"") | C17: =IFERROR(INDEX('Invite Builder'!$D:$D,ROW()-3),"") | D17: =IFERROR(INDEX('Invite Builder'!$E:$E,ROW()-3),"") | E17: =IFERROR(INDEX('Invite Builder'!$B:$B,ROW()-3),"") | F17: =IFERROR(INDEX('Invite Builder'!$I:$I,ROW()-3),"") | G17: =IFERROR(INDEX('Invite Builder'!$G:$G,ROW()-3),"") | H17: =IFERROR(INDEX('Invite Builder'!$H:$H,ROW()-3),"") | I17: =IFERROR(INDEX('Invite Builder'!$T:$T,ROW()-3),"")
A18: =IFERROR(INDEX('Invite Builder'!$A:$A,ROW()-3),"") | B18: =IFERROR(INDEX('Invite Builder'!$C:$C,ROW()-3),"") | C18: =IFERROR(INDEX('Invite Builder'!$D:$D,ROW()-3),"") | D18: =IFERROR(INDEX('Invite Builder'!$E:$E,ROW()-3),"") | E18: =IFERROR(INDEX('Invite Builder'!$B:$B,ROW()-3),"") | F18: =IFERROR(INDEX('Invite Builder'!$I:$I,ROW()-3),"") | G18: =IFERROR(INDEX('Invite Builder'!$G:$G,ROW()-3),"") | H18: =IFERROR(INDEX('Invite Builder'!$H:$H,ROW()-3),"") | I18: =IFERROR(INDEX('Invite Builder'!$T:$T,ROW()-3),"")
A19: =IFERROR(INDEX('Invite Builder'!$A:$A,ROW()-3),"") | B19: =IFERROR(INDEX('Invite Builder'!$C:$C,ROW()-3),"") | C19: =IFERROR(INDEX('Invite Builder'!$D:$D,ROW()-3),"") | D19: =IFERROR(INDEX('Invite Builder'!$E:$E,ROW()-3),"") | E19: =IFERROR(INDEX('Invite Builder'!$B:$B,ROW()-3),"") | F19: =IFERROR(INDEX('Invite Builder'!$I:$I,ROW()-3),"") | G19: =IFERROR(INDEX('Invite Builder'!$G:$G,ROW()-3),"") | H19: =IFERROR(INDEX('Invite Builder'!$H:$H,ROW()-3),"") | I19: =IFERROR(INDEX('Invite Builder'!$T:$T,ROW()-3),"")
A20: =IFERROR(INDEX('Invite Builder'!$A:$A,ROW()-3),"") | B20: =IFERROR(INDEX('Invite Builder'!$C:$C,ROW()-3),"") | C20: =IFERROR(INDEX('Invite Builder'!$D:$D,ROW()-3),"") | D20: =IFERROR(INDEX('Invite Builder'!$E:$E,ROW()-3),"") | E20: =IFERROR(INDEX('Invite Builder'!$B:$B,ROW()-3),"") | F20: =IFERROR(INDEX('Invite Builder'!$I:$I,ROW()-3),"") | G20: =IFERROR(INDEX('Invite Builder'!$G:$G,ROW()-3),"") | H20: =IFERROR(INDEX('Invite Builder'!$H:$H,ROW()-3),"") | I20: =IFERROR(INDEX('Invite Builder'!$T:$T,ROW()-3),"")
A21: =IFERROR(INDEX('Invite Builder'!$A:$A,ROW()-3),"") | B21: =IFERROR(INDEX('Invite Builder'!$C:$C,ROW()-3),"") | C21: =IFERROR(INDEX('Invite Builder'!$D:$D,ROW()-3),"") | D21: =IFERROR(INDEX('Invite Builder'!$E:$E,ROW()-3),"") | E21: =IFERROR(INDEX('Invite Builder'!$B:$B,ROW()-3),"") | F21: =IFERROR(INDEX('Invite Builder'!$I:$I,ROW()-3),"") | G21: =IFERROR(INDEX('Invite Builder'!$G:$G,ROW()-3),"") | H21: =IFERROR(INDEX('Invite Builder'!$H:$H,ROW()-3),"") | I21: =IFERROR(INDEX('Invite Builder'!$T:$T,ROW()-3),"")
A22: =IFERROR(INDEX('Invite Builder'!$A:$A,ROW()-3),"") | B22: =IFERROR(INDEX('Invite Builder'!$C:$C,ROW()-3),"") | C22: =IFERROR(INDEX('Invite Builder'!$D:$D,ROW()-3),"") | D22: =IFERROR(INDEX('Invite Builder'!$E:$E,ROW()-3),"") | E22: =IFERROR(INDEX('Invite Builder'!$B:$B,ROW()-3),"") | F22: =IFERROR(INDEX('Invite Builder'!$I:$I,ROW()-3),"") | G22: =IFERROR(INDEX('Invite Builder'!$G:$G,ROW()-3),"") | H22: =IFERROR(INDEX('Invite Builder'!$H:$H,ROW()-3),"") | I22: =IFERROR(INDEX('Invite Builder'!$T:$T,ROW()-3),"")
A23: =IFERROR(INDEX('Invite Builder'!$A:$A,ROW()-3),"") | B23: =IFERROR(INDEX('Invite Builder'!$C:$C,ROW()-3),"") | C23: =IFERROR(INDEX('Invite Builder'!$D:$D,ROW()-3),"") | D23: =IFERROR(INDEX('Invite Builder'!$E:$E,ROW()-3),"") | E23: =IFERROR(INDEX('Invite Builder'!$B:$B,ROW()-3),"") | F23: =IFERROR(INDEX('Invite Builder'!$I:$I,ROW()-3),"") | G23: =IFERROR(INDEX('Invite Builder'!$G:$G,ROW()-3),"") | H23: =IFERROR(INDEX('Invite Builder'!$H:$H,ROW()-3),"") | I23: =IFERROR(INDEX('Invite Builder'!$T:$T,ROW()-3),"")
... A204: =IFERROR(INDEX('Invite Builder'!$A:$A,ROW()-3),"") | B204: =IFERROR(INDEX('Invite Builder'!$C:$C,ROW()-3),"") | C204: =IFERROR(INDEX('Invite Builder'!$D:$D,ROW()-3),"") | D204: =IFERROR(INDEX('Invite Builder'!$E:$E,ROW()-3),"") | E204: =IFERROR(INDEX('Invite Builder'!$B:$B,ROW()-3),"") | F204: =IFERROR(INDEX('Invite Builder'!$I:$I,ROW()-3),"") | G204: =IFERROR(INDEX('Invite Builder'!$G:$G,ROW()-3),"") | H204: =IFERROR(INDEX('Invite Builder'!$H:$H,ROW()-3),"") | I204: =IFERROR(INDEX('Invite Builder'!$T:$T,ROW()-3),"")
A210: PM Showcase — Evidence Log (add wins as they happen)
A212: Quick Stats | B212: =SUMPRODUCT(--('Invite Builder'!$A$2:$A$500<>"")) | E212: Total Operations (count) | G212: How to use this tab: 1) Techs: use the left index table to find your operation; on the right, pick the Event ID to get a ready-to-paste Teams body. 2) PM brag file: after each operation, add one row in the Evidence Log. Keep it factual: what changed, proof, impact. Tip: If you add attachments/screenshots, paste the file name or SharePoint link in 'Evidence'.
A213: Done | B213: =COUNTIF('Invite Builder'!$T$2:$T$500,"Done") | E213: Ops marked Done
A214: Blocked | B214: =COUNTIF('Invite Builder'!$T$2:$T$500,"Blocked") | E214: Ops blocked (needs help)
A216: Date | B216: Event ID | C216: What I led / changed | D216: Evidence (link, note, screenshot ref) | E216: Impact (time, risk, quality) | F216: Next improvement
A217: 46051 | B217: GG-2026-01-30 | C217: Bugfix: Teams Invite Body returned 'Planned' due to Invite Builder col R (Body) being overwritten/missing formula. Restored Body formula and documented guardrail. | D217: Screenshot: PM Showcase Teams Body cell displayed only 'Planned' despite populated Invite Builder fields. | E217: Prevents blank/incorrect invites; reduces rework and missed stock details before go-live days. | F217: Add guardrail: flag rows where Body is blank or equals a Status picklist value (Planned/In Progress/Blocked/Done). Consider protecting column R.
A218: 46051 | B218: SYSTEM | C218: Added web-safe guardrails: Row QA column, dropdown validations, conditional formatting, PM Showcase QA readout, and sheet protection to prevent formula overwrites. | D218: See 'System Notes' tab; Invite Builder col V (Row QA) + named ranges (ShowAsList/StatusList/ReminderMinutesList/TimeZoneList). | E218: Catches 'Body overwritten' before copy/paste, reduces rework, keeps invites reliable under Web Excel constraints.

Sheet System Notes

Sheet Invite Builder
A1: Event ID | B1: Title | C1: Date | D1: Start Time | E1: End Time | F1: Time Zone | G1: Required Attendees | H1: Optional Attendees | I1: Location | J1: Show As | K1: Reminder (min) | L1: Purpose | M1: Stops (in order) | N1: Hard Requirements | O1: Suggested Timeline | P1: Guardrails | Q1: Completion Signals | R1: Body (Teams paste) | S1: Checkpoint Log (actuals) | T1: Status | U1: Last Updated | V1: Row QA (auto)
A2: AP-2026-01-08 | B2: Alejandro - 3HQ Key Drop + HQ Plainview Config + PBMC Prep (1/8) | C2: 46030 | D2: 0.33333333 | E2: 0.70833333 | F2: Local | G2: Alejandro Perales | H2: Ralph (3HQ) ; Khadejah Harrison ; Akbar (if he's the config owner) | I2: HQ - Plainview (multi-stop details in agenda) | J2: Busy | K2: 30 | L2: Return universal key; configure and stage devices at HQ Plainview; prep for PBMC deployment; align counts with Khadejah. | M2: 1) 3HQ - Key drop with Ralph 2) HQ - Plainview - Device configuration + staging 3) PBMC - Deployment prep / readiness | N2: - Contact Ralph first thing AM to coordinate key handoff. - Drop off universal key to Ralph at 3HQ and confirm receipt. - Head to HQ Plainview ASAP after key drop. - Configure devices at HQ. - Stage/pack for PBMC deployment. - Sync with Khadejah on counts before deployment. | O2: - 8:00-8:15 Call/text Ralph; lock handoff details - 8:15-9:00 3HQ key drop -> confirm receipt - 9:00-1:00 HQ Plainview: configure devices + verification checks - 1:00-2:00 Staging/packout for PBMC - 2:00-2:15 Sync w/ Khadejah: counts + plan - 2:15+ Travel/prepare for PBMC window | P2: - Do not accept extra add-ons without approval; log and escalate. - If Tim is involved, confirm requirements in advance. | Q2: - Key returned to Ralph + time - HQ config complete + device count - PBMC staging complete + blockers - Counts aligned with Khadejah + final count | R2: =IF($L2<>"","Purpose"&CHAR(10)&$L2&CHAR(10)&CHAR(10),"" )&"Stops (in order)"&CHAR(10)&$M2&CHAR(10)&CHAR(10)&"To-Do (hard requirements)"&CHAR(10)&$N2&CHAR(10)&CHAR(10)&"Suggested Timeline"&CHAR(10)&$O2&CHAR(10)&CHAR(10)&"Guardrails"&CHAR(10)&$P2&CHAR(10)&CHAR(10)&"Completion signals"&CHAR(10)&$Q2 | T2: Planned | U2: 46030.318 | V2: =IF($B2="","",IF(_xludf.TEXTJOIN(" | ",TRUE,IF($B2="","Missing Title",""),IF($C2="","Missing Date",""),IF($D2="","Missing Start",""),IF($E2="","Missing End",""),IF($G2="","Missing Required Attendees",""),IF($T2="","Missing Status",""),IF(AND($D2<>"",$E2<>"",$D2>=$E2),"Start>=End",""),IF(OR($R2="",LEN($R2)<60,ISNUMBER(MATCH(TRIM($R2),StatusList,0))),"Body overwritten/short",""))="","OK",_xludf.TEXTJOIN(" | ",TRUE,IF($B2="","Missing Title",""),IF($C2="","Missing Date",""),IF($D2="","Missing Start",""),IF($E2="","Missing End",""),IF($G2="","Missing Required Attendees",""),IF($T2="","Missing Status",""),IF(AND($D2<>"",$E2<>"",$D2>=$E2),"Start>=End",""),IF(OR($R2="",LEN($R2)<60,ISNUMBER(MATCH(TRIM($R2),StatusList,0))),"Body overwritten/short",""))))
A3: KH-2026-01-08 | B3: Khadejah — Inventory Counts + Locations (1 Marcus + HQ) + Pallets + Arm Attach Doc (1/8) | C3: 46030 | D3: 0.33333333 | E3: 0.70833333 | F3: Local | G3: Khadejah Harrison | H3: Rich Perez ; Bonita Outlaw | I3: HQ + 1 Marcus (multi-stop counts + pallets; details in agenda) | J3: Busy | K3: 30 | L3: Establish reliable counts + exact locations for Neuron deployment stock across HQ and 1 Marcus (including pallets); consolidate into a single master counts interface; produce shortages/blockers + runway for upcoming sites; document the arm→Neuron attach process for reuse. | M3: 1) HQ - Sweep all staging areas + pallets; log counts + exact locations 2) 1 Marcus - Sweep stock; log counts + exact locations 3) Update Inventory Master - consolidate counts; tag conflicts; timestamp 4) Arm→Neuron attach - capture steps (photos/video) + notes 5) Send EOD summary (totals, shortages, runway, next steps) | N3: - Record COUNT + EXACT LOCATION for each line item touched (no vague 'HQ'). - Use location format: [SITE] - [AREA] - [SUBAREA]. - Prioritize Neuron units + GCX arms first; then DIMs/adapters/KBM. - Tag pallets with a PalletID (P-001, P-002...) and record their contents. - No guessing: if a count conflicts, mark CONFLICT and note why. - Keep everything in the master tracker (no side spreadsheets). | O3: - 8:00-10:30 HQ sweep (zones + pallets) + initial totals - 10:30-12:30 1 Marcus sweep + totals - 12:30-1:30 Update Inventory Master + reconcile conflicts - 1:30-2:15 Arm→Neuron attach documentation (clean angles) - 2:15-2:30 Send summary to Rich (HQ vs 1 Marcus totals + blockers + runway) | P3: - Don’t move stock without updating location in the master. - If something is missing/damaged/unknown, log it immediately and flag it. - Keep photos clear; avoid capturing screens/labels not needed. - If time runs short, finish Neurons + arms + pallet manifest first. | Q3: - Master counts updated with HQ vs 1 Marcus totals + exact locations. - Pallets tagged + recorded (at least Neurons + arms per pallet). - Shortages/blockers list captured. - Arm→Neuron attach steps recorded + shared. - EOD summary sent. | R3: =IF($L3<>"","Purpose"&CHAR(10)&$L3&CHAR(10)&CHAR(10),"" )&"Stops (in order)"&CHAR(10)&$M3&CHAR(10)&CHAR(10)&"To-Do (hard requirements)"&CHAR(10)&$N3&CHAR(10)&CHAR(10)&"Suggested Timeline"&CHAR(10)&$O3&CHAR(10)&CHAR(10)&"Guardrails"&CHAR(10)&$P3&CHAR(10)&CHAR(10)&"Completion signals"&CHAR(10)&$Q3 | T3: Planned | U3: 46030.33 | V3: =IF($B3="","",IF(_xludf.TEXTJOIN(" | ",TRUE,IF($B3="","Missing Title",""),IF($C3="","Missing Date",""),IF($D3="","Missing Start",""),IF($E3="","Missing End",""),IF($G3="","Missing Required Attendees",""),IF($T3="","Missing Status",""),IF(AND($D3<>"",$E3<>"",$D3>=$E3),"Start>=End",""),IF(OR($R3="",LEN($R3)<60,ISNUMBER(MATCH(TRIM($R3),StatusList,0))),"Body overwritten/short",""))="","OK",_xludf.TEXTJOIN(" | ",TRUE,IF($B3="","Missing Title",""),IF($C3="","Missing Date",""),IF($D3="","Missing Start",""),IF($E3="","Missing End",""),IF($G3="","Missing Required Attendees",""),IF($T3="","Missing Status",""),IF(AND($D3<>"",$E3<>"",$D3>=$E3),"Start>=End",""),IF(OR($R3="",LEN($R3)<60,ISNUMBER(MATCH(TRIM($R3),StatusList,0))),"Body overwritten/short",""))))
A4: IP-2026-01-12 | B4: iPhone/Rover — Recurring Training Block (Starts Week of 1/12) | C4: 46034 | D4: 0.375 | E4: 0.75 | F4: Local | G4: Emmanuel Sanchez; Ezekiel; Erik Guzman; Julio Mojica; Asher Ali; Valentyn Nykoliuk; Tanjim Khan; Shazaib Idrees; Cyen Heyliger; Connor Hoffman | H4: Nayelin Monegro; Rich Perez | I4: Training window (no meeting link) | J4: Busy | K4: 30 | L4: Recurring iPhone/Rover shadow training window + Training Log updates; identify knowledge gaps and drive follow-up shadowing. | M4: 1) Trainee sends mentor availability + site + constraints 2) Mentor confirms capacity + schedules shadow block(s) 3) Shadow block happens 4) Same-day Training Log update (coverage + gaps + next topic) 5) Repeat as needed until well-rounded | N4: - Training Log is the source of truth - Same-day log updates after each shadow block - Capture knowledge gaps + next recommended topic - Escalate access/permissions blockers; don’t improvise | O4: Week of 1/12: schedule the first shadow blocks early in the week Ongoing: repeat shadow blocks as needed; Training Log updated same day | P4: - No surprise reassignments without notifying the group - No side chats as the “real plan” - If blocked by access/permissions, escalate immediately | Q4: - First shadow block scheduled per trainee - Training Log updated after each shadow block - Knowledge gaps logged + follow-up topics assigned | R4: iPhone/Rover Shadow Training — Recurring Block (Starts Week of 1/12) This is a training window, not a meeting. Use this block to schedule and complete shadow sessions. No one needs to join. What this is: A recurring training window for iPhone/Rover shadowing + skill-building. Each trainee completes at least 1–2 shadow blocks to start, then continues as needed. Knowledge gaps get logged and tracked. Mentors: • Emmanuel Sanchez (Lenox Hill) • Erik Guzman (PBMC) • Ezekiel (Staten Island N&S) Trainees: • Julio Mojica • Asher Ali • Valentyn Nykoliuk • Tanjim Khan • Shazaib Idrees • Cyen Heyliger • Connor Hoffman TRAINEES — DO THIS Send your mentor: • Two time windows next week you can shadow (and more as needed) • Your main site • Any constraints (access issues, hard stop time, etc.) After each shadow block: • Update the Training Log the same day (what was covered + knowledge gaps + next topic) MENTORS — DO THIS • Tell me how many trainees you can actively support at a time • Coordinate shadow blocks with those trainees • Update the Training Log with: Trainee / Mentor / Date-Time / Site / What was covered / Knowledge gaps & blockers / Next recommended topic RULE Training Log is the source of truth. No side chats as the “real plan.” | T4: Planned | U4: 46032.315 | V4: =IF($B4="","",IF(_xludf.TEXTJOIN(" | ",TRUE,IF($B4="","Missing Title",""),IF($C4="","Missing Date",""),IF($D4="","Missing Start",""),IF($E4="","Missing End",""),IF($G4="","Missing Required Attendees",""),IF($T4="","Missing Status",""),IF(AND($D4<>"",$E4<>"",$D4>=$E4),"Start>=End",""),IF(OR($R4="",LEN($R4)<60,ISNUMBER(MATCH(TRIM($R4),StatusList,0))),"Body overwritten/short",""))="","OK",_xludf.TEXTJOIN(" | ",TRUE,IF($B4="","Missing Title",""),IF($C4="","Missing Date",""),IF($D4="","Missing Start",""),IF($E4="","Missing End",""),IF($G4="","Missing Required Attendees",""),IF($T4="","Missing Status",""),IF(AND($D4<>"",$E4<>"",$D4>=$E4),"Start>=End",""),IF(OR($R4="",LEN($R4)<60,ISNUMBER(MATCH(TRIM($R4),StatusList,0))),"Body overwritten/short",""))))
A5: MV-2026-01-11 | B5: LIJ SDF Sunday — Transport + Pack-Out (Marvin Lead) — 28 all around | C5: 46033 | D5: 0.33333333 | E5: 0.70833333 | F5: Local | G5: Marvin Tate | H5: Rich Perez; Bonita Outlaw | I5: Stock staging room → LIJ SDF | J5: Busy | K5: 30 | L5: Move the correct stock to LIJ SDF for Sunday’s work; keep staging controlled; pack out everything we bring in so LIJ SDF returns to pre-arrival condition. Key rule: 28 all around (28 capsules + 28 of each required cable/cord type). | M5: 1) Staging room (pull / count / organize) 2) Load vehicle 3) LIJ SDF (deliver staged stock) 4) End-of-day pack-out + close-out proof | N5: • Confirm exact item list for Sunday (capsules + cables/cords + accessories) • Pull & stage: 28 capsules (7 boxes × 4) • Pull & stage: 28 Ethernet cables • Pull & stage: 28 power cords • Pull & stage: 28 of any other required cable/cord type (default to 28 unless PM specifies otherwise) • HQ path: if mounts/arms are delivered separately, pack out all packaging + unused materials • Keep stock orderly: stack by category; labels facing out; pallet jack accessible • Keep walking/loading path clear (no loose cables/garbage) • Take quick photo of staged load before moving out • Load securely (heavy bottom; protect fragile; prevent shifting) • Pack-out rules: remove all packaging created + all unused stock; keep device/capsule shipping boxes • Damaged/questionable items: bag/tag + bring back (no trashing devices/cables) • Final walk-through: floors clear; carts/pallets out; nothing left behind | O5: Before move: • Stage by category, count to 28, photo the staged load • Load + secure At site / end-of-day: • Pack out all packaging + unused stock • Take 2 close-out photos: (1) empty staging footprint at LIJ SDF, (2) load-out/packed carts ready to leave • Note any exceptions + who approved | P5: “Disposal” = pack out everything we bring in so LIJ SDF is as it was before we arrived. Trash/packaging only. Never devices/cables. Keep device/capsule shipping boxes. Do not leave extra stock behind unless explicitly approved; document approvals. | Q5: • 28-count confirmed for capsules + each cable/cord type • Staged-load photo captured • Site packed out (no trash/packaging left) + 2 close-out photos taken • Any exceptions documented with approver | R5: =IF($L5<>"","Purpose"&CHAR(10)&$L5&CHAR(10)&CHAR(10),"" )&"Stops (in order)"&CHAR(10)&$M5&CHAR(10)&CHAR(10)&"To-Do (hard requirements)"&CHAR(10)&$N5&CHAR(10)&CHAR(10)&"Suggested Timeline"&CHAR(10)&$O5&CHAR(10)&CHAR(10)&"Guardrails"&CHAR(10)&$P5&CHAR(10)&CHAR(10)&"Completion signals"&CHAR(10)&$Q5 | T5: Planned | U5: 46032.368 | V5: =IF($B5="","",IF(_xludf.TEXTJOIN(" | ",TRUE,IF($B5="","Missing Title",""),IF($C5="","Missing Date",""),IF($D5="","Missing Start",""),IF($E5="","Missing End",""),IF($G5="","Missing Required Attendees",""),IF($T5="","Missing Status",""),IF(AND($D5<>"",$E5<>"",$D5>=$E5),"Start>=End",""),IF(OR($R5="",LEN($R5)<60,ISNUMBER(MATCH(TRIM($R5),StatusList,0))),"Body overwritten/short",""))="","OK",_xludf.TEXTJOIN(" | ",TRUE,IF($B5="","Missing Title",""),IF($C5="","Missing Date",""),IF($D5="","Missing Start",""),IF($E5="","Missing End",""),IF($G5="","Missing Required Attendees",""),IF($T5="","Missing Status",""),IF(AND($D5<>"",$E5<>"",$D5>=$E5),"Start>=End",""),IF(OR($R5="",LEN($R5)<60,ISNUMBER(MATCH(TRIM($R5),StatusList,0))),"Body overwritten/short",""))))
A6: =IF(AND($B6<>"",$C6<>"",$D6<>"",$E6<>"",$G6<>""), UPPER( LEFT(TRIM(LEFT($G6,IFERROR(FIND(";",$G6)-1,999))),1)& IFERROR( MID(TRIM(LEFT($G6,IFERROR(FIND(";",$G6)-1,999))), FIND(" ",TRIM(LEFT($G6,IFERROR(FIND(";",$G6)-1,999))))+1,1), MID(TRIM(LEFT($G6,IFERROR(FIND(";",$G6)-1,999))),2,1) ) )&"-"&TEXT($C6,"yyyy-mm-dd"), "") | B6: Patricia — iPhone/Rover — Recurring Training Block (Starts Week of 1/21) | C6: 46041 | D6: 0.375 | E6: 0.75 | F6: Local | G6: Patricia Marrero | H6: Rich Perez; Josh Vincent | I6: LHH and the Northern Westchester Area | L6: • Train on iPhones and Mobile Devices • Avoid conflicts with other projects, particularly TOW • Increase the Volume and Integrity of Coverage in the Westchester area | M6: • LHH and the Northern Westchester Area • Clarify with Mentors | N6: • Correspond with Mentors • Train under mentors • Establish sites to cover with Eman, Connor, and Clifford | O6: Recurring until Friday, Feb 6 | P6: • No conflicts with DSE and TOW • Avoid TOW and DSE conflicts | Q6: • No conflicts with DSE and TOW • Correspondence with Mentors in Effect • Training log updated with updated knowledge gaps | R6: =IF($L6<>"","Purpose "&CHAR(10)&$L6&CHAR(10)&CHAR(10),"")& IF($M6<>"","Stops (in order) "&CHAR(10)&$M6&CHAR(10)&CHAR(10),"")& IF($N6<>"","To-Do (hard requirements) "&CHAR(10)&$N6&CHAR(10)&CHAR(10),"")& IF($O6<>"","Suggested Timeline "&CHAR(10)&$O6&CHAR(10)&CHAR(10),"")& IF($P6<>"","Guardrails "&CHAR(10)&$P6&CHAR(10)&CHAR(10),"")& IF($Q6<>"","Completion signals "&CHAR(10)&$Q6,"") | V6: =IF($B6="","",IF(_xludf.TEXTJOIN(" | ",TRUE,IF($B6="","Missing Title",""),IF($C6="","Missing Date",""),IF($D6="","Missing Start",""),IF($E6="","Missing End",""),IF($G6="","Missing Required Attendees",""),IF($T6="","Missing Status",""),IF(AND($D6<>"",$E6<>"",$D6>=$E6),"Start>=End",""),IF(OR($R6="",LEN($R6)<60,ISNUMBER(MATCH(TRIM($R6),StatusList,0))),"Body overwritten/short",""))="","OK",_xludf.TEXTJOIN(" | ",TRUE,IF($B6="","Missing Title",""),IF($C6="","Missing Date",""),IF($D6="","Missing Start",""),IF($E6="","Missing End",""),IF($G6="","Missing Required Attendees",""),IF($T6="","Missing Status",""),IF(AND($D6<>"",$E6<>"",$D6>=$E6),"Start>=End",""),IF(OR($R6="",LEN($R6)<60,ISNUMBER(MATCH(TRIM($R6),StatusList,0))),"Body overwritten/short",""))))
A7: =IF(AND($B7<>"",$C7<>"",$D7<>"",$E7<>"",$G7<>""), UPPER( LEFT(TRIM(LEFT($G7,IFERROR(FIND(";",$G7)-1,999))),1)& IFERROR( MID(TRIM(LEFT($G7,IFERROR(FIND(";",$G7)-1,999))), FIND(" ",TRIM(LEFT($G7,IFERROR(FIND(";",$G7)-1,999))))+1,1), MID(TRIM(LEFT($G7,IFERROR(FIND(";",$G7)-1,999))),2,1) ) )&"-"&TEXT($C7,"yyyy-mm-dd"), "") | B7: MEETH — Stock Delivery (Marvin Lead) | C7: 46043 | D7: 0.375 | E7: 0.45833333 | F7: Local | G7: Marvin Tate | H7: Rich Perez; Bonita Outlaw | I7: MEETH | J7: Busy | K7: 30 | L7: Deliver critical MEETH stock (QTY 2 each) and confirm clean handoff so the site can proceed without delays. | M7: 1) HQ stock room / staging (pull + verify) 2) Load vehicle (secure) 3) MEETH (deliver + handoff) 4) Return / close-out (update counts + note exceptions) | N7: ☐ Pick up required items directly from Geoff Gerber ☐ Verify all five SKUs are present (2 each) ☐ Keep items grouped and labeled for MEETH ☐ Photo staged items before loading ☐ Coordinate onsite handoff; record recipient name/area ☐ Photo delivery/handoff confirmation ☐ If missing/damaged: bag/tag + escalate immediately • Pull + verify the following stock (QTY 2 each): • B1-CPAT-DIM-14 — 2 • DIM — 2 • B1-CFU — 2 • SPEC999015 — 2 • GE-ADAPTOR — 2 • Keep items grouped + labeled for MEETH (no mixed piles) • Take a quick photo of the staged items before loading (proof + reference) • Coordinate onsite handoff (recipient name/area) and confirm delivery complete • If anything is missing/damaged: bag/tag and escalate immediately (do not substitute silently) | O7: Before departure: pull + verify + photo. At MEETH: handoff + confirm recipient. After: update tracker / notes with any exceptions. | P7: This is a controlled delivery. No improvising part substitutions without approval. Keep packaging tidy; prevent damage in transit. | Q7: All five SKUs delivered (2 each), recipient confirmed, and staging/delivery photo captured. Exceptions logged if any. | R7: =IF($L7<>"","Purpose "&CHAR(10)&$L7&CHAR(10)&CHAR(10),"")& IF($M7<>"","Stops (in order) "&CHAR(10)&$M7&CHAR(10)&CHAR(10),"")& IF($N7<>"","To-Do (hard requirements) "&CHAR(10)&$N7&CHAR(10)&CHAR(10),"")& IF($O7<>"","Suggested Timeline "&CHAR(10)&$O7&CHAR(10)&CHAR(10),"")& IF($P7<>"","Guardrails "&CHAR(10)&$P7&CHAR(10)&CHAR(10),"")& IF($Q7<>"","Completion signals "&CHAR(10)&$Q7,"") | T7: Planned | U7: 46042.5 | V7: =IF($B7="","",IF(_xludf.TEXTJOIN(" | ",TRUE,IF($B7="","Missing Title",""),IF($C7="","Missing Date",""),IF($D7="","Missing Start",""),IF($E7="","Missing End",""),IF($G7="","Missing Required Attendees",""),IF($T7="","Missing Status",""),IF(AND($D7<>"",$E7<>"",$D7>=$E7),"Start>=End",""),IF(OR($R7="",LEN($R7)<60,ISNUMBER(MATCH(TRIM($R7),StatusList,0))),"Body overwritten/short",""))="","OK",_xludf.TEXTJOIN(" | ",TRUE,IF($B7="","Missing Title",""),IF($C7="","Missing Date",""),IF($D7="","Missing Start",""),IF($E7="","Missing End",""),IF($G7="","Missing Required Attendees",""),IF($T7="","Missing Status",""),IF(AND($D7<>"",$E7<>"",$D7>=$E7),"Start>=End",""),IF(OR($R7="",LEN($R7)<60,ISNUMBER(MATCH(TRIM($R7),StatusList,0))),"Body overwritten/short",""))))
A8: =IF(AND($B8<>"",$C8<>"",$D8<>"",$E8<>"",$G8<>""), UPPER( LEFT(TRIM(LEFT($G8,IFERROR(FIND(";",$G8)-1,999))),1)& IFERROR( MID(TRIM(LEFT($G8,IFERROR(FIND(";",$G8)-1,999))), FIND(" ",TRIM(LEFT($G8,IFERROR(FIND(";",$G8)-1,999))))+1,1), MID(TRIM(LEFT($G8,IFERROR(FIND(";",$G8)-1,999))),2,1) ) )&"-"&TEXT($C8,"yyyy-mm-dd"), "") | B8: Glen Cove — OR/Endo Cybernet Peripherals Install (9 KB+Mouse, 9 Badge Readers, 9 Barcode Scanners) | C8: 46049 | D8: 0.375 | E8: 0.625 | F8: Local | G8: Khadejah Harrison; CDW Resource (TBD) | H8: Timothy Seeberger | I8: Glen Cove Hospital — OR & Endo (Cybernet) | J8: Busy | K8: 30 | L8: Install and validate 9 wired keyboard/mouse sets, 9 badge access readers, and 9 barcode scanners; connect all peripherals to the Cybernet in OR and Endo. | M8: 1) 3HQ (as needed): confirm delivery/availability of 9 cables for Glen Cove | 2) Glen Cove — OR: install/connect/test peripherals on Cybernet | 3) Glen Cove — Endo: install/connect/test peripherals on Cybernet | 4) Close-out: photos (no PHI) + confirm counts + send completion note | N8: Verify inventory (9 KB+Mouse, 9 Badge Readers, 9 Barcode Scanners; plus 9 cables if applicable) | Install + connect to correct Cybernet(s) in OR & Endo | Test: keyboard/mouse input, badge read, barcode scan | Escalate blockers immediately (ports/driver/access) | No silent substitutions | O8: Before: confirm stock/cables at 3HQ if needed | Onsite: OR first, then Endo | End: confirm with site POC + send completion update | P8: No PHI in photos | Keep cabling tidy/secured | Same-day escalation on blockers; coordinate access with site IT as needed | Q8: All 27 peripherals installed + tested in OR/Endo | Exceptions logged with owner/next step | Completion update sent | R8: =IF($L8<>"","Purpose "&CHAR(10)&$L8&CHAR(10)&CHAR(10),"")& IF($M8<>"","Stops (in order) "&CHAR(10)&$M8&CHAR(10)&CHAR(10),"")& IF($N8<>"","To-Do (hard requirements) "&CHAR(10)&$N8&CHAR(10)&CHAR(10),"")& IF($O8<>"","Suggested Timeline "&CHAR(10)&$O8&CHAR(10)&CHAR(10),"")& IF($P8<>"","Guardrails "&CHAR(10)&$P8&CHAR(10)&CHAR(10),"")& IF($Q8<>"","Completion signals "&CHAR(10)&$Q8,"") | V8: =IF($B8="","",IF(_xludf.TEXTJOIN(" | ",TRUE,IF($B8="","Missing Title",""),IF($C8="","Missing Date",""),IF($D8="","Missing Start",""),IF($E8="","Missing End",""),IF($G8="","Missing Required Attendees",""),IF($T8="","Missing Status",""),IF(AND($D8<>"",$E8<>"",$D8>=$E8),"Start>=End",""),IF(OR($R8="",LEN($R8)<60,ISNUMBER(MATCH(TRIM($R8),StatusList,0))),"Body overwritten/short",""))="","OK",_xludf.TEXTJOIN(" | ",TRUE,IF($B8="","Missing Title",""),IF($C8="","Missing Date",""),IF($D8="","Missing Start",""),IF($E8="","Missing End",""),IF($G8="","Missing Required Attendees",""),IF($T8="","Missing Status",""),IF(AND($D8<>"",$E8<>"",$D8>=$E8),"Start>=End",""),IF(OR($R8="",LEN($R8)<60,ISNUMBER(MATCH(TRIM($R8),StatusList,0))),"Body overwritten/short",""))))
A9: =IF(AND($B9<>"",$C9<>"",$D9<>"",$E9<>"",$G9<>""), UPPER( LEFT(TRIM(LEFT($G9,IFERROR(FIND(";",$G9)-1,999))),1)& IFERROR( MID(TRIM(LEFT($G9,IFERROR(FIND(";",$G9)-1,999))), FIND(" ",TRIM(LEFT($G9,IFERROR(FIND(";",$G9)-1,999))))+1,1), MID(TRIM(LEFT($G9,IFERROR(FIND(";",$G9)-1,999))),2,1) ) )&"-"&TEXT($C9,"yyyy-mm-dd"), "") | B9: Glen Cove — OR/Endo Cybernet Peripherals Install (9 KB+Mouse, 9 Badge Readers, 9 Barcode Scanners) | C9: 46049 | D9: 0.375 | E9: 0.625 | F9: Local | G9: Khadejah Harrison; CDW Resource (TBD) | H9: Timothy Seeberger | I9: Glen Cove Hospital — OR & Endo (Cybernet) | J9: Busy | K9: 30 | L9: Install and validate 9 wired keyboard/mouse sets, 9 badge access readers, and 9 barcode scanners; connect all peripherals to the Cybernet in OR and Endo. | M9: 1) 3HQ (as needed): confirm delivery/availability of 9 cables for Glen Cove | 2) Glen Cove — OR: install/connect/test peripherals on Cybernet | 3) Glen Cove — Endo: install/connect/test peripherals on Cybernet | 4) Close-out: photos (no PHI) + confirm counts + send completion note | N9: Verify inventory (9 KB+Mouse, 9 Badge Readers, 9 Barcode Scanners; plus 9 cables if applicable) | Install + connect to correct Cybernet(s) in OR & Endo | Test: keyboard/mouse input, badge read, barcode scan | Escalate blockers immediately (ports/driver/access) | No silent substitutions | O9: Before: confirm stock/cables at 3HQ if needed | Onsite: OR first, then Endo | End: confirm with site POC + send completion update | P9: No PHI in photos | Keep cabling tidy/secured | Same-day escalation on blockers; coordinate access with site IT as needed | Q9: All 27 peripherals installed + tested in OR/Endo | Exceptions logged with owner/next step | Completion update sent | R9: =IF($L9<>"","Purpose "&CHAR(10)&$L9&CHAR(10)&CHAR(10),"")& IF($M9<>"","Stops (in order) "&CHAR(10)&$M9&CHAR(10)&CHAR(10),"")& IF($N9<>"","To-Do (hard requirements) "&CHAR(10)&$N9&CHAR(10)&CHAR(10),"")& IF($O9<>"","Suggested Timeline "&CHAR(10)&$O9&CHAR(10)&CHAR(10),"")& IF($P9<>"","Guardrails "&CHAR(10)&$P9&CHAR(10)&CHAR(10),"")& IF($Q9<>"","Completion signals "&CHAR(10)&$Q9,"") | S9: Planned | U9: 46047.5 | V9: =IF($B9="","",IF(_xludf.TEXTJOIN(" | ",TRUE,IF($B9="","Missing Title",""),IF($C9="","Missing Date",""),IF($D9="","Missing Start",""),IF($E9="","Missing End",""),IF($G9="","Missing Required Attendees",""),IF($T9="","Missing Status",""),IF(AND($D9<>"",$E9<>"",$D9>=$E9),"Start>=End",""),IF(OR($R9="",LEN($R9)<60,ISNUMBER(MATCH(TRIM($R9),StatusList,0))),"Body overwritten/short",""))="","OK",_xludf.TEXTJOIN(" | ",TRUE,IF($B9="","Missing Title",""),IF($C9="","Missing Date",""),IF($D9="","Missing Start",""),IF($E9="","Missing End",""),IF($G9="","Missing Required Attendees",""),IF($T9="","Missing Status",""),IF(AND($D9<>"",$E9<>"",$D9>=$E9),"Start>=End",""),IF(OR($R9="",LEN($R9)<60,ISNUMBER(MATCH(TRIM($R9),StatusList,0))),"Body overwritten/short",""))))
A10: =IF(AND($B10<>"",$C10<>"",$D10<>"",$E10<>"",$G10<>""), UPPER( LEFT(TRIM(LEFT($G10,IFERROR(FIND(";",$G10)-1,999))),1)& IFERROR( MID(TRIM(LEFT($G10,IFERROR(FIND(";",$G10)-1,999))), FIND(" ",TRIM(LEFT($G10,IFERROR(FIND(";",$G10)-1,999))))+1,1), MID(TRIM(LEFT($G10,IFERROR(FIND(";",$G10)-1,999))),2,1) ) )&"-"&TEXT($C10,"yyyy-mm-dd"), "") | B10: Cybernet Deployment + iPad Go-Live Support (Senior + Shadow) | C10: 46052 | D10: 0.375 | E10: 0.70833333 | F10: Local | G10: Geoff Gerber; Chris Cummings | H10: Rich Perez | I10: Client Site — Cybernet Go-Live | J10: Busy | K10: 30 | L10: Deploy Cybernets and provide all-day go-live support. Client paid for 1 senior tech (Geoff) with 1 shadow tech (Chris Cummings). Stock: Geoff to have 2 Cybernets. iPad: already delivered last Friday. | M10: 1) HQ/warehouse (if needed): pull/verify 2 Cybernets for Geoff (asset tags/serials recorded). 2) Client site: confirm iPad onsite, deploy Cybernets, provide go-live support all day. 3) End-of-day: document issues + send completion note. | N10: • Geoff must have 2 Cybernets ready for deployment • iPad is already onsite (verify on arrival) • Chris shadows Geoff the full day • Log go-live issues + escalate blockers immediately | O10: AM: arrival + verify iPad + deploy Cybernets. Midday: stabilize + support go-live flow. PM: mop-up issues + handoff + send summary. | P10: No PHI in notes/photos. No silent substitutions. Escalate blockers same-day and document owners/next steps. | Q10: 2 Cybernets deployed/validated. Go-live support delivered all day. Issues/next steps logged. Completion update sent. | R10: =IF($L10<>"","Purpose "&CHAR(10)&$L10&CHAR(10)&CHAR(10),"")& IF($M10<>"","Stops (in order) "&CHAR(10)&$M10&CHAR(10)&CHAR(10),"")& IF($N10<>"","To-Do (hard requirements) "&CHAR(10)&$N10&CHAR(10)&CHAR(10),"")& IF($O10<>"","Suggested Timeline "&CHAR(10)&$O10&CHAR(10)&CHAR(10),"")& IF($P10<>"","Guardrails "&CHAR(10)&$P10&CHAR(10)&CHAR(10),"")& IF($Q10<>"","Completion signals "&CHAR(10)&$Q10,"") | U10: 46051.5 | V10: =IF($B10="","",IF(_xludf.TEXTJOIN(" | ",TRUE,IF($B10="","Missing Title",""),IF($C10="","Missing Date",""),IF($D10="","Missing Start",""),IF($E10="","Missing End",""),IF($G10="","Missing Required Attendees",""),IF($T10="","Missing Status",""),IF(AND($D10<>"",$E10<>"",$D10>=$E10),"Start>=End",""),IF(OR($R10="",LEN($R10)<60,ISNUMBER(MATCH(TRIM($R10),StatusList,0))),"Body overwritten/short",""))="","OK",_xludf.TEXTJOIN(" | ",TRUE,IF($B10="","Missing Title",""),IF($C10="","Missing Date",""),IF($D10="","Missing Start",""),IF($E10="","Missing End",""),IF($G10="","Missing Required Attendees",""),IF($T10="","Missing Status",""),IF(AND($D10<>"",$E10<>"",$D10>=$E10),"Start>=End",""),IF(OR($R10="",LEN($R10)<60,ISNUMBER(MATCH(TRIM($R10),StatusList,0))),"Body overwritten/short",""))))
A11: =IF(AND($B11<>"",$C11<>"",$D11<>"",$E11<>"",$G11<>""), UPPER( LEFT(TRIM(LEFT($G11,IFERROR(FIND(";",$G11)-1,999))),1)& IFERROR( MID(TRIM(LEFT($G11,IFERROR(FIND(";",$G11)-1,999))), FIND(" ",TRIM(LEFT($G11,IFERROR(FIND(";",$G11)-1,999))))+1,1), MID(TRIM(LEFT($G11,IFERROR(FIND(";",$G11)-1,999))),2,1) ) )&"-"&TEXT($C11,"yyyy-mm-dd"), "") | B11: CFAM — Deployment Support (One-Day Push) | C11: 46060 | D11: 0.375 | E11: 0.70833333 | F11: Local | G11: Asher Ali; Alejandro Pelales; Delroy Harris | H11: Patricia Marrero | I11: CFAM (Center for Advanced Medicine) | J11: Busy | K11: 30 | L11: Extra deployment coverage at CFAM to complete the work in one day (9–5). Focus: throughput, troubleshooting, and clean handoff. | M11: 1) 09:00 kickoff + scope check; 2) Stage devices + verify ready state; 3) Deploy + validate as you go; 4) Triage issues + escalate blockers fast; 5) 16:30 final sweep + handoff notes; 6) 17:00 exit | N11: Full 9–5 coverage; keep tracker updates current; call out blockers early; document exceptions; leave the site clean. | O11: 09:00 kickoff; 09:15 staging; 10:00 deployments rolling; 15:30 start final sweep; 16:30 handoff notes; 17:00 wrap | P11: No improvising scope changes; escalate access/permissions immediately; protect clinical areas; keep footprint minimal; avoid bottlenecks by working in parallel. | Q11: All assigned devices deployed + validated; exceptions logged with owner/next step; handoff notes sent same day. | R11: =IF($L11<>"","Purpose "&CHAR(10)&$L11&CHAR(10)&CHAR(10),"")& IF($M11<>"","Stops (in order) "&CHAR(10)&$M11&CHAR(10)&CHAR(10),"")& IF($N11<>"","To-Do (hard requirements) "&CHAR(10)&$N11&CHAR(10)&CHAR(10),"")& IF($O11<>"","Suggested Timeline "&CHAR(10)&$O11&CHAR(10)&CHAR(10),"")& IF($P11<>"","Guardrails "&CHAR(10)&$P11&CHAR(10)&CHAR(10),"")& IF($Q11<>"","Completion signals "&CHAR(10)&$Q11,"") | T11: Planned | U11: 46053 | V11: =IF($B11="","",IF(_xludf.TEXTJOIN(" | ",TRUE,IF($B11="","Missing Title",""),IF($C11="","Missing Date",""),IF($D11="","Missing Start",""),IF($E11="","Missing End",""),IF($G11="","Missing Required Attendees",""),IF($T11="","Missing Status",""),IF(AND($D11<>"",$E11<>"",$D11>=$E11),"Start>=End",""),IF(OR($R11="",LEN($R11)<60,ISNUMBER(MATCH(TRIM($R11),StatusList,0))),"Body overwritten/short",""))="","OK",_xludf.TEXTJOIN(" | ",TRUE,IF($B11="","Missing Title",""),IF($C11="","Missing Date",""),IF($D11="","Missing Start",""),IF($E11="","Missing End",""),IF($G11="","Missing Required Attendees",""),IF($T11="","Missing Status",""),IF(AND($D11<>"",$E11<>"",$D11>=$E11),"Start>=End",""),IF(OR($R11="",LEN($R11)<60,ISNUMBER(MATCH(TRIM($R11),StatusList,0))),"Body overwritten/short",""))))
A12: =IF(AND($B12<>"",$C12<>"",$D12<>"",$E12<>"",$G12<>""), UPPER( LEFT(TRIM(LEFT($G12,IFERROR(FIND(";",$G12)-1,999))),1)& IFERROR( MID(TRIM(LEFT($G12,IFERROR(FIND(";",$G12)-1,999))), FIND(" ",TRIM(LEFT($G12,IFERROR(FIND(";",$G12)-1,999))))+1,1), MID(TRIM(LEFT($G12,IFERROR(FIND(";",$G12)-1,999))),2,1) ) )&"-"&TEXT($C12,"yyyy-mm-dd"), "") | B12: LIJ SDF - Satellite Dialysis Facility - Testing Oversight (Noon-1) + Possible Cat6 Relay | C12: 46062 | D12: 0.45833333 | E12: 0.54166667 | F12: Local | G12: Khadejah Harrison | I12: LIJ SDF - Satellite Dialysis Facility | J12: Busy | K12: 30 | L12: Oversee testing support at LIJ SDF (testing window 12:00-1:00) and capture outcomes; relay up to 25 x 25-ft Cat6 cables if requested. | M12: 1) Check in with site POC + confirm testing station(s) | 2) Observe testing (12:00-1:00) + capture pass/fail/issues | 3) If requested: pull/relay 25 x 25-ft Cat6 to designated drop location | 4) Send completion note (testing results + any cable relay details) | N12: Arrive by 11:00 for setup/coordination | Document testing results (what passed/failed + owner/next step) | If Cat6 relay happens: verify count (25) and record destination | No PHI in notes/photos | Escalate blockers same-day | O12: 11:00 arrive + scope check | 12:00 testing start | 12:45 pre-wrap + confirm any cable request | 13:00 wrap + send update | P12: Keep footprint minimal in clinical areas | No PHI in notes/photos | If asked to move cables, confirm receiver + drop location before transport | Escalate access/permissions immediately | Q12: Testing observed and results captured | Issues logged with owner/next step | If Cat6 relay requested: count + destination documented | Completion update sent | R12: =IF($L12<>"","Purpose "&CHAR(10)&$L12&CHAR(10)&CHAR(10),"")& IF($M12<>"","Stops (in order) "&CHAR(10)&$M12&CHAR(10)&CHAR(10),"")& IF($N12<>"","To-Do (hard requirements) "&CHAR(10)&$N12&CHAR(10)&CHAR(10),"")& IF($O12<>"","Suggested Timeline "&CHAR(10)&$O12&CHAR(10)&CHAR(10),"")& IF($P12<>"","Guardrails "&CHAR(10)&$P12&CHAR(10)&CHAR(10),"")& IF($Q12<>"","Completion signals "&CHAR(10)&$Q12,"") | T12: Planned | U12: 46062 | V12: =IF($B12="","",IF(_xludf.TEXTJOIN(" | ",TRUE,IF($B12="","Missing Title",""),IF($C12="","Missing Date",""),IF($D12="","Missing Start",""),IF($E12="","Missing End",""),IF($G12="","Missing Required Attendees",""),IF($T12="","Missing Status",""),IF(AND($D12<>"",$E12<>"",$D12>=$E12),"Start>=End",""),IF(OR($R12="",LEN($R12)<60,ISNUMBER(MATCH(TRIM($R12),StatusList,0))),"Body overwritten/short",""))="","OK",_xludf.TEXTJOIN(" | ",TRUE,IF($B12="","Missing Title",""),IF($C12="","Missing Date",""),IF($D12="","Missing Start",""),IF($E12="","Missing End",""),IF($G12="","Missing Required Attendees",""),IF($T12="","Missing Status",""),IF(AND($D12<>"",$E12<>"",$D12>=$E12),"Start>=End",""),IF(OR($R12="",LEN($R12)<60,ISNUMBER(MATCH(TRIM($R12),StatusList,0))),"Body overwritten/short",""))))
A13: =IF(AND($B13<>"",$C13<>"",$D13<>"",$E13<>"",$G13<>""), UPPER( LEFT(TRIM(LEFT($G13,IFERROR(FIND(";",$G13)-1,999))),1)& IFERROR( MID(TRIM(LEFT($G13,IFERROR(FIND(";",$G13)-1,999))), FIND(" ",TRIM(LEFT($G13,IFERROR(FIND(";",$G13)-1,999))))+1,1), MID(TRIM(LEFT($G13,IFERROR(FIND(";",$G13)-1,999))),2,1) ) )&"-"&TEXT($C13,"yyyy-mm-dd"), "") | B13: Franklin Hospital (Valley Stream) - Peripheral Deployment (10 units) | C13: 46062 | D13: 0.70833333 | E13: 0.83333333 | F13: Local | G13: Marvin Tate; Khadejah Harrison | I13: Franklin Hospital - Valley Stream | J13: Busy | K13: 30 | L13: Deploy and validate 10 peripherals (barcode scanner(s), badge scanner(s), mouse, keyboard) at Franklin Hospital Valley Stream. | M13: 1) Check in + confirm target stations/rooms | 2) Stage peripherals + verify total count (10) | 3) Install/connect + functional test each unit as you go | 4) Label/asset-tag as required | 5) Close-out: confirm counts + document placements/exceptions + send completion note | N13: Verify inventory count before leaving/onsite (10 total) | Test each peripheral immediately (badge read, barcode scan, keyboard/mouse input) | Keep cabling tidy | Log exceptions with owner/next step | No silent substitutions | O13: 17:00 kickoff + station list | 17:15 staging | 17:30 installs rolling | 19:30 final sweep + issue triage | 20:00 wrap + send update (end time may flex if needed) | P13: No PHI in notes/photos | Escalate port/driver/access blockers immediately | Keep footprint minimal and area clean | Avoid half-finished stations; finish and validate before moving on | Q13: 10 peripherals installed + tested | Exceptions logged with owner/next step | Completion update sent | R13: =IF($L13<>"","Purpose "&CHAR(10)&$L13&CHAR(10)&CHAR(10),"")& IF($M13<>"","Stops (in order) "&CHAR(10)&$M13&CHAR(10)&CHAR(10),"")& IF($N13<>"","To-Do (hard requirements) "&CHAR(10)&$N13&CHAR(10)&CHAR(10),"")& IF($O13<>"","Suggested Timeline "&CHAR(10)&$O13&CHAR(10)&CHAR(10),"")& IF($P13<>"","Guardrails "&CHAR(10)&$P13&CHAR(10)&CHAR(10),"")& IF($Q13<>"","Completion signals "&CHAR(10)&$Q13,"") | V13: =IF($B13="","",IF(_xludf.TEXTJOIN(" | ",TRUE,IF($B13="","Missing Title",""),IF($C13="","Missing Date",""),IF($D13="","Missing Start",""),IF($E13="","Missing End",""),IF($G13="","Missing Required Attendees",""),IF($T13="","Missing Status",""),IF(AND($D13<>"",$E13<>"",$D13>=$E13),"Start>=End",""),IF(OR($R13="",LEN($R13)<60,ISNUMBER(MATCH(TRIM($R13),StatusList,0))),"Body overwritten/short",""))="","OK",_xludf.TEXTJOIN(" | ",TRUE,IF($B13="","Missing Title",""),IF($C13="","Missing Date",""),IF($D13="","Missing Start",""),IF($E13="","Missing End",""),IF($G13="","Missing Required Attendees",""),IF($T13="","Missing Status",""),IF(AND($D13<>"",$E13<>"",$D13>=$E13),"Start>=End",""),IF(OR($R13="",LEN($R13)<60,ISNUMBER(MATCH(TRIM($R13),StatusList,0))),"Body overwritten/short",""))))
A14: =IF(AND($B14<>"",$C14<>"",$D14<>"",$E14<>"",$G14<>""), UPPER( LEFT(TRIM(LEFT($G14,IFERROR(FIND(";",$G14)-1,999))),1)& IFERROR( MID(TRIM(LEFT($G14,IFERROR(FIND(";",$G14)-1,999))), FIND(" ",TRIM(LEFT($G14,IFERROR(FIND(";",$G14)-1,999))))+1,1), MID(TRIM(LEFT($G14,IFERROR(FIND(";",$G14)-1,999))),2,1) ) )&"-"&TEXT($C14,"yyyy-mm-dd"), "") | B14: LIJVS — Device Integration Install/Testing (W2) | C14: 46062 | F14: Local | G14: Khadejah Harrison; Marvin Tate | H14: Richard Perez; Tim Seeberger | I14: LIJ Valley Stream | J14: Busy | K14: 15 | L14: Device Integration install/testing. Standard deployment kit applies. Endo MX550 requires MIB card (confirm qty). | R14: =IF($L14<>"","Purpose "&CHAR(10)&$L14&CHAR(10)&CHAR(10),"")& IF($M14<>"","Stops (in order) "&CHAR(10)&$M14&CHAR(10)&CHAR(10),"")& IF($N14<>"","To-Do (hard requirements) "&CHAR(10)&$N14&CHAR(10)&CHAR(10),"")& IF($O14<>"","Suggested Timeline "&CHAR(10)&$O14&CHAR(10)&CHAR(10),"")& IF($P14<>"","Guardrails "&CHAR(10)&$P14&CHAR(10)&CHAR(10),"")& IF($Q14<>"","Completion signals "&CHAR(10)&$Q14,"") | V14: =IF($B14="","",IF(_xludf.TEXTJOIN(" | ",TRUE,IF($B14="","Missing Title",""),IF($C14="","Missing Date",""),IF($D14="","Missing Start",""),IF($E14="","Missing End",""),IF($G14="","Missing Required Attendees",""),IF($T14="","Missing Status",""),IF(AND($D14<>"",$E14<>"",$D14>=$E14),"Start>=End",""),IF(OR($R14="",LEN($R14)<60,ISNUMBER(MATCH(TRIM($R14),StatusList,0))),"Body overwritten/short",""))="","OK",_xludf.TEXTJOIN(" | ",TRUE,IF($B14="","Missing Title",""),IF($C14="","Missing Date",""),IF($D14="","Missing Start",""),IF($E14="","Missing End",""),IF($G14="","Missing Required Attendees",""),IF($T14="","Missing Status",""),IF(AND($D14<>"",$E14<>"",$D14>=$E14),"Start>=End",""),IF(OR($R14="",LEN($R14)<60,ISNUMBER(MATCH(TRIM($R14),StatusList,0))),"Body overwritten/short",""))))
A15: =IF(AND($B15<>"",$C15<>"",$D15<>"",$E15<>"",$G15<>""), UPPER( LEFT(TRIM(LEFT($G15,IFERROR(FIND(";",$G15)-1,999))),1)& IFERROR( MID(TRIM(LEFT($G15,IFERROR(FIND(";",$G15)-1,999))), FIND(" ",TRIM(LEFT($G15,IFERROR(FIND(";",$G15)-1,999))))+1,1), MID(TRIM(LEFT($G15,IFERROR(FIND(";",$G15)-1,999))),2,1) ) )&"-"&TEXT($C15,"yyyy-mm-dd"), "") | B15: CCMC — Cybernet Deployment + iPro + OU Config (14 units) — ONE location | C15: 46067 | D15: 0.33333333 | E15: 0.75 | F15: Local | G15: Alejandro Perales; Chris Cummings; Nicholas Valentin | H15: Rich Perez; Tim Seeberger | I15: CCMC | J15: Busy | K15: 15 | L15: Deploy 14 Cybernets at CCMC (ONE location) with GCX arms + peripherals; complete iPro installs and OU/group alignment. | M15: 1) Stage 14 Cybernets + peripherals + GCX arms 2) Confirm ONE location with site POC 3) Remove/replace legacy PCs as needed 4) Install GCX arms + mount Cybernets 5) Install iPro 6) Apply OU/group alignment 7) Validate badge + barcode + connectivity 8) Label/cable-manage 9) Clean-up + prep disposal pile | N15: • 14 Anesthesia Machines Upgraded with New Cybernets & Peripherals • 14 Anesthesia Machine Deployments Documented in the tracker • Clarify the disposal path with Tim (1 Marcus until they give us permission to discard or allocate somewhere) | P15: • Activate PA Creds ahead of deployment | Q15: Devices Documented and Tested | R15: =IF($L15<>"","Purpose "&CHAR(10)&$L15&CHAR(10)&CHAR(10),"")& IF($M15<>"","Stops (in order) "&CHAR(10)&$M15&CHAR(10)&CHAR(10),"")& IF($N15<>"","To-Do (hard requirements) "&CHAR(10)&$N15&CHAR(10)&CHAR(10),"")& IF($O15<>"","Suggested Timeline "&CHAR(10)&$O15&CHAR(10)&CHAR(10),"")& IF($P15<>"","Guardrails "&CHAR(10)&$P15&CHAR(10)&CHAR(10),"")& IF($Q15<>"","Completion signals "&CHAR(10)&$Q15,"") | V15: =IF($B15="","",IF(_xludf.TEXTJOIN(" | ",TRUE,IF($B15="","Missing Title",""),IF($C15="","Missing Date",""),IF($D15="","Missing Start",""),IF($E15="","Missing End",""),IF($G15="","Missing Required Attendees",""),IF($T15="","Missing Status",""),IF(AND($D15<>"",$E15<>"",$D15>=$E15),"Start>=End",""),IF(OR($R15="",LEN($R15)<60,ISNUMBER(MATCH(TRIM($R15),StatusList,0))),"Body overwritten/short",""))="","OK",_xludf.TEXTJOIN(" | ",TRUE,IF($B15="","Missing Title",""),IF($C15="","Missing Date",""),IF($D15="","Missing Start",""),IF($E15="","Missing End",""),IF($G15="","Missing Required Attendees",""),IF($T15="","Missing Status",""),IF(AND($D15<>"",$E15<>"",$D15>=$E15),"Start>=End",""),IF(OR($R15="",LEN($R15)<60,ISNUMBER(MATCH(TRIM($R15),StatusList,0))),"Body overwritten/short",""))))
A16: =IF(AND($B16<>"",$C16<>"",$D16<>"",$E16<>"",$G16<>""), UPPER( LEFT(TRIM(LEFT($G16,IFERROR(FIND(";",$G16)-1,999))),1)& IFERROR( MID(TRIM(LEFT($G16,IFERROR(FIND(";",$G16)-1,999))), FIND(" ",TRIM(LEFT($G16,IFERROR(FIND(";",$G16)-1,999))))+1,1), MID(TRIM(LEFT($G16,IFERROR(FIND(";",$G16)-1,999))),2,1) ) )&"-"&TEXT($C16,"yyyy-mm-dd"), "") | B16: CCMC — HQ → Site Delivery (14 Cybernets + Peripherals) — Marvin | C16: 46066 | D16: 0.5 | E16: 0.66666667 | F16: Local | G16: Marvin Tate | H16: Richard Perez | I16: HQ → CCMC | J16: Busy | K16: 15 | L16: Deliver 13 Cybernets + peripherals from HQ to CCMC. Confirm staging location and handoff POC on arrival. | N16: Confirm vehicle/transport; confirm receiving contact; confirm inventory count (14). | R16: =IF($L16<>"","Purpose "&CHAR(10)&$L16&CHAR(10)&CHAR(10),"")& IF($M16<>"","Stops (in order) "&CHAR(10)&$M16&CHAR(10)&CHAR(10),"")& IF($N16<>"","To-Do (hard requirements) "&CHAR(10)&$N16&CHAR(10)&CHAR(10),"")& IF($O16<>"","Suggested Timeline "&CHAR(10)&$O16&CHAR(10)&CHAR(10),"")& IF($P16<>"","Guardrails "&CHAR(10)&$P16&CHAR(10)&CHAR(10),"")& IF($Q16<>"","Completion signals "&CHAR(10)&$Q16,"") | V16: =IF($B16="","",IF(_xludf.TEXTJOIN(" | ",TRUE,IF($B16="","Missing Title",""),IF($C16="","Missing Date",""),IF($D16="","Missing Start",""),IF($E16="","Missing End",""),IF($G16="","Missing Required Attendees",""),IF($T16="","Missing Status",""),IF(AND($D16<>"",$E16<>"",$D16>=$E16),"Start>=End",""),IF(OR($R16="",LEN($R16)<60,ISNUMBER(MATCH(TRIM($R16),StatusList,0))),"Body overwritten/short",""))="","OK",_xludf.TEXTJOIN(" | ",TRUE,IF($B16="","Missing Title",""),IF($C16="","Missing Date",""),IF($D16="","Missing Start",""),IF($E16="","Missing End",""),IF($G16="","Missing Required Attendees",""),IF($T16="","Missing Status",""),IF(AND($D16<>"",$E16<>"",$D16>=$E16),"Start>=End",""),IF(OR($R16="",LEN($R16)<60,ISNUMBER(MATCH(TRIM($R16),StatusList,0))),"Body overwritten/short",""))))
A17: =IF(AND($B17<>"",$C17<>"",$D17<>"",$E17<>"",$G17<>""), UPPER( LEFT(TRIM(LEFT($G17,IFERROR(FIND(";",$G17)-1,999))),1)& IFERROR( MID(TRIM(LEFT($G17,IFERROR(FIND(";",$G17)-1,999))), FIND(" ",TRIM(LEFT($G17,IFERROR(FIND(";",$G17)-1,999))))+1,1), MID(TRIM(LEFT($G17,IFERROR(FIND(";",$G17)-1,999))),2,1) ) )&"-"&TEXT($C17,"yyyy-mm-dd"), "") | B17: CCMC — Site Disposal (Post-Deployment) — Marvin Lead | C17: 46067 | D17: 0.58333333 | E17: 0.75 | F17: Local | G17: Marvin Tate | H17: Rich Perez; Tim Seeberger | I17: CCMC | J17: Busy | K17: 15 | L17: Dispose of all deployment-related materials at CCMC: existing PCs, existing PC arms, and all boxes/trash from newly deployed equipment. | M17: 1) Identify disposal area + confirm with site POC 2) Remove existing PCs 3) Remove existing arms 4) Consolidate all boxes/trash from new gear 5) Dispose per site process 6) Confirm area left clean + take quick photo evidence (optional) | N17: • All Extras and Scraps removed from CCMC • Clarify where to move the stock with Tim (1 Marcus until they give us permission to discard or allocate somewhere) | P17: • Activate PA Creds ahead of deployment | Q17: Photograph Clean Deployment Areas | R17: =IF($L17<>"","Purpose "&CHAR(10)&$L17&CHAR(10)&CHAR(10),"")& IF($M17<>"","Stops (in order) "&CHAR(10)&$M17&CHAR(10)&CHAR(10),"")& IF($N17<>"","To-Do (hard requirements) "&CHAR(10)&$N17&CHAR(10)&CHAR(10),"")& IF($O17<>"","Suggested Timeline "&CHAR(10)&$O17&CHAR(10)&CHAR(10),"")& IF($P17<>"","Guardrails "&CHAR(10)&$P17&CHAR(10)&CHAR(10),"")& IF($Q17<>"","Completion signals "&CHAR(10)&$Q17,"") | V17: =IF($B17="","",IF(_xludf.TEXTJOIN(" | ",TRUE,IF($B17="","Missing Title",""),IF($C17="","Missing Date",""),IF($D17="","Missing Start",""),IF($E17="","Missing End",""),IF($G17="","Missing Required Attendees",""),IF($T17="","Missing Status",""),IF(AND($D17<>"",$E17<>"",$D17>=$E17),"Start>=End",""),IF(OR($R17="",LEN($R17)<60,ISNUMBER(MATCH(TRIM($R17),StatusList,0))),"Body overwritten/short",""))="","OK",_xludf.TEXTJOIN(" | ",TRUE,IF($B17="","Missing Title",""),IF($C17="","Missing Date",""),IF($D17="","Missing Start",""),IF($E17="","Missing End",""),IF($G17="","Missing Required Attendees",""),IF($T17="","Missing Status",""),IF(AND($D17<>"",$E17<>"",$D17>=$E17),"Start>=End",""),IF(OR($R17="",LEN($R17)<60,ISNUMBER(MATCH(TRIM($R17),StatusList,0))),"Body overwritten/short",""))))
