Workbook

Sheet 00_Error_Log_Device_Config
A1: Row_ID | B1: Device Type | C1: Deployed | D1: Installed | E1: Cybernet Hostname | F1: Neuron Hostname | G1: Software List | H1: PI Use Case | I1: PI Result | J1: PI Validated By | K1: PI Validated Date | L1: Error Count | M1: Error Detail
A2: =ROW() -> 2 | B2: =IFERROR(INDEX(tblDeviceConfig[Device Type],ROW()-1),"") | C2: =IFERROR(INDEX(tblDeviceConfig[Deployed],ROW()-1),"") | D2: =IFERROR(INDEX(tblDeviceConfig[Installed],ROW()-1),"") | E2: =IFERROR(INDEX(tblDeviceConfig[Cybernet Hostname],ROW()-1),"") | F2: =IFERROR(INDEX(tblDeviceConfig[Neuron Hostname],ROW()-1),"") | G2: =IFERROR(INDEX(tblDeviceConfig[Software List],ROW()-1),"") | H2: =IFERROR(INDEX(tblDeviceConfig[PI_Use_Case],ROW()-1),"") | I2: =IFERROR(INDEX(tblDeviceConfig[PI_Result],ROW()-1),"") | J2: =IFERROR(INDEX(tblDeviceConfig[PI_Validated_By],ROW()-1),"") | K2: =IFERROR(INDEX(tblDeviceConfig[PI_Validated_Date],ROW()-1),"") | L2: =SUM(IF(AND(C2="Yes",B2="Cybernet",LEN(TRIM(E2))=0),1,0),IF(AND(C2="Yes",B2="Neuron",LEN(TRIM(F2))=0),1,0),IF(AND(C2="Yes",B2="Cybernet",LEN(TRIM(G2))=0),1,0),IF(AND(C2="Yes",B2="Cybernet",LEN(TRIM(H2))=0),1,0),IF(AND(C2="Yes",LEN(TRIM(I2))>0,LEN(TRIM(J2))=0),1,0),IF(AND(C2="Yes",LEN(TRIM(J2))>0,LEN(TRIM(K2))=0),1,0)) -> 0 | M2: =(IF(AND(C2="Yes",B2="Cybernet",LEN(TRIM(E2))=0),"Missing Cybernet Hostname",""))&IF(((IF(AND(C2="Yes",B2="Cybernet",LEN(TRIM(E2))=0),"Missing Cybernet Hostname","")))<>"",IF((IF(AND(C2="Yes",B2="Neuron",LEN(TRIM(F2))=0),"Missing Neuron Hostname",""))<>""," | ",""),"")&(IF(AND(C2="Yes",B2="Neuron",LEN(TRIM(F2))=0),"Missing Neuron Hostname",""))&IF(((IF(AND(C2="Yes",B2="Cybernet",LEN(TRIM(E2))=0),"Missing Cybernet Hostname",""))&(IF(AND(C2="Yes",B2="Neuron",LEN(TRIM(F2))=0),"Missing Neuron Hostname","")))<>"",IF((IF(AND(C2="Yes",B2="Cybernet",LEN(TRIM(G2))=0),"Missing Software List",""))<>""," | ",""),"")&(IF(AND(C2="Yes",B2="Cybernet",LEN(TRIM(G2))=0),"Missing Software List",""))&IF(((IF(AND(C2="Yes",B2="Cybernet",LEN(TRIM(E2))=0),"Missing Cybernet Hostname",""))&(IF(AND(C2="Yes",B2="Neuron",LEN(TRIM(F2))=0),"Missing Neuron Hostname",""))&(IF(AND(C2="Yes",B2="Cybernet",LEN(TRIM(G2))=0),"Missing Software List","")))<>"",IF((IF(AND(C2="Yes",B2="Cybernet",LEN(TRIM(H2))=0),"Missing PI Use Case",""))<>""," | ",""),"")&(IF(AND(C2="Yes",B2="Cybernet",LEN(TRIM(H2))=0),"Missing PI Use Case",""))&IF(((IF(AND(C2="Yes",B2="Cybernet",LEN(TRIM(E2))=0),"Missing Cybernet Hostname",""))&(IF(AND(C2="Yes",B2="Neuron",LEN(TRIM(F2))=0),"Missing Neuron Hostname",""))&(IF(AND(C2="Yes",B2="Cybernet",LEN(TRIM(G2))=0),"Missing Software List",""))&(IF(AND(C2="Yes",B2="Cybernet",LEN(TRIM(H2))=0),"Missing PI Use Case","")))<>"",IF((IF(AND(C2="Yes",LEN(TRIM(I2))>0,LEN(TRIM(J2))=0),"Missing PI Validated By",""))<>""," | ",""),"")&(IF(AND(C2="Yes",LEN(TRIM(I2))>0,LEN(TRIM(J2))=0),"Missing PI Validated By",""))&IF(((IF(AND(C2="Yes",B2="Cybernet",LEN(TRIM(E2))=0),"Missing Cybernet Hostname",""))&(IF(AND(C2="Yes",B2="Neuron",LEN(TRIM(F2))=0),"Missing Neuron Hostname",""))&(IF(AND(C2="Yes",B2="Cybernet",LEN(TRIM(G2))=0),"Missing Software List",""))&(IF(AND(C2="Yes",B2="Cybernet",LEN(TRIM(H2))=0),"Missing PI Use Case",""))&(IF(AND(C2="Yes",LEN(TRIM(I2))>0,LEN(TRIM(J2))=0),"Missing PI Validated By","")))<>"",IF((IF(AND(C2="Yes",LEN(TRIM(J2))>0,LEN(TRIM(K2))=0),"Missing PI Validated Date",""))<>""," | ",""),"")&(IF(AND(C2="Yes",LEN(TRIM(J2))>0,LEN(TRIM(K2))=0),"Missing PI Validated Date",""))
A3: =ROW() -> 3 | B3: =IFERROR(INDEX(tblDeviceConfig[Device Type],ROW()-1),"") | C3: =IFERROR(INDEX(tblDeviceConfig[Deployed],ROW()-1),"") | D3: =IFERROR(INDEX(tblDeviceConfig[Installed],ROW()-1),"") | E3: =IFERROR(INDEX(tblDeviceConfig[Cybernet Hostname],ROW()-1),"") | F3: =IFERROR(INDEX(tblDeviceConfig[Neuron Hostname],ROW()-1),"") | G3: =IFERROR(INDEX(tblDeviceConfig[Software List],ROW()-1),"") | H3: =IFERROR(INDEX(tblDeviceConfig[PI_Use_Case],ROW()-1),"") | I3: =IFERROR(INDEX(tblDeviceConfig[PI_Result],ROW()-1),"") | J3: =IFERROR(INDEX(tblDeviceConfig[PI_Validated_By],ROW()-1),"") | K3: =IFERROR(INDEX(tblDeviceConfig[PI_Validated_Date],ROW()-1),"") | L3: =SUM(IF(AND(C3="Yes",B3="Cybernet",LEN(TRIM(E3))=0),1,0),IF(AND(C3="Yes",B3="Neuron",LEN(TRIM(F3))=0),1,0),IF(AND(C3="Yes",B3="Cybernet",LEN(TRIM(G3))=0),1,0),IF(AND(C3="Yes",B3="Cybernet",LEN(TRIM(H3))=0),1,0),IF(AND(C3="Yes",LEN(TRIM(I3))>0,LEN(TRIM(J3))=0),1,0),IF(AND(C3="Yes",LEN(TRIM(J3))>0,LEN(TRIM(K3))=0),1,0)) -> 0 | M3: =(IF(AND(C3="Yes",B3="Cybernet",LEN(TRIM(E3))=0),"Missing Cybernet Hostname",""))&IF(((IF(AND(C3="Yes",B3="Cybernet",LEN(TRIM(E3))=0),"Missing Cybernet Hostname","")))<>"",IF((IF(AND(C3="Yes",B3="Neuron",LEN(TRIM(F3))=0),"Missing Neuron Hostname",""))<>""," | ",""),"")&(IF(AND(C3="Yes",B3="Neuron",LEN(TRIM(F3))=0),"Missing Neuron Hostname",""))&IF(((IF(AND(C3="Yes",B3="Cybernet",LEN(TRIM(E3))=0),"Missing Cybernet Hostname",""))&(IF(AND(C3="Yes",B3="Neuron",LEN(TRIM(F3))=0),"Missing Neuron Hostname","")))<>"",IF((IF(AND(C3="Yes",B3="Cybernet",LEN(TRIM(G3))=0),"Missing Software List",""))<>""," | ",""),"")&(IF(AND(C3="Yes",B3="Cybernet",LEN(TRIM(G3))=0),"Missing Software List",""))&IF(((IF(AND(C3="Yes",B3="Cybernet",LEN(TRIM(E3))=0),"Missing Cybernet Hostname",""))&(IF(AND(C3="Yes",B3="Neuron",LEN(TRIM(F3))=0),"Missing Neuron Hostname",""))&(IF(AND(C3="Yes",B3="Cybernet",LEN(TRIM(G3))=0),"Missing Software List","")))<>"",IF((IF(AND(C3="Yes",B3="Cybernet",LEN(TRIM(H3))=0),"Missing PI Use Case",""))<>""," | ",""),"")&(IF(AND(C3="Yes",B3="Cybernet",LEN(TRIM(H3))=0),"Missing PI Use Case",""))&IF(((IF(AND(C3="Yes",B3="Cybernet",LEN(TRIM(E3))=0),"Missing Cybernet Hostname",""))&(IF(AND(C3="Yes",B3="Neuron",LEN(TRIM(F3))=0),"Missing Neuron Hostname",""))&(IF(AND(C3="Yes",B3="Cybernet",LEN(TRIM(G3))=0),"Missing Software List",""))&(IF(AND(C3="Yes",B3="Cybernet",LEN(TRIM(H3))=0),"Missing PI Use Case","")))<>"",IF((IF(AND(C3="Yes",LEN(TRIM(I3))>0,LEN(TRIM(J3))=0),"Missing PI Validated By",""))<>""," | ",""),"")&(IF(AND(C3="Yes",LEN(TRIM(I3))>0,LEN(TRIM(J3))=0),"Missing PI Validated By",""))&IF(((IF(AND(C3="Yes",B3="Cybernet",LEN(TRIM(E3))=0),"Missing Cybernet Hostname",""))&(IF(AND(C3="Yes",B3="Neuron",LEN(TRIM(F3))=0),"Missing Neuron Hostname",""))&(IF(AND(C3="Yes",B3="Cybernet",LEN(TRIM(G3))=0),"Missing Software List",""))&(IF(AND(C3="Yes",B3="Cybernet",LEN(TRIM(H3))=0),"Missing PI Use Case",""))&(IF(AND(C3="Yes",LEN(TRIM(I3))>0,LEN(TRIM(J3))=0),"Missing PI Validated By","")))<>"",IF((IF(AND(C3="Yes",LEN(TRIM(J3))>0,LEN(TRIM(K3))=0),"Missing PI Validated Date",""))<>""," | ",""),"")&(IF(AND(C3="Yes",LEN(TRIM(J3))>0,LEN(TRIM(K3))=0),"Missing PI Validated Date",""))
A4: =ROW() -> 4 | B4: =IFERROR(INDEX(tblDeviceConfig[Device Type],ROW()-1),"") | C4: =IFERROR(INDEX(tblDeviceConfig[Deployed],ROW()-1),"") | D4: =IFERROR(INDEX(tblDeviceConfig[Installed],ROW()-1),"") | E4: =IFERROR(INDEX(tblDeviceConfig[Cybernet Hostname],ROW()-1),"") | F4: =IFERROR(INDEX(tblDeviceConfig[Neuron Hostname],ROW()-1),"") | G4: =IFERROR(INDEX(tblDeviceConfig[Software List],ROW()-1),"") | H4: =IFERROR(INDEX(tblDeviceConfig[PI_Use_Case],ROW()-1),"") | I4: =IFERROR(INDEX(tblDeviceConfig[PI_Result],ROW()-1),"") | J4: =IFERROR(INDEX(tblDeviceConfig[PI_Validated_By],ROW()-1),"") | K4: =IFERROR(INDEX(tblDeviceConfig[PI_Validated_Date],ROW()-1),"") | L4: =SUM(IF(AND(C4="Yes",B4="Cybernet",LEN(TRIM(E4))=0),1,0),IF(AND(C4="Yes",B4="Neuron",LEN(TRIM(F4))=0),1,0),IF(AND(C4="Yes",B4="Cybernet",LEN(TRIM(G4))=0),1,0),IF(AND(C4="Yes",B4="Cybernet",LEN(TRIM(H4))=0),1,0),IF(AND(C4="Yes",LEN(TRIM(I4))>0,LEN(TRIM(J4))=0),1,0),IF(AND(C4="Yes",LEN(TRIM(J4))>0,LEN(TRIM(K4))=0),1,0)) -> 0 | M4: =(IF(AND(C4="Yes",B4="Cybernet",LEN(TRIM(E4))=0),"Missing Cybernet Hostname",""))&IF(((IF(AND(C4="Yes",B4="Cybernet",LEN(TRIM(E4))=0),"Missing Cybernet Hostname","")))<>"",IF((IF(AND(C4="Yes",B4="Neuron",LEN(TRIM(F4))=0),"Missing Neuron Hostname",""))<>""," | ",""),"")&(IF(AND(C4="Yes",B4="Neuron",LEN(TRIM(F4))=0),"Missing Neuron Hostname",""))&IF(((IF(AND(C4="Yes",B4="Cybernet",LEN(TRIM(E4))=0),"Missing Cybernet Hostname",""))&(IF(AND(C4="Yes",B4="Neuron",LEN(TRIM(F4))=0),"Missing Neuron Hostname","")))<>"",IF((IF(AND(C4="Yes",B4="Cybernet",LEN(TRIM(G4))=0),"Missing Software List",""))<>""," | ",""),"")&(IF(AND(C4="Yes",B4="Cybernet",LEN(TRIM(G4))=0),"Missing Software List",""))&IF(((IF(AND(C4="Yes",B4="Cybernet",LEN(TRIM(E4))=0),"Missing Cybernet Hostname",""))&(IF(AND(C4="Yes",B4="Neuron",LEN(TRIM(F4))=0),"Missing Neuron Hostname",""))&(IF(AND(C4="Yes",B4="Cybernet",LEN(TRIM(G4))=0),"Missing Software List","")))<>"",IF((IF(AND(C4="Yes",B4="Cybernet",LEN(TRIM(H4))=0),"Missing PI Use Case",""))<>""," | ",""),"")&(IF(AND(C4="Yes",B4="Cybernet",LEN(TRIM(H4))=0),"Missing PI Use Case",""))&IF(((IF(AND(C4="Yes",B4="Cybernet",LEN(TRIM(E4))=0),"Missing Cybernet Hostname",""))&(IF(AND(C4="Yes",B4="Neuron",LEN(TRIM(F4))=0),"Missing Neuron Hostname",""))&(IF(AND(C4="Yes",B4="Cybernet",LEN(TRIM(G4))=0),"Missing Software List",""))&(IF(AND(C4="Yes",B4="Cybernet",LEN(TRIM(H4))=0),"Missing PI Use Case","")))<>"",IF((IF(AND(C4="Yes",LEN(TRIM(I4))>0,LEN(TRIM(J4))=0),"Missing PI Validated By",""))<>""," | ",""),"")&(IF(AND(C4="Yes",LEN(TRIM(I4))>0,LEN(TRIM(J4))=0),"Missing PI Validated By",""))&IF(((IF(AND(C4="Yes",B4="Cybernet",LEN(TRIM(E4))=0),"Missing Cybernet Hostname",""))&(IF(AND(C4="Yes",B4="Neuron",LEN(TRIM(F4))=0),"Missing Neuron Hostname",""))&(IF(AND(C4="Yes",B4="Cybernet",LEN(TRIM(G4))=0),"Missing Software List",""))&(IF(AND(C4="Yes",B4="Cybernet",LEN(TRIM(H4))=0),"Missing PI Use Case",""))&(IF(AND(C4="Yes",LEN(TRIM(I4))>0,LEN(TRIM(J4))=0),"Missing PI Validated By","")))<>"",IF((IF(AND(C4="Yes",LEN(TRIM(J4))>0,LEN(TRIM(K4))=0),"Missing PI Validated Date",""))<>""," | ",""),"")&(IF(AND(C4="Yes",LEN(TRIM(J4))>0,LEN(TRIM(K4))=0),"Missing PI Validated Date",""))
A5: =ROW() -> 5 | B5: =IFERROR(INDEX(tblDeviceConfig[Device Type],ROW()-1),"") | C5: =IFERROR(INDEX(tblDeviceConfig[Deployed],ROW()-1),"") | D5: =IFERROR(INDEX(tblDeviceConfig[Installed],ROW()-1),"") | E5: =IFERROR(INDEX(tblDeviceConfig[Cybernet Hostname],ROW()-1),"") | F5: =IFERROR(INDEX(tblDeviceConfig[Neuron Hostname],ROW()-1),"") | G5: =IFERROR(INDEX(tblDeviceConfig[Software List],ROW()-1),"") | H5: =IFERROR(INDEX(tblDeviceConfig[PI_Use_Case],ROW()-1),"") | I5: =IFERROR(INDEX(tblDeviceConfig[PI_Result],ROW()-1),"") | J5: =IFERROR(INDEX(tblDeviceConfig[PI_Validated_By],ROW()-1),"") | K5: =IFERROR(INDEX(tblDeviceConfig[PI_Validated_Date],ROW()-1),"") | L5: =SUM(IF(AND(C5="Yes",B5="Cybernet",LEN(TRIM(E5))=0),1,0),IF(AND(C5="Yes",B5="Neuron",LEN(TRIM(F5))=0),1,0),IF(AND(C5="Yes",B5="Cybernet",LEN(TRIM(G5))=0),1,0),IF(AND(C5="Yes",B5="Cybernet",LEN(TRIM(H5))=0),1,0),IF(AND(C5="Yes",LEN(TRIM(I5))>0,LEN(TRIM(J5))=0),1,0),IF(AND(C5="Yes",LEN(TRIM(J5))>0,LEN(TRIM(K5))=0),1,0)) -> 0 | M5: =(IF(AND(C5="Yes",B5="Cybernet",LEN(TRIM(E5))=0),"Missing Cybernet Hostname",""))&IF(((IF(AND(C5="Yes",B5="Cybernet",LEN(TRIM(E5))=0),"Missing Cybernet Hostname","")))<>"",IF((IF(AND(C5="Yes",B5="Neuron",LEN(TRIM(F5))=0),"Missing Neuron Hostname",""))<>""," | ",""),"")&(IF(AND(C5="Yes",B5="Neuron",LEN(TRIM(F5))=0),"Missing Neuron Hostname",""))&IF(((IF(AND(C5="Yes",B5="Cybernet",LEN(TRIM(E5))=0),"Missing Cybernet Hostname",""))&(IF(AND(C5="Yes",B5="Neuron",LEN(TRIM(F5))=0),"Missing Neuron Hostname","")))<>"",IF((IF(AND(C5="Yes",B5="Cybernet",LEN(TRIM(G5))=0),"Missing Software List",""))<>""," | ",""),"")&(IF(AND(C5="Yes",B5="Cybernet",LEN(TRIM(G5))=0),"Missing Software List",""))&IF(((IF(AND(C5="Yes",B5="Cybernet",LEN(TRIM(E5))=0),"Missing Cybernet Hostname",""))&(IF(AND(C5="Yes",B5="Neuron",LEN(TRIM(F5))=0),"Missing Neuron Hostname",""))&(IF(AND(C5="Yes",B5="Cybernet",LEN(TRIM(G5))=0),"Missing Software List","")))<>"",IF((IF(AND(C5="Yes",B5="Cybernet",LEN(TRIM(H5))=0),"Missing PI Use Case",""))<>""," | ",""),"")&(IF(AND(C5="Yes",B5="Cybernet",LEN(TRIM(H5))=0),"Missing PI Use Case",""))&IF(((IF(AND(C5="Yes",B5="Cybernet",LEN(TRIM(E5))=0),"Missing Cybernet Hostname",""))&(IF(AND(C5="Yes",B5="Neuron",LEN(TRIM(F5))=0),"Missing Neuron Hostname",""))&(IF(AND(C5="Yes",B5="Cybernet",LEN(TRIM(G5))=0),"Missing Software List",""))&(IF(AND(C5="Yes",B5="Cybernet",LEN(TRIM(H5))=0),"Missing PI Use Case","")))<>"",IF((IF(AND(C5="Yes",LEN(TRIM(I5))>0,LEN(TRIM(J5))=0),"Missing PI Validated By",""))<>""," | ",""),"")&(IF(AND(C5="Yes",LEN(TRIM(I5))>0,LEN(TRIM(J5))=0),"Missing PI Validated By",""))&IF(((IF(AND(C5="Yes",B5="Cybernet",LEN(TRIM(E5))=0),"Missing Cybernet Hostname",""))&(IF(AND(C5="Yes",B5="Neuron",LEN(TRIM(F5))=0),"Missing Neuron Hostname",""))&(IF(AND(C5="Yes",B5="Cybernet",LEN(TRIM(G5))=0),"Missing Software List",""))&(IF(AND(C5="Yes",B5="Cybernet",LEN(TRIM(H5))=0),"Missing PI Use Case",""))&(IF(AND(C5="Yes",LEN(TRIM(I5))>0,LEN(TRIM(J5))=0),"Missing PI Validated By","")))<>"",IF((IF(AND(C5="Yes",LEN(TRIM(J5))>0,LEN(TRIM(K5))=0),"Missing PI Validated Date",""))<>""," | ",""),"")&(IF(AND(C5="Yes",LEN(TRIM(J5))>0,LEN(TRIM(K5))=0),"Missing PI Validated Date",""))
A6: =ROW() -> 6 | B6: =IFERROR(INDEX(tblDeviceConfig[Device Type],ROW()-1),"") | C6: =IFERROR(INDEX(tblDeviceConfig[Deployed],ROW()-1),"") | D6: =IFERROR(INDEX(tblDeviceConfig[Installed],ROW()-1),"") | E6: =IFERROR(INDEX(tblDeviceConfig[Cybernet Hostname],ROW()-1),"") | F6: =IFERROR(INDEX(tblDeviceConfig[Neuron Hostname],ROW()-1),"") | G6: =IFERROR(INDEX(tblDeviceConfig[Software List],ROW()-1),"") | H6: =IFERROR(INDEX(tblDeviceConfig[PI_Use_Case],ROW()-1),"") | I6: =IFERROR(INDEX(tblDeviceConfig[PI_Result],ROW()-1),"") | J6: =IFERROR(INDEX(tblDeviceConfig[PI_Validated_By],ROW()-1),"") | K6: =IFERROR(INDEX(tblDeviceConfig[PI_Validated_Date],ROW()-1),"") | L6: =SUM(IF(AND(C6="Yes",B6="Cybernet",LEN(TRIM(E6))=0),1,0),IF(AND(C6="Yes",B6="Neuron",LEN(TRIM(F6))=0),1,0),IF(AND(C6="Yes",B6="Cybernet",LEN(TRIM(G6))=0),1,0),IF(AND(C6="Yes",B6="Cybernet",LEN(TRIM(H6))=0),1,0),IF(AND(C6="Yes",LEN(TRIM(I6))>0,LEN(TRIM(J6))=0),1,0),IF(AND(C6="Yes",LEN(TRIM(J6))>0,LEN(TRIM(K6))=0),1,0)) -> 0 | M6: =(IF(AND(C6="Yes",B6="Cybernet",LEN(TRIM(E6))=0),"Missing Cybernet Hostname",""))&IF(((IF(AND(C6="Yes",B6="Cybernet",LEN(TRIM(E6))=0),"Missing Cybernet Hostname","")))<>"",IF((IF(AND(C6="Yes",B6="Neuron",LEN(TRIM(F6))=0),"Missing Neuron Hostname",""))<>""," | ",""),"")&(IF(AND(C6="Yes",B6="Neuron",LEN(TRIM(F6))=0),"Missing Neuron Hostname",""))&IF(((IF(AND(C6="Yes",B6="Cybernet",LEN(TRIM(E6))=0),"Missing Cybernet Hostname",""))&(IF(AND(C6="Yes",B6="Neuron",LEN(TRIM(F6))=0),"Missing Neuron Hostname","")))<>"",IF((IF(AND(C6="Yes",B6="Cybernet",LEN(TRIM(G6))=0),"Missing Software List",""))<>""," | ",""),"")&(IF(AND(C6="Yes",B6="Cybernet",LEN(TRIM(G6))=0),"Missing Software List",""))&IF(((IF(AND(C6="Yes",B6="Cybernet",LEN(TRIM(E6))=0),"Missing Cybernet Hostname",""))&(IF(AND(C6="Yes",B6="Neuron",LEN(TRIM(F6))=0),"Missing Neuron Hostname",""))&(IF(AND(C6="Yes",B6="Cybernet",LEN(TRIM(G6))=0),"Missing Software List","")))<>"",IF((IF(AND(C6="Yes",B6="Cybernet",LEN(TRIM(H6))=0),"Missing PI Use Case",""))<>""," | ",""),"")&(IF(AND(C6="Yes",B6="Cybernet",LEN(TRIM(H6))=0),"Missing PI Use Case",""))&IF(((IF(AND(C6="Yes",B6="Cybernet",LEN(TRIM(E6))=0),"Missing Cybernet Hostname",""))&(IF(AND(C6="Yes",B6="Neuron",LEN(TRIM(F6))=0),"Missing Neuron Hostname",""))&(IF(AND(C6="Yes",B6="Cybernet",LEN(TRIM(G6))=0),"Missing Software List",""))&(IF(AND(C6="Yes",B6="Cybernet",LEN(TRIM(H6))=0),"Missing PI Use Case","")))<>"",IF((IF(AND(C6="Yes",LEN(TRIM(I6))>0,LEN(TRIM(J6))=0),"Missing PI Validated By",""))<>""," | ",""),"")&(IF(AND(C6="Yes",LEN(TRIM(I6))>0,LEN(TRIM(J6))=0),"Missing PI Validated By",""))&IF(((IF(AND(C6="Yes",B6="Cybernet",LEN(TRIM(E6))=0),"Missing Cybernet Hostname",""))&(IF(AND(C6="Yes",B6="Neuron",LEN(TRIM(F6))=0),"Missing Neuron Hostname",""))&(IF(AND(C6="Yes",B6="Cybernet",LEN(TRIM(G6))=0),"Missing Software List",""))&(IF(AND(C6="Yes",B6="Cybernet",LEN(TRIM(H6))=0),"Missing PI Use Case",""))&(IF(AND(C6="Yes",LEN(TRIM(I6))>0,LEN(TRIM(J6))=0),"Missing PI Validated By","")))<>"",IF((IF(AND(C6="Yes",LEN(TRIM(J6))>0,LEN(TRIM(K6))=0),"Missing PI Validated Date",""))<>""," | ",""),"")&(IF(AND(C6="Yes",LEN(TRIM(J6))>0,LEN(TRIM(K6))=0),"Missing PI Validated Date",""))
A7: =ROW() -> 7 | B7: =IFERROR(INDEX(tblDeviceConfig[Device Type],ROW()-1),"") | C7: =IFERROR(INDEX(tblDeviceConfig[Deployed],ROW()-1),"") | D7: =IFERROR(INDEX(tblDeviceConfig[Installed],ROW()-1),"") | E7: =IFERROR(INDEX(tblDeviceConfig[Cybernet Hostname],ROW()-1),"") | F7: =IFERROR(INDEX(tblDeviceConfig[Neuron Hostname],ROW()-1),"") | G7: =IFERROR(INDEX(tblDeviceConfig[Software List],ROW()-1),"") | H7: =IFERROR(INDEX(tblDeviceConfig[PI_Use_Case],ROW()-1),"") | I7: =IFERROR(INDEX(tblDeviceConfig[PI_Result],ROW()-1),"") | J7: =IFERROR(INDEX(tblDeviceConfig[PI_Validated_By],ROW()-1),"") | K7: =IFERROR(INDEX(tblDeviceConfig[PI_Validated_Date],ROW()-1),"") | L7: =SUM(IF(AND(C7="Yes",B7="Cybernet",LEN(TRIM(E7))=0),1,0),IF(AND(C7="Yes",B7="Neuron",LEN(TRIM(F7))=0),1,0),IF(AND(C7="Yes",B7="Cybernet",LEN(TRIM(G7))=0),1,0),IF(AND(C7="Yes",B7="Cybernet",LEN(TRIM(H7))=0),1,0),IF(AND(C7="Yes",LEN(TRIM(I7))>0,LEN(TRIM(J7))=0),1,0),IF(AND(C7="Yes",LEN(TRIM(J7))>0,LEN(TRIM(K7))=0),1,0)) -> 0 | M7: =(IF(AND(C7="Yes",B7="Cybernet",LEN(TRIM(E7))=0),"Missing Cybernet Hostname",""))&IF(((IF(AND(C7="Yes",B7="Cybernet",LEN(TRIM(E7))=0),"Missing Cybernet Hostname","")))<>"",IF((IF(AND(C7="Yes",B7="Neuron",LEN(TRIM(F7))=0),"Missing Neuron Hostname",""))<>""," | ",""),"")&(IF(AND(C7="Yes",B7="Neuron",LEN(TRIM(F7))=0),"Missing Neuron Hostname",""))&IF(((IF(AND(C7="Yes",B7="Cybernet",LEN(TRIM(E7))=0),"Missing Cybernet Hostname",""))&(IF(AND(C7="Yes",B7="Neuron",LEN(TRIM(F7))=0),"Missing Neuron Hostname","")))<>"",IF((IF(AND(C7="Yes",B7="Cybernet",LEN(TRIM(G7))=0),"Missing Software List",""))<>""," | ",""),"")&(IF(AND(C7="Yes",B7="Cybernet",LEN(TRIM(G7))=0),"Missing Software List",""))&IF(((IF(AND(C7="Yes",B7="Cybernet",LEN(TRIM(E7))=0),"Missing Cybernet Hostname",""))&(IF(AND(C7="Yes",B7="Neuron",LEN(TRIM(F7))=0),"Missing Neuron Hostname",""))&(IF(AND(C7="Yes",B7="Cybernet",LEN(TRIM(G7))=0),"Missing Software List","")))<>"",IF((IF(AND(C7="Yes",B7="Cybernet",LEN(TRIM(H7))=0),"Missing PI Use Case",""))<>""," | ",""),"")&(IF(AND(C7="Yes",B7="Cybernet",LEN(TRIM(H7))=0),"Missing PI Use Case",""))&IF(((IF(AND(C7="Yes",B7="Cybernet",LEN(TRIM(E7))=0),"Missing Cybernet Hostname",""))&(IF(AND(C7="Yes",B7="Neuron",LEN(TRIM(F7))=0),"Missing Neuron Hostname",""))&(IF(AND(C7="Yes",B7="Cybernet",LEN(TRIM(G7))=0),"Missing Software List",""))&(IF(AND(C7="Yes",B7="Cybernet",LEN(TRIM(H7))=0),"Missing PI Use Case","")))<>"",IF((IF(AND(C7="Yes",LEN(TRIM(I7))>0,LEN(TRIM(J7))=0),"Missing PI Validated By",""))<>""," | ",""),"")&(IF(AND(C7="Yes",LEN(TRIM(I7))>0,LEN(TRIM(J7))=0),"Missing PI Validated By",""))&IF(((IF(AND(C7="Yes",B7="Cybernet",LEN(TRIM(E7))=0),"Missing Cybernet Hostname",""))&(IF(AND(C7="Yes",B7="Neuron",LEN(TRIM(F7))=0),"Missing Neuron Hostname",""))&(IF(AND(C7="Yes",B7="Cybernet",LEN(TRIM(G7))=0),"Missing Software List",""))&(IF(AND(C7="Yes",B7="Cybernet",LEN(TRIM(H7))=0),"Missing PI Use Case",""))&(IF(AND(C7="Yes",LEN(TRIM(I7))>0,LEN(TRIM(J7))=0),"Missing PI Validated By","")))<>"",IF((IF(AND(C7="Yes",LEN(TRIM(J7))>0,LEN(TRIM(K7))=0),"Missing PI Validated Date",""))<>""," | ",""),"")&(IF(AND(C7="Yes",LEN(TRIM(J7))>0,LEN(TRIM(K7))=0),"Missing PI Validated Date",""))
A8: =ROW() -> 8 | B8: =IFERROR(INDEX(tblDeviceConfig[Device Type],ROW()-1),"") | C8: =IFERROR(INDEX(tblDeviceConfig[Deployed],ROW()-1),"") | D8: =IFERROR(INDEX(tblDeviceConfig[Installed],ROW()-1),"") | E8: =IFERROR(INDEX(tblDeviceConfig[Cybernet Hostname],ROW()-1),"") | F8: =IFERROR(INDEX(tblDeviceConfig[Neuron Hostname],ROW()-1),"") | G8: =IFERROR(INDEX(tblDeviceConfig[Software List],ROW()-1),"") | H8: =IFERROR(INDEX(tblDeviceConfig[PI_Use_Case],ROW()-1),"") | I8: =IFERROR(INDEX(tblDeviceConfig[PI_Result],ROW()-1),"") | J8: =IFERROR(INDEX(tblDeviceConfig[PI_Validated_By],ROW()-1),"") | K8: =IFERROR(INDEX(tblDeviceConfig[PI_Validated_Date],ROW()-1),"") | L8: =SUM(IF(AND(C8="Yes",B8="Cybernet",LEN(TRIM(E8))=0),1,0),IF(AND(C8="Yes",B8="Neuron",LEN(TRIM(F8))=0),1,0),IF(AND(C8="Yes",B8="Cybernet",LEN(TRIM(G8))=0),1,0),IF(AND(C8="Yes",B8="Cybernet",LEN(TRIM(H8))=0),1,0),IF(AND(C8="Yes",LEN(TRIM(I8))>0,LEN(TRIM(J8))=0),1,0),IF(AND(C8="Yes",LEN(TRIM(J8))>0,LEN(TRIM(K8))=0),1,0)) -> 0 | M8: =(IF(AND(C8="Yes",B8="Cybernet",LEN(TRIM(E8))=0),"Missing Cybernet Hostname",""))&IF(((IF(AND(C8="Yes",B8="Cybernet",LEN(TRIM(E8))=0),"Missing Cybernet Hostname","")))<>"",IF((IF(AND(C8="Yes",B8="Neuron",LEN(TRIM(F8))=0),"Missing Neuron Hostname",""))<>""," | ",""),"")&(IF(AND(C8="Yes",B8="Neuron",LEN(TRIM(F8))=0),"Missing Neuron Hostname",""))&IF(((IF(AND(C8="Yes",B8="Cybernet",LEN(TRIM(E8))=0),"Missing Cybernet Hostname",""))&(IF(AND(C8="Yes",B8="Neuron",LEN(TRIM(F8))=0),"Missing Neuron Hostname","")))<>"",IF((IF(AND(C8="Yes",B8="Cybernet",LEN(TRIM(G8))=0),"Missing Software List",""))<>""," | ",""),"")&(IF(AND(C8="Yes",B8="Cybernet",LEN(TRIM(G8))=0),"Missing Software List",""))&IF(((IF(AND(C8="Yes",B8="Cybernet",LEN(TRIM(E8))=0),"Missing Cybernet Hostname",""))&(IF(AND(C8="Yes",B8="Neuron",LEN(TRIM(F8))=0),"Missing Neuron Hostname",""))&(IF(AND(C8="Yes",B8="Cybernet",LEN(TRIM(G8))=0),"Missing Software List","")))<>"",IF((IF(AND(C8="Yes",B8="Cybernet",LEN(TRIM(H8))=0),"Missing PI Use Case",""))<>""," | ",""),"")&(IF(AND(C8="Yes",B8="Cybernet",LEN(TRIM(H8))=0),"Missing PI Use Case",""))&IF(((IF(AND(C8="Yes",B8="Cybernet",LEN(TRIM(E8))=0),"Missing Cybernet Hostname",""))&(IF(AND(C8="Yes",B8="Neuron",LEN(TRIM(F8))=0),"Missing Neuron Hostname",""))&(IF(AND(C8="Yes",B8="Cybernet",LEN(TRIM(G8))=0),"Missing Software List",""))&(IF(AND(C8="Yes",B8="Cybernet",LEN(TRIM(H8))=0),"Missing PI Use Case","")))<>"",IF((IF(AND(C8="Yes",LEN(TRIM(I8))>0,LEN(TRIM(J8))=0),"Missing PI Validated By",""))<>""," | ",""),"")&(IF(AND(C8="Yes",LEN(TRIM(I8))>0,LEN(TRIM(J8))=0),"Missing PI Validated By",""))&IF(((IF(AND(C8="Yes",B8="Cybernet",LEN(TRIM(E8))=0),"Missing Cybernet Hostname",""))&(IF(AND(C8="Yes",B8="Neuron",LEN(TRIM(F8))=0),"Missing Neuron Hostname",""))&(IF(AND(C8="Yes",B8="Cybernet",LEN(TRIM(G8))=0),"Missing Software List",""))&(IF(AND(C8="Yes",B8="Cybernet",LEN(TRIM(H8))=0),"Missing PI Use Case",""))&(IF(AND(C8="Yes",LEN(TRIM(I8))>0,LEN(TRIM(J8))=0),"Missing PI Validated By","")))<>"",IF((IF(AND(C8="Yes",LEN(TRIM(J8))>0,LEN(TRIM(K8))=0),"Missing PI Validated Date",""))<>""," | ",""),"")&(IF(AND(C8="Yes",LEN(TRIM(J8))>0,LEN(TRIM(K8))=0),"Missing PI Validated Date",""))
A9: =ROW() -> 9 | B9: =IFERROR(INDEX(tblDeviceConfig[Device Type],ROW()-1),"") | C9: =IFERROR(INDEX(tblDeviceConfig[Deployed],ROW()-1),"") | D9: =IFERROR(INDEX(tblDeviceConfig[Installed],ROW()-1),"") | E9: =IFERROR(INDEX(tblDeviceConfig[Cybernet Hostname],ROW()-1),"") | F9: =IFERROR(INDEX(tblDeviceConfig[Neuron Hostname],ROW()-1),"") | G9: =IFERROR(INDEX(tblDeviceConfig[Software List],ROW()-1),"") | H9: =IFERROR(INDEX(tblDeviceConfig[PI_Use_Case],ROW()-1),"") | I9: =IFERROR(INDEX(tblDeviceConfig[PI_Result],ROW()-1),"") | J9: =IFERROR(INDEX(tblDeviceConfig[PI_Validated_By],ROW()-1),"") | K9: =IFERROR(INDEX(tblDeviceConfig[PI_Validated_Date],ROW()-1),"") | L9: =SUM(IF(AND(C9="Yes",B9="Cybernet",LEN(TRIM(E9))=0),1,0),IF(AND(C9="Yes",B9="Neuron",LEN(TRIM(F9))=0),1,0),IF(AND(C9="Yes",B9="Cybernet",LEN(TRIM(G9))=0),1,0),IF(AND(C9="Yes",B9="Cybernet",LEN(TRIM(H9))=0),1,0),IF(AND(C9="Yes",LEN(TRIM(I9))>0,LEN(TRIM(J9))=0),1,0),IF(AND(C9="Yes",LEN(TRIM(J9))>0,LEN(TRIM(K9))=0),1,0)) -> 0 | M9: =(IF(AND(C9="Yes",B9="Cybernet",LEN(TRIM(E9))=0),"Missing Cybernet Hostname",""))&IF(((IF(AND(C9="Yes",B9="Cybernet",LEN(TRIM(E9))=0),"Missing Cybernet Hostname","")))<>"",IF((IF(AND(C9="Yes",B9="Neuron",LEN(TRIM(F9))=0),"Missing Neuron Hostname",""))<>""," | ",""),"")&(IF(AND(C9="Yes",B9="Neuron",LEN(TRIM(F9))=0),"Missing Neuron Hostname",""))&IF(((IF(AND(C9="Yes",B9="Cybernet",LEN(TRIM(E9))=0),"Missing Cybernet Hostname",""))&(IF(AND(C9="Yes",B9="Neuron",LEN(TRIM(F9))=0),"Missing Neuron Hostname","")))<>"",IF((IF(AND(C9="Yes",B9="Cybernet",LEN(TRIM(G9))=0),"Missing Software List",""))<>""," | ",""),"")&(IF(AND(C9="Yes",B9="Cybernet",LEN(TRIM(G9))=0),"Missing Software List",""))&IF(((IF(AND(C9="Yes",B9="Cybernet",LEN(TRIM(E9))=0),"Missing Cybernet Hostname",""))&(IF(AND(C9="Yes",B9="Neuron",LEN(TRIM(F9))=0),"Missing Neuron Hostname",""))&(IF(AND(C9="Yes",B9="Cybernet",LEN(TRIM(G9))=0),"Missing Software List","")))<>"",IF((IF(AND(C9="Yes",B9="Cybernet",LEN(TRIM(H9))=0),"Missing PI Use Case",""))<>""," | ",""),"")&(IF(AND(C9="Yes",B9="Cybernet",LEN(TRIM(H9))=0),"Missing PI Use Case",""))&IF(((IF(AND(C9="Yes",B9="Cybernet",LEN(TRIM(E9))=0),"Missing Cybernet Hostname",""))&(IF(AND(C9="Yes",B9="Neuron",LEN(TRIM(F9))=0),"Missing Neuron Hostname",""))&(IF(AND(C9="Yes",B9="Cybernet",LEN(TRIM(G9))=0),"Missing Software List",""))&(IF(AND(C9="Yes",B9="Cybernet",LEN(TRIM(H9))=0),"Missing PI Use Case","")))<>"",IF((IF(AND(C9="Yes",LEN(TRIM(I9))>0,LEN(TRIM(J9))=0),"Missing PI Validated By",""))<>""," | ",""),"")&(IF(AND(C9="Yes",LEN(TRIM(I9))>0,LEN(TRIM(J9))=0),"Missing PI Validated By",""))&IF(((IF(AND(C9="Yes",B9="Cybernet",LEN(TRIM(E9))=0),"Missing Cybernet Hostname",""))&(IF(AND(C9="Yes",B9="Neuron",LEN(TRIM(F9))=0),"Missing Neuron Hostname",""))&(IF(AND(C9="Yes",B9="Cybernet",LEN(TRIM(G9))=0),"Missing Software List",""))&(IF(AND(C9="Yes",B9="Cybernet",LEN(TRIM(H9))=0),"Missing PI Use Case",""))&(IF(AND(C9="Yes",LEN(TRIM(I9))>0,LEN(TRIM(J9))=0),"Missing PI Validated By","")))<>"",IF((IF(AND(C9="Yes",LEN(TRIM(J9))>0,LEN(TRIM(K9))=0),"Missing PI Validated Date",""))<>""," | ",""),"")&(IF(AND(C9="Yes",LEN(TRIM(J9))>0,LEN(TRIM(K9))=0),"Missing PI Validated Date",""))
A10: =ROW() -> 10 | B10: =IFERROR(INDEX(tblDeviceConfig[Device Type],ROW()-1),"") | C10: =IFERROR(INDEX(tblDeviceConfig[Deployed],ROW()-1),"") | D10: =IFERROR(INDEX(tblDeviceConfig[Installed],ROW()-1),"") | E10: =IFERROR(INDEX(tblDeviceConfig[Cybernet Hostname],ROW()-1),"") | F10: =IFERROR(INDEX(tblDeviceConfig[Neuron Hostname],ROW()-1),"") | G10: =IFERROR(INDEX(tblDeviceConfig[Software List],ROW()-1),"") | H10: =IFERROR(INDEX(tblDeviceConfig[PI_Use_Case],ROW()-1),"") | I10: =IFERROR(INDEX(tblDeviceConfig[PI_Result],ROW()-1),"") | J10: =IFERROR(INDEX(tblDeviceConfig[PI_Validated_By],ROW()-1),"") | K10: =IFERROR(INDEX(tblDeviceConfig[PI_Validated_Date],ROW()-1),"") | L10: =SUM(IF(AND(C10="Yes",B10="Cybernet",LEN(TRIM(E10))=0),1,0),IF(AND(C10="Yes",B10="Neuron",LEN(TRIM(F10))=0),1,0),IF(AND(C10="Yes",B10="Cybernet",LEN(TRIM(G10))=0),1,0),IF(AND(C10="Yes",B10="Cybernet",LEN(TRIM(H10))=0),1,0),IF(AND(C10="Yes",LEN(TRIM(I10))>0,LEN(TRIM(J10))=0),1,0),IF(AND(C10="Yes",LEN(TRIM(J10))>0,LEN(TRIM(K10))=0),1,0)) -> 0 | M10: =(IF(AND(C10="Yes",B10="Cybernet",LEN(TRIM(E10))=0),"Missing Cybernet Hostname",""))&IF(((IF(AND(C10="Yes",B10="Cybernet",LEN(TRIM(E10))=0),"Missing Cybernet Hostname","")))<>"",IF((IF(AND(C10="Yes",B10="Neuron",LEN(TRIM(F10))=0),"Missing Neuron Hostname",""))<>""," | ",""),"")&(IF(AND(C10="Yes",B10="Neuron",LEN(TRIM(F10))=0),"Missing Neuron Hostname",""))&IF(((IF(AND(C10="Yes",B10="Cybernet",LEN(TRIM(E10))=0),"Missing Cybernet Hostname",""))&(IF(AND(C10="Yes",B10="Neuron",LEN(TRIM(F10))=0),"Missing Neuron Hostname","")))<>"",IF((IF(AND(C10="Yes",B10="Cybernet",LEN(TRIM(G10))=0),"Missing Software List",""))<>""," | ",""),"")&(IF(AND(C10="Yes",B10="Cybernet",LEN(TRIM(G10))=0),"Missing Software List",""))&IF(((IF(AND(C10="Yes",B10="Cybernet",LEN(TRIM(E10))=0),"Missing Cybernet Hostname",""))&(IF(AND(C10="Yes",B10="Neuron",LEN(TRIM(F10))=0),"Missing Neuron Hostname",""))&(IF(AND(C10="Yes",B10="Cybernet",LEN(TRIM(G10))=0),"Missing Software List","")))<>"",IF((IF(AND(C10="Yes",B10="Cybernet",LEN(TRIM(H10))=0),"Missing PI Use Case",""))<>""," | ",""),"")&(IF(AND(C10="Yes",B10="Cybernet",LEN(TRIM(H10))=0),"Missing PI Use Case",""))&IF(((IF(AND(C10="Yes",B10="Cybernet",LEN(TRIM(E10))=0),"Missing Cybernet Hostname",""))&(IF(AND(C10="Yes",B10="Neuron",LEN(TRIM(F10))=0),"Missing Neuron Hostname",""))&(IF(AND(C10="Yes",B10="Cybernet",LEN(TRIM(G10))=0),"Missing Software List",""))&(IF(AND(C10="Yes",B10="Cybernet",LEN(TRIM(H10))=0),"Missing PI Use Case","")))<>"",IF((IF(AND(C10="Yes",LEN(TRIM(I10))>0,LEN(TRIM(J10))=0),"Missing PI Validated By",""))<>""," | ",""),"")&(IF(AND(C10="Yes",LEN(TRIM(I10))>0,LEN(TRIM(J10))=0),"Missing PI Validated By",""))&IF(((IF(AND(C10="Yes",B10="Cybernet",LEN(TRIM(E10))=0),"Missing Cybernet Hostname",""))&(IF(AND(C10="Yes",B10="Neuron",LEN(TRIM(F10))=0),"Missing Neuron Hostname",""))&(IF(AND(C10="Yes",B10="Cybernet",LEN(TRIM(G10))=0),"Missing Software List",""))&(IF(AND(C10="Yes",B10="Cybernet",LEN(TRIM(H10))=0),"Missing PI Use Case",""))&(IF(AND(C10="Yes",LEN(TRIM(I10))>0,LEN(TRIM(J10))=0),"Missing PI Validated By","")))<>"",IF((IF(AND(C10="Yes",LEN(TRIM(J10))>0,LEN(TRIM(K10))=0),"Missing PI Validated Date",""))<>""," | ",""),"")&(IF(AND(C10="Yes",LEN(TRIM(J10))>0,LEN(TRIM(K10))=0),"Missing PI Validated Date",""))
A11: =ROW() -> 11 | B11: =IFERROR(INDEX(tblDeviceConfig[Device Type],ROW()-1),"") | C11: =IFERROR(INDEX(tblDeviceConfig[Deployed],ROW()-1),"") | D11: =IFERROR(INDEX(tblDeviceConfig[Installed],ROW()-1),"") | E11: =IFERROR(INDEX(tblDeviceConfig[Cybernet Hostname],ROW()-1),"") | F11: =IFERROR(INDEX(tblDeviceConfig[Neuron Hostname],ROW()-1),"") | G11: =IFERROR(INDEX(tblDeviceConfig[Software List],ROW()-1),"") | H11: =IFERROR(INDEX(tblDeviceConfig[PI_Use_Case],ROW()-1),"") | I11: =IFERROR(INDEX(tblDeviceConfig[PI_Result],ROW()-1),"") | J11: =IFERROR(INDEX(tblDeviceConfig[PI_Validated_By],ROW()-1),"") | K11: =IFERROR(INDEX(tblDeviceConfig[PI_Validated_Date],ROW()-1),"") | L11: =SUM(IF(AND(C11="Yes",B11="Cybernet",LEN(TRIM(E11))=0),1,0),IF(AND(C11="Yes",B11="Neuron",LEN(TRIM(F11))=0),1,0),IF(AND(C11="Yes",B11="Cybernet",LEN(TRIM(G11))=0),1,0),IF(AND(C11="Yes",B11="Cybernet",LEN(TRIM(H11))=0),1,0),IF(AND(C11="Yes",LEN(TRIM(I11))>0,LEN(TRIM(J11))=0),1,0),IF(AND(C11="Yes",LEN(TRIM(J11))>0,LEN(TRIM(K11))=0),1,0)) -> 0 | M11: =(IF(AND(C11="Yes",B11="Cybernet",LEN(TRIM(E11))=0),"Missing Cybernet Hostname",""))&IF(((IF(AND(C11="Yes",B11="Cybernet",LEN(TRIM(E11))=0),"Missing Cybernet Hostname","")))<>"",IF((IF(AND(C11="Yes",B11="Neuron",LEN(TRIM(F11))=0),"Missing Neuron Hostname",""))<>""," | ",""),"")&(IF(AND(C11="Yes",B11="Neuron",LEN(TRIM(F11))=0),"Missing Neuron Hostname",""))&IF(((IF(AND(C11="Yes",B11="Cybernet",LEN(TRIM(E11))=0),"Missing Cybernet Hostname",""))&(IF(AND(C11="Yes",B11="Neuron",LEN(TRIM(F11))=0),"Missing Neuron Hostname","")))<>"",IF((IF(AND(C11="Yes",B11="Cybernet",LEN(TRIM(G11))=0),"Missing Software List",""))<>""," | ",""),"")&(IF(AND(C11="Yes",B11="Cybernet",LEN(TRIM(G11))=0),"Missing Software List",""))&IF(((IF(AND(C11="Yes",B11="Cybernet",LEN(TRIM(E11))=0),"Missing Cybernet Hostname",""))&(IF(AND(C11="Yes",B11="Neuron",LEN(TRIM(F11))=0),"Missing Neuron Hostname",""))&(IF(AND(C11="Yes",B11="Cybernet",LEN(TRIM(G11))=0),"Missing Software List","")))<>"",IF((IF(AND(C11="Yes",B11="Cybernet",LEN(TRIM(H11))=0),"Missing PI Use Case",""))<>""," | ",""),"")&(IF(AND(C11="Yes",B11="Cybernet",LEN(TRIM(H11))=0),"Missing PI Use Case",""))&IF(((IF(AND(C11="Yes",B11="Cybernet",LEN(TRIM(E11))=0),"Missing Cybernet Hostname",""))&(IF(AND(C11="Yes",B11="Neuron",LEN(TRIM(F11))=0),"Missing Neuron Hostname",""))&(IF(AND(C11="Yes",B11="Cybernet",LEN(TRIM(G11))=0),"Missing Software List",""))&(IF(AND(C11="Yes",B11="Cybernet",LEN(TRIM(H11))=0),"Missing PI Use Case","")))<>"",IF((IF(AND(C11="Yes",LEN(TRIM(I11))>0,LEN(TRIM(J11))=0),"Missing PI Validated By",""))<>""," | ",""),"")&(IF(AND(C11="Yes",LEN(TRIM(I11))>0,LEN(TRIM(J11))=0),"Missing PI Validated By",""))&IF(((IF(AND(C11="Yes",B11="Cybernet",LEN(TRIM(E11))=0),"Missing Cybernet Hostname",""))&(IF(AND(C11="Yes",B11="Neuron",LEN(TRIM(F11))=0),"Missing Neuron Hostname",""))&(IF(AND(C11="Yes",B11="Cybernet",LEN(TRIM(G11))=0),"Missing Software List",""))&(IF(AND(C11="Yes",B11="Cybernet",LEN(TRIM(H11))=0),"Missing PI Use Case",""))&(IF(AND(C11="Yes",LEN(TRIM(I11))>0,LEN(TRIM(J11))=0),"Missing PI Validated By","")))<>"",IF((IF(AND(C11="Yes",LEN(TRIM(J11))>0,LEN(TRIM(K11))=0),"Missing PI Validated Date",""))<>""," | ",""),"")&(IF(AND(C11="Yes",LEN(TRIM(J11))>0,LEN(TRIM(K11))=0),"Missing PI Validated Date",""))
A12: =ROW() -> 12 | B12: =IFERROR(INDEX(tblDeviceConfig[Device Type],ROW()-1),"") | C12: =IFERROR(INDEX(tblDeviceConfig[Deployed],ROW()-1),"") | D12: =IFERROR(INDEX(tblDeviceConfig[Installed],ROW()-1),"") | E12: =IFERROR(INDEX(tblDeviceConfig[Cybernet Hostname],ROW()-1),"") | F12: =IFERROR(INDEX(tblDeviceConfig[Neuron Hostname],ROW()-1),"") | G12: =IFERROR(INDEX(tblDeviceConfig[Software List],ROW()-1),"") | H12: =IFERROR(INDEX(tblDeviceConfig[PI_Use_Case],ROW()-1),"") | I12: =IFERROR(INDEX(tblDeviceConfig[PI_Result],ROW()-1),"") | J12: =IFERROR(INDEX(tblDeviceConfig[PI_Validated_By],ROW()-1),"") | K12: =IFERROR(INDEX(tblDeviceConfig[PI_Validated_Date],ROW()-1),"") | L12: =SUM(IF(AND(C12="Yes",B12="Cybernet",LEN(TRIM(E12))=0),1,0),IF(AND(C12="Yes",B12="Neuron",LEN(TRIM(F12))=0),1,0),IF(AND(C12="Yes",B12="Cybernet",LEN(TRIM(G12))=0),1,0),IF(AND(C12="Yes",B12="Cybernet",LEN(TRIM(H12))=0),1,0),IF(AND(C12="Yes",LEN(TRIM(I12))>0,LEN(TRIM(J12))=0),1,0),IF(AND(C12="Yes",LEN(TRIM(J12))>0,LEN(TRIM(K12))=0),1,0)) -> 0 | M12: =(IF(AND(C12="Yes",B12="Cybernet",LEN(TRIM(E12))=0),"Missing Cybernet Hostname",""))&IF(((IF(AND(C12="Yes",B12="Cybernet",LEN(TRIM(E12))=0),"Missing Cybernet Hostname","")))<>"",IF((IF(AND(C12="Yes",B12="Neuron",LEN(TRIM(F12))=0),"Missing Neuron Hostname",""))<>""," | ",""),"")&(IF(AND(C12="Yes",B12="Neuron",LEN(TRIM(F12))=0),"Missing Neuron Hostname",""))&IF(((IF(AND(C12="Yes",B12="Cybernet",LEN(TRIM(E12))=0),"Missing Cybernet Hostname",""))&(IF(AND(C12="Yes",B12="Neuron",LEN(TRIM(F12))=0),"Missing Neuron Hostname","")))<>"",IF((IF(AND(C12="Yes",B12="Cybernet",LEN(TRIM(G12))=0),"Missing Software List",""))<>""," | ",""),"")&(IF(AND(C12="Yes",B12="Cybernet",LEN(TRIM(G12))=0),"Missing Software List",""))&IF(((IF(AND(C12="Yes",B12="Cybernet",LEN(TRIM(E12))=0),"Missing Cybernet Hostname",""))&(IF(AND(C12="Yes",B12="Neuron",LEN(TRIM(F12))=0),"Missing Neuron Hostname",""))&(IF(AND(C12="Yes",B12="Cybernet",LEN(TRIM(G12))=0),"Missing Software List","")))<>"",IF((IF(AND(C12="Yes",B12="Cybernet",LEN(TRIM(H12))=0),"Missing PI Use Case",""))<>""," | ",""),"")&(IF(AND(C12="Yes",B12="Cybernet",LEN(TRIM(H12))=0),"Missing PI Use Case",""))&IF(((IF(AND(C12="Yes",B12="Cybernet",LEN(TRIM(E12))=0),"Missing Cybernet Hostname",""))&(IF(AND(C12="Yes",B12="Neuron",LEN(TRIM(F12))=0),"Missing Neuron Hostname",""))&(IF(AND(C12="Yes",B12="Cybernet",LEN(TRIM(G12))=0),"Missing Software List",""))&(IF(AND(C12="Yes",B12="Cybernet",LEN(TRIM(H12))=0),"Missing PI Use Case","")))<>"",IF((IF(AND(C12="Yes",LEN(TRIM(I12))>0,LEN(TRIM(J12))=0),"Missing PI Validated By",""))<>""," | ",""),"")&(IF(AND(C12="Yes",LEN(TRIM(I12))>0,LEN(TRIM(J12))=0),"Missing PI Validated By",""))&IF(((IF(AND(C12="Yes",B12="Cybernet",LEN(TRIM(E12))=0),"Missing Cybernet Hostname",""))&(IF(AND(C12="Yes",B12="Neuron",LEN(TRIM(F12))=0),"Missing Neuron Hostname",""))&(IF(AND(C12="Yes",B12="Cybernet",LEN(TRIM(G12))=0),"Missing Software List",""))&(IF(AND(C12="Yes",B12="Cybernet",LEN(TRIM(H12))=0),"Missing PI Use Case",""))&(IF(AND(C12="Yes",LEN(TRIM(I12))>0,LEN(TRIM(J12))=0),"Missing PI Validated By","")))<>"",IF((IF(AND(C12="Yes",LEN(TRIM(J12))>0,LEN(TRIM(K12))=0),"Missing PI Validated Date",""))<>""," | ",""),"")&(IF(AND(C12="Yes",LEN(TRIM(J12))>0,LEN(TRIM(K12))=0),"Missing PI Validated Date",""))
A13: =ROW() -> 13 | B13: =IFERROR(INDEX(tblDeviceConfig[Device Type],ROW()-1),"") | C13: =IFERROR(INDEX(tblDeviceConfig[Deployed],ROW()-1),"") | D13: =IFERROR(INDEX(tblDeviceConfig[Installed],ROW()-1),"") | E13: =IFERROR(INDEX(tblDeviceConfig[Cybernet Hostname],ROW()-1),"") | F13: =IFERROR(INDEX(tblDeviceConfig[Neuron Hostname],ROW()-1),"") | G13: =IFERROR(INDEX(tblDeviceConfig[Software List],ROW()-1),"") | H13: =IFERROR(INDEX(tblDeviceConfig[PI_Use_Case],ROW()-1),"") | I13: =IFERROR(INDEX(tblDeviceConfig[PI_Result],ROW()-1),"") | J13: =IFERROR(INDEX(tblDeviceConfig[PI_Validated_By],ROW()-1),"") | K13: =IFERROR(INDEX(tblDeviceConfig[PI_Validated_Date],ROW()-1),"") | L13: =SUM(IF(AND(C13="Yes",B13="Cybernet",LEN(TRIM(E13))=0),1,0),IF(AND(C13="Yes",B13="Neuron",LEN(TRIM(F13))=0),1,0),IF(AND(C13="Yes",B13="Cybernet",LEN(TRIM(G13))=0),1,0),IF(AND(C13="Yes",B13="Cybernet",LEN(TRIM(H13))=0),1,0),IF(AND(C13="Yes",LEN(TRIM(I13))>0,LEN(TRIM(J13))=0),1,0),IF(AND(C13="Yes",LEN(TRIM(J13))>0,LEN(TRIM(K13))=0),1,0)) -> 0 | M13: =(IF(AND(C13="Yes",B13="Cybernet",LEN(TRIM(E13))=0),"Missing Cybernet Hostname",""))&IF(((IF(AND(C13="Yes",B13="Cybernet",LEN(TRIM(E13))=0),"Missing Cybernet Hostname","")))<>"",IF((IF(AND(C13="Yes",B13="Neuron",LEN(TRIM(F13))=0),"Missing Neuron Hostname",""))<>""," | ",""),"")&(IF(AND(C13="Yes",B13="Neuron",LEN(TRIM(F13))=0),"Missing Neuron Hostname",""))&IF(((IF(AND(C13="Yes",B13="Cybernet",LEN(TRIM(E13))=0),"Missing Cybernet Hostname",""))&(IF(AND(C13="Yes",B13="Neuron",LEN(TRIM(F13))=0),"Missing Neuron Hostname","")))<>"",IF((IF(AND(C13="Yes",B13="Cybernet",LEN(TRIM(G13))=0),"Missing Software List",""))<>""," | ",""),"")&(IF(AND(C13="Yes",B13="Cybernet",LEN(TRIM(G13))=0),"Missing Software List",""))&IF(((IF(AND(C13="Yes",B13="Cybernet",LEN(TRIM(E13))=0),"Missing Cybernet Hostname",""))&(IF(AND(C13="Yes",B13="Neuron",LEN(TRIM(F13))=0),"Missing Neuron Hostname",""))&(IF(AND(C13="Yes",B13="Cybernet",LEN(TRIM(G13))=0),"Missing Software List","")))<>"",IF((IF(AND(C13="Yes",B13="Cybernet",LEN(TRIM(H13))=0),"Missing PI Use Case",""))<>""," | ",""),"")&(IF(AND(C13="Yes",B13="Cybernet",LEN(TRIM(H13))=0),"Missing PI Use Case",""))&IF(((IF(AND(C13="Yes",B13="Cybernet",LEN(TRIM(E13))=0),"Missing Cybernet Hostname",""))&(IF(AND(C13="Yes",B13="Neuron",LEN(TRIM(F13))=0),"Missing Neuron Hostname",""))&(IF(AND(C13="Yes",B13="Cybernet",LEN(TRIM(G13))=0),"Missing Software List",""))&(IF(AND(C13="Yes",B13="Cybernet",LEN(TRIM(H13))=0),"Missing PI Use Case","")))<>"",IF((IF(AND(C13="Yes",LEN(TRIM(I13))>0,LEN(TRIM(J13))=0),"Missing PI Validated By",""))<>""," | ",""),"")&(IF(AND(C13="Yes",LEN(TRIM(I13))>0,LEN(TRIM(J13))=0),"Missing PI Validated By",""))&IF(((IF(AND(C13="Yes",B13="Cybernet",LEN(TRIM(E13))=0),"Missing Cybernet Hostname",""))&(IF(AND(C13="Yes",B13="Neuron",LEN(TRIM(F13))=0),"Missing Neuron Hostname",""))&(IF(AND(C13="Yes",B13="Cybernet",LEN(TRIM(G13))=0),"Missing Software List",""))&(IF(AND(C13="Yes",B13="Cybernet",LEN(TRIM(H13))=0),"Missing PI Use Case",""))&(IF(AND(C13="Yes",LEN(TRIM(I13))>0,LEN(TRIM(J13))=0),"Missing PI Validated By","")))<>"",IF((IF(AND(C13="Yes",LEN(TRIM(J13))>0,LEN(TRIM(K13))=0),"Missing PI Validated Date",""))<>""," | ",""),"")&(IF(AND(C13="Yes",LEN(TRIM(J13))>0,LEN(TRIM(K13))=0),"Missing PI Validated Date",""))
... A532: =ROW() | B532: =IFERROR(INDEX(tblDeviceConfig[Device Type],ROW()-1),"") | C532: =IFERROR(INDEX(tblDeviceConfig[Deployed],ROW()-1),"") | D532: =IFERROR(INDEX(tblDeviceConfig[Installed],ROW()-1),"") | E532: =IFERROR(INDEX(tblDeviceConfig[Cybernet Hostname],ROW()-1),"") | F532: =IFERROR(INDEX(tblDeviceConfig[Neuron Hostname],ROW()-1),"") | G532: =IFERROR(INDEX(tblDeviceConfig[Software List],ROW()-1),"") | H532: =IFERROR(INDEX(tblDeviceConfig[PI_Use_Case],ROW()-1),"") | I532: =IFERROR(INDEX(tblDeviceConfig[PI_Result],ROW()-1),"") | J532: =IFERROR(INDEX(tblDeviceConfig[PI_Validated_By],ROW()-1),"") | K532: =IFERROR(INDEX(tblDeviceConfig[PI_Validated_Date],ROW()-1),"") | L532: =SUM(IF(AND(C532="Yes",B532="Cybernet",LEN(TRIM(E532))=0),1,0),IF(AND(C532="Yes",B532="Neuron",LEN(TRIM(F532))=0),1,0),IF(AND(C532="Yes",B532="Cybernet",LEN(TRIM(G532))=0),1,0),IF(AND(C532="Yes",B532="Cybernet",LEN(TRIM(H532))=0),1,0),IF(AND(C532="Yes",LEN(TRIM(I532))>0,LEN(TRIM(J532))=0),1,0),IF(AND(C532="Yes",LEN(TRIM(J532))>0,LEN(TRIM(K532))=0),1,0)) | M532: =(IF(AND(C532="Yes",B532="Cybernet",LEN(TRIM(E532))=0),"Missing Cybernet Hostname",""))&IF(((IF(AND(C532="Yes",B532="Cybernet",LEN(TRIM(E532))=0),"Missing Cybernet Hostname","")))<>"",IF((IF(AND(C532="Yes",B532="Neuron",LEN(TRIM(F532))=0),"Missing Neuron Hostname",""))<>""," | ",""),"")&(IF(AND(C532="Yes",B532="Neuron",LEN(TRIM(F532))=0),"Missing Neuron Hostname",""))&IF(((IF(AND(C532="Yes",B532="Cybernet",LEN(TRIM(E532))=0),"Missing Cybernet Hostname",""))&(IF(AND(C532="Yes",B532="Neuron",LEN(TRIM(F532))=0),"Missing Neuron Hostname","")))<>"",IF((IF(AND(C532="Yes",B532="Cybernet",LEN(TRIM(G532))=0),"Missing Software List",""))<>""," | ",""),"")&(IF(AND(C532="Yes",B532="Cybernet",LEN(TRIM(G532))=0),"Missing Software List",""))&IF(((IF(AND(C532="Yes",B532="Cybernet",LEN(TRIM(E532))=0),"Missing Cybernet Hostname",""))&(IF(AND(C532="Yes",B532="Neuron",LEN(TRIM(F532))=0),"Missing Neuron Hostname",""))&(IF(AND(C532="Yes",B532="Cybernet",LEN(TRIM(G532))=0),"Missing Software List","")))<>"",IF((IF(AND(C532="Yes",B532="Cybernet",LEN(TRIM(H532))=0),"Missing PI Use Case",""))<>""," | ",""),"")&(IF(AND(C532="Yes",B532="Cybernet",LEN(TRIM(H532))=0),"Missing PI Use Case",""))&IF(((IF(AND(C532="Yes",B532="Cybernet",LEN(TRIM(E532))=0),"Missing Cybernet Hostname",""))&(IF(AND(C532="Yes",B532="Neuron",LEN(TRIM(F532))=0),"Missing Neuron Hostname",""))&(IF(AND(C532="Yes",B532="Cybernet",LEN(TRIM(G532))=0),"Missing Software List",""))&(IF(AND(C532="Yes",B532="Cybernet",LEN(TRIM(H532))=0),"Missing PI Use Case","")))<>"",IF((IF(AND(C532="Yes",LEN(TRIM(I532))>0,LEN(TRIM(J532))=0),"Missing PI Validated By",""))<>""," | ",""),"")&(IF(AND(C532="Yes",LEN(TRIM(I532))>0,LEN(TRIM(J532))=0),"Missing PI Validated By",""))&IF(((IF(AND(C532="Yes",B532="Cybernet",LEN(TRIM(E532))=0),"Missing Cybernet Hostname",""))&(IF(AND(C532="Yes",B532="Neuron",LEN(TRIM(F532))=0),"Missing Neuron Hostname",""))&(IF(AND(C532="Yes",B532="Cybernet",LEN(TRIM(G532))=0),"Missing Software List",""))&(IF(AND(C532="Yes",B532="Cybernet",LEN(TRIM(H532))=0),"Missing PI Use Case",""))&(IF(AND(C532="Yes",LEN(TRIM(I532))>0,LEN(TRIM(J532))=0),"Missing PI Validated By","")))<>"",IF((IF(AND(C532="Yes",LEN(TRIM(J532))>0,LEN(TRIM(K532))=0),"Missing PI Validated Date",""))<>""," | ",""),"")&(IF(AND(C532="Yes",LEN(TRIM(J532))>0,LEN(TRIM(K532))=0),"Missing PI Validated Date",""))

Sheet 00_CF_Dictionary
A1: Sheet | B1: Table | C1: AppliesTo | D1: RuleType | E1: Priority | F1: Formula | G1: dxfId | H1: Purpose | I1: Color/category
A2: 00_Error_Log_Device_Config | B2: DeviceConfigErrorLog | C2: 12 - Device_Configuration!$A$2:$CC$532 | D2: expression | E2: 2 | F2: $L2>0 | G2: 44 | H2: Error flag (error count > 0) | I2: Red
A3: 00_Error_Log_Device_Config | B3: DeviceConfigErrorLog | C3: 12 - Device_Configuration!$BL$2:$CC$532 | D3: expression | E3: 3 | F3: $L2=0 | G3: 43 | H3: No errors (error count = 0) | I3: Green
A4: 00_Error_Log_Device_Config | B4: DeviceConfigErrorLog | C4: 12 - Device_Configuration!$D$2:$D$532 | D4: expression | E4: 4 | F4: $L2>0 | G4: 42 | H4: Missing config (data gap) | I4: Yellow
A5: 01_Warehouse_Ledger | C5: C8 | D5: expression | E5: 1 | F5: AND(TRIM($A8)="",OR($B8<>"",$C8<>"",$D8<>"",$E8<>"",$F8<>"",$I8<>"")) | G5: 37 | I5: FFF8CBAD
A6: 01_Warehouse_Ledger | C6: C8 | D6: expression | E6: 2 | F6: AND(TRIM($A8)<>"",COUNTIF($A$2:$A$2002,$A8)>1) | G6: 36 | I6: FFF8CBAD
A7: 01_Warehouse_Ledger | C7: A2:R7 A8:B8 A9:R2002 D8:R8 | D7: expression | E7: 3 | F7: AND(TRIM($A2)="",OR($B2<>"",$C2<>"",$D2<>"",$E2<>"",$I2<>"",$J2<>"")) | G7: 41 | I7: FFF8CBAD
A8: 01_Warehouse_Ledger | C8: A2:R7 A8:B8 A9:R2002 D8:R8 | D8: expression | E8: 4 | F8: AND(TRIM($A2)<>"",NOT(AND(LEFT($A2,4)="PAL-",LEN($A2)=11,ISNUMBER(--MID($A2,5,7))))) | G8: 40 | I8: FFF8CBAD
A9: 01_Warehouse_Ledger | C9: A2:R7 A8:B8 A9:R2002 D8:R8 | D9: expression | E9: 5 | F9: AND(TRIM($A2)<>"",COUNTIF($A$2:$A$2002,$A2)>1) | G9: 39 | I9: FFF8CBAD
A10: 01_Warehouse_Ledger | C10: A2:R7 A8:B8 A9:R2002 D8:R8 | D10: expression | E10: 6 | F10: AND(TRIM($A2)<>"",$C2<>"",$D2<>"",$D2<>"0",$C2<>$D2) | G10: 38 | I10: FFFFF2CC
A11: 02_Warehouse_Locations | C11: A133 | D11: expression | E11: 1 | F11: AND(TRIM($A133)="",OR($B133<>"",$C133<>"",$D133<>"",$E133<>"",$F133<>"",$I133<>"")) | G11: 35 | I11: FFF8CBAD
A12: 02_Warehouse_Locations | C12: A133 | D12: expression | E12: 2 | F12: AND(TRIM($A133)<>"",COUNTIF($A$2:$A$2002,$A133)>1) | G12: 34 | I12: FFF8CBAD
A13: 02_Warehouse_Locations | C13: A2:I132 A134:I2002 | D13: expression | E13: 3 | F13: AND(TRIM($A2)="",OR($B2<>"",$C2<>"",$D2<>"",$E2<>"",$F2<>"",$I2<>"")) | G13: 33 | I13: FFF8CBAD
A14: 02_Warehouse_Locations | C14: A2:I132 A134:I2002 | D14: expression | E14: 4 | F14: AND(TRIM($A2)<>"",COUNTIF($A$2:$A$2002,$A2)>1) | G14: 32 | I14: FFF8CBAD
A15: 02_Warehouse_Locations | C15: B133:I133 | D15: expression | E15: 116 | F15: AND(TRIM(#REF!)="",OR($B133<>"",$C133<>"",$D133<>"",$E133<>"",$F133<>"",$I133<>"")) | G15: 31 | I15: FFF8CBAD
A16: 02_Warehouse_Locations | C16: B133:I133 | D16: expression | E16: 117 | F16: AND(TRIM(#REF!)<>"",COUNTIF($A$2:$A$2002,#REF!)>1) | G16: 30 | I16: FFF8CBAD
... A23: 05_Scan_Lookup | C23: B3 | D23: expression | E23: 4 | F23: AND(TRIM($A3)<>"",$C3<>"",$D3<>"",$D3<>"0",$C3<>$D3) | G23: 23 | I23: FFFFF2CC
A24: 12 - Device_Configuration | B24: tblDeviceConfig | C24: 12 - Device_Configuration!$BL$2:$BL$532 | D24: expression | E24: 1 | F24: $F2="Yes" | G24: 0 | H24: Duplicates/conflicts (DupDeployed=Yes) | I24: Red
A25: 12 - Device_Configuration | B25: tblDeviceConfig | C25: 12 - Device_Configuration!$BM$2:$BM$532 | D25: expression | E25: 2 | F25: AND($A2="Cybernet",$B2="Yes",$C2<>"Yes",LEN(TRIM(R2))=0) | G25: 5 | H25: Cybernet Hostname required (pre-install) | I25: Yellow
A26: 12 - Device_Configuration | B26: tblDeviceConfig | C26: 12 - Device_Configuration!$BN$2:$BN$532 | D26: expression | E26: 3 | F26: AND($A2="Neuron",$B2="Yes",$C2<>"Yes",LEN(TRIM(S2))=0) | G26: 5 | H26: Neuron Hostname required (pre-install) | I26: Yellow
A27: 12 - Device_Configuration | B27: tblDeviceConfig | C27: 12 - Device_Configuration!$BO$2:$BO$532 | D27: expression | E27: 4 | F27: AND($A2="Cybernet",$B2="Yes",$C2<>"Yes",LEN(TRIM(BH2))=0) | G27: 5 | H27: Software_List required for Cybernet (pre-install) | I27: Yellow
A28: 12 - Device_Configuration | B28: tblDeviceConfig | C28: 12 - Device_Configuration!$BP$2:$BP$532 | D28: expression | E28: 5 | F28: AND($C2="Yes",LEN(TRIM(INDEX($1:$1048576,ROW(),COLUMN())))=0) | G28: 45 | H28: PI required fields (post-install: Installed=Yes) | I28: Purple
A29: 14 - Config Log | B29: tblConfigSnapshot | C29: I2:I503 | D29: expression | E29: 8 | F29: AND($I2<>"",OR($K2="Yes",$J2="PM Approved")) | G29: 6 | I29: Green
A30: 14 - Config Log | B30: tblConfigSnapshot | C30: I2:I503 | D30: expression | E30: 9 | F30: AND($I2<>"",NOT(OR($K2="Yes",$J2="PM Approved"))) | G30: 5 | I30: Yellow
A31: 14 - Config Log | B31: tblConfigSnapshot | C31: Q2:Q503 | D31: expression | E31: 10 | F31: Q2<>"" | G31: 4 | I31: Red
A32: 14 - Config Log | B32: tblConfigSnapshot | C32: R2:R503 | D32: expression | E32: 11 | F32: R2<>"" | G32: 3 | I32: FFFFE699
A33: 14 - Config Log | B33: tblConfigSnapshot | C33: S2:S503 | D33: expression | E33: 12 | F33: S2<>"" | G33: 2 | I33: FFFFE699
A34: 14 - Config Log | B34: tblConfigSnapshot | C34: T2:T503 | D34: expression | E34: 13 | F34: AND(T2<>"",T2="OK") | G34: 1 | I34: Green
A35: 14 - Config Log | B35: tblConfigSnapshot | C35: T2:T503 | D35: expression | E35: 14 | F35: AND(T2<>"",T2<>"OK") | G35: 0 | I35: Red
A36: 15 - Imaging Progress | C36: D1:D1048576 | D36: cellIs | E36: 1 | F36: 100% | G36: 12
A37: 15 - Imaging Progress | C37: F2:F14 | D37: cellIs | E37: 2 | F37: 20 | G37: 11
A38: 15 - Imaging Progress | C38: F2:F14 | D38: cellIs | E38: 3 | F38: 2 | G38: 10
A39: 15 - Imaging Progress | C39: F2:F14 | D39: cellIs | E39: 4 | F39: 6 | 9 | G39: 9
A40: 15 - Imaging Progress | C40: F2:F14 | D40: cellIs | E40: 5 | F40: 3 | 5 | G40: 8
A41: 15 - Imaging Progress | C41: F2:F15 | D41: cellIs | E41: 6 | F41: 10 | 20 | G41: 7

Sheet 00_README
A1: Use this sheet as the quick operating guide. Enter data only in the non-AUTO columns. For pallet moves, log the move once in 03_Warehouse_Movements and 01_Warehouse_Ledger updates itself.
A2: Task
A4: Go to tab | B4: Edit these columns | C4: Notes / outcome | D4: Add / update a pallet
A5: 01_Warehouse_Ledger | B5: A,B,C,E,F,G,I,J,K,L | C5: One row per pallet. Do NOT type in CurrentLocationCode / LastMove fields (AUTO). | D5: Move a pallet
A6: 03_Warehouse_Movements | B6: A,B,C,E,H,I,J (F,G optional) | C6: Add one movement row (MOVE / RECEIVE / SHIP / RETURN / etc). Ledger CurrentLocationCode + LastMoveTS update automatically. | D6: Add / update a location
A7: 02_Warehouse_Locations | B7: A–G,I | C7: One row per warehouse slot. QR_Payload auto = LocationCode. | D7: Print QR labels
A8: 04_Label_Export | B8: Nothing (auto list) | C8: Print LOCATION labels (top section) and PALLET labels (starts at row 505). QR payload stays minimal (LocationCode / PalletID). | D8: Find where a pallet is
A9: 05_Scan_Lookup | B9: Scan into B3 | C9: Scan Pallet QR -> see CurrentLocationCode + map fields instantly. | D9: Tie a device to a pallet
A10: BL (PalletID (Manual)) | B10: 12 - Device_Configuration | C10: Enter PalletID on the device row -> BM/BN/BO auto-fill Warehouse Location + Pallet Status + Last Move TS. | D10: Pallet moves - the 30-second routine
A13: 1)
A14: Go to 03_Warehouse_Movements and add a NEW row at the top of the data (first blank row). | B14: 2)
A15: Fill: Timestamp (A), Action (B)=MOVE, PalletID (C)=scan or type, ToLocation (E)=scan location code, ByWho (H), Ref (I) if relevant, Notes (J) if needed. Optional: Item (F) + Qty (G) if you are tracking contents. | B15: 3)
A16: Do NOT edit FromLocation (D). It auto-fills from the pallet’s prior state (based on 01_Warehouse_Ledger). | B16: 4)
A17: Sanity check: open 01_Warehouse_Ledger -> CurrentLocationCode (AUTO) and LastMoveTS (AUTO) should update for that PalletID. | B17: 5)
A18: Optional: if the move changed the pallet’s lifecycle (STAGED/DEPLOYED/RETURNED), update PalletStatus (E) on 01_Warehouse_Ledger. | B18: Data rules (don’t break the tracker)
A20: • Only type into columns that are NOT labeled (AUTO) or (deprecated).
A21: • PalletIDs must exist in 01_Warehouse_Ledger before you reference them anywhere else (moves, device config, contents, labels).
A22: • PalletID format enforced by the ledger CF: PAL-0000001 (PAL- + 7 digits). Duplicates highlight.
A23: • LocationCode: pick from 02_Warehouse_Locations (use dropdowns where present).
A24: • If a cell looks formula-driven, leave it alone. Don’t paste over formulas.
A25: • If you must paste, paste VALUES only (not formatting) into input columns.
A26: • When in doubt: use 05_Scan_Lookup to verify the pallet’s current location before moving anything.
A27: Quick troubleshooting
A29: • 05_Scan_Lookup shows blanks -> confirm you scanned a valid PalletID that exists in 01_Warehouse_Ledger column A.
A30: • Move row highlights -> check required fields in 03_Warehouse_Movements: Timestamp (A), Action (B), PalletID (C), ToLocation (E).
A31: • FromLocation (AUTO) stays blank -> the pallet is unknown to the ledger or has no prior location. Add the pallet to 01_Warehouse_Ledger, set HomeLocationCode (C), then re-enter the move row.
A32: • CurrentLocationCode not updating -> confirm 03_Warehouse_Movements has a row with that PalletID and a ToLocation value; then check 01_Warehouse_Ledger columns D and M for that pallet.
... A92: TOOLING ERROR LOG (AUTO-GENERATED)
A94: ErrID | B94: Layer | C94: Part | D94: What | E94: Why | F94: Fix | G94: QA | H94: Evidence
A95: E-011 | B95: packaging | C95: /xl/worksheets/sheet1.xml | D95: Excel repair replaced sheet1-3 (XML error) | E95: Sheet XML serialized with non-canonical namespace prefixes (ns0/ns1/ns2) after tool rewrite; Excel for Desktop treats as invalid and replaces parts. | F95: Rewrite worksheets 1-3 with canonical namespace prefixes (default worksheet namespace + mc + xr + r). Preserve all other parts byte-for-byte. | G95: Desktop open should not prompt repair; Web should open in Edit without 'Couldn't open workbook'. | H95: error066400_01.xml: replaced sheet1-3
A96: E-012 | B96: tables | C96: /xl/tables/table9.xml | D96: Excel repaired tblDeviceConfig table XML | E96: table9.xml schema or namespace mismatch triggered table repair in Desktop. | F96: Replace table9.xml with Active tblDeviceConfig table XML; set id=10; keep ref A1:CC532. | G96: Open in Desktop: no 'Repaired Records: Table ... table9.xml'. | H96: error066400_01.xml: repaired table9
A97: E-013 | B97: web | C97: Excel for Web open | D97: Web rejects workbook as corrupt/unsupported | E97: Desktop repair indicates underlying OOXML invalid in sheets 1-3 and/or table; Web hard-fails instead of repairing. | F97: After canonicalization + table9 replacement, upload new candidate and confirm Web opens. | G97: Open in Web: loads without modal; goes to last tab or activeTab; Device tab not blank. | H97: screenshot: 'Couldn't open workbook'

Sheet 01_Warehouse_Ledger
A1: PalletID | B1: HomeLocationCode | C1: CurrentLocationCode (AUTO) | D1: PalletStatus | E1: Compliance | F1: TTL_Days | G1: Expires (AUTO) | H1: ContentsSummary | I1: CreatedDate | J1: Notes | K1: CreatedBy | L1: LastMoveTS (AUTO) | M1: LastMovedBy (AUTO) | N1: QR_Payload_Pallet (deprecated) | O1: ReceiptDate (deprecated) | P1: Ref (deprecated) | Q1: Item (deprecated) | R1: QtyReceived (deprecated) | S1: Serials (deprecated) | T1: EnteredBy_RAW (deprecated) | U1: Legacy_RawInputs (deprecated) | V1: StockLines (AUTO) | W1: StockQtyTotal (AUTO) | X1: StockUniquePN (AUTO) | Y1: StockHasPN (AUTO) | Z1: PAL-0000001
A2: OVERFLOW-RICH-CYBERNETS-CFAM-CCMC | B2: CHRIS_OVERFLOW_A_ZONE3 | C2: ACTIVE | D2: =IF($C2="","",IFERROR(LOOKUP(2,1/('03_Warehouse_Movements'!$C$2:$C$500=$A2),'03_Warehouse_Movements'!$E$2:$E$500),$C2)) -> ACTIVE | E2: STANDARD | F2: CYBERNETS CFAM/CCMC QTY:15 | G2: 7 | H2: =IF(AND($F2="TEMP",$G2>0,$M2<>""),$M2+$G2,"") | I2: NORTHWELL NUERON PROJECT | J2: Alejandro Perales | K2: 46053 | L2: B:WH-Z1-A01-AISLE-FLOOR-02 F:OVERFLOW-<ClientLastName>-PO<PO>-<Category>-<Seq> D:WH-Z1-A01-AISLE-FLOOR-02 | M2: =IF($C2="","",IFERROR(LOOKUP(2,1/('03_Warehouse_Movements'!$C$2:$C$500=$A2),'03_Warehouse_Movements'!$A$2:$A$500),"")) | N2: =IF($C2="","",IFERROR(LOOKUP(2,1/('03_Warehouse_Movements'!$C$2:$C$500=$A2),'03_Warehouse_Movements'!$H$2:$H$500),"")) | O2: =A2 -> OVERFLOW-RICH-CYBERNETS-CFAM-CCMC | P2: 46284 | Q2: 144180 | V2: PAL-0000002 | W2: =IF($A2="","",COUNTIF('07_Pallet_Contents'!$A$2:$A$3000,$A2)) -> 0 | X2: =IF($A2="","",SUMIF('07_Pallet_Contents'!$A$2:$A$3000,$A2,'07_Pallet_Contents'!$D$2:$D$3000)) -> 0 | Y2: =IF($A2="","",SUMIF('07_Pallet_Contents'!$A$2:$A$3000,$A2,'07_Pallet_Contents'!$I$2:$I$3000)) -> 0 | Z2: =IF($A2="","",IF(COUNTIF('07_Pallet_Contents'!$A$2:$A$3000,$A2)>0,"Yes",""))
A3: WH-STAGE-IN | C3: STAGED | D3: =IF($C3="","",IFERROR(LOOKUP(2,1/('03_Warehouse_Movements'!$C$2:$C$500=$A3),'03_Warehouse_Movements'!$E$2:$E$500),$C3)) -> STAGED | E3: SAFE | F3: SAMPLE: Monitors 24-40 | H3: =IF(AND($F3="TEMP",$G3>0,$M3<>""),$M3+$G3,"") | I3: SAMPLE: replace with real notes / serials / constraints | J3: SAMPLE-TECH | K3: 46052 | L3: B:OVERFLOW-<ClientLastName>-PO<PO>-<Category>-<Seq> | M3: =IF($C3="","",IFERROR(LOOKUP(2,1/('03_Warehouse_Movements'!$C$2:$C$500=$A3),'03_Warehouse_Movements'!$A$2:$A$500),"")) | N3: =IF($C3="","",IFERROR(LOOKUP(2,1/('03_Warehouse_Movements'!$C$2:$C$500=$A3),'03_Warehouse_Movements'!$H$2:$H$500),"")) | O3: =A3 -> WH-STAGE-IN | V3: PAL-0000003 | W3: =IF($A2="","",COUNTIF('07_Pallet_Contents'!$A$2:$A$3000,$A2)) -> 0 | X3: =IF($A2="","",SUMIF('07_Pallet_Contents'!$A$2:$A$3000,$A2,'07_Pallet_Contents'!$D$2:$D$3000)) -> 0 | Y3: =IF($A2="","",SUMIF('07_Pallet_Contents'!$A$2:$A$3000,$A2,'07_Pallet_Contents'!$I$2:$I$3000)) -> 0 | Z3: =IF($A2="","",IF(COUNTIF('07_Pallet_Contents'!$A$2:$A$3000,$A2)>0,"Yes",""))
A4: OVERFLOW-CHRIS-UMAIR_TICKETS- | B4: CHRIS_OVERFLOW_A_ZONE1 | C4: UNSAFE | D4: =IF($C4="","",IFERROR(LOOKUP(2,1/('03_Warehouse_Movements'!$C$2:$C$500=$A4),'03_Warehouse_Movements'!$E$2:$E$500),$C4)) -> UNSAFE | E4: STANDARD | F4: Monitors T24-40 | H4: =IF(AND($F4="TEMP",$G4>0,$M4<>""),$M4+$G4,"") | I4: 24 Day Ticket | J4: B:OVERFLOW-CHRIS-UMAIR_TICKETS- D:CHRIS_OVERFLOW_A_ZONE1 | K4: 46046 | L4: B:WH-Z1-A01-AISLE-FLOOR-02 F:OVERFLOW-<ClientLastName>-PO<PO>-<Category>-<Seq> D:WH-Z1-A01-AISLE-FLOOR-02 | M4: =IF($C4="","",IFERROR(LOOKUP(2,1/('03_Warehouse_Movements'!$C$2:$C$500=$A4),'03_Warehouse_Movements'!$A$2:$A$500),"")) | N4: =IF($C4="","",IFERROR(LOOKUP(2,1/('03_Warehouse_Movements'!$C$2:$C$500=$A4),'03_Warehouse_Movements'!$H$2:$H$500),"")) | O4: =A4 -> OVERFLOW-CHRIS-UMAIR_TICKETS- | U4: 46046 | V4: PAL-0000004 | W4: =IF($A2="","",COUNTIF('07_Pallet_Contents'!$A$2:$A$3000,$A2)) -> 0 | X4: =IF($A2="","",SUMIF('07_Pallet_Contents'!$A$2:$A$3000,$A2,'07_Pallet_Contents'!$D$2:$D$3000)) -> 0 | Y4: =IF($A2="","",SUMIF('07_Pallet_Contents'!$A$2:$A$3000,$A2,'07_Pallet_Contents'!$I$2:$I$3000)) -> 0 | Z4: =IF($A2="","",IF(COUNTIF('07_Pallet_Contents'!$A$2:$A$3000,$A2)>0,"Yes",""))
A5: WH-Z1-AisleO-Bay10-Level1 | B5: 48x T24i-30 | C5: 48x T24i-30 | D5: =IF($C5="","",IFERROR(LOOKUP(2,1/('03_Warehouse_Movements'!$C$2:$C$500=$A5),'03_Warehouse_Movements'!$E$2:$E$500),$C5)) -> 48x T24i-30 | E5: STANDARD | F5: SAMPLE: Monitors 24-40 | H5: =IF(AND($F5="TEMP",$G5>0,$M5<>""),$M5+$G5,"") | I5: Geoff Gerber | J5: SAMPLE-TECH | K5: 46051 | L5: B:OVERFLOW-CHRIS- D:CHRIS_OVERFLOW_A_ZONE1 | M5: =IF($C5="","",IFERROR(LOOKUP(2,1/('03_Warehouse_Movements'!$C$2:$C$500=$A5),'03_Warehouse_Movements'!$A$2:$A$500),"")) | N5: =IF($C5="","",IFERROR(LOOKUP(2,1/('03_Warehouse_Movements'!$C$2:$C$500=$A5),'03_Warehouse_Movements'!$H$2:$H$500),"")) | O5: =A5 -> WH-Z1-AisleO-Bay10-Level1 | U5: 46051 | V5: PAL-0000005 | W5: =IF($A2="","",COUNTIF('07_Pallet_Contents'!$A$2:$A$3000,$A2)) -> 0 | X5: =IF($A2="","",SUMIF('07_Pallet_Contents'!$A$2:$A$3000,$A2,'07_Pallet_Contents'!$D$2:$D$3000)) -> 0 | Y5: =IF($A2="","",SUMIF('07_Pallet_Contents'!$A$2:$A$3000,$A2,'07_Pallet_Contents'!$I$2:$I$3000)) -> 0 | Z5: =IF($A2="","",IF(COUNTIF('07_Pallet_Contents'!$A$2:$A$3000,$A2)>0,"Yes",""))
A6: Northwell Capsule & GCX | B6: WH-ZR-AisleM-Bay1-Level3 | C6: capsule & GCX | D6: =IF($C6="","",IFERROR(LOOKUP(2,1/('03_Warehouse_Movements'!$C$2:$C$500=$A6),'03_Warehouse_Movements'!$E$2:$E$500),$C6)) -> capsule & GCX | E6: STANDARD | F6: SAMPLE: Monitors 24-40 | H6: =IF(AND($F6="TEMP",$G6>0,$M6<>""),$M6+$G6,"") | I6: crate looks broken, contents are tightly wrapped / unable to 100% verify actually contents of boxes | J6: Khadejah Harrison | K6: 46059 | L6: PAL-0000006 | M6: =IF($C6="","",IFERROR(LOOKUP(2,1/('03_Warehouse_Movements'!$C$2:$C$500=$A6),'03_Warehouse_Movements'!$A$2:$A$500),"")) | N6: =IF($C6="","",IFERROR(LOOKUP(2,1/('03_Warehouse_Movements'!$C$2:$C$500=$A6),'03_Warehouse_Movements'!$H$2:$H$500),"")) | O6: =A6 -> Northwell Capsule & GCX | W6: =IF($A2="","",COUNTIF('07_Pallet_Contents'!$A$2:$A$3000,$A2)) -> 0 | X6: =IF($A2="","",SUMIF('07_Pallet_Contents'!$A$2:$A$3000,$A2,'07_Pallet_Contents'!$D$2:$D$3000)) -> 0 | Y6: =IF($A2="","",SUMIF('07_Pallet_Contents'!$A$2:$A$3000,$A2,'07_Pallet_Contents'!$I$2:$I$3000)) -> 0 | Z6: =IF($A2="","",IF(COUNTIF('07_Pallet_Contents'!$A$2:$A$3000,$A2)>0,"Yes",""))
