Workbook

Sheet 00_Error_Log_Device_Config
A1: Row_ID | B1: Device Type | C1: Deployed | D1: Installed | E1: Cybernet Hostname | F1: Neuron Hostname | G1: Software List | H1: PI Use Case | I1: PI Result | J1: PI Validated By | K1: PI Validated Date | L1: Error Count | M1: Error Detail
A2: =ROW() -> 2 | B2: =IFERROR(INDEX(tblDeviceConfig[Device Type],ROW()-1),"") -> Neuron | C2: =IFERROR(INDEX(tblDeviceConfig[Deployed],ROW()-1),"") -> Yes | D2: =IFERROR(INDEX(tblDeviceConfig[Installed],ROW()-1),"") -> Yes | E2: =IFERROR(INDEX(tblDeviceConfig[Cybernet Hostname],ROW()-1),"") -> 0 | F2: =IFERROR(INDEX(tblDeviceConfig[Neuron Hostname],ROW()-1),"") -> LIJ-SDF-MACH-A | G2: =IFERROR(INDEX(tblDeviceConfig[Software List],ROW()-1),"") -> iPro Epic Satellite ALLSCRIPTS EPIC BCA | H2: =IFERROR(INDEX(tblDeviceConfig[PI_Use_Case],ROW()-1),"") -> 0 | I2: =IFERROR(INDEX(tblDeviceConfig[PI_Result],ROW()-1),"") -> 0 | J2: =IFERROR(INDEX(tblDeviceConfig[PI_Validated_By],ROW()-1),"") -> 0 | K2: =IFERROR(INDEX(tblDeviceConfig[PI_Validated_Date],ROW()-1),"") -> 0 | L2: =SUM(IF(AND(C2="Yes",B2="Cybernet",LEN(TRIM(E2))=0),1,0),IF(AND(C2="Yes",B2="Neuron",LEN(TRIM(F2))=0),1,0),IF(AND(C2="Yes",B2="Cybernet",LEN(TRIM(G2))=0),1,0),IF(AND(C2="Yes",B2="Cybernet",LEN(TRIM(H2))=0),1,0),IF(AND(C2="Yes",LEN(TRIM(I2))>0,LEN(TRIM(J2))=0),1,0),IF(AND(C2="Yes",LEN(TRIM(J2))>0,LEN(TRIM(K2))=0),1,0)) -> 0 | M2: =(IF(AND(C2="Yes",B2="Cybernet",LEN(TRIM(E2))=0),"Missing Cybernet Hostname",""))&IF(((IF(AND(C2="Yes",B2="Cybernet",LEN(TRIM(E2))=0),"Missing Cybernet Hostname","")))<>"",IF((IF(AND(C2="Yes",B2="Neuron",LEN(TRIM(F2))=0),"Missing Neuron Hostname",""))<>""," | ",""),"")&(IF(AND(C2="Yes",B2="Neuron",LEN(TRIM(F2))=0),"Missing Neuron Hostname",""))&IF(((IF(AND(C2="Yes",B2="Cybernet",LEN(TRIM(E2))=0),"Missing Cybernet Hostname",""))&(IF(AND(C2="Yes",B2="Neuron",LEN(TRIM(F2))=0),"Missing Neuron Hostname","")))<>"",IF((IF(AND(C2="Yes",B2="Cybernet",LEN(TRIM(G2))=0),"Missing Software List",""))<>""," | ",""),"")&(IF(AND(C2="Yes",B2="Cybernet",LEN(TRIM(G2))=0),"Missing Software List",""))&IF(((IF(AND(C2="Yes",B2="Cybernet",LEN(TRIM(E2))=0),"Missing Cybernet Hostname",""))&(IF(AND(C2="Yes",B2="Neuron",LEN(TRIM(F2))=0),"Missing Neuron Hostname",""))&(IF(AND(C2="Yes",B2="Cybernet",LEN(TRIM(G2))=0),"Missing Software List","")))<>"",IF((IF(AND(C2="Yes",B2="Cybernet",LEN(TRIM(H2))=0),"Missing PI Use Case",""))<>""," | ",""),"")&(IF(AND(C2="Yes",B2="Cybernet",LEN(TRIM(H2))=0),"Missing PI Use Case",""))&IF(((IF(AND(C2="Yes",B2="Cybernet",LEN(TRIM(E2))=0),"Missing Cybernet Hostname",""))&(IF(AND(C2="Yes",B2="Neuron",LEN(TRIM(F2))=0),"Missing Neuron Hostname",""))&(IF(AND(C2="Yes",B2="Cybernet",LEN(TRIM(G2))=0),"Missing Software List",""))&(IF(AND(C2="Yes",B2="Cybernet",LEN(TRIM(H2))=0),"Missing PI Use Case","")))<>"",IF((IF(AND(C2="Yes",LEN(TRIM(I2))>0,LEN(TRIM(J2))=0),"Missing PI Validated By",""))<>""," | ",""),"")&(IF(AND(C2="Yes",LEN(TRIM(I2))>0,LEN(TRIM(J2))=0),"Missing PI Validated By",""))&IF(((IF(AND(C2="Yes",B2="Cybernet",LEN(TRIM(E2))=0),"Missing Cybernet Hostname",""))&(IF(AND(C2="Yes",B2="Neuron",LEN(TRIM(F2))=0),"Missing Neuron Hostname",""))&(IF(AND(C2="Yes",B2="Cybernet",LEN(TRIM(G2))=0),"Missing Software List",""))&(IF(AND(C2="Yes",B2="Cybernet",LEN(TRIM(H2))=0),"Missing PI Use Case",""))&(IF(AND(C2="Yes",LEN(TRIM(I2))>0,LEN(TRIM(J2))=0),"Missing PI Validated By","")))<>"",IF((IF(AND(C2="Yes",LEN(TRIM(J2))>0,LEN(TRIM(K2))=0),"Missing PI Validated Date",""))<>""," | ",""),"")&(IF(AND(C2="Yes",LEN(TRIM(J2))>0,LEN(TRIM(K2))=0),"Missing PI Validated Date",""))
A3: =ROW() -> 3 | B3: =IFERROR(INDEX(tblDeviceConfig[Device Type],ROW()-1),"") -> Neuron | C3: =IFERROR(INDEX(tblDeviceConfig[Deployed],ROW()-1),"") -> Yes | D3: =IFERROR(INDEX(tblDeviceConfig[Installed],ROW()-1),"") -> Yes | E3: =IFERROR(INDEX(tblDeviceConfig[Cybernet Hostname],ROW()-1),"") -> 0 | F3: =IFERROR(INDEX(tblDeviceConfig[Neuron Hostname],ROW()-1),"") -> LIJ-SDF-MACH-B | G3: =IFERROR(INDEX(tblDeviceConfig[Software List],ROW()-1),"") -> 0 | H3: =IFERROR(INDEX(tblDeviceConfig[PI_Use_Case],ROW()-1),"") -> 0 | I3: =IFERROR(INDEX(tblDeviceConfig[PI_Result],ROW()-1),"") -> 0 | J3: =IFERROR(INDEX(tblDeviceConfig[PI_Validated_By],ROW()-1),"") -> 0 | K3: =IFERROR(INDEX(tblDeviceConfig[PI_Validated_Date],ROW()-1),"") -> 0 | L3: =SUM(IF(AND(C3="Yes",B3="Cybernet",LEN(TRIM(E3))=0),1,0),IF(AND(C3="Yes",B3="Neuron",LEN(TRIM(F3))=0),1,0),IF(AND(C3="Yes",B3="Cybernet",LEN(TRIM(G3))=0),1,0),IF(AND(C3="Yes",B3="Cybernet",LEN(TRIM(H3))=0),1,0),IF(AND(C3="Yes",LEN(TRIM(I3))>0,LEN(TRIM(J3))=0),1,0),IF(AND(C3="Yes",LEN(TRIM(J3))>0,LEN(TRIM(K3))=0),1,0)) -> 0 | M3: =(IF(AND(C3="Yes",B3="Cybernet",LEN(TRIM(E3))=0),"Missing Cybernet Hostname",""))&IF(((IF(AND(C3="Yes",B3="Cybernet",LEN(TRIM(E3))=0),"Missing Cybernet Hostname","")))<>"",IF((IF(AND(C3="Yes",B3="Neuron",LEN(TRIM(F3))=0),"Missing Neuron Hostname",""))<>""," | ",""),"")&(IF(AND(C3="Yes",B3="Neuron",LEN(TRIM(F3))=0),"Missing Neuron Hostname",""))&IF(((IF(AND(C3="Yes",B3="Cybernet",LEN(TRIM(E3))=0),"Missing Cybernet Hostname",""))&(IF(AND(C3="Yes",B3="Neuron",LEN(TRIM(F3))=0),"Missing Neuron Hostname","")))<>"",IF((IF(AND(C3="Yes",B3="Cybernet",LEN(TRIM(G3))=0),"Missing Software List",""))<>""," | ",""),"")&(IF(AND(C3="Yes",B3="Cybernet",LEN(TRIM(G3))=0),"Missing Software List",""))&IF(((IF(AND(C3="Yes",B3="Cybernet",LEN(TRIM(E3))=0),"Missing Cybernet Hostname",""))&(IF(AND(C3="Yes",B3="Neuron",LEN(TRIM(F3))=0),"Missing Neuron Hostname",""))&(IF(AND(C3="Yes",B3="Cybernet",LEN(TRIM(G3))=0),"Missing Software List","")))<>"",IF((IF(AND(C3="Yes",B3="Cybernet",LEN(TRIM(H3))=0),"Missing PI Use Case",""))<>""," | ",""),"")&(IF(AND(C3="Yes",B3="Cybernet",LEN(TRIM(H3))=0),"Missing PI Use Case",""))&IF(((IF(AND(C3="Yes",B3="Cybernet",LEN(TRIM(E3))=0),"Missing Cybernet Hostname",""))&(IF(AND(C3="Yes",B3="Neuron",LEN(TRIM(F3))=0),"Missing Neuron Hostname",""))&(IF(AND(C3="Yes",B3="Cybernet",LEN(TRIM(G3))=0),"Missing Software List",""))&(IF(AND(C3="Yes",B3="Cybernet",LEN(TRIM(H3))=0),"Missing PI Use Case","")))<>"",IF((IF(AND(C3="Yes",LEN(TRIM(I3))>0,LEN(TRIM(J3))=0),"Missing PI Validated By",""))<>""," | ",""),"")&(IF(AND(C3="Yes",LEN(TRIM(I3))>0,LEN(TRIM(J3))=0),"Missing PI Validated By",""))&IF(((IF(AND(C3="Yes",B3="Cybernet",LEN(TRIM(E3))=0),"Missing Cybernet Hostname",""))&(IF(AND(C3="Yes",B3="Neuron",LEN(TRIM(F3))=0),"Missing Neuron Hostname",""))&(IF(AND(C3="Yes",B3="Cybernet",LEN(TRIM(G3))=0),"Missing Software List",""))&(IF(AND(C3="Yes",B3="Cybernet",LEN(TRIM(H3))=0),"Missing PI Use Case",""))&(IF(AND(C3="Yes",LEN(TRIM(I3))>0,LEN(TRIM(J3))=0),"Missing PI Validated By","")))<>"",IF((IF(AND(C3="Yes",LEN(TRIM(J3))>0,LEN(TRIM(K3))=0),"Missing PI Validated Date",""))<>""," | ",""),"")&(IF(AND(C3="Yes",LEN(TRIM(J3))>0,LEN(TRIM(K3))=0),"Missing PI Validated Date",""))
A4: =ROW() -> 4 | B4: =IFERROR(INDEX(tblDeviceConfig[Device Type],ROW()-1),"") -> Neuron | C4: =IFERROR(INDEX(tblDeviceConfig[Deployed],ROW()-1),"") -> Yes | D4: =IFERROR(INDEX(tblDeviceConfig[Installed],ROW()-1),"") -> Yes | E4: =IFERROR(INDEX(tblDeviceConfig[Cybernet Hostname],ROW()-1),"") -> 0 | F4: =IFERROR(INDEX(tblDeviceConfig[Neuron Hostname],ROW()-1),"") -> LIJ-SDF-MACH-C | G4: =IFERROR(INDEX(tblDeviceConfig[Software List],ROW()-1),"") -> 0 | H4: =IFERROR(INDEX(tblDeviceConfig[PI_Use_Case],ROW()-1),"") -> 0 | I4: =IFERROR(INDEX(tblDeviceConfig[PI_Result],ROW()-1),"") -> 0 | J4: =IFERROR(INDEX(tblDeviceConfig[PI_Validated_By],ROW()-1),"") -> 0 | K4: =IFERROR(INDEX(tblDeviceConfig[PI_Validated_Date],ROW()-1),"") -> 0 | L4: =SUM(IF(AND(C4="Yes",B4="Cybernet",LEN(TRIM(E4))=0),1,0),IF(AND(C4="Yes",B4="Neuron",LEN(TRIM(F4))=0),1,0),IF(AND(C4="Yes",B4="Cybernet",LEN(TRIM(G4))=0),1,0),IF(AND(C4="Yes",B4="Cybernet",LEN(TRIM(H4))=0),1,0),IF(AND(C4="Yes",LEN(TRIM(I4))>0,LEN(TRIM(J4))=0),1,0),IF(AND(C4="Yes",LEN(TRIM(J4))>0,LEN(TRIM(K4))=0),1,0)) -> 0 | M4: =(IF(AND(C4="Yes",B4="Cybernet",LEN(TRIM(E4))=0),"Missing Cybernet Hostname",""))&IF(((IF(AND(C4="Yes",B4="Cybernet",LEN(TRIM(E4))=0),"Missing Cybernet Hostname","")))<>"",IF((IF(AND(C4="Yes",B4="Neuron",LEN(TRIM(F4))=0),"Missing Neuron Hostname",""))<>""," | ",""),"")&(IF(AND(C4="Yes",B4="Neuron",LEN(TRIM(F4))=0),"Missing Neuron Hostname",""))&IF(((IF(AND(C4="Yes",B4="Cybernet",LEN(TRIM(E4))=0),"Missing Cybernet Hostname",""))&(IF(AND(C4="Yes",B4="Neuron",LEN(TRIM(F4))=0),"Missing Neuron Hostname","")))<>"",IF((IF(AND(C4="Yes",B4="Cybernet",LEN(TRIM(G4))=0),"Missing Software List",""))<>""," | ",""),"")&(IF(AND(C4="Yes",B4="Cybernet",LEN(TRIM(G4))=0),"Missing Software List",""))&IF(((IF(AND(C4="Yes",B4="Cybernet",LEN(TRIM(E4))=0),"Missing Cybernet Hostname",""))&(IF(AND(C4="Yes",B4="Neuron",LEN(TRIM(F4))=0),"Missing Neuron Hostname",""))&(IF(AND(C4="Yes",B4="Cybernet",LEN(TRIM(G4))=0),"Missing Software List","")))<>"",IF((IF(AND(C4="Yes",B4="Cybernet",LEN(TRIM(H4))=0),"Missing PI Use Case",""))<>""," | ",""),"")&(IF(AND(C4="Yes",B4="Cybernet",LEN(TRIM(H4))=0),"Missing PI Use Case",""))&IF(((IF(AND(C4="Yes",B4="Cybernet",LEN(TRIM(E4))=0),"Missing Cybernet Hostname",""))&(IF(AND(C4="Yes",B4="Neuron",LEN(TRIM(F4))=0),"Missing Neuron Hostname",""))&(IF(AND(C4="Yes",B4="Cybernet",LEN(TRIM(G4))=0),"Missing Software List",""))&(IF(AND(C4="Yes",B4="Cybernet",LEN(TRIM(H4))=0),"Missing PI Use Case","")))<>"",IF((IF(AND(C4="Yes",LEN(TRIM(I4))>0,LEN(TRIM(J4))=0),"Missing PI Validated By",""))<>""," | ",""),"")&(IF(AND(C4="Yes",LEN(TRIM(I4))>0,LEN(TRIM(J4))=0),"Missing PI Validated By",""))&IF(((IF(AND(C4="Yes",B4="Cybernet",LEN(TRIM(E4))=0),"Missing Cybernet Hostname",""))&(IF(AND(C4="Yes",B4="Neuron",LEN(TRIM(F4))=0),"Missing Neuron Hostname",""))&(IF(AND(C4="Yes",B4="Cybernet",LEN(TRIM(G4))=0),"Missing Software List",""))&(IF(AND(C4="Yes",B4="Cybernet",LEN(TRIM(H4))=0),"Missing PI Use Case",""))&(IF(AND(C4="Yes",LEN(TRIM(I4))>0,LEN(TRIM(J4))=0),"Missing PI Validated By","")))<>"",IF((IF(AND(C4="Yes",LEN(TRIM(J4))>0,LEN(TRIM(K4))=0),"Missing PI Validated Date",""))<>""," | ",""),"")&(IF(AND(C4="Yes",LEN(TRIM(J4))>0,LEN(TRIM(K4))=0),"Missing PI Validated Date",""))
A5: =ROW() -> 5 | B5: =IFERROR(INDEX(tblDeviceConfig[Device Type],ROW()-1),"") -> Neuron | C5: =IFERROR(INDEX(tblDeviceConfig[Deployed],ROW()-1),"") -> Yes | D5: =IFERROR(INDEX(tblDeviceConfig[Installed],ROW()-1),"") -> Yes | E5: =IFERROR(INDEX(tblDeviceConfig[Cybernet Hostname],ROW()-1),"") -> 0 | F5: =IFERROR(INDEX(tblDeviceConfig[Neuron Hostname],ROW()-1),"") -> LIJ-SDF-MACH-D | G5: =IFERROR(INDEX(tblDeviceConfig[Software List],ROW()-1),"") -> 0 | H5: =IFERROR(INDEX(tblDeviceConfig[PI_Use_Case],ROW()-1),"") -> 0 | I5: =IFERROR(INDEX(tblDeviceConfig[PI_Result],ROW()-1),"") -> 0 | J5: =IFERROR(INDEX(tblDeviceConfig[PI_Validated_By],ROW()-1),"") -> 0 | K5: =IFERROR(INDEX(tblDeviceConfig[PI_Validated_Date],ROW()-1),"") -> 0 | L5: =SUM(IF(AND(C5="Yes",B5="Cybernet",LEN(TRIM(E5))=0),1,0),IF(AND(C5="Yes",B5="Neuron",LEN(TRIM(F5))=0),1,0),IF(AND(C5="Yes",B5="Cybernet",LEN(TRIM(G5))=0),1,0),IF(AND(C5="Yes",B5="Cybernet",LEN(TRIM(H5))=0),1,0),IF(AND(C5="Yes",LEN(TRIM(I5))>0,LEN(TRIM(J5))=0),1,0),IF(AND(C5="Yes",LEN(TRIM(J5))>0,LEN(TRIM(K5))=0),1,0)) -> 0 | M5: =(IF(AND(C5="Yes",B5="Cybernet",LEN(TRIM(E5))=0),"Missing Cybernet Hostname",""))&IF(((IF(AND(C5="Yes",B5="Cybernet",LEN(TRIM(E5))=0),"Missing Cybernet Hostname","")))<>"",IF((IF(AND(C5="Yes",B5="Neuron",LEN(TRIM(F5))=0),"Missing Neuron Hostname",""))<>""," | ",""),"")&(IF(AND(C5="Yes",B5="Neuron",LEN(TRIM(F5))=0),"Missing Neuron Hostname",""))&IF(((IF(AND(C5="Yes",B5="Cybernet",LEN(TRIM(E5))=0),"Missing Cybernet Hostname",""))&(IF(AND(C5="Yes",B5="Neuron",LEN(TRIM(F5))=0),"Missing Neuron Hostname","")))<>"",IF((IF(AND(C5="Yes",B5="Cybernet",LEN(TRIM(G5))=0),"Missing Software List",""))<>""," | ",""),"")&(IF(AND(C5="Yes",B5="Cybernet",LEN(TRIM(G5))=0),"Missing Software List",""))&IF(((IF(AND(C5="Yes",B5="Cybernet",LEN(TRIM(E5))=0),"Missing Cybernet Hostname",""))&(IF(AND(C5="Yes",B5="Neuron",LEN(TRIM(F5))=0),"Missing Neuron Hostname",""))&(IF(AND(C5="Yes",B5="Cybernet",LEN(TRIM(G5))=0),"Missing Software List","")))<>"",IF((IF(AND(C5="Yes",B5="Cybernet",LEN(TRIM(H5))=0),"Missing PI Use Case",""))<>""," | ",""),"")&(IF(AND(C5="Yes",B5="Cybernet",LEN(TRIM(H5))=0),"Missing PI Use Case",""))&IF(((IF(AND(C5="Yes",B5="Cybernet",LEN(TRIM(E5))=0),"Missing Cybernet Hostname",""))&(IF(AND(C5="Yes",B5="Neuron",LEN(TRIM(F5))=0),"Missing Neuron Hostname",""))&(IF(AND(C5="Yes",B5="Cybernet",LEN(TRIM(G5))=0),"Missing Software List",""))&(IF(AND(C5="Yes",B5="Cybernet",LEN(TRIM(H5))=0),"Missing PI Use Case","")))<>"",IF((IF(AND(C5="Yes",LEN(TRIM(I5))>0,LEN(TRIM(J5))=0),"Missing PI Validated By",""))<>""," | ",""),"")&(IF(AND(C5="Yes",LEN(TRIM(I5))>0,LEN(TRIM(J5))=0),"Missing PI Validated By",""))&IF(((IF(AND(C5="Yes",B5="Cybernet",LEN(TRIM(E5))=0),"Missing Cybernet Hostname",""))&(IF(AND(C5="Yes",B5="Neuron",LEN(TRIM(F5))=0),"Missing Neuron Hostname",""))&(IF(AND(C5="Yes",B5="Cybernet",LEN(TRIM(G5))=0),"Missing Software List",""))&(IF(AND(C5="Yes",B5="Cybernet",LEN(TRIM(H5))=0),"Missing PI Use Case",""))&(IF(AND(C5="Yes",LEN(TRIM(I5))>0,LEN(TRIM(J5))=0),"Missing PI Validated By","")))<>"",IF((IF(AND(C5="Yes",LEN(TRIM(J5))>0,LEN(TRIM(K5))=0),"Missing PI Validated Date",""))<>""," | ",""),"")&(IF(AND(C5="Yes",LEN(TRIM(J5))>0,LEN(TRIM(K5))=0),"Missing PI Validated Date",""))
A6: =ROW() -> 6 | B6: =IFERROR(INDEX(tblDeviceConfig[Device Type],ROW()-1),"") -> Neuron | C6: =IFERROR(INDEX(tblDeviceConfig[Deployed],ROW()-1),"") -> Yes | D6: =IFERROR(INDEX(tblDeviceConfig[Installed],ROW()-1),"") -> Yes | E6: =IFERROR(INDEX(tblDeviceConfig[Cybernet Hostname],ROW()-1),"") -> 0 | F6: =IFERROR(INDEX(tblDeviceConfig[Neuron Hostname],ROW()-1),"") -> LIJ-SDF-MACH-E | G6: =IFERROR(INDEX(tblDeviceConfig[Software List],ROW()-1),"") -> 0 | H6: =IFERROR(INDEX(tblDeviceConfig[PI_Use_Case],ROW()-1),"") -> 0 | I6: =IFERROR(INDEX(tblDeviceConfig[PI_Result],ROW()-1),"") -> 0 | J6: =IFERROR(INDEX(tblDeviceConfig[PI_Validated_By],ROW()-1),"") -> 0 | K6: =IFERROR(INDEX(tblDeviceConfig[PI_Validated_Date],ROW()-1),"") -> 0 | L6: =SUM(IF(AND(C6="Yes",B6="Cybernet",LEN(TRIM(E6))=0),1,0),IF(AND(C6="Yes",B6="Neuron",LEN(TRIM(F6))=0),1,0),IF(AND(C6="Yes",B6="Cybernet",LEN(TRIM(G6))=0),1,0),IF(AND(C6="Yes",B6="Cybernet",LEN(TRIM(H6))=0),1,0),IF(AND(C6="Yes",LEN(TRIM(I6))>0,LEN(TRIM(J6))=0),1,0),IF(AND(C6="Yes",LEN(TRIM(J6))>0,LEN(TRIM(K6))=0),1,0)) -> 0 | M6: =(IF(AND(C6="Yes",B6="Cybernet",LEN(TRIM(E6))=0),"Missing Cybernet Hostname",""))&IF(((IF(AND(C6="Yes",B6="Cybernet",LEN(TRIM(E6))=0),"Missing Cybernet Hostname","")))<>"",IF((IF(AND(C6="Yes",B6="Neuron",LEN(TRIM(F6))=0),"Missing Neuron Hostname",""))<>""," | ",""),"")&(IF(AND(C6="Yes",B6="Neuron",LEN(TRIM(F6))=0),"Missing Neuron Hostname",""))&IF(((IF(AND(C6="Yes",B6="Cybernet",LEN(TRIM(E6))=0),"Missing Cybernet Hostname",""))&(IF(AND(C6="Yes",B6="Neuron",LEN(TRIM(F6))=0),"Missing Neuron Hostname","")))<>"",IF((IF(AND(C6="Yes",B6="Cybernet",LEN(TRIM(G6))=0),"Missing Software List",""))<>""," | ",""),"")&(IF(AND(C6="Yes",B6="Cybernet",LEN(TRIM(G6))=0),"Missing Software List",""))&IF(((IF(AND(C6="Yes",B6="Cybernet",LEN(TRIM(E6))=0),"Missing Cybernet Hostname",""))&(IF(AND(C6="Yes",B6="Neuron",LEN(TRIM(F6))=0),"Missing Neuron Hostname",""))&(IF(AND(C6="Yes",B6="Cybernet",LEN(TRIM(G6))=0),"Missing Software List","")))<>"",IF((IF(AND(C6="Yes",B6="Cybernet",LEN(TRIM(H6))=0),"Missing PI Use Case",""))<>""," | ",""),"")&(IF(AND(C6="Yes",B6="Cybernet",LEN(TRIM(H6))=0),"Missing PI Use Case",""))&IF(((IF(AND(C6="Yes",B6="Cybernet",LEN(TRIM(E6))=0),"Missing Cybernet Hostname",""))&(IF(AND(C6="Yes",B6="Neuron",LEN(TRIM(F6))=0),"Missing Neuron Hostname",""))&(IF(AND(C6="Yes",B6="Cybernet",LEN(TRIM(G6))=0),"Missing Software List",""))&(IF(AND(C6="Yes",B6="Cybernet",LEN(TRIM(H6))=0),"Missing PI Use Case","")))<>"",IF((IF(AND(C6="Yes",LEN(TRIM(I6))>0,LEN(TRIM(J6))=0),"Missing PI Validated By",""))<>""," | ",""),"")&(IF(AND(C6="Yes",LEN(TRIM(I6))>0,LEN(TRIM(J6))=0),"Missing PI Validated By",""))&IF(((IF(AND(C6="Yes",B6="Cybernet",LEN(TRIM(E6))=0),"Missing Cybernet Hostname",""))&(IF(AND(C6="Yes",B6="Neuron",LEN(TRIM(F6))=0),"Missing Neuron Hostname",""))&(IF(AND(C6="Yes",B6="Cybernet",LEN(TRIM(G6))=0),"Missing Software List",""))&(IF(AND(C6="Yes",B6="Cybernet",LEN(TRIM(H6))=0),"Missing PI Use Case",""))&(IF(AND(C6="Yes",LEN(TRIM(I6))>0,LEN(TRIM(J6))=0),"Missing PI Validated By","")))<>"",IF((IF(AND(C6="Yes",LEN(TRIM(J6))>0,LEN(TRIM(K6))=0),"Missing PI Validated Date",""))<>""," | ",""),"")&(IF(AND(C6="Yes",LEN(TRIM(J6))>0,LEN(TRIM(K6))=0),"Missing PI Validated Date",""))
A7: =ROW() -> 7 | B7: =IFERROR(INDEX(tblDeviceConfig[Device Type],ROW()-1),"") -> Neuron | C7: =IFERROR(INDEX(tblDeviceConfig[Deployed],ROW()-1),"") -> Yes | D7: =IFERROR(INDEX(tblDeviceConfig[Installed],ROW()-1),"") -> Yes | E7: =IFERROR(INDEX(tblDeviceConfig[Cybernet Hostname],ROW()-1),"") -> 0 | F7: =IFERROR(INDEX(tblDeviceConfig[Neuron Hostname],ROW()-1),"") -> LIJ-SDF-MACH-F | G7: =IFERROR(INDEX(tblDeviceConfig[Software List],ROW()-1),"") -> 0 | H7: =IFERROR(INDEX(tblDeviceConfig[PI_Use_Case],ROW()-1),"") -> 0 | I7: =IFERROR(INDEX(tblDeviceConfig[PI_Result],ROW()-1),"") -> 0 | J7: =IFERROR(INDEX(tblDeviceConfig[PI_Validated_By],ROW()-1),"") -> 0 | K7: =IFERROR(INDEX(tblDeviceConfig[PI_Validated_Date],ROW()-1),"") -> 0 | L7: =SUM(IF(AND(C7="Yes",B7="Cybernet",LEN(TRIM(E7))=0),1,0),IF(AND(C7="Yes",B7="Neuron",LEN(TRIM(F7))=0),1,0),IF(AND(C7="Yes",B7="Cybernet",LEN(TRIM(G7))=0),1,0),IF(AND(C7="Yes",B7="Cybernet",LEN(TRIM(H7))=0),1,0),IF(AND(C7="Yes",LEN(TRIM(I7))>0,LEN(TRIM(J7))=0),1,0),IF(AND(C7="Yes",LEN(TRIM(J7))>0,LEN(TRIM(K7))=0),1,0)) -> 0 | M7: =(IF(AND(C7="Yes",B7="Cybernet",LEN(TRIM(E7))=0),"Missing Cybernet Hostname",""))&IF(((IF(AND(C7="Yes",B7="Cybernet",LEN(TRIM(E7))=0),"Missing Cybernet Hostname","")))<>"",IF((IF(AND(C7="Yes",B7="Neuron",LEN(TRIM(F7))=0),"Missing Neuron Hostname",""))<>""," | ",""),"")&(IF(AND(C7="Yes",B7="Neuron",LEN(TRIM(F7))=0),"Missing Neuron Hostname",""))&IF(((IF(AND(C7="Yes",B7="Cybernet",LEN(TRIM(E7))=0),"Missing Cybernet Hostname",""))&(IF(AND(C7="Yes",B7="Neuron",LEN(TRIM(F7))=0),"Missing Neuron Hostname","")))<>"",IF((IF(AND(C7="Yes",B7="Cybernet",LEN(TRIM(G7))=0),"Missing Software List",""))<>""," | ",""),"")&(IF(AND(C7="Yes",B7="Cybernet",LEN(TRIM(G7))=0),"Missing Software List",""))&IF(((IF(AND(C7="Yes",B7="Cybernet",LEN(TRIM(E7))=0),"Missing Cybernet Hostname",""))&(IF(AND(C7="Yes",B7="Neuron",LEN(TRIM(F7))=0),"Missing Neuron Hostname",""))&(IF(AND(C7="Yes",B7="Cybernet",LEN(TRIM(G7))=0),"Missing Software List","")))<>"",IF((IF(AND(C7="Yes",B7="Cybernet",LEN(TRIM(H7))=0),"Missing PI Use Case",""))<>""," | ",""),"")&(IF(AND(C7="Yes",B7="Cybernet",LEN(TRIM(H7))=0),"Missing PI Use Case",""))&IF(((IF(AND(C7="Yes",B7="Cybernet",LEN(TRIM(E7))=0),"Missing Cybernet Hostname",""))&(IF(AND(C7="Yes",B7="Neuron",LEN(TRIM(F7))=0),"Missing Neuron Hostname",""))&(IF(AND(C7="Yes",B7="Cybernet",LEN(TRIM(G7))=0),"Missing Software List",""))&(IF(AND(C7="Yes",B7="Cybernet",LEN(TRIM(H7))=0),"Missing PI Use Case","")))<>"",IF((IF(AND(C7="Yes",LEN(TRIM(I7))>0,LEN(TRIM(J7))=0),"Missing PI Validated By",""))<>""," | ",""),"")&(IF(AND(C7="Yes",LEN(TRIM(I7))>0,LEN(TRIM(J7))=0),"Missing PI Validated By",""))&IF(((IF(AND(C7="Yes",B7="Cybernet",LEN(TRIM(E7))=0),"Missing Cybernet Hostname",""))&(IF(AND(C7="Yes",B7="Neuron",LEN(TRIM(F7))=0),"Missing Neuron Hostname",""))&(IF(AND(C7="Yes",B7="Cybernet",LEN(TRIM(G7))=0),"Missing Software List",""))&(IF(AND(C7="Yes",B7="Cybernet",LEN(TRIM(H7))=0),"Missing PI Use Case",""))&(IF(AND(C7="Yes",LEN(TRIM(I7))>0,LEN(TRIM(J7))=0),"Missing PI Validated By","")))<>"",IF((IF(AND(C7="Yes",LEN(TRIM(J7))>0,LEN(TRIM(K7))=0),"Missing PI Validated Date",""))<>""," | ",""),"")&(IF(AND(C7="Yes",LEN(TRIM(J7))>0,LEN(TRIM(K7))=0),"Missing PI Validated Date",""))
A8: =ROW() -> 8 | B8: =IFERROR(INDEX(tblDeviceConfig[Device Type],ROW()-1),"") -> Neuron | C8: =IFERROR(INDEX(tblDeviceConfig[Deployed],ROW()-1),"") -> Yes | D8: =IFERROR(INDEX(tblDeviceConfig[Installed],ROW()-1),"") -> Yes | E8: =IFERROR(INDEX(tblDeviceConfig[Cybernet Hostname],ROW()-1),"") -> 0 | F8: =IFERROR(INDEX(tblDeviceConfig[Neuron Hostname],ROW()-1),"") -> LIJ-SDF-MACH-G | G8: =IFERROR(INDEX(tblDeviceConfig[Software List],ROW()-1),"") -> 0 | H8: =IFERROR(INDEX(tblDeviceConfig[PI_Use_Case],ROW()-1),"") -> 0 | I8: =IFERROR(INDEX(tblDeviceConfig[PI_Result],ROW()-1),"") -> 0 | J8: =IFERROR(INDEX(tblDeviceConfig[PI_Validated_By],ROW()-1),"") -> 0 | K8: =IFERROR(INDEX(tblDeviceConfig[PI_Validated_Date],ROW()-1),"") -> 0 | L8: =SUM(IF(AND(C8="Yes",B8="Cybernet",LEN(TRIM(E8))=0),1,0),IF(AND(C8="Yes",B8="Neuron",LEN(TRIM(F8))=0),1,0),IF(AND(C8="Yes",B8="Cybernet",LEN(TRIM(G8))=0),1,0),IF(AND(C8="Yes",B8="Cybernet",LEN(TRIM(H8))=0),1,0),IF(AND(C8="Yes",LEN(TRIM(I8))>0,LEN(TRIM(J8))=0),1,0),IF(AND(C8="Yes",LEN(TRIM(J8))>0,LEN(TRIM(K8))=0),1,0)) -> 0 | M8: =(IF(AND(C8="Yes",B8="Cybernet",LEN(TRIM(E8))=0),"Missing Cybernet Hostname",""))&IF(((IF(AND(C8="Yes",B8="Cybernet",LEN(TRIM(E8))=0),"Missing Cybernet Hostname","")))<>"",IF((IF(AND(C8="Yes",B8="Neuron",LEN(TRIM(F8))=0),"Missing Neuron Hostname",""))<>""," | ",""),"")&(IF(AND(C8="Yes",B8="Neuron",LEN(TRIM(F8))=0),"Missing Neuron Hostname",""))&IF(((IF(AND(C8="Yes",B8="Cybernet",LEN(TRIM(E8))=0),"Missing Cybernet Hostname",""))&(IF(AND(C8="Yes",B8="Neuron",LEN(TRIM(F8))=0),"Missing Neuron Hostname","")))<>"",IF((IF(AND(C8="Yes",B8="Cybernet",LEN(TRIM(G8))=0),"Missing Software List",""))<>""," | ",""),"")&(IF(AND(C8="Yes",B8="Cybernet",LEN(TRIM(G8))=0),"Missing Software List",""))&IF(((IF(AND(C8="Yes",B8="Cybernet",LEN(TRIM(E8))=0),"Missing Cybernet Hostname",""))&(IF(AND(C8="Yes",B8="Neuron",LEN(TRIM(F8))=0),"Missing Neuron Hostname",""))&(IF(AND(C8="Yes",B8="Cybernet",LEN(TRIM(G8))=0),"Missing Software List","")))<>"",IF((IF(AND(C8="Yes",B8="Cybernet",LEN(TRIM(H8))=0),"Missing PI Use Case",""))<>""," | ",""),"")&(IF(AND(C8="Yes",B8="Cybernet",LEN(TRIM(H8))=0),"Missing PI Use Case",""))&IF(((IF(AND(C8="Yes",B8="Cybernet",LEN(TRIM(E8))=0),"Missing Cybernet Hostname",""))&(IF(AND(C8="Yes",B8="Neuron",LEN(TRIM(F8))=0),"Missing Neuron Hostname",""))&(IF(AND(C8="Yes",B8="Cybernet",LEN(TRIM(G8))=0),"Missing Software List",""))&(IF(AND(C8="Yes",B8="Cybernet",LEN(TRIM(H8))=0),"Missing PI Use Case","")))<>"",IF((IF(AND(C8="Yes",LEN(TRIM(I8))>0,LEN(TRIM(J8))=0),"Missing PI Validated By",""))<>""," | ",""),"")&(IF(AND(C8="Yes",LEN(TRIM(I8))>0,LEN(TRIM(J8))=0),"Missing PI Validated By",""))&IF(((IF(AND(C8="Yes",B8="Cybernet",LEN(TRIM(E8))=0),"Missing Cybernet Hostname",""))&(IF(AND(C8="Yes",B8="Neuron",LEN(TRIM(F8))=0),"Missing Neuron Hostname",""))&(IF(AND(C8="Yes",B8="Cybernet",LEN(TRIM(G8))=0),"Missing Software List",""))&(IF(AND(C8="Yes",B8="Cybernet",LEN(TRIM(H8))=0),"Missing PI Use Case",""))&(IF(AND(C8="Yes",LEN(TRIM(I8))>0,LEN(TRIM(J8))=0),"Missing PI Validated By","")))<>"",IF((IF(AND(C8="Yes",LEN(TRIM(J8))>0,LEN(TRIM(K8))=0),"Missing PI Validated Date",""))<>""," | ",""),"")&(IF(AND(C8="Yes",LEN(TRIM(J8))>0,LEN(TRIM(K8))=0),"Missing PI Validated Date",""))
A9: =ROW() -> 9 | B9: =IFERROR(INDEX(tblDeviceConfig[Device Type],ROW()-1),"") -> Neuron | C9: =IFERROR(INDEX(tblDeviceConfig[Deployed],ROW()-1),"") -> Yes | D9: =IFERROR(INDEX(tblDeviceConfig[Installed],ROW()-1),"") -> Yes | E9: =IFERROR(INDEX(tblDeviceConfig[Cybernet Hostname],ROW()-1),"") -> 0 | F9: =IFERROR(INDEX(tblDeviceConfig[Neuron Hostname],ROW()-1),"") -> LIJ-SDF-MACH-H | G9: =IFERROR(INDEX(tblDeviceConfig[Software List],ROW()-1),"") -> 0 | H9: =IFERROR(INDEX(tblDeviceConfig[PI_Use_Case],ROW()-1),"") -> 0 | I9: =IFERROR(INDEX(tblDeviceConfig[PI_Result],ROW()-1),"") -> 0 | J9: =IFERROR(INDEX(tblDeviceConfig[PI_Validated_By],ROW()-1),"") -> 0 | K9: =IFERROR(INDEX(tblDeviceConfig[PI_Validated_Date],ROW()-1),"") -> 0 | L9: =SUM(IF(AND(C9="Yes",B9="Cybernet",LEN(TRIM(E9))=0),1,0),IF(AND(C9="Yes",B9="Neuron",LEN(TRIM(F9))=0),1,0),IF(AND(C9="Yes",B9="Cybernet",LEN(TRIM(G9))=0),1,0),IF(AND(C9="Yes",B9="Cybernet",LEN(TRIM(H9))=0),1,0),IF(AND(C9="Yes",LEN(TRIM(I9))>0,LEN(TRIM(J9))=0),1,0),IF(AND(C9="Yes",LEN(TRIM(J9))>0,LEN(TRIM(K9))=0),1,0)) -> 0 | M9: =(IF(AND(C9="Yes",B9="Cybernet",LEN(TRIM(E9))=0),"Missing Cybernet Hostname",""))&IF(((IF(AND(C9="Yes",B9="Cybernet",LEN(TRIM(E9))=0),"Missing Cybernet Hostname","")))<>"",IF((IF(AND(C9="Yes",B9="Neuron",LEN(TRIM(F9))=0),"Missing Neuron Hostname",""))<>""," | ",""),"")&(IF(AND(C9="Yes",B9="Neuron",LEN(TRIM(F9))=0),"Missing Neuron Hostname",""))&IF(((IF(AND(C9="Yes",B9="Cybernet",LEN(TRIM(E9))=0),"Missing Cybernet Hostname",""))&(IF(AND(C9="Yes",B9="Neuron",LEN(TRIM(F9))=0),"Missing Neuron Hostname","")))<>"",IF((IF(AND(C9="Yes",B9="Cybernet",LEN(TRIM(G9))=0),"Missing Software List",""))<>""," | ",""),"")&(IF(AND(C9="Yes",B9="Cybernet",LEN(TRIM(G9))=0),"Missing Software List",""))&IF(((IF(AND(C9="Yes",B9="Cybernet",LEN(TRIM(E9))=0),"Missing Cybernet Hostname",""))&(IF(AND(C9="Yes",B9="Neuron",LEN(TRIM(F9))=0),"Missing Neuron Hostname",""))&(IF(AND(C9="Yes",B9="Cybernet",LEN(TRIM(G9))=0),"Missing Software List","")))<>"",IF((IF(AND(C9="Yes",B9="Cybernet",LEN(TRIM(H9))=0),"Missing PI Use Case",""))<>""," | ",""),"")&(IF(AND(C9="Yes",B9="Cybernet",LEN(TRIM(H9))=0),"Missing PI Use Case",""))&IF(((IF(AND(C9="Yes",B9="Cybernet",LEN(TRIM(E9))=0),"Missing Cybernet Hostname",""))&(IF(AND(C9="Yes",B9="Neuron",LEN(TRIM(F9))=0),"Missing Neuron Hostname",""))&(IF(AND(C9="Yes",B9="Cybernet",LEN(TRIM(G9))=0),"Missing Software List",""))&(IF(AND(C9="Yes",B9="Cybernet",LEN(TRIM(H9))=0),"Missing PI Use Case","")))<>"",IF((IF(AND(C9="Yes",LEN(TRIM(I9))>0,LEN(TRIM(J9))=0),"Missing PI Validated By",""))<>""," | ",""),"")&(IF(AND(C9="Yes",LEN(TRIM(I9))>0,LEN(TRIM(J9))=0),"Missing PI Validated By",""))&IF(((IF(AND(C9="Yes",B9="Cybernet",LEN(TRIM(E9))=0),"Missing Cybernet Hostname",""))&(IF(AND(C9="Yes",B9="Neuron",LEN(TRIM(F9))=0),"Missing Neuron Hostname",""))&(IF(AND(C9="Yes",B9="Cybernet",LEN(TRIM(G9))=0),"Missing Software List",""))&(IF(AND(C9="Yes",B9="Cybernet",LEN(TRIM(H9))=0),"Missing PI Use Case",""))&(IF(AND(C9="Yes",LEN(TRIM(I9))>0,LEN(TRIM(J9))=0),"Missing PI Validated By","")))<>"",IF((IF(AND(C9="Yes",LEN(TRIM(J9))>0,LEN(TRIM(K9))=0),"Missing PI Validated Date",""))<>""," | ",""),"")&(IF(AND(C9="Yes",LEN(TRIM(J9))>0,LEN(TRIM(K9))=0),"Missing PI Validated Date",""))
A10: =ROW() -> 10 | B10: =IFERROR(INDEX(tblDeviceConfig[Device Type],ROW()-1),"") -> Neuron | C10: =IFERROR(INDEX(tblDeviceConfig[Deployed],ROW()-1),"") -> Yes | D10: =IFERROR(INDEX(tblDeviceConfig[Installed],ROW()-1),"") -> Yes | E10: =IFERROR(INDEX(tblDeviceConfig[Cybernet Hostname],ROW()-1),"") -> 0 | F10: =IFERROR(INDEX(tblDeviceConfig[Neuron Hostname],ROW()-1),"") -> LIJ-SDF-MACH-I | G10: =IFERROR(INDEX(tblDeviceConfig[Software List],ROW()-1),"") -> 0 | H10: =IFERROR(INDEX(tblDeviceConfig[PI_Use_Case],ROW()-1),"") -> 0 | I10: =IFERROR(INDEX(tblDeviceConfig[PI_Result],ROW()-1),"") -> 0 | J10: =IFERROR(INDEX(tblDeviceConfig[PI_Validated_By],ROW()-1),"") -> 0 | K10: =IFERROR(INDEX(tblDeviceConfig[PI_Validated_Date],ROW()-1),"") -> 0 | L10: =SUM(IF(AND(C10="Yes",B10="Cybernet",LEN(TRIM(E10))=0),1,0),IF(AND(C10="Yes",B10="Neuron",LEN(TRIM(F10))=0),1,0),IF(AND(C10="Yes",B10="Cybernet",LEN(TRIM(G10))=0),1,0),IF(AND(C10="Yes",B10="Cybernet",LEN(TRIM(H10))=0),1,0),IF(AND(C10="Yes",LEN(TRIM(I10))>0,LEN(TRIM(J10))=0),1,0),IF(AND(C10="Yes",LEN(TRIM(J10))>0,LEN(TRIM(K10))=0),1,0)) -> 0 | M10: =(IF(AND(C10="Yes",B10="Cybernet",LEN(TRIM(E10))=0),"Missing Cybernet Hostname",""))&IF(((IF(AND(C10="Yes",B10="Cybernet",LEN(TRIM(E10))=0),"Missing Cybernet Hostname","")))<>"",IF((IF(AND(C10="Yes",B10="Neuron",LEN(TRIM(F10))=0),"Missing Neuron Hostname",""))<>""," | ",""),"")&(IF(AND(C10="Yes",B10="Neuron",LEN(TRIM(F10))=0),"Missing Neuron Hostname",""))&IF(((IF(AND(C10="Yes",B10="Cybernet",LEN(TRIM(E10))=0),"Missing Cybernet Hostname",""))&(IF(AND(C10="Yes",B10="Neuron",LEN(TRIM(F10))=0),"Missing Neuron Hostname","")))<>"",IF((IF(AND(C10="Yes",B10="Cybernet",LEN(TRIM(G10))=0),"Missing Software List",""))<>""," | ",""),"")&(IF(AND(C10="Yes",B10="Cybernet",LEN(TRIM(G10))=0),"Missing Software List",""))&IF(((IF(AND(C10="Yes",B10="Cybernet",LEN(TRIM(E10))=0),"Missing Cybernet Hostname",""))&(IF(AND(C10="Yes",B10="Neuron",LEN(TRIM(F10))=0),"Missing Neuron Hostname",""))&(IF(AND(C10="Yes",B10="Cybernet",LEN(TRIM(G10))=0),"Missing Software List","")))<>"",IF((IF(AND(C10="Yes",B10="Cybernet",LEN(TRIM(H10))=0),"Missing PI Use Case",""))<>""," | ",""),"")&(IF(AND(C10="Yes",B10="Cybernet",LEN(TRIM(H10))=0),"Missing PI Use Case",""))&IF(((IF(AND(C10="Yes",B10="Cybernet",LEN(TRIM(E10))=0),"Missing Cybernet Hostname",""))&(IF(AND(C10="Yes",B10="Neuron",LEN(TRIM(F10))=0),"Missing Neuron Hostname",""))&(IF(AND(C10="Yes",B10="Cybernet",LEN(TRIM(G10))=0),"Missing Software List",""))&(IF(AND(C10="Yes",B10="Cybernet",LEN(TRIM(H10))=0),"Missing PI Use Case","")))<>"",IF((IF(AND(C10="Yes",LEN(TRIM(I10))>0,LEN(TRIM(J10))=0),"Missing PI Validated By",""))<>""," | ",""),"")&(IF(AND(C10="Yes",LEN(TRIM(I10))>0,LEN(TRIM(J10))=0),"Missing PI Validated By",""))&IF(((IF(AND(C10="Yes",B10="Cybernet",LEN(TRIM(E10))=0),"Missing Cybernet Hostname",""))&(IF(AND(C10="Yes",B10="Neuron",LEN(TRIM(F10))=0),"Missing Neuron Hostname",""))&(IF(AND(C10="Yes",B10="Cybernet",LEN(TRIM(G10))=0),"Missing Software List",""))&(IF(AND(C10="Yes",B10="Cybernet",LEN(TRIM(H10))=0),"Missing PI Use Case",""))&(IF(AND(C10="Yes",LEN(TRIM(I10))>0,LEN(TRIM(J10))=0),"Missing PI Validated By","")))<>"",IF((IF(AND(C10="Yes",LEN(TRIM(J10))>0,LEN(TRIM(K10))=0),"Missing PI Validated Date",""))<>""," | ",""),"")&(IF(AND(C10="Yes",LEN(TRIM(J10))>0,LEN(TRIM(K10))=0),"Missing PI Validated Date",""))
A11: =ROW() -> 11 | B11: =IFERROR(INDEX(tblDeviceConfig[Device Type],ROW()-1),"") -> Neuron | C11: =IFERROR(INDEX(tblDeviceConfig[Deployed],ROW()-1),"") -> Yes | D11: =IFERROR(INDEX(tblDeviceConfig[Installed],ROW()-1),"") -> Yes | E11: =IFERROR(INDEX(tblDeviceConfig[Cybernet Hostname],ROW()-1),"") -> 0 | F11: =IFERROR(INDEX(tblDeviceConfig[Neuron Hostname],ROW()-1),"") -> LIJ-SDF-MACH-J | G11: =IFERROR(INDEX(tblDeviceConfig[Software List],ROW()-1),"") -> 0 | H11: =IFERROR(INDEX(tblDeviceConfig[PI_Use_Case],ROW()-1),"") -> 0 | I11: =IFERROR(INDEX(tblDeviceConfig[PI_Result],ROW()-1),"") -> 0 | J11: =IFERROR(INDEX(tblDeviceConfig[PI_Validated_By],ROW()-1),"") -> 0 | K11: =IFERROR(INDEX(tblDeviceConfig[PI_Validated_Date],ROW()-1),"") -> 0 | L11: =SUM(IF(AND(C11="Yes",B11="Cybernet",LEN(TRIM(E11))=0),1,0),IF(AND(C11="Yes",B11="Neuron",LEN(TRIM(F11))=0),1,0),IF(AND(C11="Yes",B11="Cybernet",LEN(TRIM(G11))=0),1,0),IF(AND(C11="Yes",B11="Cybernet",LEN(TRIM(H11))=0),1,0),IF(AND(C11="Yes",LEN(TRIM(I11))>0,LEN(TRIM(J11))=0),1,0),IF(AND(C11="Yes",LEN(TRIM(J11))>0,LEN(TRIM(K11))=0),1,0)) -> 0 | M11: =(IF(AND(C11="Yes",B11="Cybernet",LEN(TRIM(E11))=0),"Missing Cybernet Hostname",""))&IF(((IF(AND(C11="Yes",B11="Cybernet",LEN(TRIM(E11))=0),"Missing Cybernet Hostname","")))<>"",IF((IF(AND(C11="Yes",B11="Neuron",LEN(TRIM(F11))=0),"Missing Neuron Hostname",""))<>""," | ",""),"")&(IF(AND(C11="Yes",B11="Neuron",LEN(TRIM(F11))=0),"Missing Neuron Hostname",""))&IF(((IF(AND(C11="Yes",B11="Cybernet",LEN(TRIM(E11))=0),"Missing Cybernet Hostname",""))&(IF(AND(C11="Yes",B11="Neuron",LEN(TRIM(F11))=0),"Missing Neuron Hostname","")))<>"",IF((IF(AND(C11="Yes",B11="Cybernet",LEN(TRIM(G11))=0),"Missing Software List",""))<>""," | ",""),"")&(IF(AND(C11="Yes",B11="Cybernet",LEN(TRIM(G11))=0),"Missing Software List",""))&IF(((IF(AND(C11="Yes",B11="Cybernet",LEN(TRIM(E11))=0),"Missing Cybernet Hostname",""))&(IF(AND(C11="Yes",B11="Neuron",LEN(TRIM(F11))=0),"Missing Neuron Hostname",""))&(IF(AND(C11="Yes",B11="Cybernet",LEN(TRIM(G11))=0),"Missing Software List","")))<>"",IF((IF(AND(C11="Yes",B11="Cybernet",LEN(TRIM(H11))=0),"Missing PI Use Case",""))<>""," | ",""),"")&(IF(AND(C11="Yes",B11="Cybernet",LEN(TRIM(H11))=0),"Missing PI Use Case",""))&IF(((IF(AND(C11="Yes",B11="Cybernet",LEN(TRIM(E11))=0),"Missing Cybernet Hostname",""))&(IF(AND(C11="Yes",B11="Neuron",LEN(TRIM(F11))=0),"Missing Neuron Hostname",""))&(IF(AND(C11="Yes",B11="Cybernet",LEN(TRIM(G11))=0),"Missing Software List",""))&(IF(AND(C11="Yes",B11="Cybernet",LEN(TRIM(H11))=0),"Missing PI Use Case","")))<>"",IF((IF(AND(C11="Yes",LEN(TRIM(I11))>0,LEN(TRIM(J11))=0),"Missing PI Validated By",""))<>""," | ",""),"")&(IF(AND(C11="Yes",LEN(TRIM(I11))>0,LEN(TRIM(J11))=0),"Missing PI Validated By",""))&IF(((IF(AND(C11="Yes",B11="Cybernet",LEN(TRIM(E11))=0),"Missing Cybernet Hostname",""))&(IF(AND(C11="Yes",B11="Neuron",LEN(TRIM(F11))=0),"Missing Neuron Hostname",""))&(IF(AND(C11="Yes",B11="Cybernet",LEN(TRIM(G11))=0),"Missing Software List",""))&(IF(AND(C11="Yes",B11="Cybernet",LEN(TRIM(H11))=0),"Missing PI Use Case",""))&(IF(AND(C11="Yes",LEN(TRIM(I11))>0,LEN(TRIM(J11))=0),"Missing PI Validated By","")))<>"",IF((IF(AND(C11="Yes",LEN(TRIM(J11))>0,LEN(TRIM(K11))=0),"Missing PI Validated Date",""))<>""," | ",""),"")&(IF(AND(C11="Yes",LEN(TRIM(J11))>0,LEN(TRIM(K11))=0),"Missing PI Validated Date",""))
A12: =ROW() -> 12 | B12: =IFERROR(INDEX(tblDeviceConfig[Device Type],ROW()-1),"") -> Neuron | C12: =IFERROR(INDEX(tblDeviceConfig[Deployed],ROW()-1),"") -> Yes | D12: =IFERROR(INDEX(tblDeviceConfig[Installed],ROW()-1),"") -> Yes | E12: =IFERROR(INDEX(tblDeviceConfig[Cybernet Hostname],ROW()-1),"") -> 0 | F12: =IFERROR(INDEX(tblDeviceConfig[Neuron Hostname],ROW()-1),"") -> LIJ-SDF-MACH-K | G12: =IFERROR(INDEX(tblDeviceConfig[Software List],ROW()-1),"") -> 0 | H12: =IFERROR(INDEX(tblDeviceConfig[PI_Use_Case],ROW()-1),"") -> 0 | I12: =IFERROR(INDEX(tblDeviceConfig[PI_Result],ROW()-1),"") -> 0 | J12: =IFERROR(INDEX(tblDeviceConfig[PI_Validated_By],ROW()-1),"") -> 0 | K12: =IFERROR(INDEX(tblDeviceConfig[PI_Validated_Date],ROW()-1),"") -> 0 | L12: =SUM(IF(AND(C12="Yes",B12="Cybernet",LEN(TRIM(E12))=0),1,0),IF(AND(C12="Yes",B12="Neuron",LEN(TRIM(F12))=0),1,0),IF(AND(C12="Yes",B12="Cybernet",LEN(TRIM(G12))=0),1,0),IF(AND(C12="Yes",B12="Cybernet",LEN(TRIM(H12))=0),1,0),IF(AND(C12="Yes",LEN(TRIM(I12))>0,LEN(TRIM(J12))=0),1,0),IF(AND(C12="Yes",LEN(TRIM(J12))>0,LEN(TRIM(K12))=0),1,0)) -> 0 | M12: =(IF(AND(C12="Yes",B12="Cybernet",LEN(TRIM(E12))=0),"Missing Cybernet Hostname",""))&IF(((IF(AND(C12="Yes",B12="Cybernet",LEN(TRIM(E12))=0),"Missing Cybernet Hostname","")))<>"",IF((IF(AND(C12="Yes",B12="Neuron",LEN(TRIM(F12))=0),"Missing Neuron Hostname",""))<>""," | ",""),"")&(IF(AND(C12="Yes",B12="Neuron",LEN(TRIM(F12))=0),"Missing Neuron Hostname",""))&IF(((IF(AND(C12="Yes",B12="Cybernet",LEN(TRIM(E12))=0),"Missing Cybernet Hostname",""))&(IF(AND(C12="Yes",B12="Neuron",LEN(TRIM(F12))=0),"Missing Neuron Hostname","")))<>"",IF((IF(AND(C12="Yes",B12="Cybernet",LEN(TRIM(G12))=0),"Missing Software List",""))<>""," | ",""),"")&(IF(AND(C12="Yes",B12="Cybernet",LEN(TRIM(G12))=0),"Missing Software List",""))&IF(((IF(AND(C12="Yes",B12="Cybernet",LEN(TRIM(E12))=0),"Missing Cybernet Hostname",""))&(IF(AND(C12="Yes",B12="Neuron",LEN(TRIM(F12))=0),"Missing Neuron Hostname",""))&(IF(AND(C12="Yes",B12="Cybernet",LEN(TRIM(G12))=0),"Missing Software List","")))<>"",IF((IF(AND(C12="Yes",B12="Cybernet",LEN(TRIM(H12))=0),"Missing PI Use Case",""))<>""," | ",""),"")&(IF(AND(C12="Yes",B12="Cybernet",LEN(TRIM(H12))=0),"Missing PI Use Case",""))&IF(((IF(AND(C12="Yes",B12="Cybernet",LEN(TRIM(E12))=0),"Missing Cybernet Hostname",""))&(IF(AND(C12="Yes",B12="Neuron",LEN(TRIM(F12))=0),"Missing Neuron Hostname",""))&(IF(AND(C12="Yes",B12="Cybernet",LEN(TRIM(G12))=0),"Missing Software List",""))&(IF(AND(C12="Yes",B12="Cybernet",LEN(TRIM(H12))=0),"Missing PI Use Case","")))<>"",IF((IF(AND(C12="Yes",LEN(TRIM(I12))>0,LEN(TRIM(J12))=0),"Missing PI Validated By",""))<>""," | ",""),"")&(IF(AND(C12="Yes",LEN(TRIM(I12))>0,LEN(TRIM(J12))=0),"Missing PI Validated By",""))&IF(((IF(AND(C12="Yes",B12="Cybernet",LEN(TRIM(E12))=0),"Missing Cybernet Hostname",""))&(IF(AND(C12="Yes",B12="Neuron",LEN(TRIM(F12))=0),"Missing Neuron Hostname",""))&(IF(AND(C12="Yes",B12="Cybernet",LEN(TRIM(G12))=0),"Missing Software List",""))&(IF(AND(C12="Yes",B12="Cybernet",LEN(TRIM(H12))=0),"Missing PI Use Case",""))&(IF(AND(C12="Yes",LEN(TRIM(I12))>0,LEN(TRIM(J12))=0),"Missing PI Validated By","")))<>"",IF((IF(AND(C12="Yes",LEN(TRIM(J12))>0,LEN(TRIM(K12))=0),"Missing PI Validated Date",""))<>""," | ",""),"")&(IF(AND(C12="Yes",LEN(TRIM(J12))>0,LEN(TRIM(K12))=0),"Missing PI Validated Date",""))
A13: =ROW() -> 13 | B13: =IFERROR(INDEX(tblDeviceConfig[Device Type],ROW()-1),"") -> Neuron | C13: =IFERROR(INDEX(tblDeviceConfig[Deployed],ROW()-1),"") -> Yes | D13: =IFERROR(INDEX(tblDeviceConfig[Installed],ROW()-1),"") -> Yes | E13: =IFERROR(INDEX(tblDeviceConfig[Cybernet Hostname],ROW()-1),"") -> 0 | F13: =IFERROR(INDEX(tblDeviceConfig[Neuron Hostname],ROW()-1),"") -> LIJ-SDF-MACH-L | G13: =IFERROR(INDEX(tblDeviceConfig[Software List],ROW()-1),"") -> 0 | H13: =IFERROR(INDEX(tblDeviceConfig[PI_Use_Case],ROW()-1),"") -> 0 | I13: =IFERROR(INDEX(tblDeviceConfig[PI_Result],ROW()-1),"") -> 0 | J13: =IFERROR(INDEX(tblDeviceConfig[PI_Validated_By],ROW()-1),"") -> 0 | K13: =IFERROR(INDEX(tblDeviceConfig[PI_Validated_Date],ROW()-1),"") -> 0 | L13: =SUM(IF(AND(C13="Yes",B13="Cybernet",LEN(TRIM(E13))=0),1,0),IF(AND(C13="Yes",B13="Neuron",LEN(TRIM(F13))=0),1,0),IF(AND(C13="Yes",B13="Cybernet",LEN(TRIM(G13))=0),1,0),IF(AND(C13="Yes",B13="Cybernet",LEN(TRIM(H13))=0),1,0),IF(AND(C13="Yes",LEN(TRIM(I13))>0,LEN(TRIM(J13))=0),1,0),IF(AND(C13="Yes",LEN(TRIM(J13))>0,LEN(TRIM(K13))=0),1,0)) -> 0 | M13: =(IF(AND(C13="Yes",B13="Cybernet",LEN(TRIM(E13))=0),"Missing Cybernet Hostname",""))&IF(((IF(AND(C13="Yes",B13="Cybernet",LEN(TRIM(E13))=0),"Missing Cybernet Hostname","")))<>"",IF((IF(AND(C13="Yes",B13="Neuron",LEN(TRIM(F13))=0),"Missing Neuron Hostname",""))<>""," | ",""),"")&(IF(AND(C13="Yes",B13="Neuron",LEN(TRIM(F13))=0),"Missing Neuron Hostname",""))&IF(((IF(AND(C13="Yes",B13="Cybernet",LEN(TRIM(E13))=0),"Missing Cybernet Hostname",""))&(IF(AND(C13="Yes",B13="Neuron",LEN(TRIM(F13))=0),"Missing Neuron Hostname","")))<>"",IF((IF(AND(C13="Yes",B13="Cybernet",LEN(TRIM(G13))=0),"Missing Software List",""))<>""," | ",""),"")&(IF(AND(C13="Yes",B13="Cybernet",LEN(TRIM(G13))=0),"Missing Software List",""))&IF(((IF(AND(C13="Yes",B13="Cybernet",LEN(TRIM(E13))=0),"Missing Cybernet Hostname",""))&(IF(AND(C13="Yes",B13="Neuron",LEN(TRIM(F13))=0),"Missing Neuron Hostname",""))&(IF(AND(C13="Yes",B13="Cybernet",LEN(TRIM(G13))=0),"Missing Software List","")))<>"",IF((IF(AND(C13="Yes",B13="Cybernet",LEN(TRIM(H13))=0),"Missing PI Use Case",""))<>""," | ",""),"")&(IF(AND(C13="Yes",B13="Cybernet",LEN(TRIM(H13))=0),"Missing PI Use Case",""))&IF(((IF(AND(C13="Yes",B13="Cybernet",LEN(TRIM(E13))=0),"Missing Cybernet Hostname",""))&(IF(AND(C13="Yes",B13="Neuron",LEN(TRIM(F13))=0),"Missing Neuron Hostname",""))&(IF(AND(C13="Yes",B13="Cybernet",LEN(TRIM(G13))=0),"Missing Software List",""))&(IF(AND(C13="Yes",B13="Cybernet",LEN(TRIM(H13))=0),"Missing PI Use Case","")))<>"",IF((IF(AND(C13="Yes",LEN(TRIM(I13))>0,LEN(TRIM(J13))=0),"Missing PI Validated By",""))<>""," | ",""),"")&(IF(AND(C13="Yes",LEN(TRIM(I13))>0,LEN(TRIM(J13))=0),"Missing PI Validated By",""))&IF(((IF(AND(C13="Yes",B13="Cybernet",LEN(TRIM(E13))=0),"Missing Cybernet Hostname",""))&(IF(AND(C13="Yes",B13="Neuron",LEN(TRIM(F13))=0),"Missing Neuron Hostname",""))&(IF(AND(C13="Yes",B13="Cybernet",LEN(TRIM(G13))=0),"Missing Software List",""))&(IF(AND(C13="Yes",B13="Cybernet",LEN(TRIM(H13))=0),"Missing PI Use Case",""))&(IF(AND(C13="Yes",LEN(TRIM(I13))>0,LEN(TRIM(J13))=0),"Missing PI Validated By","")))<>"",IF((IF(AND(C13="Yes",LEN(TRIM(J13))>0,LEN(TRIM(K13))=0),"Missing PI Validated Date",""))<>""," | ",""),"")&(IF(AND(C13="Yes",LEN(TRIM(J13))>0,LEN(TRIM(K13))=0),"Missing PI Validated Date",""))
... A532: =ROW() -> 532 | B532: =IFERROR(INDEX(tblDeviceConfig[Device Type],ROW()-1),"") -> Neuron | C532: =IFERROR(INDEX(tblDeviceConfig[Deployed],ROW()-1),"") -> 0 | D532: =IFERROR(INDEX(tblDeviceConfig[Installed],ROW()-1),"") -> 0 | E532: =IFERROR(INDEX(tblDeviceConfig[Cybernet Hostname],ROW()-1),"") -> 0 | F532: =IFERROR(INDEX(tblDeviceConfig[Neuron Hostname],ROW()-1),"") -> LIJ-SDF-MACH-AC | G532: =IFERROR(INDEX(tblDeviceConfig[Software List],ROW()-1),"") -> 0 | H532: =IFERROR(INDEX(tblDeviceConfig[PI_Use_Case],ROW()-1),"") -> 0 | I532: =IFERROR(INDEX(tblDeviceConfig[PI_Result],ROW()-1),"") -> 0 | J532: =IFERROR(INDEX(tblDeviceConfig[PI_Validated_By],ROW()-1),"") -> 0 | K532: =IFERROR(INDEX(tblDeviceConfig[PI_Validated_Date],ROW()-1),"") -> 0 | L532: =SUM(IF(AND(C532="Yes",B532="Cybernet",LEN(TRIM(E532))=0),1,0),IF(AND(C532="Yes",B532="Neuron",LEN(TRIM(F532))=0),1,0),IF(AND(C532="Yes",B532="Cybernet",LEN(TRIM(G532))=0),1,0),IF(AND(C532="Yes",B532="Cybernet",LEN(TRIM(H532))=0),1,0),IF(AND(C532="Yes",LEN(TRIM(I532))>0,LEN(TRIM(J532))=0),1,0),IF(AND(C532="Yes",LEN(TRIM(J532))>0,LEN(TRIM(K532))=0),1,0)) -> 0 | M532: =(IF(AND(C532="Yes",B532="Cybernet",LEN(TRIM(E532))=0),"Missing Cybernet Hostname",""))&IF(((IF(AND(C532="Yes",B532="Cybernet",LEN(TRIM(E532))=0),"Missing Cybernet Hostname","")))<>"",IF((IF(AND(C532="Yes",B532="Neuron",LEN(TRIM(F532))=0),"Missing Neuron Hostname",""))<>""," | ",""),"")&(IF(AND(C532="Yes",B532="Neuron",LEN(TRIM(F532))=0),"Missing Neuron Hostname",""))&IF(((IF(AND(C532="Yes",B532="Cybernet",LEN(TRIM(E532))=0),"Missing Cybernet Hostname",""))&(IF(AND(C532="Yes",B532="Neuron",LEN(TRIM(F532))=0),"Missing Neuron Hostname","")))<>"",IF((IF(AND(C532="Yes",B532="Cybernet",LEN(TRIM(G532))=0),"Missing Software List",""))<>""," | ",""),"")&(IF(AND(C532="Yes",B532="Cybernet",LEN(TRIM(G532))=0),"Missing Software List",""))&IF(((IF(AND(C532="Yes",B532="Cybernet",LEN(TRIM(E532))=0),"Missing Cybernet Hostname",""))&(IF(AND(C532="Yes",B532="Neuron",LEN(TRIM(F532))=0),"Missing Neuron Hostname",""))&(IF(AND(C532="Yes",B532="Cybernet",LEN(TRIM(G532))=0),"Missing Software List","")))<>"",IF((IF(AND(C532="Yes",B532="Cybernet",LEN(TRIM(H532))=0),"Missing PI Use Case",""))<>""," | ",""),"")&(IF(AND(C532="Yes",B532="Cybernet",LEN(TRIM(H532))=0),"Missing PI Use Case",""))&IF(((IF(AND(C532="Yes",B532="Cybernet",LEN(TRIM(E532))=0),"Missing Cybernet Hostname",""))&(IF(AND(C532="Yes",B532="Neuron",LEN(TRIM(F532))=0),"Missing Neuron Hostname",""))&(IF(AND(C532="Yes",B532="Cybernet",LEN(TRIM(G532))=0),"Missing Software List",""))&(IF(AND(C532="Yes",B532="Cybernet",LEN(TRIM(H532))=0),"Missing PI Use Case","")))<>"",IF((IF(AND(C532="Yes",LEN(TRIM(I532))>0,LEN(TRIM(J532))=0),"Missing PI Validated By",""))<>""," | ",""),"")&(IF(AND(C532="Yes",LEN(TRIM(I532))>0,LEN(TRIM(J532))=0),"Missing PI Validated By",""))&IF(((IF(AND(C532="Yes",B532="Cybernet",LEN(TRIM(E532))=0),"Missing Cybernet Hostname",""))&(IF(AND(C532="Yes",B532="Neuron",LEN(TRIM(F532))=0),"Missing Neuron Hostname",""))&(IF(AND(C532="Yes",B532="Cybernet",LEN(TRIM(G532))=0),"Missing Software List",""))&(IF(AND(C532="Yes",B532="Cybernet",LEN(TRIM(H532))=0),"Missing PI Use Case",""))&(IF(AND(C532="Yes",LEN(TRIM(I532))>0,LEN(TRIM(J532))=0),"Missing PI Validated By","")))<>"",IF((IF(AND(C532="Yes",LEN(TRIM(J532))>0,LEN(TRIM(K532))=0),"Missing PI Validated Date",""))<>""," | ",""),"")&(IF(AND(C532="Yes",LEN(TRIM(J532))>0,LEN(TRIM(K532))=0),"Missing PI Validated Date",""))

Sheet 00_CF_Dictionary
A1: Sheet | B1: Table | C1: AppliesTo | D1: RuleType | E1: Priority | F1: Formula | G1: dxfId | H1: Purpose | I1: Color/category | J1: Color Signature | K1: Color Name | L1: Cause
A2: 00_Error_Log_Device_Config | B2: DeviceConfigErrorLog | C2: Deployments!$A$2:$CC$532 | D2: expression | E2: 2 | F2: $L2>0 | G2: 44 | H2: Error flag (error count > 0) | I2: Red | J2: fill:solid:fg(theme=4|tint=0.59999389629810485):bg(indexed=64)||font:none
A3: 00_Error_Log_Device_Config | B3: DeviceConfigErrorLog | C3: Deployments!$BL$2:$CC$532 | D3: expression | E3: 3 | F3: $L2=0 | G3: 43 | H3: No errors (error count = 0) | I3: Green | J3: fill:solid:fg(rgb=FF8B0000):bg(rgb=FF8B0000)||font:color(rgb=FFFFFFFF)
A4: 00_Error_Log_Device_Config | B4: DeviceConfigErrorLog | C4: Deployments!$D$2:$D$532 | D4: expression | E4: 4 | F4: $L2>0 | G4: 42 | H4: Missing config (data gap) | I4: Yellow | J4: fill:solid:fg(rgb=FFFFEB9C):bg(rgb=FFFFEB9C)||font:none
A5: 01_Warehouse_Ledger | C5: C8 | D5: expression | E5: 1 | F5: AND(TRIM($A8)="",OR($B8<>"",$C8<>"",$D8<>"",$E8<>"",$F8<>"",$I8<>"")) | G5: 37 | I5: FFF8CBAD | J5: fill:solid:fg(rgb=FFF4CCCC):bg(rgb=FFF4CCCC)||font:none
A6: 01_Warehouse_Ledger | C6: C8 | D6: expression | E6: 2 | F6: AND(TRIM($A8)<>"",COUNTIF($A$2:$A$2002,$A8)>1) | G6: 36 | I6: FFF8CBAD | J6: fill:solid:fg(rgb=FFFFC7CE):bg(rgb=FFFFC7CE)||font:b|color(rgb=FF9C0006)
A7: 01_Warehouse_Ledger | C7: A2:R7 A8:B8 A9:R2002 D8:R8 | D7: expression | E7: 3 | F7: AND(TRIM($A2)="",OR($B2<>"",$C2<>"",$D2<>"",$E2<>"",$I2<>"",$J2<>"")) | G7: 41 | I7: FFF8CBAD | J7: fill:solid:fg(rgb=FFFFC7CE):bg(rgb=FFFFC7CE)||font:b|color(rgb=FF9C0006)
A8: 01_Warehouse_Ledger | C8: A2:R7 A8:B8 A9:R2002 D8:R8 | D8: expression | E8: 4 | F8: AND(TRIM($A2)<>"",NOT(AND(LEFT($A2,4)="PAL-",LEN($A2)=11,ISNUMBER(--MID($A2,5,7))))) | G8: 40 | I8: FFF8CBAD | J8: fill:solid:fg(rgb=FFFFEB9C):bg(rgb=FFFFEB9C)||font:none
A9: 01_Warehouse_Ledger | C9: A2:R7 A8:B8 A9:R2002 D8:R8 | D9: expression | E9: 5 | F9: AND(TRIM($A2)<>"",COUNTIF($A$2:$A$2002,$A2)>1) | G9: 39 | I9: FFF8CBAD | J9: fill:solid:fg(rgb=FFC6EFCE):bg(rgb=FFC6EFCE)||font:b|color(rgb=FF006100)
A10: 01_Warehouse_Ledger | C10: A2:R7 A8:B8 A9:R2002 D8:R8 | D10: expression | E10: 6 | F10: AND(TRIM($A2)<>"",$C2<>"",$D2<>"",$D2<>"0",$C2<>$D2) | G10: 38 | I10: FFFFF2CC | J10: fill:solid:fg(rgb=FFFCE4D6):bg(rgb=FFFCE4D6)||font:b|color(rgb=FF9C5700)
A11: 02_Warehouse_Locations | C11: A133 | D11: expression | E11: 1 | F11: AND(TRIM($A133)="",OR($B133<>"",$C133<>"",$D133<>"",$E133<>"",$F133<>"",$I133<>"")) | G11: 35 | I11: FFF8CBAD | J11: fill:solid:fg(rgb=FFFFC7CE):bg(rgb=FFFFC7CE)||font:b|color(rgb=FF9C0006)
A12: 02_Warehouse_Locations | C12: A133 | D12: expression | E12: 2 | F12: AND(TRIM($A133)<>"",COUNTIF($A$2:$A$2002,$A133)>1) | G12: 34 | I12: FFF8CBAD | J12: fill::fg(none):bg(rgb=FFFFEB9C)||font:color(rgb=FF9C5700)
A13: 02_Warehouse_Locations | C13: A2:I132 A134:I2002 | D13: expression | E13: 3 | F13: AND(TRIM($A2)="",OR($B2<>"",$C2<>"",$D2<>"",$E2<>"",$F2<>"",$I2<>"")) | G13: 33 | I13: FFF8CBAD | J13: fill::fg(none):bg(rgb=FFC6EFCE)||font:color(rgb=FF006100)
A14: 02_Warehouse_Locations | C14: A2:I132 A134:I2002 | D14: expression | E14: 4 | F14: AND(TRIM($A2)<>"",COUNTIF($A$2:$A$2002,$A2)>1) | G14: 32 | I14: FFF8CBAD | J14: fill:solid:fg(rgb=FFC6EFCE):bg(none)||font:none
A15: 02_Warehouse_Locations | C15: B133:I133 | D15: expression | E15: 116 | F15: AND(TRIM(#REF!)="",OR($B133<>"",$C133<>"",$D133<>"",$E133<>"",$F133<>"",$I133<>"")) | G15: 31 | I15: FFF8CBAD | J15: fill:solid:fg(rgb=FFFFEB9C):bg(none)||font:none
A16: 02_Warehouse_Locations | C16: B133:I133 | D16: expression | E16: 117 | F16: AND(TRIM(#REF!)<>"",COUNTIF($A$2:$A$2002,#REF!)>1) | G16: 30 | I16: FFF8CBAD | J16: fill:solid:fg(rgb=FFC6EFCE):bg(rgb=FFC6EFCE)||font:none
... A23: 05_Scan_Lookup | C23: B3 | D23: expression | E23: 4 | F23: AND(TRIM($A3)<>"",$C3<>"",$D3<>"",$D3<>"0",$C3<>$D3) | G23: 23 | I23: FFFFF2CC | J23: fill:solid:fg(rgb=FFFFC7CE):bg(rgb=FFFFC7CE)||font:b|color(rgb=FF9C0006)
A24: ZZ_Deprecated | B24: tblDeviceConfig | C24: Deployments!$BL$2:$BL$532 | D24: expression | E24: 1 | F24: $F2="Yes" | G24: 0 | H24: Deprecated – regenerated rules appended below | I24: Deprecated | J24: fill:solid:fg(rgb=FFFFC7CE):bg(rgb=FFFFC7CE)||font:none
A25: ZZ_Deprecated | B25: tblDeviceConfig | C25: Deployments!$BM$2:$BM$532 | D25: expression | E25: 2 | F25: AND($A2="Cybernet",$B2="Yes",$C2<>"Yes",LEN(TRIM(R2))=0) | G25: 5 | H25: Deprecated – regenerated rules appended below | I25: Deprecated | J25: fill:solid:fg(rgb=FFFFEB9C):bg(rgb=FFFFEB9C)||font:none
A26: ZZ_Deprecated | B26: tblDeviceConfig | C26: Deployments!$BN$2:$BN$532 | D26: expression | E26: 3 | F26: AND($A2="Neuron",$B2="Yes",$C2<>"Yes",LEN(TRIM(S2))=0) | G26: 5 | H26: Deprecated – regenerated rules appended below | I26: Deprecated | J26: fill:solid:fg(rgb=FFFFEB9C):bg(rgb=FFFFEB9C)||font:none
A27: ZZ_Deprecated | B27: tblDeviceConfig | C27: Deployments!$BO$2:$BO$532 | D27: expression | E27: 4 | F27: AND($A2="Cybernet",$B2="Yes",$C2<>"Yes",LEN(TRIM(BH2))=0) | G27: 5 | H27: Deprecated – regenerated rules appended below | I27: Deprecated | J27: fill:solid:fg(rgb=FFFFEB9C):bg(rgb=FFFFEB9C)||font:none
A28: ZZ_Deprecated | B28: tblDeviceConfig | C28: Deployments!$BP$2:$BP$532 | D28: expression | E28: 5 | F28: AND($C2="Yes",LEN(TRIM(INDEX($1:$1048576,ROW(),COLUMN())))=0) | G28: 45 | H28: Deprecated – regenerated rules appended below | I28: Deprecated | J28: fill:solid:fg(rgb=FFFFC7CE):bg(rgb=FFFFC7CE)||font:b|color(rgb=FF9C0006)
A29: 14 - Config Log | B29: tblConfigSnapshot | C29: I2:I503 | D29: expression | E29: 8 | F29: AND($I2<>"",OR($K2="Yes",$J2="PM Approved")) | G29: 6 | I29: Green | J29: fill:solid:fg(rgb=FFC6EFCE):bg(rgb=FFC6EFCE)||font:none
A30: 14 - Config Log | B30: tblConfigSnapshot | C30: I2:I503 | D30: expression | E30: 9 | F30: AND($I2<>"",NOT(OR($K2="Yes",$J2="PM Approved"))) | G30: 5 | I30: Yellow | J30: fill:solid:fg(rgb=FFFFEB9C):bg(rgb=FFFFEB9C)||font:none
A31: 14 - Config Log | B31: tblConfigSnapshot | C31: Q2:Q503 | D31: expression | E31: 10 | F31: Q2<>"" | G31: 4 | I31: Red | J31: fill:solid:fg(rgb=FFFFC7CE):bg(rgb=FFFFC7CE)||font:none
A32: 14 - Config Log | B32: tblConfigSnapshot | C32: R2:R503 | D32: expression | E32: 11 | F32: R2<>"" | G32: 3 | I32: FFFFE699 | J32: fill:solid:fg(rgb=FFFFE699):bg(rgb=FFFFE699)||font:none
A33: 14 - Config Log | B33: tblConfigSnapshot | C33: S2:S503 | D33: expression | E33: 12 | F33: S2<>"" | G33: 2 | I33: FFFFE699 | J33: fill:solid:fg(rgb=FFFFE699):bg(rgb=FFFFE699)||font:none
A34: 14 - Config Log | B34: tblConfigSnapshot | C34: T2:T503 | D34: expression | E34: 13 | F34: AND(T2<>"",T2="OK") | G34: 1 | I34: Green | J34: fill:solid:fg(rgb=FFC6EFCE):bg(rgb=FFC6EFCE)||font:none
A35: 14 - Config Log | B35: tblConfigSnapshot | C35: T2:T503 | D35: expression | E35: 14 | F35: AND(T2<>"",T2<>"OK") | G35: 0 | I35: Red | J35: fill:solid:fg(rgb=FFFFC7CE):bg(rgb=FFFFC7CE)||font:none
A36: 15 - Imaging Progress | C36: D1:D1048576 | D36: cellIs | E36: 1 | F36: 100% | G36: 12 | J36: fill:solid:fg(none):bg(theme=6|tint=0.79998168889431442)||font:color(rgb=FF00B050)
A37: 15 - Imaging Progress | C37: F2:F14 | D37: cellIs | E37: 2 | F37: 20 | G37: 11 | J37: fill:solid:fg(none):bg(rgb=FF92D050)||font:color(theme=1)
A38: 15 - Imaging Progress | C38: F2:F14 | D38: cellIs | E38: 3 | F38: 2 | G38: 10 | J38: fill:solid:fg(none):bg(rgb=FFFF0000)||font:color(theme=1)
A39: 15 - Imaging Progress | C39: F2:F14 | D39: cellIs | E39: 4 | F39: 6 | 9 | G39: 9 | J39: fill:solid:fg(none):bg(rgb=FFFEFFA6)||font:color(theme=1)
A40: 15 - Imaging Progress | C40: F2:F14 | D40: cellIs | E40: 5 | F40: 3 | 5 | G40: 8 | J40: fill:solid:fg(none):bg(theme=9|tint=0.59999389629810485)||font:color(theme=1)
A41: 15 - Imaging Progress | C41: F2:F15 | D41: cellIs | E41: 6 | F41: 10 | 20 | G41: 7 | J41: fill:solid:fg(none):bg(theme=6|tint=0.79998168889431442)||font:color(theme=1)
A42: Deployments | B42: tblDeviceConfig | C42: Deployments!CC2:CC532 A2:BZ49 T50:BZ100 AJ101:BZ103 AJ104:AQ104 T106:BZ149 T105:AQ105 AS104:BZ105 A50:R149 T101:AH101 T103:AH104 U102:AH102 A150:BZ531 | D42: expression | E42: 1 | F42: $F2="Yes" | G42: 43 | H42: Duplicates/conflicts flag (DupDeployed=Yes) | I42: Other | J42: fill:solid:fg(rgb=FF8B0000):bg(rgb=FF8B0000)||font:color(rgb=FFFFFFFF)
A43: Deployments | B43: tblDeviceConfig | C43: Deployments!B2:B532 | D43: expression | E43: 4 | F43: LOWER(TRIM($B2))="no" | G43: 42 | H43: Rule – see formula | I43: Yellow | J43: fill:solid:fg(rgb=FFFFEB9C):bg(rgb=FFFFEB9C)||font:none
A44: Deployments | B44: tblDeviceConfig | C44: Deployments!R99:R144 | D44: expression | E44: 5 | F44: AND(INDEX($A:$BI,ROW(),MATCH("Deployed",$A$1:$BI$1,0))="Yes",LEN(TRIM(N99))=0) | G44: 38 | H44: Rule – see formula | I44: Other | J44: fill:solid:fg(rgb=FFFCE4D6):bg(rgb=FFFCE4D6)||font:b|color(rgb=FF9C5700)
A45: Deployments | B45: tblDeviceConfig | C45: Deployments!I2:I532 | D45: expression | E45: 7 | F45: AND($A2<>"",LEN(TRIM($I2))=0) | G45: 40 | H45: Rule – see formula | I45: Yellow | J45: fill:solid:fg(rgb=FFFFEB9C):bg(rgb=FFFFEB9C)||font:none
A46: Deployments | B46: tblDeviceConfig | C46: Deployments!BI2:BI532 | D46: expression | E46: 17 | F46: AND($A2="Cybernet",UPPER(TRIM($B2))="YES",LEN(TRIM($BI2))=0) | G46: 71 | H46: Cybernet Software List missing (Deployed=Yes) | I46: Teal | J46: fill:solid:fg(rgb=FF00B0F0):bg(indexed=64)||font:none | K46: Teal | L46: Deployed Cybernet but Software List is blank
...

Sheet 00_README
A1: Use this sheet as the quick operating guide. Enter data only in the non-AUTO columns. For pallet moves, log the move once in 03_Warehouse_Movements and 01_Warehouse_Ledger updates itself.
A2: Task
A4: Go to tab | B4: Edit these columns | C4: Notes / outcome | D4: Add / update a pallet
A5: 01_Warehouse_Ledger | B5: A,B,C,E,F,G,I,J,K,L | C5: One row per pallet. Do NOT type in CurrentLocationCode / LastMove fields (AUTO). | D5: Move a pallet
A6: 03_Warehouse_Movements | B6: A,B,C,E,H,I,J (F,G optional) | C6: Add one movement row (MOVE / RECEIVE / SHIP / RETURN / etc). Ledger CurrentLocationCode + LastMoveTS update automatically. | D6: Add / update a location
A7: 02_Warehouse_Locations | B7: A–G,I | C7: One row per warehouse slot. QR_Payload auto = LocationCode. | D7: Print QR labels
A8: 04_Label_Export | B8: Nothing (auto list) | C8: Print LOCATION labels (top section) and PALLET labels (starts at row 505). QR payload stays minimal (LocationCode / PalletID). | D8: Find where a pallet is
A9: 05_Scan_Lookup | B9: Scan into B3 | C9: Scan Pallet QR -> see CurrentLocationCode + map fields instantly. | D9: Tie a device to a pallet
A10: BL (PalletID (Manual)) | B10: Deployments | C10: Enter PalletID on the device row -> BM/BN/BO auto-fill Warehouse Location + Pallet Status + Last Move TS. | D10: Pallet moves - the 30-second routine
A13: 1)
A14: Go to 03_Warehouse_Movements and add a NEW row at the top of the data (first blank row). | B14: 2)
A15: Fill: Timestamp (A), Action (B)=MOVE, PalletID (C)=scan or type, ToLocation (E)=scan location code, ByWho (H), Ref (I) if relevant, Notes (J) if needed. Optional: Item (F) + Qty (G) if you are tracking contents. | B15: 3)
A16: Do NOT edit FromLocation (D). It auto-fills from the pallet’s prior state (based on 01_Warehouse_Ledger). | B16: 4)
A17: Sanity check: open 01_Warehouse_Ledger -> CurrentLocationCode (AUTO) and LastMoveTS (AUTO) should update for that PalletID. | B17: 5)
A18: Optional: if the move changed the pallet’s lifecycle (STAGED/DEPLOYED/RETURNED), update PalletStatus (E) on 01_Warehouse_Ledger. | B18: Data rules (don’t break the tracker)
A20: • Only type into columns that are NOT labeled (AUTO) or (deprecated).
A21: • PalletIDs must exist in 01_Warehouse_Ledger before you reference them anywhere else (moves, device config, contents, labels).
A22: • PalletID format enforced by the ledger CF: PAL-0000001 (PAL- + 7 digits). Duplicates highlight.
A23: • LocationCode: pick from 02_Warehouse_Locations (use dropdowns where present).
A24: • If a cell looks formula-driven, leave it alone. Don’t paste over formulas.
A25: • If you must paste, paste VALUES only (not formatting) into input columns.
A26: • When in doubt: use 05_Scan_Lookup to verify the pallet’s current location before moving anything.
A27: Quick troubleshooting
A29: • 05_Scan_Lookup shows blanks -> confirm you scanned a valid PalletID that exists in 01_Warehouse_Ledger column A.
A30: • Move row highlights -> check required fields in 03_Warehouse_Movements: Timestamp (A), Action (B), PalletID (C), ToLocation (E).
A31: • FromLocation (AUTO) stays blank -> the pallet is unknown to the ledger or has no prior location. Add the pallet to 01_Warehouse_Ledger, set HomeLocationCode (C), then re-enter the move row.
A32: • CurrentLocationCode not updating -> confirm 03_Warehouse_Movements has a row with that PalletID and a ToLocation value; then check 01_Warehouse_Ledger columns D and M for that pallet.
... A92: TOOLING ERROR LOG (AUTO-GENERATED)
A94: ErrID | B94: Layer | C94: Part | D94: What | E94: Why | F94: Fix | G94: QA | H94: Evidence
A95: E-011 | B95: packaging | C95: /xl/worksheets/sheet1-3.xml | D95: Excel repair replaced worksheets 1-3 (XML error) | E95: Worksheet XML serialized with non-canonical namespace prefixes (xmlns_ns0 / <ns0_...>); Desktop repair replaces the parts and Web may refuse to open. | F95: Rewrite worksheets 1-3 with canonical namespaces (default worksheet ns + mc/xr/r). Preserve all other parts byte-for-byte. | G95: Desktop opens without repair; Web opens in Edit without 'WORKBOOK REPAIRED' banner. | H95: error066400_01.xml: replaced sheet1-3
A96: E-012 | B96: tables | C96: /xl/tables/table9.xml + sheet12 header | D96: tblDeviceConfig table header mismatch triggers repair | E96: tableColumn names encode line breaks as (e.g., Medical Device Class/Model) but header cells used literal newlines; Excel repairs the table on open. | F96: Make header cells match tableColumn names exactly (use strings) OR update table9 column names consistently. Do not delete/reorder sharedStrings. | G96: Web opens without repair banner; Desktop produces no new error*.xml. Table ref remains A1:CC532 (81 cols). | H96: diff: table9.xml names vs sheet12 row1
A97: E-013 | B97: data | C97: /xl/sharedStrings.xml + sheet12 A2:CC532 | D97: Deployed/Installed and other fields show wrong text (sharedStrings drift) | E97: SharedStrings were edited by deletion/reorder in a prior candidate, shifting indices. Cells still point to old indices so values display as unrelated strings. | F97: Integration rule: never delete/reorder sharedStrings. Overwrite non-formula columns in A2:CC532 with Active values; append new strings only; keep formula columns intact. | G97: Spot-check B2/C2 and random rows: values match Active; formulas still compute; Web renders correctly. | H97: Web screenshot showing wrong values; candidate i092 B2!=Yes

Sheet 01_Warehouse_Ledger
A1: PalletID | B1: HomeLocationCode | C1: CurrentLocationCode (AUTO) | D1: PalletStatus | E1: Compliance | F1: TTL_Days | G1: Expires (AUTO) | H1: ContentsSummary | I1: CreatedDate | J1: Notes | K1: CreatedBy | L1: LastMoveTS (AUTO) | M1: LastMovedBy (AUTO) | N1: QR_Payload_Pallet (deprecated) | O1: ReceiptDate (deprecated) | P1: Ref (deprecated) | Q1: Item (deprecated) | R1: QtyReceived (deprecated) | S1: Serials (deprecated) | T1: EnteredBy_RAW (deprecated) | U1: Legacy_RawInputs (deprecated) | V1: StockLines (AUTO) | W1: StockQtyTotal (AUTO) | X1: StockUniquePN (AUTO) | Y1: StockHasPN (AUTO) | Z1: PAL-0000001
