Workbook

Sheet 00_Error_Log_Device_Config
A1: Row_ID | B1: Device Type | C1: Deployed | D1: Installed | E1: Cybernet Hostname | F1: Neuron Hostname | G1: Software List | H1: PI Use Case | I1: PI Result | J1: PI Validated By | K1: PI Validated Date | L1: Error Count | M1: Error Detail
A2: =ROW() -> 2 | B2: =IFERROR(_xlfn.SINGLE(INDEX(#REF!,ROW()-1)),"") -> Neuron | C2: =IFERROR(_xlfn.SINGLE(INDEX(#REF!,ROW()-1)),"") -> Yes | D2: =IFERROR(_xlfn.SINGLE(INDEX(#REF!,ROW()-1)),"") -> Yes | E2: =IFERROR(_xlfn.SINGLE(INDEX(#REF!,ROW()-1)),"") -> 0 | F2: =IFERROR(_xlfn.SINGLE(INDEX(#REF!,ROW()-1)),"") -> LIJ-SDF-MACH-A | G2: =IFERROR(_xlfn.SINGLE(INDEX(#REF!,ROW()-1)),"") -> iPro Epic Satellite ALLSCRIPTS EPIC BCA | H2: =IFERROR(_xlfn.SINGLE(INDEX(#REF!,ROW()-1)),"") -> 0 | I2: =IFERROR(_xlfn.SINGLE(INDEX(#REF!,ROW()-1)),"") -> 0 | ... K2: =IFERROR(_xlfn.SINGLE(INDEX(#REF!,ROW()-1)),"") -> 0 | L2: =SUM(IF(AND(C2="Yes",B2="Cybernet",LEN(TRIM(E2))=0),1,0),IF(AND(C2="Yes",B2="Neuron",LEN(TRIM(F2))=0),1,0),IF(AND(C2="Yes",B2="Cybernet",LEN(TRIM(G2))=0),1,0),IF(AND(C2="Yes",B2="Cybernet",LEN(TRIM(H2))=0),1,0),IF(AND(C2="Yes",LEN(TRIM(I2))>0,LEN(TRIM(J2))=0),1,0),IF(AND(C2="Yes",LEN(TRIM(J2))>0,LEN(TRIM(K2))=0),1,0)) -> 0 | M2: =(IF(AND(C2="Yes",B2="Cybernet",LEN(TRIM(E2))=0),"Missing Cybernet Hostname",""))&IF(((IF(AND(C2="Yes",B2="Cybernet",LEN(TRIM(E2))=0),"Missing Cybernet Hostname","")))<>"",IF((IF(AND(C2="Yes",B2="Neuron",LEN(TRIM(F2))=0),"Missing Neuron Hostname",""))<>""," | ",""),"")&(IF(AND(C2="Yes",B2="Neuron",LEN(TRIM(F2))=0),"Missing Neuron Hostname",""))&IF(((IF(AND(C2="Yes",B2="Cybernet",LEN(TRIM(E2))=0),"Missing Cybernet Hostname",""))&(IF(AND(C2="Yes",B2="Neuron",LEN(TRIM(F2))=0),"Missing Neuron Hostname","")))<>"",IF((IF(AND(C2="Yes",B2="Cybernet",LEN(TRIM(G2))=0),"Missing Software List",""))<>""," | ",""),"")&(IF(AND(C2="Yes",B2="Cybernet",LEN(TRIM(G2))=0),"Missing Software List",""))&IF(((IF(AND(C2="Yes",B2="Cybernet",LEN(TRIM(E2))=0),"Missing Cybernet Hostname",""))&(IF(AND(C2="Yes",B2="Neuron",LEN(TRIM(F2))=0),"Missing Neuron Hostname",""))&(IF(AND(C2="Yes",B2="Cybernet",LEN(TRIM(G2))=0),"Missing Software List","")))<>"",IF((IF(AND(C2="Yes",B2="Cybernet",LEN(TRIM(H2))=0),"Missing PI Use Case",""))<>""," | ",""),"")&(IF(AND(C2="Yes",B2="Cybernet",LEN(TRIM(H2))=0),"Missing PI Use Case",""))&IF(((IF(AND(C2="Yes",B2="Cybernet",LEN(TRIM(E2))=0),"Missing Cybernet Hostname",""))&(IF(AND(C2="Yes",B2="Neuron",LEN(TRIM(F2))=0),"Missing Neuron Hostname",""))&(IF(AND(C2="Yes",B2="Cybernet",LEN(TRIM(G2))=0),"Missing Software List",""))&(IF(AND(C2="Yes",B2="Cybernet",LEN(TRIM(H2))=0),"Missing PI Use Case","")))<>"",IF((IF(AND(C2="Yes",LEN(TRIM(I2))>0,LEN(TRIM(J2))=0),"Missing PI Validated By",""))<>""," | ",""),"")&(IF(AND(C2="Yes",LEN(TRIM(I2))>0,LEN(TRIM(J2))=0),"Missing PI Validated By",""))&IF(((IF(AND(C2="Yes",B2="Cybernet",LEN(TRIM(E2))=0),"Missing Cybernet Hostname",""))&(IF(AND(C2="Yes",B2="Neuron",LEN(TRIM(F2))=0),"Missing Neuron Hostname",""))&(IF(AND(C2="Yes",B2="Cybernet",LEN(TRIM(G2))=0),"Missing Software List",""))&(IF(AND(C2="Yes",B2="Cybernet",LEN(TRIM(H2))=0),"Missing PI Use Case",""))&(IF(AND(C2="Yes",LEN(TRIM(I2))>0,LEN(TRIM(J2))=0),"Missing PI Validated By","")))<>"",IF((IF(AND(C2="Yes",LEN(TRIM(J2))>0,LEN(TRIM(K2))=0),"Missing PI Validated Date",""))<>""," | ",""),"")&(IF(AND(C2="Yes",LEN(TRIM(J2))>0,LEN(TRIM(K2))=0),"Missing PI Validated Date",""))
A3: =ROW() -> 3 | B3: =IFERROR(_xlfn.SINGLE(INDEX(#REF!,ROW()-1)),"") -> Neuron | C3: =IFERROR(_xlfn.SINGLE(INDEX(#REF!,ROW()-1)),"") -> Yes | D3: =IFERROR(_xlfn.SINGLE(INDEX(#REF!,ROW()-1)),"") -> Yes | E3: =IFERROR(_xlfn.SINGLE(INDEX(#REF!,ROW()-1)),"") -> 0 | F3: =IFERROR(_xlfn.SINGLE(INDEX(#REF!,ROW()-1)),"") -> LIJ-SDF-MACH-B | G3: =IFERROR(_xlfn.SINGLE(INDEX(#REF!,ROW()-1)),"") -> 0 | H3: =IFERROR(_xlfn.SINGLE(INDEX(#REF!,ROW()-1)),"") -> 0 | I3: =IFERROR(_xlfn.SINGLE(INDEX(#REF!,ROW()-1)),"") -> 0 | ... K3: =IFERROR(_xlfn.SINGLE(INDEX(#REF!,ROW()-1)),"") -> 0 | L3: =SUM(IF(AND(C3="Yes",B3="Cybernet",LEN(TRIM(E3))=0),1,0),IF(AND(C3="Yes",B3="Neuron",LEN(TRIM(F3))=0),1,0),IF(AND(C3="Yes",B3="Cybernet",LEN(TRIM(G3))=0),1,0),IF(AND(C3="Yes",B3="Cybernet",LEN(TRIM(H3))=0),1,0),IF(AND(C3="Yes",LEN(TRIM(I3))>0,LEN(TRIM(J3))=0),1,0),IF(AND(C3="Yes",LEN(TRIM(J3))>0,LEN(TRIM(K3))=0),1,0)) -> 0 | M3: =(IF(AND(C3="Yes",B3="Cybernet",LEN(TRIM(E3))=0),"Missing Cybernet Hostname",""))&IF(((IF(AND(C3="Yes",B3="Cybernet",LEN(TRIM(E3))=0),"Missing Cybernet Hostname","")))<>"",IF((IF(AND(C3="Yes",B3="Neuron",LEN(TRIM(F3))=0),"Missing Neuron Hostname",""))<>""," | ",""),"")&(IF(AND(C3="Yes",B3="Neuron",LEN(TRIM(F3))=0),"Missing Neuron Hostname",""))&IF(((IF(AND(C3="Yes",B3="Cybernet",LEN(TRIM(E3))=0),"Missing Cybernet Hostname",""))&(IF(AND(C3="Yes",B3="Neuron",LEN(TRIM(F3))=0),"Missing Neuron Hostname","")))<>"",IF((IF(AND(C3="Yes",B3="Cybernet",LEN(TRIM(G3))=0),"Missing Software List",""))<>""," | ",""),"")&(IF(AND(C3="Yes",B3="Cybernet",LEN(TRIM(G3))=0),"Missing Software List",""))&IF(((IF(AND(C3="Yes",B3="Cybernet",LEN(TRIM(E3))=0),"Missing Cybernet Hostname",""))&(IF(AND(C3="Yes",B3="Neuron",LEN(TRIM(F3))=0),"Missing Neuron Hostname",""))&(IF(AND(C3="Yes",B3="Cybernet",LEN(TRIM(G3))=0),"Missing Software List","")))<>"",IF((IF(AND(C3="Yes",B3="Cybernet",LEN(TRIM(H3))=0),"Missing PI Use Case",""))<>""," | ",""),"")&(IF(AND(C3="Yes",B3="Cybernet",LEN(TRIM(H3))=0),"Missing PI Use Case",""))&IF(((IF(AND(C3="Yes",B3="Cybernet",LEN(TRIM(E3))=0),"Missing Cybernet Hostname",""))&(IF(AND(C3="Yes",B3="Neuron",LEN(TRIM(F3))=0),"Missing Neuron Hostname",""))&(IF(AND(C3="Yes",B3="Cybernet",LEN(TRIM(G3))=0),"Missing Software List",""))&(IF(AND(C3="Yes",B3="Cybernet",LEN(TRIM(H3))=0),"Missing PI Use Case","")))<>"",IF((IF(AND(C3="Yes",LEN(TRIM(I3))>0,LEN(TRIM(J3))=0),"Missing PI Validated By",""))<>""," | ",""),"")&(IF(AND(C3="Yes",LEN(TRIM(I3))>0,LEN(TRIM(J3))=0),"Missing PI Validated By",""))&IF(((IF(AND(C3="Yes",B3="Cybernet",LEN(TRIM(E3))=0),"Missing Cybernet Hostname",""))&(IF(AND(C3="Yes",B3="Neuron",LEN(TRIM(F3))=0),"Missing Neuron Hostname",""))&(IF(AND(C3="Yes",B3="Cybernet",LEN(TRIM(G3))=0),"Missing Software List",""))&(IF(AND(C3="Yes",B3="Cybernet",LEN(TRIM(H3))=0),"Missing PI Use Case",""))&(IF(AND(C3="Yes",LEN(TRIM(I3))>0,LEN(TRIM(J3))=0),"Missing PI Validated By","")))<>"",IF((IF(AND(C3="Yes",LEN(TRIM(J3))>0,LEN(TRIM(K3))=0),"Missing PI Validated Date",""))<>""," | ",""),"")&(IF(AND(C3="Yes",LEN(TRIM(J3))>0,LEN(TRIM(K3))=0),"Missing PI Validated Date",""))
A4: =ROW() -> 4 | B4: =IFERROR(_xlfn.SINGLE(INDEX(#REF!,ROW()-1)),"") -> Neuron | C4: =IFERROR(_xlfn.SINGLE(INDEX(#REF!,ROW()-1)),"") -> Yes | D4: =IFERROR(_xlfn.SINGLE(INDEX(#REF!,ROW()-1)),"") -> Yes | E4: =IFERROR(_xlfn.SINGLE(INDEX(#REF!,ROW()-1)),"") -> 0 | F4: =IFERROR(_xlfn.SINGLE(INDEX(#REF!,ROW()-1)),"") -> LIJ-SDF-MACH-C | G4: =IFERROR(_xlfn.SINGLE(INDEX(#REF!,ROW()-1)),"") -> 0 | H4: =IFERROR(_xlfn.SINGLE(INDEX(#REF!,ROW()-1)),"") -> 0 | I4: =IFERROR(_xlfn.SINGLE(INDEX(#REF!,ROW()-1)),"") -> 0 | ... K4: =IFERROR(_xlfn.SINGLE(INDEX(#REF!,ROW()-1)),"") -> 0 | L4: =SUM(IF(AND(C4="Yes",B4="Cybernet",LEN(TRIM(E4))=0),1,0),IF(AND(C4="Yes",B4="Neuron",LEN(TRIM(F4))=0),1,0),IF(AND(C4="Yes",B4="Cybernet",LEN(TRIM(G4))=0),1,0),IF(AND(C4="Yes",B4="Cybernet",LEN(TRIM(H4))=0),1,0),IF(AND(C4="Yes",LEN(TRIM(I4))>0,LEN(TRIM(J4))=0),1,0),IF(AND(C4="Yes",LEN(TRIM(J4))>0,LEN(TRIM(K4))=0),1,0)) -> 0 | M4: =(IF(AND(C4="Yes",B4="Cybernet",LEN(TRIM(E4))=0),"Missing Cybernet Hostname",""))&IF(((IF(AND(C4="Yes",B4="Cybernet",LEN(TRIM(E4))=0),"Missing Cybernet Hostname","")))<>"",IF((IF(AND(C4="Yes",B4="Neuron",LEN(TRIM(F4))=0),"Missing Neuron Hostname",""))<>""," | ",""),"")&(IF(AND(C4="Yes",B4="Neuron",LEN(TRIM(F4))=0),"Missing Neuron Hostname",""))&IF(((IF(AND(C4="Yes",B4="Cybernet",LEN(TRIM(E4))=0),"Missing Cybernet Hostname",""))&(IF(AND(C4="Yes",B4="Neuron",LEN(TRIM(F4))=0),"Missing Neuron Hostname","")))<>"",IF((IF(AND(C4="Yes",B4="Cybernet",LEN(TRIM(G4))=0),"Missing Software List",""))<>""," | ",""),"")&(IF(AND(C4="Yes",B4="Cybernet",LEN(TRIM(G4))=0),"Missing Software List",""))&IF(((IF(AND(C4="Yes",B4="Cybernet",LEN(TRIM(E4))=0),"Missing Cybernet Hostname",""))&(IF(AND(C4="Yes",B4="Neuron",LEN(TRIM(F4))=0),"Missing Neuron Hostname",""))&(IF(AND(C4="Yes",B4="Cybernet",LEN(TRIM(G4))=0),"Missing Software List","")))<>"",IF((IF(AND(C4="Yes",B4="Cybernet",LEN(TRIM(H4))=0),"Missing PI Use Case",""))<>""," | ",""),"")&(IF(AND(C4="Yes",B4="Cybernet",LEN(TRIM(H4))=0),"Missing PI Use Case",""))&IF(((IF(AND(C4="Yes",B4="Cybernet",LEN(TRIM(E4))=0),"Missing Cybernet Hostname",""))&(IF(AND(C4="Yes",B4="Neuron",LEN(TRIM(F4))=0),"Missing Neuron Hostname",""))&(IF(AND(C4="Yes",B4="Cybernet",LEN(TRIM(G4))=0),"Missing Software List",""))&(IF(AND(C4="Yes",B4="Cybernet",LEN(TRIM(H4))=0),"Missing PI Use Case","")))<>"",IF((IF(AND(C4="Yes",LEN(TRIM(I4))>0,LEN(TRIM(J4))=0),"Missing PI Validated By",""))<>""," | ",""),"")&(IF(AND(C4="Yes",LEN(TRIM(I4))>0,LEN(TRIM(J4))=0),"Missing PI Validated By",""))&IF(((IF(AND(C4="Yes",B4="Cybernet",LEN(TRIM(E4))=0),"Missing Cybernet Hostname",""))&(IF(AND(C4="Yes",B4="Neuron",LEN(TRIM(F4))=0),"Missing Neuron Hostname",""))&(IF(AND(C4="Yes",B4="Cybernet",LEN(TRIM(G4))=0),"Missing Software List",""))&(IF(AND(C4="Yes",B4="Cybernet",LEN(TRIM(H4))=0),"Missing PI Use Case",""))&(IF(AND(C4="Yes",LEN(TRIM(I4))>0,LEN(TRIM(J4))=0),"Missing PI Validated By","")))<>"",IF((IF(AND(C4="Yes",LEN(TRIM(J4))>0,LEN(TRIM(K4))=0),"Missing PI Validated Date",""))<>""," | ",""),"")&(IF(AND(C4="Yes",LEN(TRIM(J4))>0,LEN(TRIM(K4))=0),"Missing PI Validated Date",""))
A5: =ROW() -> 5 | B5: =IFERROR(_xlfn.SINGLE(INDEX(#REF!,ROW()-1)),"") -> Neuron | C5: =IFERROR(_xlfn.SINGLE(INDEX(#REF!,ROW()-1)),"") -> Yes | D5: =IFERROR(_xlfn.SINGLE(INDEX(#REF!,ROW()-1)),"") -> Yes | E5: =IFERROR(_xlfn.SINGLE(INDEX(#REF!,ROW()-1)),"") -> 0 | F5: =IFERROR(_xlfn.SINGLE(INDEX(#REF!,ROW()-1)),"") -> LIJ-SDF-MACH-D | G5: =IFERROR(_xlfn.SINGLE(INDEX(#REF!,ROW()-1)),"") -> 0 | H5: =IFERROR(_xlfn.SINGLE(INDEX(#REF!,ROW()-1)),"") -> 0 | I5: =IFERROR(_xlfn.SINGLE(INDEX(#REF!,ROW()-1)),"") -> 0 | ... K5: =IFERROR(_xlfn.SINGLE(INDEX(#REF!,ROW()-1)),"") -> 0 | L5: =SUM(IF(AND(C5="Yes",B5="Cybernet",LEN(TRIM(E5))=0),1,0),IF(AND(C5="Yes",B5="Neuron",LEN(TRIM(F5))=0),1,0),IF(AND(C5="Yes",B5="Cybernet",LEN(TRIM(G5))=0),1,0),IF(AND(C5="Yes",B5="Cybernet",LEN(TRIM(H5))=0),1,0),IF(AND(C5="Yes",LEN(TRIM(I5))>0,LEN(TRIM(J5))=0),1,0),IF(AND(C5="Yes",LEN(TRIM(J5))>0,LEN(TRIM(K5))=0),1,0)) -> 0 | M5: =(IF(AND(C5="Yes",B5="Cybernet",LEN(TRIM(E5))=0),"Missing Cybernet Hostname",""))&IF(((IF(AND(C5="Yes",B5="Cybernet",LEN(TRIM(E5))=0),"Missing Cybernet Hostname","")))<>"",IF((IF(AND(C5="Yes",B5="Neuron",LEN(TRIM(F5))=0),"Missing Neuron Hostname",""))<>""," | ",""),"")&(IF(AND(C5="Yes",B5="Neuron",LEN(TRIM(F5))=0),"Missing Neuron Hostname",""))&IF(((IF(AND(C5="Yes",B5="Cybernet",LEN(TRIM(E5))=0),"Missing Cybernet Hostname",""))&(IF(AND(C5="Yes",B5="Neuron",LEN(TRIM(F5))=0),"Missing Neuron Hostname","")))<>"",IF((IF(AND(C5="Yes",B5="Cybernet",LEN(TRIM(G5))=0),"Missing Software List",""))<>""," | ",""),"")&(IF(AND(C5="Yes",B5="Cybernet",LEN(TRIM(G5))=0),"Missing Software List",""))&IF(((IF(AND(C5="Yes",B5="Cybernet",LEN(TRIM(E5))=0),"Missing Cybernet Hostname",""))&(IF(AND(C5="Yes",B5="Neuron",LEN(TRIM(F5))=0),"Missing Neuron Hostname",""))&(IF(AND(C5="Yes",B5="Cybernet",LEN(TRIM(G5))=0),"Missing Software List","")))<>"",IF((IF(AND(C5="Yes",B5="Cybernet",LEN(TRIM(H5))=0),"Missing PI Use Case",""))<>""," | ",""),"")&(IF(AND(C5="Yes",B5="Cybernet",LEN(TRIM(H5))=0),"Missing PI Use Case",""))&IF(((IF(AND(C5="Yes",B5="Cybernet",LEN(TRIM(E5))=0),"Missing Cybernet Hostname",""))&(IF(AND(C5="Yes",B5="Neuron",LEN(TRIM(F5))=0),"Missing Neuron Hostname",""))&(IF(AND(C5="Yes",B5="Cybernet",LEN(TRIM(G5))=0),"Missing Software List",""))&(IF(AND(C5="Yes",B5="Cybernet",LEN(TRIM(H5))=0),"Missing PI Use Case","")))<>"",IF((IF(AND(C5="Yes",LEN(TRIM(I5))>0,LEN(TRIM(J5))=0),"Missing PI Validated By",""))<>""," | ",""),"")&(IF(AND(C5="Yes",LEN(TRIM(I5))>0,LEN(TRIM(J5))=0),"Missing PI Validated By",""))&IF(((IF(AND(C5="Yes",B5="Cybernet",LEN(TRIM(E5))=0),"Missing Cybernet Hostname",""))&(IF(AND(C5="Yes",B5="Neuron",LEN(TRIM(F5))=0),"Missing Neuron Hostname",""))&(IF(AND(C5="Yes",B5="Cybernet",LEN(TRIM(G5))=0),"Missing Software List",""))&(IF(AND(C5="Yes",B5="Cybernet",LEN(TRIM(H5))=0),"Missing PI Use Case",""))&(IF(AND(C5="Yes",LEN(TRIM(I5))>0,LEN(TRIM(J5))=0),"Missing PI Validated By","")))<>"",IF((IF(AND(C5="Yes",LEN(TRIM(J5))>0,LEN(TRIM(K5))=0),"Missing PI Validated Date",""))<>""," | ",""),"")&(IF(AND(C5="Yes",LEN(TRIM(J5))>0,LEN(TRIM(K5))=0),"Missing PI Validated Date",""))
A6: =ROW() -> 6 | B6: =IFERROR(_xlfn.SINGLE(INDEX(#REF!,ROW()-1)),"") -> Neuron | C6: =IFERROR(_xlfn.SINGLE(INDEX(#REF!,ROW()-1)),"") -> Yes | D6: =IFERROR(_xlfn.SINGLE(INDEX(#REF!,ROW()-1)),"") -> Yes | E6: =IFERROR(_xlfn.SINGLE(INDEX(#REF!,ROW()-1)),"") -> 0 | F6: =IFERROR(_xlfn.SINGLE(INDEX(#REF!,ROW()-1)),"") -> LIJ-SDF-MACH-E | G6: =IFERROR(_xlfn.SINGLE(INDEX(#REF!,ROW()-1)),"") -> 0 | H6: =IFERROR(_xlfn.SINGLE(INDEX(#REF!,ROW()-1)),"") -> 0 | I6: =IFERROR(_xlfn.SINGLE(INDEX(#REF!,ROW()-1)),"") -> 0 | ... K6: =IFERROR(_xlfn.SINGLE(INDEX(#REF!,ROW()-1)),"") -> 0 | L6: =SUM(IF(AND(C6="Yes",B6="Cybernet",LEN(TRIM(E6))=0),1,0),IF(AND(C6="Yes",B6="Neuron",LEN(TRIM(F6))=0),1,0),IF(AND(C6="Yes",B6="Cybernet",LEN(TRIM(G6))=0),1,0),IF(AND(C6="Yes",B6="Cybernet",LEN(TRIM(H6))=0),1,0),IF(AND(C6="Yes",LEN(TRIM(I6))>0,LEN(TRIM(J6))=0),1,0),IF(AND(C6="Yes",LEN(TRIM(J6))>0,LEN(TRIM(K6))=0),1,0)) -> 0 | M6: =(IF(AND(C6="Yes",B6="Cybernet",LEN(TRIM(E6))=0),"Missing Cybernet Hostname",""))&IF(((IF(AND(C6="Yes",B6="Cybernet",LEN(TRIM(E6))=0),"Missing Cybernet Hostname","")))<>"",IF((IF(AND(C6="Yes",B6="Neuron",LEN(TRIM(F6))=0),"Missing Neuron Hostname",""))<>""," | ",""),"")&(IF(AND(C6="Yes",B6="Neuron",LEN(TRIM(F6))=0),"Missing Neuron Hostname",""))&IF(((IF(AND(C6="Yes",B6="Cybernet",LEN(TRIM(E6))=0),"Missing Cybernet Hostname",""))&(IF(AND(C6="Yes",B6="Neuron",LEN(TRIM(F6))=0),"Missing Neuron Hostname","")))<>"",IF((IF(AND(C6="Yes",B6="Cybernet",LEN(TRIM(G6))=0),"Missing Software List",""))<>""," | ",""),"")&(IF(AND(C6="Yes",B6="Cybernet",LEN(TRIM(G6))=0),"Missing Software List",""))&IF(((IF(AND(C6="Yes",B6="Cybernet",LEN(TRIM(E6))=0),"Missing Cybernet Hostname",""))&(IF(AND(C6="Yes",B6="Neuron",LEN(TRIM(F6))=0),"Missing Neuron Hostname",""))&(IF(AND(C6="Yes",B6="Cybernet",LEN(TRIM(G6))=0),"Missing Software List","")))<>"",IF((IF(AND(C6="Yes",B6="Cybernet",LEN(TRIM(H6))=0),"Missing PI Use Case",""))<>""," | ",""),"")&(IF(AND(C6="Yes",B6="Cybernet",LEN(TRIM(H6))=0),"Missing PI Use Case",""))&IF(((IF(AND(C6="Yes",B6="Cybernet",LEN(TRIM(E6))=0),"Missing Cybernet Hostname",""))&(IF(AND(C6="Yes",B6="Neuron",LEN(TRIM(F6))=0),"Missing Neuron Hostname",""))&(IF(AND(C6="Yes",B6="Cybernet",LEN(TRIM(G6))=0),"Missing Software List",""))&(IF(AND(C6="Yes",B6="Cybernet",LEN(TRIM(H6))=0),"Missing PI Use Case","")))<>"",IF((IF(AND(C6="Yes",LEN(TRIM(I6))>0,LEN(TRIM(J6))=0),"Missing PI Validated By",""))<>""," | ",""),"")&(IF(AND(C6="Yes",LEN(TRIM(I6))>0,LEN(TRIM(J6))=0),"Missing PI Validated By",""))&IF(((IF(AND(C6="Yes",B6="Cybernet",LEN(TRIM(E6))=0),"Missing Cybernet Hostname",""))&(IF(AND(C6="Yes",B6="Neuron",LEN(TRIM(F6))=0),"Missing Neuron Hostname",""))&(IF(AND(C6="Yes",B6="Cybernet",LEN(TRIM(G6))=0),"Missing Software List",""))&(IF(AND(C6="Yes",B6="Cybernet",LEN(TRIM(H6))=0),"Missing PI Use Case",""))&(IF(AND(C6="Yes",LEN(TRIM(I6))>0,LEN(TRIM(J6))=0),"Missing PI Validated By","")))<>"",IF((IF(AND(C6="Yes",LEN(TRIM(J6))>0,LEN(TRIM(K6))=0),"Missing PI Validated Date",""))<>""," | ",""),"")&(IF(AND(C6="Yes",LEN(TRIM(J6))>0,LEN(TRIM(K6))=0),"Missing PI Validated Date",""))
A7: =ROW() -> 7 | B7: =IFERROR(_xlfn.SINGLE(INDEX(#REF!,ROW()-1)),"") -> Neuron | C7: =IFERROR(_xlfn.SINGLE(INDEX(#REF!,ROW()-1)),"") -> Yes | D7: =IFERROR(_xlfn.SINGLE(INDEX(#REF!,ROW()-1)),"") -> Yes | E7: =IFERROR(_xlfn.SINGLE(INDEX(#REF!,ROW()-1)),"") -> 0 | F7: =IFERROR(_xlfn.SINGLE(INDEX(#REF!,ROW()-1)),"") -> LIJ-SDF-MACH-F | G7: =IFERROR(_xlfn.SINGLE(INDEX(#REF!,ROW()-1)),"") -> 0 | H7: =IFERROR(_xlfn.SINGLE(INDEX(#REF!,ROW()-1)),"") -> 0 | I7: =IFERROR(_xlfn.SINGLE(INDEX(#REF!,ROW()-1)),"") -> 0 | ... K7: =IFERROR(_xlfn.SINGLE(INDEX(#REF!,ROW()-1)),"") -> 0 | L7: =SUM(IF(AND(C7="Yes",B7="Cybernet",LEN(TRIM(E7))=0),1,0),IF(AND(C7="Yes",B7="Neuron",LEN(TRIM(F7))=0),1,0),IF(AND(C7="Yes",B7="Cybernet",LEN(TRIM(G7))=0),1,0),IF(AND(C7="Yes",B7="Cybernet",LEN(TRIM(H7))=0),1,0),IF(AND(C7="Yes",LEN(TRIM(I7))>0,LEN(TRIM(J7))=0),1,0),IF(AND(C7="Yes",LEN(TRIM(J7))>0,LEN(TRIM(K7))=0),1,0)) -> 0 | M7: =(IF(AND(C7="Yes",B7="Cybernet",LEN(TRIM(E7))=0),"Missing Cybernet Hostname",""))&IF(((IF(AND(C7="Yes",B7="Cybernet",LEN(TRIM(E7))=0),"Missing Cybernet Hostname","")))<>"",IF((IF(AND(C7="Yes",B7="Neuron",LEN(TRIM(F7))=0),"Missing Neuron Hostname",""))<>""," | ",""),"")&(IF(AND(C7="Yes",B7="Neuron",LEN(TRIM(F7))=0),"Missing Neuron Hostname",""))&IF(((IF(AND(C7="Yes",B7="Cybernet",LEN(TRIM(E7))=0),"Missing Cybernet Hostname",""))&(IF(AND(C7="Yes",B7="Neuron",LEN(TRIM(F7))=0),"Missing Neuron Hostname","")))<>"",IF((IF(AND(C7="Yes",B7="Cybernet",LEN(TRIM(G7))=0),"Missing Software List",""))<>""," | ",""),"")&(IF(AND(C7="Yes",B7="Cybernet",LEN(TRIM(G7))=0),"Missing Software List",""))&IF(((IF(AND(C7="Yes",B7="Cybernet",LEN(TRIM(E7))=0),"Missing Cybernet Hostname",""))&(IF(AND(C7="Yes",B7="Neuron",LEN(TRIM(F7))=0),"Missing Neuron Hostname",""))&(IF(AND(C7="Yes",B7="Cybernet",LEN(TRIM(G7))=0),"Missing Software List","")))<>"",IF((IF(AND(C7="Yes",B7="Cybernet",LEN(TRIM(H7))=0),"Missing PI Use Case",""))<>""," | ",""),"")&(IF(AND(C7="Yes",B7="Cybernet",LEN(TRIM(H7))=0),"Missing PI Use Case",""))&IF(((IF(AND(C7="Yes",B7="Cybernet",LEN(TRIM(E7))=0),"Missing Cybernet Hostname",""))&(IF(AND(C7="Yes",B7="Neuron",LEN(TRIM(F7))=0),"Missing Neuron Hostname",""))&(IF(AND(C7="Yes",B7="Cybernet",LEN(TRIM(G7))=0),"Missing Software List",""))&(IF(AND(C7="Yes",B7="Cybernet",LEN(TRIM(H7))=0),"Missing PI Use Case","")))<>"",IF((IF(AND(C7="Yes",LEN(TRIM(I7))>0,LEN(TRIM(J7))=0),"Missing PI Validated By",""))<>""," | ",""),"")&(IF(AND(C7="Yes",LEN(TRIM(I7))>0,LEN(TRIM(J7))=0),"Missing PI Validated By",""))&IF(((IF(AND(C7="Yes",B7="Cybernet",LEN(TRIM(E7))=0),"Missing Cybernet Hostname",""))&(IF(AND(C7="Yes",B7="Neuron",LEN(TRIM(F7))=0),"Missing Neuron Hostname",""))&(IF(AND(C7="Yes",B7="Cybernet",LEN(TRIM(G7))=0),"Missing Software List",""))&(IF(AND(C7="Yes",B7="Cybernet",LEN(TRIM(H7))=0),"Missing PI Use Case",""))&(IF(AND(C7="Yes",LEN(TRIM(I7))>0,LEN(TRIM(J7))=0),"Missing PI Validated By","")))<>"",IF((IF(AND(C7="Yes",LEN(TRIM(J7))>0,LEN(TRIM(K7))=0),"Missing PI Validated Date",""))<>""," | ",""),"")&(IF(AND(C7="Yes",LEN(TRIM(J7))>0,LEN(TRIM(K7))=0),"Missing PI Validated Date",""))
A8: =ROW() -> 8 | B8: =IFERROR(_xlfn.SINGLE(INDEX(#REF!,ROW()-1)),"") -> Neuron | C8: =IFERROR(_xlfn.SINGLE(INDEX(#REF!,ROW()-1)),"") -> Yes | D8: =IFERROR(_xlfn.SINGLE(INDEX(#REF!,ROW()-1)),"") -> Yes | E8: =IFERROR(_xlfn.SINGLE(INDEX(#REF!,ROW()-1)),"") -> 0 | F8: =IFERROR(_xlfn.SINGLE(INDEX(#REF!,ROW()-1)),"") -> LIJ-SDF-MACH-G | G8: =IFERROR(_xlfn.SINGLE(INDEX(#REF!,ROW()-1)),"") -> 0 | H8: =IFERROR(_xlfn.SINGLE(INDEX(#REF!,ROW()-1)),"") -> 0 | I8: =IFERROR(_xlfn.SINGLE(INDEX(#REF!,ROW()-1)),"") -> 0 | ... K8: =IFERROR(_xlfn.SINGLE(INDEX(#REF!,ROW()-1)),"") -> 0 | L8: =SUM(IF(AND(C8="Yes",B8="Cybernet",LEN(TRIM(E8))=0),1,0),IF(AND(C8="Yes",B8="Neuron",LEN(TRIM(F8))=0),1,0),IF(AND(C8="Yes",B8="Cybernet",LEN(TRIM(G8))=0),1,0),IF(AND(C8="Yes",B8="Cybernet",LEN(TRIM(H8))=0),1,0),IF(AND(C8="Yes",LEN(TRIM(I8))>0,LEN(TRIM(J8))=0),1,0),IF(AND(C8="Yes",LEN(TRIM(J8))>0,LEN(TRIM(K8))=0),1,0)) -> 0 | M8: =(IF(AND(C8="Yes",B8="Cybernet",LEN(TRIM(E8))=0),"Missing Cybernet Hostname",""))&IF(((IF(AND(C8="Yes",B8="Cybernet",LEN(TRIM(E8))=0),"Missing Cybernet Hostname","")))<>"",IF((IF(AND(C8="Yes",B8="Neuron",LEN(TRIM(F8))=0),"Missing Neuron Hostname",""))<>""," | ",""),"")&(IF(AND(C8="Yes",B8="Neuron",LEN(TRIM(F8))=0),"Missing Neuron Hostname",""))&IF(((IF(AND(C8="Yes",B8="Cybernet",LEN(TRIM(E8))=0),"Missing Cybernet Hostname",""))&(IF(AND(C8="Yes",B8="Neuron",LEN(TRIM(F8))=0),"Missing Neuron Hostname","")))<>"",IF((IF(AND(C8="Yes",B8="Cybernet",LEN(TRIM(G8))=0),"Missing Software List",""))<>""," | ",""),"")&(IF(AND(C8="Yes",B8="Cybernet",LEN(TRIM(G8))=0),"Missing Software List",""))&IF(((IF(AND(C8="Yes",B8="Cybernet",LEN(TRIM(E8))=0),"Missing Cybernet Hostname",""))&(IF(AND(C8="Yes",B8="Neuron",LEN(TRIM(F8))=0),"Missing Neuron Hostname",""))&(IF(AND(C8="Yes",B8="Cybernet",LEN(TRIM(G8))=0),"Missing Software List","")))<>"",IF((IF(AND(C8="Yes",B8="Cybernet",LEN(TRIM(H8))=0),"Missing PI Use Case",""))<>""," | ",""),"")&(IF(AND(C8="Yes",B8="Cybernet",LEN(TRIM(H8))=0),"Missing PI Use Case",""))&IF(((IF(AND(C8="Yes",B8="Cybernet",LEN(TRIM(E8))=0),"Missing Cybernet Hostname",""))&(IF(AND(C8="Yes",B8="Neuron",LEN(TRIM(F8))=0),"Missing Neuron Hostname",""))&(IF(AND(C8="Yes",B8="Cybernet",LEN(TRIM(G8))=0),"Missing Software List",""))&(IF(AND(C8="Yes",B8="Cybernet",LEN(TRIM(H8))=0),"Missing PI Use Case","")))<>"",IF((IF(AND(C8="Yes",LEN(TRIM(I8))>0,LEN(TRIM(J8))=0),"Missing PI Validated By",""))<>""," | ",""),"")&(IF(AND(C8="Yes",LEN(TRIM(I8))>0,LEN(TRIM(J8))=0),"Missing PI Validated By",""))&IF(((IF(AND(C8="Yes",B8="Cybernet",LEN(TRIM(E8))=0),"Missing Cybernet Hostname",""))&(IF(AND(C8="Yes",B8="Neuron",LEN(TRIM(F8))=0),"Missing Neuron Hostname",""))&(IF(AND(C8="Yes",B8="Cybernet",LEN(TRIM(G8))=0),"Missing Software List",""))&(IF(AND(C8="Yes",B8="Cybernet",LEN(TRIM(H8))=0),"Missing PI Use Case",""))&(IF(AND(C8="Yes",LEN(TRIM(I8))>0,LEN(TRIM(J8))=0),"Missing PI Validated By","")))<>"",IF((IF(AND(C8="Yes",LEN(TRIM(J8))>0,LEN(TRIM(K8))=0),"Missing PI Validated Date",""))<>""," | ",""),"")&(IF(AND(C8="Yes",LEN(TRIM(J8))>0,LEN(TRIM(K8))=0),"Missing PI Validated Date",""))
A9: =ROW() -> 9 | B9: =IFERROR(_xlfn.SINGLE(INDEX(#REF!,ROW()-1)),"") -> Neuron | C9: =IFERROR(_xlfn.SINGLE(INDEX(#REF!,ROW()-1)),"") -> Yes | D9: =IFERROR(_xlfn.SINGLE(INDEX(#REF!,ROW()-1)),"") -> Yes | E9: =IFERROR(_xlfn.SINGLE(INDEX(#REF!,ROW()-1)),"") -> 0 | F9: =IFERROR(_xlfn.SINGLE(INDEX(#REF!,ROW()-1)),"") -> LIJ-SDF-MACH-H | G9: =IFERROR(_xlfn.SINGLE(INDEX(#REF!,ROW()-1)),"") -> 0 | H9: =IFERROR(_xlfn.SINGLE(INDEX(#REF!,ROW()-1)),"") -> 0 | I9: =IFERROR(_xlfn.SINGLE(INDEX(#REF!,ROW()-1)),"") -> 0 | ... K9: =IFERROR(_xlfn.SINGLE(INDEX(#REF!,ROW()-1)),"") -> 0 | L9: =SUM(IF(AND(C9="Yes",B9="Cybernet",LEN(TRIM(E9))=0),1,0),IF(AND(C9="Yes",B9="Neuron",LEN(TRIM(F9))=0),1,0),IF(AND(C9="Yes",B9="Cybernet",LEN(TRIM(G9))=0),1,0),IF(AND(C9="Yes",B9="Cybernet",LEN(TRIM(H9))=0),1,0),IF(AND(C9="Yes",LEN(TRIM(I9))>0,LEN(TRIM(J9))=0),1,0),IF(AND(C9="Yes",LEN(TRIM(J9))>0,LEN(TRIM(K9))=0),1,0)) -> 0 | M9: =(IF(AND(C9="Yes",B9="Cybernet",LEN(TRIM(E9))=0),"Missing Cybernet Hostname",""))&IF(((IF(AND(C9="Yes",B9="Cybernet",LEN(TRIM(E9))=0),"Missing Cybernet Hostname","")))<>"",IF((IF(AND(C9="Yes",B9="Neuron",LEN(TRIM(F9))=0),"Missing Neuron Hostname",""))<>""," | ",""),"")&(IF(AND(C9="Yes",B9="Neuron",LEN(TRIM(F9))=0),"Missing Neuron Hostname",""))&IF(((IF(AND(C9="Yes",B9="Cybernet",LEN(TRIM(E9))=0),"Missing Cybernet Hostname",""))&(IF(AND(C9="Yes",B9="Neuron",LEN(TRIM(F9))=0),"Missing Neuron Hostname","")))<>"",IF((IF(AND(C9="Yes",B9="Cybernet",LEN(TRIM(G9))=0),"Missing Software List",""))<>""," | ",""),"")&(IF(AND(C9="Yes",B9="Cybernet",LEN(TRIM(G9))=0),"Missing Software List",""))&IF(((IF(AND(C9="Yes",B9="Cybernet",LEN(TRIM(E9))=0),"Missing Cybernet Hostname",""))&(IF(AND(C9="Yes",B9="Neuron",LEN(TRIM(F9))=0),"Missing Neuron Hostname",""))&(IF(AND(C9="Yes",B9="Cybernet",LEN(TRIM(G9))=0),"Missing Software List","")))<>"",IF((IF(AND(C9="Yes",B9="Cybernet",LEN(TRIM(H9))=0),"Missing PI Use Case",""))<>""," | ",""),"")&(IF(AND(C9="Yes",B9="Cybernet",LEN(TRIM(H9))=0),"Missing PI Use Case",""))&IF(((IF(AND(C9="Yes",B9="Cybernet",LEN(TRIM(E9))=0),"Missing Cybernet Hostname",""))&(IF(AND(C9="Yes",B9="Neuron",LEN(TRIM(F9))=0),"Missing Neuron Hostname",""))&(IF(AND(C9="Yes",B9="Cybernet",LEN(TRIM(G9))=0),"Missing Software List",""))&(IF(AND(C9="Yes",B9="Cybernet",LEN(TRIM(H9))=0),"Missing PI Use Case","")))<>"",IF((IF(AND(C9="Yes",LEN(TRIM(I9))>0,LEN(TRIM(J9))=0),"Missing PI Validated By",""))<>""," | ",""),"")&(IF(AND(C9="Yes",LEN(TRIM(I9))>0,LEN(TRIM(J9))=0),"Missing PI Validated By",""))&IF(((IF(AND(C9="Yes",B9="Cybernet",LEN(TRIM(E9))=0),"Missing Cybernet Hostname",""))&(IF(AND(C9="Yes",B9="Neuron",LEN(TRIM(F9))=0),"Missing Neuron Hostname",""))&(IF(AND(C9="Yes",B9="Cybernet",LEN(TRIM(G9))=0),"Missing Software List",""))&(IF(AND(C9="Yes",B9="Cybernet",LEN(TRIM(H9))=0),"Missing PI Use Case",""))&(IF(AND(C9="Yes",LEN(TRIM(I9))>0,LEN(TRIM(J9))=0),"Missing PI Validated By","")))<>"",IF((IF(AND(C9="Yes",LEN(TRIM(J9))>0,LEN(TRIM(K9))=0),"Missing PI Validated Date",""))<>""," | ",""),"")&(IF(AND(C9="Yes",LEN(TRIM(J9))>0,LEN(TRIM(K9))=0),"Missing PI Validated Date",""))
A10: =ROW() -> 10 | B10: =IFERROR(_xlfn.SINGLE(INDEX(#REF!,ROW()-1)),"") -> Neuron | C10: =IFERROR(_xlfn.SINGLE(INDEX(#REF!,ROW()-1)),"") -> Yes | D10: =IFERROR(_xlfn.SINGLE(INDEX(#REF!,ROW()-1)),"") -> Yes | E10: =IFERROR(_xlfn.SINGLE(INDEX(#REF!,ROW()-1)),"") -> 0 | F10: =IFERROR(_xlfn.SINGLE(INDEX(#REF!,ROW()-1)),"") -> LIJ-SDF-MACH-I | G10: =IFERROR(_xlfn.SINGLE(INDEX(#REF!,ROW()-1)),"") -> 0 | H10: =IFERROR(_xlfn.SINGLE(INDEX(#REF!,ROW()-1)),"") -> 0 | I10: =IFERROR(_xlfn.SINGLE(INDEX(#REF!,ROW()-1)),"") -> 0 | ... K10: =IFERROR(_xlfn.SINGLE(INDEX(#REF!,ROW()-1)),"") -> 0 | L10: =SUM(IF(AND(C10="Yes",B10="Cybernet",LEN(TRIM(E10))=0),1,0),IF(AND(C10="Yes",B10="Neuron",LEN(TRIM(F10))=0),1,0),IF(AND(C10="Yes",B10="Cybernet",LEN(TRIM(G10))=0),1,0),IF(AND(C10="Yes",B10="Cybernet",LEN(TRIM(H10))=0),1,0),IF(AND(C10="Yes",LEN(TRIM(I10))>0,LEN(TRIM(J10))=0),1,0),IF(AND(C10="Yes",LEN(TRIM(J10))>0,LEN(TRIM(K10))=0),1,0)) -> 0 | M10: =(IF(AND(C10="Yes",B10="Cybernet",LEN(TRIM(E10))=0),"Missing Cybernet Hostname",""))&IF(((IF(AND(C10="Yes",B10="Cybernet",LEN(TRIM(E10))=0),"Missing Cybernet Hostname","")))<>"",IF((IF(AND(C10="Yes",B10="Neuron",LEN(TRIM(F10))=0),"Missing Neuron Hostname",""))<>""," | ",""),"")&(IF(AND(C10="Yes",B10="Neuron",LEN(TRIM(F10))=0),"Missing Neuron Hostname",""))&IF(((IF(AND(C10="Yes",B10="Cybernet",LEN(TRIM(E10))=0),"Missing Cybernet Hostname",""))&(IF(AND(C10="Yes",B10="Neuron",LEN(TRIM(F10))=0),"Missing Neuron Hostname","")))<>"",IF((IF(AND(C10="Yes",B10="Cybernet",LEN(TRIM(G10))=0),"Missing Software List",""))<>""," | ",""),"")&(IF(AND(C10="Yes",B10="Cybernet",LEN(TRIM(G10))=0),"Missing Software List",""))&IF(((IF(AND(C10="Yes",B10="Cybernet",LEN(TRIM(E10))=0),"Missing Cybernet Hostname",""))&(IF(AND(C10="Yes",B10="Neuron",LEN(TRIM(F10))=0),"Missing Neuron Hostname",""))&(IF(AND(C10="Yes",B10="Cybernet",LEN(TRIM(G10))=0),"Missing Software List","")))<>"",IF((IF(AND(C10="Yes",B10="Cybernet",LEN(TRIM(H10))=0),"Missing PI Use Case",""))<>""," | ",""),"")&(IF(AND(C10="Yes",B10="Cybernet",LEN(TRIM(H10))=0),"Missing PI Use Case",""))&IF(((IF(AND(C10="Yes",B10="Cybernet",LEN(TRIM(E10))=0),"Missing Cybernet Hostname",""))&(IF(AND(C10="Yes",B10="Neuron",LEN(TRIM(F10))=0),"Missing Neuron Hostname",""))&(IF(AND(C10="Yes",B10="Cybernet",LEN(TRIM(G10))=0),"Missing Software List",""))&(IF(AND(C10="Yes",B10="Cybernet",LEN(TRIM(H10))=0),"Missing PI Use Case","")))<>"",IF((IF(AND(C10="Yes",LEN(TRIM(I10))>0,LEN(TRIM(J10))=0),"Missing PI Validated By",""))<>""," | ",""),"")&(IF(AND(C10="Yes",LEN(TRIM(I10))>0,LEN(TRIM(J10))=0),"Missing PI Validated By",""))&IF(((IF(AND(C10="Yes",B10="Cybernet",LEN(TRIM(E10))=0),"Missing Cybernet Hostname",""))&(IF(AND(C10="Yes",B10="Neuron",LEN(TRIM(F10))=0),"Missing Neuron Hostname",""))&(IF(AND(C10="Yes",B10="Cybernet",LEN(TRIM(G10))=0),"Missing Software List",""))&(IF(AND(C10="Yes",B10="Cybernet",LEN(TRIM(H10))=0),"Missing PI Use Case",""))&(IF(AND(C10="Yes",LEN(TRIM(I10))>0,LEN(TRIM(J10))=0),"Missing PI Validated By","")))<>"",IF((IF(AND(C10="Yes",LEN(TRIM(J10))>0,LEN(TRIM(K10))=0),"Missing PI Validated Date",""))<>""," | ",""),"")&(IF(AND(C10="Yes",LEN(TRIM(J10))>0,LEN(TRIM(K10))=0),"Missing PI Validated Date",""))
A11: =ROW() -> 11 | B11: =IFERROR(_xlfn.SINGLE(INDEX(#REF!,ROW()-1)),"") -> Neuron | C11: =IFERROR(_xlfn.SINGLE(INDEX(#REF!,ROW()-1)),"") -> Yes | D11: =IFERROR(_xlfn.SINGLE(INDEX(#REF!,ROW()-1)),"") -> Yes | E11: =IFERROR(_xlfn.SINGLE(INDEX(#REF!,ROW()-1)),"") -> 0 | F11: =IFERROR(_xlfn.SINGLE(INDEX(#REF!,ROW()-1)),"") -> LIJ-SDF-MACH-J | G11: =IFERROR(_xlfn.SINGLE(INDEX(#REF!,ROW()-1)),"") -> 0 | H11: =IFERROR(_xlfn.SINGLE(INDEX(#REF!,ROW()-1)),"") -> 0 | I11: =IFERROR(_xlfn.SINGLE(INDEX(#REF!,ROW()-1)),"") -> 0 | ... K11: =IFERROR(_xlfn.SINGLE(INDEX(#REF!,ROW()-1)),"") -> 0 | L11: =SUM(IF(AND(C11="Yes",B11="Cybernet",LEN(TRIM(E11))=0),1,0),IF(AND(C11="Yes",B11="Neuron",LEN(TRIM(F11))=0),1,0),IF(AND(C11="Yes",B11="Cybernet",LEN(TRIM(G11))=0),1,0),IF(AND(C11="Yes",B11="Cybernet",LEN(TRIM(H11))=0),1,0),IF(AND(C11="Yes",LEN(TRIM(I11))>0,LEN(TRIM(J11))=0),1,0),IF(AND(C11="Yes",LEN(TRIM(J11))>0,LEN(TRIM(K11))=0),1,0)) -> 0 | M11: =(IF(AND(C11="Yes",B11="Cybernet",LEN(TRIM(E11))=0),"Missing Cybernet Hostname",""))&IF(((IF(AND(C11="Yes",B11="Cybernet",LEN(TRIM(E11))=0),"Missing Cybernet Hostname","")))<>"",IF((IF(AND(C11="Yes",B11="Neuron",LEN(TRIM(F11))=0),"Missing Neuron Hostname",""))<>""," | ",""),"")&(IF(AND(C11="Yes",B11="Neuron",LEN(TRIM(F11))=0),"Missing Neuron Hostname",""))&IF(((IF(AND(C11="Yes",B11="Cybernet",LEN(TRIM(E11))=0),"Missing Cybernet Hostname",""))&(IF(AND(C11="Yes",B11="Neuron",LEN(TRIM(F11))=0),"Missing Neuron Hostname","")))<>"",IF((IF(AND(C11="Yes",B11="Cybernet",LEN(TRIM(G11))=0),"Missing Software List",""))<>""," | ",""),"")&(IF(AND(C11="Yes",B11="Cybernet",LEN(TRIM(G11))=0),"Missing Software List",""))&IF(((IF(AND(C11="Yes",B11="Cybernet",LEN(TRIM(E11))=0),"Missing Cybernet Hostname",""))&(IF(AND(C11="Yes",B11="Neuron",LEN(TRIM(F11))=0),"Missing Neuron Hostname",""))&(IF(AND(C11="Yes",B11="Cybernet",LEN(TRIM(G11))=0),"Missing Software List","")))<>"",IF((IF(AND(C11="Yes",B11="Cybernet",LEN(TRIM(H11))=0),"Missing PI Use Case",""))<>""," | ",""),"")&(IF(AND(C11="Yes",B11="Cybernet",LEN(TRIM(H11))=0),"Missing PI Use Case",""))&IF(((IF(AND(C11="Yes",B11="Cybernet",LEN(TRIM(E11))=0),"Missing Cybernet Hostname",""))&(IF(AND(C11="Yes",B11="Neuron",LEN(TRIM(F11))=0),"Missing Neuron Hostname",""))&(IF(AND(C11="Yes",B11="Cybernet",LEN(TRIM(G11))=0),"Missing Software List",""))&(IF(AND(C11="Yes",B11="Cybernet",LEN(TRIM(H11))=0),"Missing PI Use Case","")))<>"",IF((IF(AND(C11="Yes",LEN(TRIM(I11))>0,LEN(TRIM(J11))=0),"Missing PI Validated By",""))<>""," | ",""),"")&(IF(AND(C11="Yes",LEN(TRIM(I11))>0,LEN(TRIM(J11))=0),"Missing PI Validated By",""))&IF(((IF(AND(C11="Yes",B11="Cybernet",LEN(TRIM(E11))=0),"Missing Cybernet Hostname",""))&(IF(AND(C11="Yes",B11="Neuron",LEN(TRIM(F11))=0),"Missing Neuron Hostname",""))&(IF(AND(C11="Yes",B11="Cybernet",LEN(TRIM(G11))=0),"Missing Software List",""))&(IF(AND(C11="Yes",B11="Cybernet",LEN(TRIM(H11))=0),"Missing PI Use Case",""))&(IF(AND(C11="Yes",LEN(TRIM(I11))>0,LEN(TRIM(J11))=0),"Missing PI Validated By","")))<>"",IF((IF(AND(C11="Yes",LEN(TRIM(J11))>0,LEN(TRIM(K11))=0),"Missing PI Validated Date",""))<>""," | ",""),"")&(IF(AND(C11="Yes",LEN(TRIM(J11))>0,LEN(TRIM(K11))=0),"Missing PI Validated Date",""))
A12: =ROW() -> 12 | B12: =IFERROR(_xlfn.SINGLE(INDEX(#REF!,ROW()-1)),"") -> Neuron | C12: =IFERROR(_xlfn.SINGLE(INDEX(#REF!,ROW()-1)),"") -> Yes | D12: =IFERROR(_xlfn.SINGLE(INDEX(#REF!,ROW()-1)),"") -> Yes | E12: =IFERROR(_xlfn.SINGLE(INDEX(#REF!,ROW()-1)),"") -> 0 | F12: =IFERROR(_xlfn.SINGLE(INDEX(#REF!,ROW()-1)),"") -> LIJ-SDF-MACH-K | G12: =IFERROR(_xlfn.SINGLE(INDEX(#REF!,ROW()-1)),"") -> 0 | H12: =IFERROR(_xlfn.SINGLE(INDEX(#REF!,ROW()-1)),"") -> 0 | I12: =IFERROR(_xlfn.SINGLE(INDEX(#REF!,ROW()-1)),"") -> 0 | ... K12: =IFERROR(_xlfn.SINGLE(INDEX(#REF!,ROW()-1)),"") -> 0 | L12: =SUM(IF(AND(C12="Yes",B12="Cybernet",LEN(TRIM(E12))=0),1,0),IF(AND(C12="Yes",B12="Neuron",LEN(TRIM(F12))=0),1,0),IF(AND(C12="Yes",B12="Cybernet",LEN(TRIM(G12))=0),1,0),IF(AND(C12="Yes",B12="Cybernet",LEN(TRIM(H12))=0),1,0),IF(AND(C12="Yes",LEN(TRIM(I12))>0,LEN(TRIM(J12))=0),1,0),IF(AND(C12="Yes",LEN(TRIM(J12))>0,LEN(TRIM(K12))=0),1,0)) -> 0 | M12: =(IF(AND(C12="Yes",B12="Cybernet",LEN(TRIM(E12))=0),"Missing Cybernet Hostname",""))&IF(((IF(AND(C12="Yes",B12="Cybernet",LEN(TRIM(E12))=0),"Missing Cybernet Hostname","")))<>"",IF((IF(AND(C12="Yes",B12="Neuron",LEN(TRIM(F12))=0),"Missing Neuron Hostname",""))<>""," | ",""),"")&(IF(AND(C12="Yes",B12="Neuron",LEN(TRIM(F12))=0),"Missing Neuron Hostname",""))&IF(((IF(AND(C12="Yes",B12="Cybernet",LEN(TRIM(E12))=0),"Missing Cybernet Hostname",""))&(IF(AND(C12="Yes",B12="Neuron",LEN(TRIM(F12))=0),"Missing Neuron Hostname","")))<>"",IF((IF(AND(C12="Yes",B12="Cybernet",LEN(TRIM(G12))=0),"Missing Software List",""))<>""," | ",""),"")&(IF(AND(C12="Yes",B12="Cybernet",LEN(TRIM(G12))=0),"Missing Software List",""))&IF(((IF(AND(C12="Yes",B12="Cybernet",LEN(TRIM(E12))=0),"Missing Cybernet Hostname",""))&(IF(AND(C12="Yes",B12="Neuron",LEN(TRIM(F12))=0),"Missing Neuron Hostname",""))&(IF(AND(C12="Yes",B12="Cybernet",LEN(TRIM(G12))=0),"Missing Software List","")))<>"",IF((IF(AND(C12="Yes",B12="Cybernet",LEN(TRIM(H12))=0),"Missing PI Use Case",""))<>""," | ",""),"")&(IF(AND(C12="Yes",B12="Cybernet",LEN(TRIM(H12))=0),"Missing PI Use Case",""))&IF(((IF(AND(C12="Yes",B12="Cybernet",LEN(TRIM(E12))=0),"Missing Cybernet Hostname",""))&(IF(AND(C12="Yes",B12="Neuron",LEN(TRIM(F12))=0),"Missing Neuron Hostname",""))&(IF(AND(C12="Yes",B12="Cybernet",LEN(TRIM(G12))=0),"Missing Software List",""))&(IF(AND(C12="Yes",B12="Cybernet",LEN(TRIM(H12))=0),"Missing PI Use Case","")))<>"",IF((IF(AND(C12="Yes",LEN(TRIM(I12))>0,LEN(TRIM(J12))=0),"Missing PI Validated By",""))<>""," | ",""),"")&(IF(AND(C12="Yes",LEN(TRIM(I12))>0,LEN(TRIM(J12))=0),"Missing PI Validated By",""))&IF(((IF(AND(C12="Yes",B12="Cybernet",LEN(TRIM(E12))=0),"Missing Cybernet Hostname",""))&(IF(AND(C12="Yes",B12="Neuron",LEN(TRIM(F12))=0),"Missing Neuron Hostname",""))&(IF(AND(C12="Yes",B12="Cybernet",LEN(TRIM(G12))=0),"Missing Software List",""))&(IF(AND(C12="Yes",B12="Cybernet",LEN(TRIM(H12))=0),"Missing PI Use Case",""))&(IF(AND(C12="Yes",LEN(TRIM(I12))>0,LEN(TRIM(J12))=0),"Missing PI Validated By","")))<>"",IF((IF(AND(C12="Yes",LEN(TRIM(J12))>0,LEN(TRIM(K12))=0),"Missing PI Validated Date",""))<>""," | ",""),"")&(IF(AND(C12="Yes",LEN(TRIM(J12))>0,LEN(TRIM(K12))=0),"Missing PI Validated Date",""))
A13: =ROW() -> 13 | B13: =IFERROR(_xlfn.SINGLE(INDEX(#REF!,ROW()-1)),"") -> Neuron | C13: =IFERROR(_xlfn.SINGLE(INDEX(#REF!,ROW()-1)),"") -> Yes | D13: =IFERROR(_xlfn.SINGLE(INDEX(#REF!,ROW()-1)),"") -> Yes | E13: =IFERROR(_xlfn.SINGLE(INDEX(#REF!,ROW()-1)),"") -> 0 | F13: =IFERROR(_xlfn.SINGLE(INDEX(#REF!,ROW()-1)),"") -> LIJ-SDF-MACH-L | G13: =IFERROR(_xlfn.SINGLE(INDEX(#REF!,ROW()-1)),"") -> 0 | H13: =IFERROR(_xlfn.SINGLE(INDEX(#REF!,ROW()-1)),"") -> 0 | I13: =IFERROR(_xlfn.SINGLE(INDEX(#REF!,ROW()-1)),"") -> 0 | ... K13: =IFERROR(_xlfn.SINGLE(INDEX(#REF!,ROW()-1)),"") -> 0 | L13: =SUM(IF(AND(C13="Yes",B13="Cybernet",LEN(TRIM(E13))=0),1,0),IF(AND(C13="Yes",B13="Neuron",LEN(TRIM(F13))=0),1,0),IF(AND(C13="Yes",B13="Cybernet",LEN(TRIM(G13))=0),1,0),IF(AND(C13="Yes",B13="Cybernet",LEN(TRIM(H13))=0),1,0),IF(AND(C13="Yes",LEN(TRIM(I13))>0,LEN(TRIM(J13))=0),1,0),IF(AND(C13="Yes",LEN(TRIM(J13))>0,LEN(TRIM(K13))=0),1,0)) -> 0 | M13: =(IF(AND(C13="Yes",B13="Cybernet",LEN(TRIM(E13))=0),"Missing Cybernet Hostname",""))&IF(((IF(AND(C13="Yes",B13="Cybernet",LEN(TRIM(E13))=0),"Missing Cybernet Hostname","")))<>"",IF((IF(AND(C13="Yes",B13="Neuron",LEN(TRIM(F13))=0),"Missing Neuron Hostname",""))<>""," | ",""),"")&(IF(AND(C13="Yes",B13="Neuron",LEN(TRIM(F13))=0),"Missing Neuron Hostname",""))&IF(((IF(AND(C13="Yes",B13="Cybernet",LEN(TRIM(E13))=0),"Missing Cybernet Hostname",""))&(IF(AND(C13="Yes",B13="Neuron",LEN(TRIM(F13))=0),"Missing Neuron Hostname","")))<>"",IF((IF(AND(C13="Yes",B13="Cybernet",LEN(TRIM(G13))=0),"Missing Software List",""))<>""," | ",""),"")&(IF(AND(C13="Yes",B13="Cybernet",LEN(TRIM(G13))=0),"Missing Software List",""))&IF(((IF(AND(C13="Yes",B13="Cybernet",LEN(TRIM(E13))=0),"Missing Cybernet Hostname",""))&(IF(AND(C13="Yes",B13="Neuron",LEN(TRIM(F13))=0),"Missing Neuron Hostname",""))&(IF(AND(C13="Yes",B13="Cybernet",LEN(TRIM(G13))=0),"Missing Software List","")))<>"",IF((IF(AND(C13="Yes",B13="Cybernet",LEN(TRIM(H13))=0),"Missing PI Use Case",""))<>""," | ",""),"")&(IF(AND(C13="Yes",B13="Cybernet",LEN(TRIM(H13))=0),"Missing PI Use Case",""))&IF(((IF(AND(C13="Yes",B13="Cybernet",LEN(TRIM(E13))=0),"Missing Cybernet Hostname",""))&(IF(AND(C13="Yes",B13="Neuron",LEN(TRIM(F13))=0),"Missing Neuron Hostname",""))&(IF(AND(C13="Yes",B13="Cybernet",LEN(TRIM(G13))=0),"Missing Software List",""))&(IF(AND(C13="Yes",B13="Cybernet",LEN(TRIM(H13))=0),"Missing PI Use Case","")))<>"",IF((IF(AND(C13="Yes",LEN(TRIM(I13))>0,LEN(TRIM(J13))=0),"Missing PI Validated By",""))<>""," | ",""),"")&(IF(AND(C13="Yes",LEN(TRIM(I13))>0,LEN(TRIM(J13))=0),"Missing PI Validated By",""))&IF(((IF(AND(C13="Yes",B13="Cybernet",LEN(TRIM(E13))=0),"Missing Cybernet Hostname",""))&(IF(AND(C13="Yes",B13="Neuron",LEN(TRIM(F13))=0),"Missing Neuron Hostname",""))&(IF(AND(C13="Yes",B13="Cybernet",LEN(TRIM(G13))=0),"Missing Software List",""))&(IF(AND(C13="Yes",B13="Cybernet",LEN(TRIM(H13))=0),"Missing PI Use Case",""))&(IF(AND(C13="Yes",LEN(TRIM(I13))>0,LEN(TRIM(J13))=0),"Missing PI Validated By","")))<>"",IF((IF(AND(C13="Yes",LEN(TRIM(J13))>0,LEN(TRIM(K13))=0),"Missing PI Validated Date",""))<>""," | ",""),"")&(IF(AND(C13="Yes",LEN(TRIM(J13))>0,LEN(TRIM(K13))=0),"Missing PI Validated Date",""))
... A532: =ROW() -> 532 | B532: =IFERROR(_xlfn.SINGLE(INDEX(#REF!,ROW()-1)),"") -> Neuron | C532: =IFERROR(_xlfn.SINGLE(INDEX(#REF!,ROW()-1)),"") -> 0 | D532: =IFERROR(_xlfn.SINGLE(INDEX(#REF!,ROW()-1)),"") -> 0 | E532: =IFERROR(_xlfn.SINGLE(INDEX(#REF!,ROW()-1)),"") -> 0 | F532: =IFERROR(_xlfn.SINGLE(INDEX(#REF!,ROW()-1)),"") -> LIJ-SDF-MACH-AC | G532: =IFERROR(_xlfn.SINGLE(INDEX(#REF!,ROW()-1)),"") -> 0 | H532: =IFERROR(_xlfn.SINGLE(INDEX(#REF!,ROW()-1)),"") -> 0 | I532: =IFERROR(_xlfn.SINGLE(INDEX(#REF!,ROW()-1)),"") -> 0 | ... K532: =IFERROR(_xlfn.SINGLE(INDEX(#REF!,ROW()-1)),"") -> 0 | L532: =SUM(IF(AND(C532="Yes",B532="Cybernet",LEN(TRIM(E532))=0),1,0),IF(AND(C532="Yes",B532="Neuron",LEN(TRIM(F532))=0),1,0),IF(AND(C532="Yes",B532="Cybernet",LEN(TRIM(G532))=0),1,0),IF(AND(C532="Yes",B532="Cybernet",LEN(TRIM(H532))=0),1,0),IF(AND(C532="Yes",LEN(TRIM(I532))>0,LEN(TRIM(J532))=0),1,0),IF(AND(C532="Yes",LEN(TRIM(J532))>0,LEN(TRIM(K532))=0),1,0)) -> 0 | M532: =(IF(AND(C532="Yes",B532="Cybernet",LEN(TRIM(E532))=0),"Missing Cybernet Hostname",""))&IF(((IF(AND(C532="Yes",B532="Cybernet",LEN(TRIM(E532))=0),"Missing Cybernet Hostname","")))<>"",IF((IF(AND(C532="Yes",B532="Neuron",LEN(TRIM(F532))=0),"Missing Neuron Hostname",""))<>""," | ",""),"")&(IF(AND(C532="Yes",B532="Neuron",LEN(TRIM(F532))=0),"Missing Neuron Hostname",""))&IF(((IF(AND(C532="Yes",B532="Cybernet",LEN(TRIM(E532))=0),"Missing Cybernet Hostname",""))&(IF(AND(C532="Yes",B532="Neuron",LEN(TRIM(F532))=0),"Missing Neuron Hostname","")))<>"",IF((IF(AND(C532="Yes",B532="Cybernet",LEN(TRIM(G532))=0),"Missing Software List",""))<>""," | ",""),"")&(IF(AND(C532="Yes",B532="Cybernet",LEN(TRIM(G532))=0),"Missing Software List",""))&IF(((IF(AND(C532="Yes",B532="Cybernet",LEN(TRIM(E532))=0),"Missing Cybernet Hostname",""))&(IF(AND(C532="Yes",B532="Neuron",LEN(TRIM(F532))=0),"Missing Neuron Hostname",""))&(IF(AND(C532="Yes",B532="Cybernet",LEN(TRIM(G532))=0),"Missing Software List","")))<>"",IF((IF(AND(C532="Yes",B532="Cybernet",LEN(TRIM(H532))=0),"Missing PI Use Case",""))<>""," | ",""),"")&(IF(AND(C532="Yes",B532="Cybernet",LEN(TRIM(H532))=0),"Missing PI Use Case",""))&IF(((IF(AND(C532="Yes",B532="Cybernet",LEN(TRIM(E532))=0),"Missing Cybernet Hostname",""))&(IF(AND(C532="Yes",B532="Neuron",LEN(TRIM(F532))=0),"Missing Neuron Hostname",""))&(IF(AND(C532="Yes",B532="Cybernet",LEN(TRIM(G532))=0),"Missing Software List",""))&(IF(AND(C532="Yes",B532="Cybernet",LEN(TRIM(H532))=0),"Missing PI Use Case","")))<>"",IF((IF(AND(C532="Yes",LEN(TRIM(I532))>0,LEN(TRIM(J532))=0),"Missing PI Validated By",""))<>""," | ",""),"")&(IF(AND(C532="Yes",LEN(TRIM(I532))>0,LEN(TRIM(J532))=0),"Missing PI Validated By",""))&IF(((IF(AND(C532="Yes",B532="Cybernet",LEN(TRIM(E532))=0),"Missing Cybernet Hostname",""))&(IF(AND(C532="Yes",B532="Neuron",LEN(TRIM(F532))=0),"Missing Neuron Hostname",""))&(IF(AND(C532="Yes",B532="Cybernet",LEN(TRIM(G532))=0),"Missing Software List",""))&(IF(AND(C532="Yes",B532="Cybernet",LEN(TRIM(H532))=0),"Missing PI Use Case",""))&(IF(AND(C532="Yes",LEN(TRIM(I532))>0,LEN(TRIM(J532))=0),"Missing PI Validated By","")))<>"",IF((IF(AND(C532="Yes",LEN(TRIM(J532))>0,LEN(TRIM(K532))=0),"Missing PI Validated Date",""))<>""," | ",""),"")&(IF(AND(C532="Yes",LEN(TRIM(J532))>0,LEN(TRIM(K532))=0),"Missing PI Validated Date",""))

Sheet 00_CF_Dictionary

Sheet 00_README
A1: Use this sheet as the quick operating guide. Enter data only in the non-AUTO columns. For pallet moves, log the move once in 03_Warehouse_Movements and 01_Warehouse_Ledger updates itself.
A2: Task
A4: Go to tab | B4: Edit these columns | C4: Notes / outcome | D4: Add / update a pallet
A5: 01_Warehouse_Ledger | B5: A,B,C,E,F,G,I,J,K,L | C5: One row per pallet. Do NOT type in CurrentLocationCode / LastMove fields (AUTO). | D5: Move a pallet
A6: 03_Warehouse_Movements | B6: A,B,C,E,H,I,J (F,G optional) | C6: Add one movement row (MOVE / RECEIVE / SHIP / RETURN / etc). Ledger CurrentLocationCode + LastMoveTS update automatically. | D6: Add / update a location
A7: 02_Warehouse_Locations | B7: A–G,I | C7: One row per warehouse slot. QR_Payload auto = LocationCode. | D7: Print QR labels
A8: 04_Label_Export | B8: Nothing (auto list) | C8: Print LOCATION labels (top section) and PALLET labels (starts at row 505). QR payload stays minimal (LocationCode / PalletID). | D8: Find where a pallet is
A9: 05_Scan_Lookup | B9: Scan into B3 | C9: Scan Pallet QR -> see CurrentLocationCode + map fields instantly. | D9: Tie a device to a pallet
A10: BL (PalletID (Manual)) | B10: Deployments | C10: Enter PalletID on the device row -> BM/BN/BO auto-fill Warehouse Location + Pallet Status + Last Move TS. | D10: Pallet moves - the 30-second routine
A13: 1)
A14: Go to 03_Warehouse_Movements and add a NEW row at the top of the data (first blank row). | B14: 2)
A15: Fill: Timestamp (A), Action (B)=MOVE, PalletID (C)=scan or type, ToLocation (E)=scan location code, ByWho (H), Ref (I) if relevant, Notes (J) if needed. Optional: Item (F) + Qty (G) if you are tracking contents. | B15: 3)
A16: Do NOT edit FromLocation (D). It auto-fills from the pallet’s prior state (based on 01_Warehouse_Ledger). | B16: 4)
A17: Sanity check: open 01_Warehouse_Ledger -> CurrentLocationCode (AUTO) and LastMoveTS (AUTO) should update for that PalletID. | B17: 5)
A18: Optional: if the move changed the pallet’s lifecycle (STAGED/DEPLOYED/RETURNED), update PalletStatus (E) on 01_Warehouse_Ledger. | B18: Data rules (don’t break the tracker)
A20: • Only type into columns that are NOT labeled (AUTO) or (deprecated).
A21: • PalletIDs must exist in 01_Warehouse_Ledger before you reference them anywhere else (moves, device config, contents, labels).
A22: • PalletID format enforced by the ledger CF: PAL-0000001 (PAL- + 7 digits). Duplicates highlight.
A23: • LocationCode: pick from 02_Warehouse_Locations (use dropdowns where present).
A24: • If a cell looks formula-driven, leave it alone. Don’t paste over formulas.
A25: • If you must paste, paste VALUES only (not formatting) into input columns.
A26: • When in doubt: use 05_Scan_Lookup to verify the pallet’s current location before moving anything.
A27: Quick troubleshooting
A29: • 05_Scan_Lookup shows blanks -> confirm you scanned a valid PalletID that exists in 01_Warehouse_Ledger column A.
A30: • Move row highlights -> check required fields in 03_Warehouse_Movements: Timestamp (A), Action (B), PalletID (C), ToLocation (E).
A31: • FromLocation (AUTO) stays blank -> the pallet is unknown to the ledger or has no prior location. Add the pallet to 01_Warehouse_Ledger, set HomeLocationCode (C), then re-enter the move row.
A32: • CurrentLocationCode not updating -> confirm 03_Warehouse_Movements has a row with that PalletID and a ToLocation value; then check 01_Warehouse_Ledger columns D and M for that pallet.
... A92: TOOLING ERROR LOG (AUTO-GENERATED)
A94: ErrID | B94: Layer | C94: Part | D94: What | E94: Why | F94: Fix | G94: QA | H94: Evidence
A95: E-011 | B95: packaging | C95: /xl/worksheets/sheet1-3.xml | D95: Excel repair replaced worksheets 1-3 (XML error) | E95: Worksheet XML serialized with non-canonical namespace prefixes (xmlns_ns0 / <ns0_...>); Desktop repair replaces the parts and Web may refuse to open. | F95: Rewrite worksheets 1-3 with canonical namespaces (default worksheet ns + mc/xr/r). Preserve all other parts byte-for-byte. | G95: Desktop opens without repair; Web opens in Edit without 'WORKBOOK REPAIRED' banner. | H95: error066400_01.xml: replaced sheet1-3
A96: E-012 | B96: tables | C96: /xl/tables/table9.xml + sheet12 header | D96: tblDeviceConfig table header mismatch triggers repair | E96: tableColumn names encode line breaks as (e.g., Medical Device Class/Model) but header cells used literal newlines; Excel repairs the table on open. | F96: Make header cells match tableColumn names exactly (use strings) OR update table9 column names consistently. Do not delete/reorder sharedStrings. | G96: Web opens without repair banner; Desktop produces no new error*.xml. Table ref remains A1:CC532 (81 cols). | H96: diff: table9.xml names vs sheet12 row1
A97: E-013 | B97: data | C97: /xl/sharedStrings.xml + sheet12 A2:CC532 | D97: Deployed/Installed and other fields show wrong text (sharedStrings drift) | E97: SharedStrings were edited by deletion/reorder in a prior candidate, shifting indices. Cells still point to old indices so values display as unrelated strings. | F97: Integration rule: never delete/reorder sharedStrings. Overwrite non-formula columns in A2:CC532 with Active values; append new strings only; keep formula columns intact. | G97: Spot-check B2/C2 and random rows: values match Active; formulas still compute; Web renders correctly. | H97: Web screenshot showing wrong values; candidate i092 B2!=Yes

Sheet 01_Warehouse_Ledger
A1: PalletID | B1: HomeLocationCode | C1: CurrentLocationCode (AUTO) | D1: PalletStatus | E1: Compliance | F1: TTL_Days | G1: Expires (AUTO) | H1: ContentsSummary | I1: CreatedDate | J1: Notes | K1: CreatedBy | L1: LastMoveTS (AUTO) | M1: LastMovedBy (AUTO) | N1: QR_Payload_Pallet (deprecated) | O1: ReceiptDate (deprecated) | P1: Ref (deprecated) | Q1: Item (deprecated) | R1: QtyReceived (deprecated) | S1: Serials (deprecated) | T1: EnteredBy_RAW (deprecated) | U1: Legacy_RawInputs (deprecated) | V1: StockLines (AUTO) | W1: StockQtyTotal (AUTO) | X1: StockUniquePN (AUTO) | Y1: StockHasPN (AUTO) | Z1: PAL-0000001
A2: OVERFLOW-RICH-CYBERNETS-CFAM-CCMC | B2: CHRIS_OVERFLOW_A_ZONE3 | C2: ACTIVE | D2: =IF($C2="","",IFERROR(LOOKUP(2,1/('03_Warehouse_Movements'!$C$2:$C$500=$A2),'03_Warehouse_Movements'!$E$2:$E$500),$C2)) -> ACTIVE | E2: STANDARD | F2: CYBERNETS CFAM/CCMC QTY:15 | G2: 7 | H2: =IF(AND($F2="TEMP",$G2>0,$M2<>""),$M2+$G2,"") | I2: NORTHWELL NUERON PROJECT | J2: Alejandro Perales | K2: 46053 | L2: B:WH-Z1-A01-AISLE-FLOOR-02 F:OVERFLOW-<ClientLastName>-PO<PO>-<Category>-<Seq> D:WH-Z1-A01-AISLE-FLOOR-02 | M2: =IF($C2="","",IFERROR(LOOKUP(2,1/('03_Warehouse_Movements'!$C$2:$C$500=$A2),'03_Warehouse_Movements'!$A$2:$A$500),"")) | N2: =IF($C2="","",IFERROR(LOOKUP(2,1/('03_Warehouse_Movements'!$C$2:$C$500=$A2),'03_Warehouse_Movements'!$H$2:$H$500),"")) | O2: =A2 -> OVERFLOW-RICH-CYBERNETS-CFAM-CCMC | P2: 46284 | Q2: 144180 | V2: PAL-0000002 | W2: =IF($A2="","",COUNTIF('07_Pallet_Contents'!$A$2:$A$3000,$A2)) -> 0 | X2: =IF($A2="","",SUMIF('07_Pallet_Contents'!$A$2:$A$3000,$A2,'07_Pallet_Contents'!$D$2:$D$3000)) -> 0 | Y2: =IF($A2="","",SUMIF('07_Pallet_Contents'!$A$2:$A$3000,$A2,'07_Pallet_Contents'!$I$2:$I$3000)) -> 0 | Z2: =IF($A2="","",IF(COUNTIF('07_Pallet_Contents'!$A$2:$A$3000,$A2)>0,"Yes",""))
A3: WH-STAGE-IN | C3: STAGED | D3: =IF($C3="","",IFERROR(LOOKUP(2,1/('03_Warehouse_Movements'!$C$2:$C$500=$A3),'03_Warehouse_Movements'!$E$2:$E$500),$C3)) -> STAGED | E3: SAFE | F3: SAMPLE: Monitors 24-40 | H3: =IF(AND($F3="TEMP",$G3>0,$M3<>""),$M3+$G3,"") | I3: SAMPLE: replace with real notes / serials / constraints | J3: SAMPLE-TECH | K3: 46052 | L3: B:OVERFLOW-<ClientLastName>-PO<PO>-<Category>-<Seq> | M3: =IF($C3="","",IFERROR(LOOKUP(2,1/('03_Warehouse_Movements'!$C$2:$C$500=$A3),'03_Warehouse_Movements'!$A$2:$A$500),"")) | N3: =IF($C3="","",IFERROR(LOOKUP(2,1/('03_Warehouse_Movements'!$C$2:$C$500=$A3),'03_Warehouse_Movements'!$H$2:$H$500),"")) | O3: =A3 -> WH-STAGE-IN | V3: PAL-0000003 | W3: =IF($A2="","",COUNTIF('07_Pallet_Contents'!$A$2:$A$3000,$A2)) -> 0 | X3: =IF($A2="","",SUMIF('07_Pallet_Contents'!$A$2:$A$3000,$A2,'07_Pallet_Contents'!$D$2:$D$3000)) -> 0 | Y3: =IF($A2="","",SUMIF('07_Pallet_Contents'!$A$2:$A$3000,$A2,'07_Pallet_Contents'!$I$2:$I$3000)) -> 0 | Z3: =IF($A2="","",IF(COUNTIF('07_Pallet_Contents'!$A$2:$A$3000,$A2)>0,"Yes",""))
A4: OVERFLOW-CHRIS-UMAIR_TICKETS- | B4: CHRIS_OVERFLOW_A_ZONE1 | C4: UNSAFE | D4: =IF($C4="","",IFERROR(LOOKUP(2,1/('03_Warehouse_Movements'!$C$2:$C$500=$A4),'03_Warehouse_Movements'!$E$2:$E$500),$C4)) -> UNSAFE | E4: STANDARD | F4: Monitors T24-40 | H4: =IF(AND($F4="TEMP",$G4>0,$M4<>""),$M4+$G4,"") | I4: 24 Day Ticket | J4: B:OVERFLOW-CHRIS-UMAIR_TICKETS- D:CHRIS_OVERFLOW_A_ZONE1 | K4: 46046 | L4: B:WH-Z1-A01-AISLE-FLOOR-02 F:OVERFLOW-<ClientLastName>-PO<PO>-<Category>-<Seq> D:WH-Z1-A01-AISLE-FLOOR-02 | M4: =IF($C4="","",IFERROR(LOOKUP(2,1/('03_Warehouse_Movements'!$C$2:$C$500=$A4),'03_Warehouse_Movements'!$A$2:$A$500),"")) | N4: =IF($C4="","",IFERROR(LOOKUP(2,1/('03_Warehouse_Movements'!$C$2:$C$500=$A4),'03_Warehouse_Movements'!$H$2:$H$500),"")) | O4: =A4 -> OVERFLOW-CHRIS-UMAIR_TICKETS- | U4: 46046 | V4: PAL-0000004 | W4: =IF($A2="","",COUNTIF('07_Pallet_Contents'!$A$2:$A$3000,$A2)) -> 0 | X4: =IF($A2="","",SUMIF('07_Pallet_Contents'!$A$2:$A$3000,$A2,'07_Pallet_Contents'!$D$2:$D$3000)) -> 0 | Y4: =IF($A2="","",SUMIF('07_Pallet_Contents'!$A$2:$A$3000,$A2,'07_Pallet_Contents'!$I$2:$I$3000)) -> 0 | Z4: =IF($A2="","",IF(COUNTIF('07_Pallet_Contents'!$A$2:$A$3000,$A2)>0,"Yes",""))
A5: WH-Z1-AisleO-Bay10-Level1 | B5: 48x T24i-30 | C5: 48x T24i-30 | D5: =IF($C5="","",IFERROR(LOOKUP(2,1/('03_Warehouse_Movements'!$C$2:$C$500=$A5),'03_Warehouse_Movements'!$E$2:$E$500),$C5)) -> 48x T24i-30 | E5: STANDARD | F5: SAMPLE: Monitors 24-40 | H5: =IF(AND($F5="TEMP",$G5>0,$M5<>""),$M5+$G5,"") | I5: Geoff Gerber | J5: SAMPLE-TECH | K5: 46051 | L5: B:OVERFLOW-CHRIS- D:CHRIS_OVERFLOW_A_ZONE1 | M5: =IF($C5="","",IFERROR(LOOKUP(2,1/('03_Warehouse_Movements'!$C$2:$C$500=$A5),'03_Warehouse_Movements'!$A$2:$A$500),"")) | N5: =IF($C5="","",IFERROR(LOOKUP(2,1/('03_Warehouse_Movements'!$C$2:$C$500=$A5),'03_Warehouse_Movements'!$H$2:$H$500),"")) | O5: =A5 -> WH-Z1-AisleO-Bay10-Level1 | U5: 46051 | V5: PAL-0000005 | W5: =IF($A2="","",COUNTIF('07_Pallet_Contents'!$A$2:$A$3000,$A2)) -> 0 | X5: =IF($A2="","",SUMIF('07_Pallet_Contents'!$A$2:$A$3000,$A2,'07_Pallet_Contents'!$D$2:$D$3000)) -> 0 | Y5: =IF($A2="","",SUMIF('07_Pallet_Contents'!$A$2:$A$3000,$A2,'07_Pallet_Contents'!$I$2:$I$3000)) -> 0 | Z5: =IF($A2="","",IF(COUNTIF('07_Pallet_Contents'!$A$2:$A$3000,$A2)>0,"Yes",""))
A6: Northwell Capsule & GCX | B6: WH-ZR-AisleM-Bay1-Level3 | C6: capsule & GCX | D6: =IF($C6="","",IFERROR(LOOKUP(2,1/('03_Warehouse_Movements'!$C$2:$C$500=$A6),'03_Warehouse_Movements'!$E$2:$E$500),$C6)) -> capsule & GCX | E6: STANDARD | F6: SAMPLE: Monitors 24-40 | H6: =IF(AND($F6="TEMP",$G6>0,$M6<>""),$M6+$G6,"") | I6: crate looks broken, contents are tightly wrapped / unable to 100% verify actually contents of boxes | J6: Khadejah Harrison | K6: 46059 | L6: PAL-0000006 | M6: =IF($C6="","",IFERROR(LOOKUP(2,1/('03_Warehouse_Movements'!$C$2:$C$500=$A6),'03_Warehouse_Movements'!$A$2:$A$500),"")) | N6: =IF($C6="","",IFERROR(LOOKUP(2,1/('03_Warehouse_Movements'!$C$2:$C$500=$A6),'03_Warehouse_Movements'!$H$2:$H$500),"")) | O6: =A6 -> Northwell Capsule & GCX | W6: =IF($A2="","",COUNTIF('07_Pallet_Contents'!$A$2:$A$3000,$A2)) -> 0 | X6: =IF($A2="","",SUMIF('07_Pallet_Contents'!$A$2:$A$3000,$A2,'07_Pallet_Contents'!$D$2:$D$3000)) -> 0 | Y6: =IF($A2="","",SUMIF('07_Pallet_Contents'!$A$2:$A$3000,$A2,'07_Pallet_Contents'!$I$2:$I$3000)) -> 0 | Z6: =IF($A2="","",IF(COUNTIF('07_Pallet_Contents'!$A$2:$A$3000,$A2)>0,"Yes",""))
A7: WH-Z1-NOOverflow | C7: 19x T24 Thinkvision Monitor 63CFMAR1US | D7: =IF($C7="","",IFERROR(LOOKUP(2,1/('03_Warehouse_Movements'!$C$2:$C$500=$A7),'03_Warehouse_Movements'!$E$2:$E$500),$C7)) -> 19x T24 Thinkvision Monitor 63CFMAR1US | E7: SAFE | F7: SAMPLE: Monitors 24-40 | H7: =IF(AND($F7="TEMP",$G7>0,$M7<>""),$M7+$G7,"") | I7: PAL-0000007 | K7: 46052 | L7: B:OVERFLOW-CHRIS- D:CHRIS_OVERFLOW_A_ZONE1 | M7: =IF($C7="","",IFERROR(LOOKUP(2,1/('03_Warehouse_Movements'!$C$2:$C$500=$A7),'03_Warehouse_Movements'!$A$2:$A$500),"")) | N7: =IF($C7="","",IFERROR(LOOKUP(2,1/('03_Warehouse_Movements'!$C$2:$C$500=$A7),'03_Warehouse_Movements'!$H$2:$H$500),"")) | O7: =A7 -> WH-Z1-NOOverflow | W7: =IF($A2="","",COUNTIF('07_Pallet_Contents'!$A$2:$A$3000,$A2)) -> 0 | X7: =IF($A2="","",SUMIF('07_Pallet_Contents'!$A$2:$A$3000,$A2,'07_Pallet_Contents'!$D$2:$D$3000)) -> 0 | Y7: =IF($A2="","",SUMIF('07_Pallet_Contents'!$A$2:$A$3000,$A2,'07_Pallet_Contents'!$I$2:$I$3000)) -> 0 | Z7: =IF($A2="","",IF(COUNTIF('07_Pallet_Contents'!$A$2:$A$3000,$A2)>0,"Yes",""))
A8: WH-Z1-AisleO-Bay7-Level1 | C8: TEMP | D8: =IF($C8="","",IFERROR(LOOKUP(2,1/('03_Warehouse_Movements'!$C$2:$C$500=$A8),'03_Warehouse_Movements'!$E$2:$E$500),$C8)) -> TEMP | E8: SAFE | F8: PAL-0000008 | G8: 14 | H8: =IF(AND($F8="TEMP",$G8>0,$M8<>""),$M8+$G8,"") | I8: Geoff Gerber | J8: SAMPLE-TECH | K8: 46052 | L8: B:OVERFLOW-CHRIS- D:CHRIS_OVERFLOW_A_ZONE1 | M8: =IF($C8="","",IFERROR(LOOKUP(2,1/('03_Warehouse_Movements'!$C$2:$C$500=$A8),'03_Warehouse_Movements'!$A$2:$A$500),"")) | N8: =IF($C8="","",IFERROR(LOOKUP(2,1/('03_Warehouse_Movements'!$C$2:$C$500=$A8),'03_Warehouse_Movements'!$H$2:$H$500),"")) | O8: =A8 -> WH-Z1-AisleO-Bay7-Level1 | W8: =IF($A2="","",COUNTIF('07_Pallet_Contents'!$A$2:$A$3000,$A2)) -> 0 | X8: =IF($A2="","",SUMIF('07_Pallet_Contents'!$A$2:$A$3000,$A2,'07_Pallet_Contents'!$D$2:$D$3000)) -> 0 | Y8: =IF($A2="","",SUMIF('07_Pallet_Contents'!$A$2:$A$3000,$A2,'07_Pallet_Contents'!$I$2:$I$3000)) -> 0 | Z8: =IF($A2="","",IF(COUNTIF('07_Pallet_Contents'!$A$2:$A$3000,$A2)>0,"Yes",""))
A9: OVERFLOW-SAMPLE-PO1007-CAT3-PAL008 | B9: WH-Z1-AisleA-Bay1-Level5 | C9: SAMPLE: Power Supplies | D9: =IF($C9="","",IFERROR(LOOKUP(2,1/('03_Warehouse_Movements'!$C$2:$C$500=$A9),'03_Warehouse_Movements'!$E$2:$E$500),$C9)) -> SAMPLE: Power Supplies | E9: STANDARD | F9: SAMPLE: Monitors 24-40 | H9: =IF(AND($F9="TEMP",$G9>0,$M9<>""),$M9+$G9,"") | I9: PAL-0000009 | J9: SAMPLE-TECH | K9: 46052 | L9: B:OVERFLOW-<ClientLastName>-PO<PO>-<Category>-<Seq> | M9: =IF($C9="","",IFERROR(LOOKUP(2,1/('03_Warehouse_Movements'!$C$2:$C$500=$A9),'03_Warehouse_Movements'!$A$2:$A$500),"")) | N9: =IF($C9="","",IFERROR(LOOKUP(2,1/('03_Warehouse_Movements'!$C$2:$C$500=$A9),'03_Warehouse_Movements'!$H$2:$H$500),"")) | O9: =A9 -> OVERFLOW-SAMPLE-PO1007-CAT3-PAL008 | W9: =IF($A2="","",COUNTIF('07_Pallet_Contents'!$A$2:$A$3000,$A2)) -> 0 | X9: =IF($A2="","",SUMIF('07_Pallet_Contents'!$A$2:$A$3000,$A2,'07_Pallet_Contents'!$D$2:$D$3000)) -> 0 | Y9: =IF($A2="","",SUMIF('07_Pallet_Contents'!$A$2:$A$3000,$A2,'07_Pallet_Contents'!$I$2:$I$3000)) -> 0 | Z9: =IF($A2="","",IF(COUNTIF('07_Pallet_Contents'!$A$2:$A$3000,$A2)>0,"Yes",""))
A10: WH-Z1-AisleA-Bay1-Level6 | C10: SAMPLE: Imaging Equipment | D10: =IF($C10="","",IFERROR(LOOKUP(2,1/('03_Warehouse_Movements'!$C$2:$C$500=$A10),'03_Warehouse_Movements'!$E$2:$E$500),$C10)) -> SAMPLE: Imaging Equipment | E10: STANDARD | F10: SAMPLE: Monitors 24-40 | H10: =IF(AND($F10="TEMP",$G10>0,$M10<>""),$M10+$G10,"") | I10: PAL-0000010 | J10: SAMPLE-TECH | K10: 46052 | L10: B:OVERFLOW-<ClientLastName>-PO<PO>-<Category>-<Seq> | M10: =IF($C10="","",IFERROR(LOOKUP(2,1/('03_Warehouse_Movements'!$C$2:$C$500=$A10),'03_Warehouse_Movements'!$A$2:$A$500),"")) | N10: =IF($C10="","",IFERROR(LOOKUP(2,1/('03_Warehouse_Movements'!$C$2:$C$500=$A10),'03_Warehouse_Movements'!$H$2:$H$500),"")) | O10: =A10 -> WH-Z1-AisleA-Bay1-Level6 | W10: =IF($A2="","",COUNTIF('07_Pallet_Contents'!$A$2:$A$3000,$A2)) -> 0 | X10: =IF($A2="","",SUMIF('07_Pallet_Contents'!$A$2:$A$3000,$A2,'07_Pallet_Contents'!$D$2:$D$3000)) -> 0 | Y10: =IF($A2="","",SUMIF('07_Pallet_Contents'!$A$2:$A$3000,$A2,'07_Pallet_Contents'!$I$2:$I$3000)) -> 0 | Z10: =IF($A2="","",IF(COUNTIF('07_Pallet_Contents'!$A$2:$A$3000,$A2)>0,"Yes",""))
A11: WH-Z1-AisleA-Bay1-Level7 | C11: SAMPLE: Misc Hardware | D11: =IF($C11="","",IFERROR(LOOKUP(2,1/('03_Warehouse_Movements'!$C$2:$C$500=$A11),'03_Warehouse_Movements'!$E$2:$E$500),$C11)) -> SAMPLE: Misc Hardware | E11: STANDARD | F11: SAMPLE: Monitors 24-40 | H11: =IF(AND($F11="TEMP",$G11>0,$M11<>""),$M11+$G11,"") | I11: B | J11: SAMPLE-TECH | K11: 46052 | L11: B:OVERFLOW-<ClientLastName>-PO<PO>-<Category>-<Seq> | M11: =IF($C11="","",IFERROR(LOOKUP(2,1/('03_Warehouse_Movements'!$C$2:$C$500=$A11),'03_Warehouse_Movements'!$A$2:$A$500),"")) | N11: =IF($C11="","",IFERROR(LOOKUP(2,1/('03_Warehouse_Movements'!$C$2:$C$500=$A11),'03_Warehouse_Movements'!$H$2:$H$500),"")) | O11: =A11 -> WH-Z1-AisleA-Bay1-Level7 | Q11: PAL-0000011 | W11: =IF($A2="","",COUNTIF('07_Pallet_Contents'!$A$2:$A$3000,$A2)) -> 0 | X11: =IF($A2="","",SUMIF('07_Pallet_Contents'!$A$2:$A$3000,$A2,'07_Pallet_Contents'!$D$2:$D$3000)) -> 0 | Y11: =IF($A2="","",SUMIF('07_Pallet_Contents'!$A$2:$A$3000,$A2,'07_Pallet_Contents'!$I$2:$I$3000)) -> 0 | Z11: =IF($A2="","",IF(COUNTIF('07_Pallet_Contents'!$A$2:$A$3000,$A2)>0,"Yes",""))
A12: WH-Z1-AisleA-Bay1-Level8 | C12: SAMPLE: Dell Devices | D12: =IF($C12="","",IFERROR(LOOKUP(2,1/('03_Warehouse_Movements'!$C$2:$C$500=$A12),'03_Warehouse_Movements'!$E$2:$E$500),$C12)) -> SAMPLE: Dell Devices | E12: STANDARD | F12: SAMPLE: Monitors 24-40 | H12: =IF(AND($F12="TEMP",$G12>0,$M12<>""),$M12+$G12,"") | I12: PAL-0000012 | J12: SAMPLE-TECH | K12: 46052 | L12: B:OVERFLOW-<ClientLastName>-PO<PO>-<Category>-<Seq> | M12: =IF($C12="","",IFERROR(LOOKUP(2,1/('03_Warehouse_Movements'!$C$2:$C$500=$A12),'03_Warehouse_Movements'!$A$2:$A$500),"")) | N12: =IF($C12="","",IFERROR(LOOKUP(2,1/('03_Warehouse_Movements'!$C$2:$C$500=$A12),'03_Warehouse_Movements'!$H$2:$H$500),"")) | O12: =A12 -> WH-Z1-AisleA-Bay1-Level8 | W12: =IF($A2="","",COUNTIF('07_Pallet_Contents'!$A$2:$A$3000,$A2)) -> 0 | X12: =IF($A2="","",SUMIF('07_Pallet_Contents'!$A$2:$A$3000,$A2,'07_Pallet_Contents'!$D$2:$D$3000)) -> 0 | Y12: =IF($A2="","",SUMIF('07_Pallet_Contents'!$A$2:$A$3000,$A2,'07_Pallet_Contents'!$I$2:$I$3000)) -> 0 | Z12: =IF($A2="","",IF(COUNTIF('07_Pallet_Contents'!$A$2:$A$3000,$A2)>0,"Yes",""))
