Workbook
Name ItemModel: '12.1-My Inventory List'!$D$2:$D$1048576
Name ItemType: '12.1-My Inventory List'!$A$2:$A$1048576

Sheet 00_Error_Log
A1: Log ID | B1: Logged On | C1: Version | D1: Scope | E1: Category | F1: Severity | G1: Trigger | H1: Issue | I1: Impact | J1: Fix / Next Step | K1: Owner | L1: Status | M1: Notes / Evidence
A2: 1 | B2: 2026-03-07 | C2: vNext10 official schema | D2: Deployments | E2: Duplicate CF | F2: High | G2: Schema refactor | H2: Duplicate conditional formatting stopped matching the moved identity columns. | I2: Duplicates were not reliably flagged during entry. | J2: Rebuilt duplicate CF against the official candidate schema and made it always-on. | L2: Resolved | M2: Watch fields: Cybernet/Neuron hostnames, serials, Cybernet MAC, asset tag, dialysis, anesthesia, medical device serial.
A3: 2 | B3: 2026-03-07 | C3: vNext10 official schema | D3: Workbook | E3: Error log design | F3: Medium | G3: Tracker debugging | H3: Error log was deployment-scoped instead of workbook-scoped. | I3: Tracker/process mistakes were buried inside row-level noise. | J3: Converted the sheet into a workbook debug log for schema, CF, repair, and release issues. | L3: Resolved | M3: Use this log for workbook bugs and version regressions, not deployment rows.
A4: 3 | B4: 2026-03-07 | C4: vNext10 official schema | D4: Deployments | E4: Data refresh | F4: Medium | G4: Refactored candidate + active tracker | H4: Loaded current active Deployments data into the refactored candidate schema by header name. | I4: Keeps the official schema while avoiding stale row data. | J4: Future backfill from deprecated sheets should happen in a dedicated integration pass. | L4: Resolved | M4: Copied manual fields from the active 2026-03-07 tracker; auto/formula columns stay formula-driven.

Sheet 00_CF_Dictionary
A1: Sheet | B1: Table | C1: AppliesTo | D1: RuleType | E1: Priority | F1: Formula | G1: dxfId | H1: Purpose | I1: Color/category | J1: Color Signature | K1: Color Name | L1: Cause
A5: 01_Warehouse_Ledger | C5: C8 | D5: expression | E5: 1 | F5: AND(TRIM($A8)="",OR($B8<>"",$C8<>"",$D8<>"",$E8<>"",$F8<>"",$I8<>"")) | G5: 37 | I5: FFF8CBAD | J5: fill:solid:fg(rgb=FFF4CCCC):bg(rgb=FFF4CCCC)||font:none
A6: 01_Warehouse_Ledger | C6: C8 | D6: expression | E6: 2 | F6: AND(TRIM($A8)<>"",COUNTIF($A$2:$A$2002,$A8)>1) | G6: 36 | I6: FFF8CBAD | J6: fill:solid:fg(rgb=FFFFC7CE):bg(rgb=FFFFC7CE)||font:b|color(rgb=FF9C0006)
A7: 01_Warehouse_Ledger | C7: A2:R7 A8:B8 A9:R2002 D8:R8 | D7: expression | E7: 3 | F7: AND(TRIM($A2)="",OR($B2<>"",$C2<>"",$D2<>"",$E2<>"",$I2<>"",$J2<>"")) | G7: 41 | I7: FFF8CBAD | J7: fill:solid:fg(rgb=FFFFC7CE):bg(rgb=FFFFC7CE)||font:b|color(rgb=FF9C0006)
A8: 01_Warehouse_Ledger | C8: A2:R7 A8:B8 A9:R2002 D8:R8 | D8: expression | E8: 4 | F8: AND(TRIM($A2)<>"",NOT(AND(LEFT($A2,4)="PAL-",LEN($A2)=11,ISNUMBER(--MID($A2,5,7))))) | G8: 40 | I8: FFF8CBAD | J8: fill:solid:fg(rgb=FFFFEB9C):bg(rgb=FFFFEB9C)||font:none
A9: 01_Warehouse_Ledger | C9: A2:R7 A8:B8 A9:R2002 D8:R8 | D9: expression | E9: 5 | F9: AND(TRIM($A2)<>"",COUNTIF($A$2:$A$2002,$A2)>1) | G9: 39 | I9: FFF8CBAD | J9: fill:solid:fg(rgb=FFC6EFCE):bg(rgb=FFC6EFCE)||font:b|color(rgb=FF006100)
A10: 01_Warehouse_Ledger | C10: A2:R7 A8:B8 A9:R2002 D8:R8 | D10: expression | E10: 6 | F10: AND(TRIM($A2)<>"",$C2<>"",$D2<>"",$D2<>"0",$C2<>$D2) | G10: 38 | I10: FFFFF2CC | J10: fill:solid:fg(rgb=FFFCE4D6):bg(rgb=FFFCE4D6)||font:b|color(rgb=FF9C5700)
A11: 02_Warehouse_Locations | C11: A133 | D11: expression | E11: 1 | F11: AND(TRIM($A133)="",OR($B133<>"",$C133<>"",$D133<>"",$E133<>"",$F133<>"",$I133<>"")) | G11: 35 | I11: FFF8CBAD | J11: fill:solid:fg(rgb=FFFFC7CE):bg(rgb=FFFFC7CE)||font:b|color(rgb=FF9C0006)
A12: 02_Warehouse_Locations | C12: A133 | D12: expression | E12: 2 | F12: AND(TRIM($A133)<>"",COUNTIF($A$2:$A$2002,$A133)>1) | G12: 34 | I12: FFF8CBAD | J12: fill::fg(none):bg(rgb=FFFFEB9C)||font:color(rgb=FF9C5700)
A13: 02_Warehouse_Locations | C13: A2:I132 A134:I2002 | D13: expression | E13: 3 | F13: AND(TRIM($A2)="",OR($B2<>"",$C2<>"",$D2<>"",$E2<>"",$F2<>"",$I2<>"")) | G13: 33 | I13: FFF8CBAD | J13: fill::fg(none):bg(rgb=FFC6EFCE)||font:color(rgb=FF006100)
A14: 02_Warehouse_Locations | C14: A2:I132 A134:I2002 | D14: expression | E14: 4 | F14: AND(TRIM($A2)<>"",COUNTIF($A$2:$A$2002,$A2)>1) | G14: 32 | I14: FFF8CBAD | J14: fill:solid:fg(rgb=FFC6EFCE):bg(none)||font:none
A15: 02_Warehouse_Locations | C15: B133:I133 | D15: expression | E15: 116 | F15: AND(TRIM(#REF!)="",OR($B133<>"",$C133<>"",$D133<>"",$E133<>"",$F133<>"",$I133<>"")) | G15: 31 | I15: FFF8CBAD | J15: fill:solid:fg(rgb=FFFFEB9C):bg(none)||font:none
A16: 02_Warehouse_Locations | C16: B133:I133 | D16: expression | E16: 117 | F16: AND(TRIM(#REF!)<>"",COUNTIF($A$2:$A$2002,#REF!)>1) | G16: 30 | I16: FFF8CBAD | J16: fill:solid:fg(rgb=FFC6EFCE):bg(rgb=FFC6EFCE)||font:none
... A23: 05_Scan_Lookup | C23: B3 | D23: expression | E23: 4 | F23: AND(TRIM($A3)<>"",$C3<>"",$D3<>"",$D3<>"0",$C3<>$D3) | G23: 23 | I23: FFFFF2CC | J23: fill:solid:fg(rgb=FFFFC7CE):bg(rgb=FFFFC7CE)||font:b|color(rgb=FF9C0006)
A24: ZZ_Deprecated | B24: tblDeviceConfig | C24: Deployments!$BL$2:$BL$532 | D24: expression | E24: 1 | F24: $F2="Yes" | G24: 0 | H24: Deprecated – regenerated rules appended below | I24: Deprecated | J24: fill:solid:fg(rgb=FFFFC7CE):bg(rgb=FFFFC7CE)||font:none
A25: ZZ_Deprecated | B25: tblDeviceConfig | C25: Deployments!$BM$2:$BM$532 | D25: expression | E25: 2 | F25: AND($A2="Cybernet",$B2="Yes",$C2<>"Yes",LEN(TRIM(R2))=0) | G25: 5 | H25: Deprecated – regenerated rules appended below | I25: Deprecated | J25: fill:solid:fg(rgb=FFFFEB9C):bg(rgb=FFFFEB9C)||font:none
A26: ZZ_Deprecated | B26: tblDeviceConfig | C26: Deployments!$BN$2:$BN$532 | D26: expression | E26: 3 | F26: AND($A2="Neuron",$B2="Yes",$C2<>"Yes",LEN(TRIM(S2))=0) | G26: 5 | H26: Deprecated – regenerated rules appended below | I26: Deprecated | J26: fill:solid:fg(rgb=FFFFEB9C):bg(rgb=FFFFEB9C)||font:none
A27: ZZ_Deprecated | B27: tblDeviceConfig | C27: Deployments!$BO$2:$BO$532 | D27: expression | E27: 4 | F27: AND($A2="Cybernet",$B2="Yes",$C2<>"Yes",LEN(TRIM(BH2))=0) | G27: 5 | H27: Deprecated – regenerated rules appended below | I27: Deprecated | J27: fill:solid:fg(rgb=FFFFEB9C):bg(rgb=FFFFEB9C)||font:none
A28: ZZ_Deprecated | B28: tblDeviceConfig | C28: Deployments!$BP$2:$BP$532 | D28: expression | E28: 5 | F28: AND($C2="Yes",LEN(TRIM(INDEX($1:$1048576,ROW(),COLUMN())))=0) | G28: 45 | H28: Deprecated – regenerated rules appended below | I28: Deprecated | J28: fill:solid:fg(rgb=FFFFC7CE):bg(rgb=FFFFC7CE)||font:b|color(rgb=FF9C0006)
A29: 14 - Config Log | B29: tblConfigSnapshot | C29: I2:I503 | D29: expression | E29: 8 | F29: AND($I2<>"",OR($K2="Yes",$J2="PM Approved")) | G29: 6 | I29: Green | J29: fill:solid:fg(rgb=FFC6EFCE):bg(rgb=FFC6EFCE)||font:none
A30: 14 - Config Log | B30: tblConfigSnapshot | C30: I2:I503 | D30: expression | E30: 9 | F30: AND($I2<>"",NOT(OR($K2="Yes",$J2="PM Approved"))) | G30: 5 | I30: Yellow | J30: fill:solid:fg(rgb=FFFFEB9C):bg(rgb=FFFFEB9C)||font:none
A31: 14 - Config Log | B31: tblConfigSnapshot | C31: Q2:Q503 | D31: expression | E31: 10 | F31: Q2<>"" | G31: 4 | I31: Red | J31: fill:solid:fg(rgb=FFFFC7CE):bg(rgb=FFFFC7CE)||font:none
A32: 14 - Config Log | B32: tblConfigSnapshot | C32: R2:R503 | D32: expression | E32: 11 | F32: R2<>"" | G32: 3 | I32: FFFFE699 | J32: fill:solid:fg(rgb=FFFFE699):bg(rgb=FFFFE699)||font:none
A33: 14 - Config Log | B33: tblConfigSnapshot | C33: S2:S503 | D33: expression | E33: 12 | F33: S2<>"" | G33: 2 | I33: FFFFE699 | J33: fill:solid:fg(rgb=FFFFE699):bg(rgb=FFFFE699)||font:none
A34: 14 - Config Log | B34: tblConfigSnapshot | C34: T2:T503 | D34: expression | E34: 13 | F34: AND(T2<>"",T2="OK") | G34: 1 | I34: Green | J34: fill:solid:fg(rgb=FFC6EFCE):bg(rgb=FFC6EFCE)||font:none
A35: 14 - Config Log | B35: tblConfigSnapshot | C35: T2:T503 | D35: expression | E35: 14 | F35: AND(T2<>"",T2<>"OK") | G35: 0 | I35: Red | J35: fill:solid:fg(rgb=FFFFC7CE):bg(rgb=FFFFC7CE)||font:none
A36: 15 - Imaging Progress | C36: D1:D1048576 | D36: cellIs | E36: 1 | F36: 100% | G36: 12 | J36: fill:solid:fg(none):bg(theme=6|tint=0.79998168889431442)||font:color(rgb=FF00B050)
A37: 15 - Imaging Progress | C37: F2:F14 | D37: cellIs | E37: 2 | F37: 20 | G37: 11 | J37: fill:solid:fg(none):bg(rgb=FF92D050)||font:color(theme=1)
A38: 15 - Imaging Progress | C38: F2:F14 | D38: cellIs | E38: 3 | F38: 2 | G38: 10 | J38: fill:solid:fg(none):bg(rgb=FFFF0000)||font:color(theme=1)
A39: 15 - Imaging Progress | C39: F2:F14 | D39: cellIs | E39: 4 | F39: 6 | 9 | G39: 9 | J39: fill:solid:fg(none):bg(rgb=FFFEFFA6)||font:color(theme=1)
A40: 15 - Imaging Progress | C40: F2:F14 | D40: cellIs | E40: 5 | F40: 3 | 5 | G40: 8 | J40: fill:solid:fg(none):bg(theme=9|tint=0.59999389629810485)||font:color(theme=1)
A41: 15 - Imaging Progress | C41: F2:F15 | D41: cellIs | E41: 6 | F41: 10 | 20 | G41: 7 | J41: fill:solid:fg(none):bg(theme=6|tint=0.79998168889431442)||font:color(theme=1)
A42: Deployments | B42: tblDeviceConfig | C42: Deployments!CC2:CC532 A2:BZ49 T50:BZ100 AJ101:BZ103 AJ104:AQ104 T106:BZ149 T105:AQ105 AS104:BZ105 A50:R149 T101:AH101 T103:AH104 U102:AH102 A150:BZ531 | D42: expression | E42: 1 | F42: $F2="Yes" | G42: 43 | H42: Duplicates/conflicts flag (DupDeployed=Yes) | I42: Other | J42: fill:solid:fg(rgb=FF8B0000):bg(rgb=FF8B0000)||font:color(rgb=FFFFFFFF)
A43: Deployments | B43: tblDeviceConfig | C43: Deployments!B2:B532 | D43: expression | E43: 4 | F43: LOWER(TRIM($B2))="no" | G43: 42 | H43: Rule – see formula | I43: Yellow | J43: fill:solid:fg(rgb=FFFFEB9C):bg(rgb=FFFFEB9C)||font:none
A44: Deployments | B44: tblDeviceConfig | C44: Deployments!R99:R144 | D44: expression | E44: 5 | F44: AND(INDEX($A:$BI,ROW(),MATCH("Deployed",$A$1:$BI$1,0))="Yes",LEN(TRIM(N99))=0) | G44: 38 | H44: Rule – see formula | I44: Other | J44: fill:solid:fg(rgb=FFFCE4D6):bg(rgb=FFFCE4D6)||font:b|color(rgb=FF9C5700)
A45: Deployments | B45: tblDeviceConfig | C45: Deployments!I2:I532 | D45: expression | E45: 7 | F45: AND($A2<>"",LEN(TRIM($I2))=0) | G45: 40 | H45: Rule – see formula | I45: Yellow | J45: fill:solid:fg(rgb=FFFFEB9C):bg(rgb=FFFFEB9C)||font:none
A46: Deployments | B46: tblDeviceConfig | C46: Deployments!BI2:BI532 | D46: expression | E46: 17 | F46: AND($A2="Cybernet",UPPER(TRIM($B2))="YES",LEN(TRIM($BI2))=0) | G46: 71 | H46: Cybernet Software List missing (Deployed=Yes) | I46: Teal | J46: fill:solid:fg(rgb=FF00B0F0):bg(indexed=64)||font:none | K46: Teal | L46: Deployed Cybernet but Software List is blank
A47: Deployments | B47: tblDeviceConfig | C47: Deployments!BI2:BI532 | D47: expression | E47: 18 | F47: AND($A2="Cybernet",UPPER(TRIM($B2))="YES",LEN(TRIM($BI2))>0) | G47: 33 | H47: Cybernet Software List present (Deployed=Yes) | I47: Green | J47: fill:patternFill:bg(rgb=FFC6EFCE)||font:color(rgb=FF006100) | K47: Green | L47: Deployed Cybernet has Software List (apps accounted for)
A48: Deployments | B48: tblDeviceConfig | C48: Deployments!BM2:BM532 | D48: expression | E48: 25 | F48: BI2="Yes" | G48: 32 | H48: Rule – see formula | I48: Green | J48: fill:solid:fg(rgb=FFC6EFCE):bg(none)||font:none
A49: Deployments | B49: tblDeviceConfig | C49: Deployments!BM2:BM532 | D49: expression | E49: 26 | F49: BI2="Blocked" | G49: 31 | H49: Rule – see formula | I49: Yellow | J49: fill:solid:fg(rgb=FFFFEB9C):bg(none)||font:none
...

Sheet 00_README
A1: Use this sheet as the quick operating guide. Enter data only in the non-AUTO columns. For pallet moves, log the move once in 03_Warehouse_Movements and 01_Warehouse_Ledger updates itself.
A2: Task
A4: Go to tab | B4: Edit these columns | C4: Notes / outcome | D4: Add / update a pallet
A5: 01_Warehouse_Ledger | B5: A,B,C,E,F,G,I,J,K,L | C5: One row per pallet. Do NOT type in CurrentLocationCode / LastMove fields (AUTO). | D5: Move a pallet
A6: 03_Warehouse_Movements | B6: A,B,C,E,H,I,J (F,G optional) | C6: Add one movement row (MOVE / RECEIVE / SHIP / RETURN / etc). Ledger CurrentLocationCode + LastMoveTS update automatically. | D6: Add / update a location
A7: 02_Warehouse_Locations | B7: A–G,I | C7: One row per warehouse slot. QR_Payload auto = LocationCode. | D7: Print QR labels
A8: 04_Label_Export | B8: Nothing (auto list) | C8: Print LOCATION labels (top section) and PALLET labels (starts at row 505). QR payload stays minimal (LocationCode / PalletID). | D8: Find where a pallet is
A9: 05_Scan_Lookup | B9: Scan into B3 | C9: Scan Pallet QR -> see CurrentLocationCode + map fields instantly. | D9: Tie a device to a pallet
A10: BL (PalletID (Manual)) | B10: Deployments | C10: Enter PalletID on the device row -> BM/BN/BO auto-fill Warehouse Location + Pallet Status + Last Move TS. | D10: Pallet moves - the 30-second routine
A13: 1)
A14: Go to 03_Warehouse_Movements and add a NEW row at the top of the data (first blank row). | B14: 2)
A15: Fill: Timestamp (A), Action (B)=MOVE, PalletID (C)=scan or type, ToLocation (E)=scan location code, ByWho (H), Ref (I) if relevant, Notes (J) if needed. Optional: Item (F) + Qty (G) if you are tracking contents. | B15: 3)
A16: Do NOT edit FromLocation (D). It auto-fills from the pallet’s prior state (based on 01_Warehouse_Ledger). | B16: 4)
A17: Sanity check: open 01_Warehouse_Ledger -> CurrentLocationCode (AUTO) and LastMoveTS (AUTO) should update for that PalletID. | B17: 5)
A18: Optional: if the move changed the pallet’s lifecycle (STAGED/DEPLOYED/RETURNED), update PalletStatus (E) on 01_Warehouse_Ledger. | B18: Data rules (don’t break the tracker)
A20: • Only type into columns that are NOT labeled (AUTO) or (deprecated).
A21: • PalletIDs must exist in 01_Warehouse_Ledger before you reference them anywhere else (moves, device config, contents, labels).
A22: • PalletID format enforced by the ledger CF: PAL-0000001 (PAL- + 7 digits). Duplicates highlight.
A23: • LocationCode: pick from 02_Warehouse_Locations (use dropdowns where present).
A24: • If a cell looks formula-driven, leave it alone. Don’t paste over formulas.
A25: • If you must paste, paste VALUES only (not formatting) into input columns.
A26: • When in doubt: use 05_Scan_Lookup to verify the pallet’s current location before moving anything.
A27: Quick troubleshooting
A29: • 05_Scan_Lookup shows blanks -> confirm you scanned a valid PalletID that exists in 01_Warehouse_Ledger column A.
A30: • Move row highlights -> check required fields in 03_Warehouse_Movements: Timestamp (A), Action (B), PalletID (C), ToLocation (E).
A31: • FromLocation (AUTO) stays blank -> the pallet is unknown to the ledger or has no prior location. Add the pallet to 01_Warehouse_Ledger, set HomeLocationCode (C), then re-enter the move row.
A32: • CurrentLocationCode not updating -> confirm 03_Warehouse_Movements has a row with that PalletID and a ToLocation value; then check 01_Warehouse_Ledger columns D and M for that pallet.
... A92: TOOLING ERROR LOG (AUTO-GENERATED)
A94: ErrID | B94: Layer | C94: Part | D94: What | E94: Why | F94: Fix | G94: QA | H94: Evidence
A95: E-011 | B95: packaging | C95: /xl/worksheets/sheet1-3.xml | D95: Excel repair replaced worksheets 1-3 (XML error) | E95: Worksheet XML serialized with non-canonical namespace prefixes (xmlns_ns0 / <ns0_...>); Desktop repair replaces the parts and Web may refuse to open. | F95: Rewrite worksheets 1-3 with canonical namespaces (default worksheet ns + mc/xr/r). Preserve all other parts byte-for-byte. | G95: Desktop opens without repair; Web opens in Edit without 'WORKBOOK REPAIRED' banner. | H95: error066400_01.xml: replaced sheet1-3
A96: E-012 | B96: tables | C96: /xl/tables/table9.xml + sheet12 header | D96: tblDeviceConfig table header mismatch triggers repair | E96: tableColumn names encode line breaks as (e.g., Medical Device Class/Model) but header cells used literal newlines; Excel repairs the table on open. | F96: Make header cells match tableColumn names exactly (use strings) OR update table9 column names consistently. Do not delete/reorder sharedStrings. | G96: Web opens without repair banner; Desktop produces no new error*.xml. Table ref remains A1:CC532 (81 cols). | H96: diff: table9.xml names vs sheet12 row1
A97: E-013 | B97: data | C97: /xl/sharedStrings.xml + sheet12 A2:CC532 | D97: Deployed/Installed and other fields show wrong text (sharedStrings drift) | E97: SharedStrings were edited by deletion/reorder in a prior candidate, shifting indices. Cells still point to old indices so values display as unrelated strings. | F97: Integration rule: never delete/reorder sharedStrings. Overwrite non-formula columns in A2:CC532 with Active values; append new strings only; keep formula columns intact. | G97: Spot-check B2/C2 and random rows: values match Active; formulas still compute; Web renders correctly. | H97: Web screenshot showing wrong values; candidate i092 B2!=Yes
A98: E-014 | B98: runlog | C98: 2026-03-04 0928 | D98: Base: CANDIDATE_DeploymentTracker_vNext10_2026-03-04_1315_WEBSAFE.xlsx | E98: Output: CANDIDATE_DeploymentTracker_vNext10_2026-03-04_0928_WEBSAFE.xlsx | F98: Edited parts: xl/styles.xml; xl/worksheets/sheet4.xml; xl/worksheets/sheet5.xml; xl/worksheets/sheet8.xml; xl/sharedStrings.xml; xl/worksheets/sheet3.xml | G98: Why: styles.xml had mc:Ignorable="x14ac x16r2 xr" but missing xmlns decls (validator); web_repaired styles.xml adds these namespaces. Also 3 CF sqref singletons not canonical (C8, A133, B3). | H98: Stop-ship: no ns0 prefixes; no xlfn/xlpm/xludf tokens; tblDeviceConfig wiring preserved; CF sqref canonical; rels/tableParts preserved; Web outcome PENDING.
A100: OFFICIAL DEPLOYMENTS SCHEMA NOTE
A101: The official schema is the current column order on Deployments row 1 in this workbook.
A102: When refactoring, update these together: Deployments headers, duplicate CF, DesignationChanged, DupDeployed, 00_CF_Dictionary, and 00_README.

Sheet 01_Warehouse_Ledger
A1: PalletID | B1: HomeLocationCode | C1: CurrentLocationCode (AUTO) | D1: PalletStatus | E1: Compliance | F1: TTL_Days | G1: Expires (AUTO) | H1: ContentsSummary | I1: CreatedDate | J1: Notes | K1: CreatedBy | L1: LastMoveTS (AUTO) | M1: LastMovedBy (AUTO) | N1: QR_Payload_Pallet (deprecated) | O1: ReceiptDate (deprecated) | P1: Ref (deprecated) | Q1: Item (deprecated) | R1: QtyReceived (deprecated) | S1: Serials (deprecated) | T1: EnteredBy_RAW (deprecated) | U1: Legacy_RawInputs (deprecated) | V1: StockLines (AUTO) | W1: StockQtyTotal (AUTO) | X1: StockUniquePN (AUTO) | Y1: StockHasPN (AUTO) | Z1: PAL-0000001
A2: OVERFLOW-RICH-CYBERNETS-CFAM-CCMC | B2: CHRIS_OVERFLOW_A_ZONE3 | C2: ACTIVE | D2: =IF($C2="","",IFERROR(LOOKUP(2,1/('03_Warehouse_Movements'!$C$2:$C$500=$A2),'03_Warehouse_Movements'!$E$2:$E$500),$C2)) | E2: STANDARD | F2: CYBERNETS CFAM/CCMC QTY:15 | G2: 7 | H2: =IF(AND($F2="TEMP",$G2>0,$M2<>""),$M2+$G2,"") | I2: NORTHWELL NUERON PROJECT | J2: Alejandro Perales | K2: 46053 | L2: B:WH-Z1-A01-AISLE-FLOOR-02 F:OVERFLOW-<ClientLastName>-PO<PO>-<Category>-<Seq> D:WH-Z1-A01-AISLE-FLOOR-02 | M2: =IF($C2="","",IFERROR(LOOKUP(2,1/('03_Warehouse_Movements'!$C$2:$C$500=$A2),'03_Warehouse_Movements'!$A$2:$A$500),"")) | N2: =IF($C2="","",IFERROR(LOOKUP(2,1/('03_Warehouse_Movements'!$C$2:$C$500=$A2),'03_Warehouse_Movements'!$H$2:$H$500),"")) | O2: =A2 | P2: 46284 | Q2: 144180 | V2: PAL-0000002 | W2: =IF($A2="","",COUNTIF('07_Pallet_Contents'!$A$2:$A$3000,$A2)) | X2: =IF($A2="","",SUMIF('07_Pallet_Contents'!$A$2:$A$3000,$A2,'07_Pallet_Contents'!$D$2:$D$3000)) | Y2: =IF($A2="","",SUMIF('07_Pallet_Contents'!$A$2:$A$3000,$A2,'07_Pallet_Contents'!$I$2:$I$3000)) | Z2: =IF($A2="","",IF(COUNTIF('07_Pallet_Contents'!$A$2:$A$3000,$A2)>0,"Yes",""))
A3: WH-STAGE-IN | C3: STAGED | D3: =IF($C3="","",IFERROR(LOOKUP(2,1/('03_Warehouse_Movements'!$C$2:$C$500=$A3),'03_Warehouse_Movements'!$E$2:$E$500),$C3)) | E3: SAFE | F3: SAMPLE: Monitors 24-40 | H3: =IF(AND($F3="TEMP",$G3>0,$M3<>""),$M3+$G3,"") | I3: SAMPLE: replace with real notes / serials / constraints | J3: SAMPLE-TECH | K3: 46052 | L3: B:OVERFLOW-<ClientLastName>-PO<PO>-<Category>-<Seq> | M3: =IF($C3="","",IFERROR(LOOKUP(2,1/('03_Warehouse_Movements'!$C$2:$C$500=$A3),'03_Warehouse_Movements'!$A$2:$A$500),"")) | N3: =IF($C3="","",IFERROR(LOOKUP(2,1/('03_Warehouse_Movements'!$C$2:$C$500=$A3),'03_Warehouse_Movements'!$H$2:$H$500),"")) | O3: =A3 | V3: PAL-0000003 | W3: =IF($A2="","",COUNTIF('07_Pallet_Contents'!$A$2:$A$3000,$A2)) | X3: =IF($A2="","",SUMIF('07_Pallet_Contents'!$A$2:$A$3000,$A2,'07_Pallet_Contents'!$D$2:$D$3000)) | Y3: =IF($A2="","",SUMIF('07_Pallet_Contents'!$A$2:$A$3000,$A2,'07_Pallet_Contents'!$I$2:$I$3000)) | Z3: =IF($A2="","",IF(COUNTIF('07_Pallet_Contents'!$A$2:$A$3000,$A2)>0,"Yes",""))
A4: OVERFLOW-CHRIS-UMAIR_TICKETS- | B4: CHRIS_OVERFLOW_A_ZONE1 | C4: UNSAFE | D4: =IF($C4="","",IFERROR(LOOKUP(2,1/('03_Warehouse_Movements'!$C$2:$C$500=$A4),'03_Warehouse_Movements'!$E$2:$E$500),$C4)) | E4: STANDARD | F4: Monitors T24-40 | H4: =IF(AND($F4="TEMP",$G4>0,$M4<>""),$M4+$G4,"") | I4: 24 Day Ticket | J4: B:OVERFLOW-CHRIS-UMAIR_TICKETS- D:CHRIS_OVERFLOW_A_ZONE1 | K4: 46046 | L4: B:WH-Z1-A01-AISLE-FLOOR-02 F:OVERFLOW-<ClientLastName>-PO<PO>-<Category>-<Seq> D:WH-Z1-A01-AISLE-FLOOR-02 | M4: =IF($C4="","",IFERROR(LOOKUP(2,1/('03_Warehouse_Movements'!$C$2:$C$500=$A4),'03_Warehouse_Movements'!$A$2:$A$500),"")) | N4: =IF($C4="","",IFERROR(LOOKUP(2,1/('03_Warehouse_Movements'!$C$2:$C$500=$A4),'03_Warehouse_Movements'!$H$2:$H$500),"")) | O4: =A4 | U4: 46046 | V4: PAL-0000004 | W4: =IF($A2="","",COUNTIF('07_Pallet_Contents'!$A$2:$A$3000,$A2)) | X4: =IF($A2="","",SUMIF('07_Pallet_Contents'!$A$2:$A$3000,$A2,'07_Pallet_Contents'!$D$2:$D$3000)) | Y4: =IF($A2="","",SUMIF('07_Pallet_Contents'!$A$2:$A$3000,$A2,'07_Pallet_Contents'!$I$2:$I$3000)) | Z4: =IF($A2="","",IF(COUNTIF('07_Pallet_Contents'!$A$2:$A$3000,$A2)>0,"Yes",""))
A5: WH-Z1-AisleO-Bay10-Level1 | B5: 48x T24i-30 | C5: 48x T24i-30 | D5: =IF($C5="","",IFERROR(LOOKUP(2,1/('03_Warehouse_Movements'!$C$2:$C$500=$A5),'03_Warehouse_Movements'!$E$2:$E$500),$C5)) | E5: STANDARD | F5: SAMPLE: Monitors 24-40 | H5: =IF(AND($F5="TEMP",$G5>0,$M5<>""),$M5+$G5,"") | I5: Geoff Gerber | J5: SAMPLE-TECH | K5: 46051 | L5: B:OVERFLOW-CHRIS- D:CHRIS_OVERFLOW_A_ZONE1 | M5: =IF($C5="","",IFERROR(LOOKUP(2,1/('03_Warehouse_Movements'!$C$2:$C$500=$A5),'03_Warehouse_Movements'!$A$2:$A$500),"")) | N5: =IF($C5="","",IFERROR(LOOKUP(2,1/('03_Warehouse_Movements'!$C$2:$C$500=$A5),'03_Warehouse_Movements'!$H$2:$H$500),"")) | O5: =A5 | U5: 46051 | V5: PAL-0000005 | W5: =IF($A2="","",COUNTIF('07_Pallet_Contents'!$A$2:$A$3000,$A2)) | X5: =IF($A2="","",SUMIF('07_Pallet_Contents'!$A$2:$A$3000,$A2,'07_Pallet_Contents'!$D$2:$D$3000)) | Y5: =IF($A2="","",SUMIF('07_Pallet_Contents'!$A$2:$A$3000,$A2,'07_Pallet_Contents'!$I$2:$I$3000)) | Z5: =IF($A2="","",IF(COUNTIF('07_Pallet_Contents'!$A$2:$A$3000,$A2)>0,"Yes",""))
A6: Northwell Capsule & GCX | B6: WH-ZR-AisleM-Bay1-Level3 | C6: capsule & GCX | D6: =IF($C6="","",IFERROR(LOOKUP(2,1/('03_Warehouse_Movements'!$C$2:$C$500=$A6),'03_Warehouse_Movements'!$E$2:$E$500),$C6)) | E6: STANDARD | F6: SAMPLE: Monitors 24-40 | H6: =IF(AND($F6="TEMP",$G6>0,$M6<>""),$M6+$G6,"") | I6: crate looks broken, contents are tightly wrapped / unable to 100% verify actually contents of boxes | J6: Khadejah Harrison | K6: 46059 | L6: PAL-0000006 | M6: =IF($C6="","",IFERROR(LOOKUP(2,1/('03_Warehouse_Movements'!$C$2:$C$500=$A6),'03_Warehouse_Movements'!$A$2:$A$500),"")) | N6: =IF($C6="","",IFERROR(LOOKUP(2,1/('03_Warehouse_Movements'!$C$2:$C$500=$A6),'03_Warehouse_Movements'!$H$2:$H$500),"")) | O6: =A6 | W6: =IF($A2="","",COUNTIF('07_Pallet_Contents'!$A$2:$A$3000,$A2)) | X6: =IF($A2="","",SUMIF('07_Pallet_Contents'!$A$2:$A$3000,$A2,'07_Pallet_Contents'!$D$2:$D$3000)) | Y6: =IF($A2="","",SUMIF('07_Pallet_Contents'!$A$2:$A$3000,$A2,'07_Pallet_Contents'!$I$2:$I$3000)) | Z6: =IF($A2="","",IF(COUNTIF('07_Pallet_Contents'!$A$2:$A$3000,$A2)>0,"Yes",""))
A7: WH-Z1-NOOverflow | C7: 19x T24 Thinkvision Monitor 63CFMAR1US | D7: =IF($C7="","",IFERROR(LOOKUP(2,1/('03_Warehouse_Movements'!$C$2:$C$500=$A7),'03_Warehouse_Movements'!$E$2:$E$500),$C7)) | E7: SAFE | F7: SAMPLE: Monitors 24-40 | H7: =IF(AND($F7="TEMP",$G7>0,$M7<>""),$M7+$G7,"") | I7: PAL-0000007 | K7: 46052 | L7: B:OVERFLOW-CHRIS- D:CHRIS_OVERFLOW_A_ZONE1 | M7: =IF($C7="","",IFERROR(LOOKUP(2,1/('03_Warehouse_Movements'!$C$2:$C$500=$A7),'03_Warehouse_Movements'!$A$2:$A$500),"")) | N7: =IF($C7="","",IFERROR(LOOKUP(2,1/('03_Warehouse_Movements'!$C$2:$C$500=$A7),'03_Warehouse_Movements'!$H$2:$H$500),"")) | O7: =A7 | W7: =IF($A2="","",COUNTIF('07_Pallet_Contents'!$A$2:$A$3000,$A2)) | X7: =IF($A2="","",SUMIF('07_Pallet_Contents'!$A$2:$A$3000,$A2,'07_Pallet_Contents'!$D$2:$D$3000)) | Y7: =IF($A2="","",SUMIF('07_Pallet_Contents'!$A$2:$A$3000,$A2,'07_Pallet_Contents'!$I$2:$I$3000)) | Z7: =IF($A2="","",IF(COUNTIF('07_Pallet_Contents'!$A$2:$A$3000,$A2)>0,"Yes",""))
A8: WH-Z1-AisleO-Bay7-Level1 | C8: TEMP | D8: =IF($C8="","",IFERROR(LOOKUP(2,1/('03_Warehouse_Movements'!$C$2:$C$500=$A8),'03_Warehouse_Movements'!$E$2:$E$500),$C8)) | E8: SAFE | F8: PAL-0000008 | G8: 14 | H8: =IF(AND($F8="TEMP",$G8>0,$M8<>""),$M8+$G8,"") | I8: Geoff Gerber | J8: SAMPLE-TECH | K8: 46052 | L8: B:OVERFLOW-CHRIS- D:CHRIS_OVERFLOW_A_ZONE1 | M8: =IF($C8="","",IFERROR(LOOKUP(2,1/('03_Warehouse_Movements'!$C$2:$C$500=$A8),'03_Warehouse_Movements'!$A$2:$A$500),"")) | N8: =IF($C8="","",IFERROR(LOOKUP(2,1/('03_Warehouse_Movements'!$C$2:$C$500=$A8),'03_Warehouse_Movements'!$H$2:$H$500),"")) | O8: =A8 | W8: =IF($A2="","",COUNTIF('07_Pallet_Contents'!$A$2:$A$3000,$A2)) | X8: =IF($A2="","",SUMIF('07_Pallet_Contents'!$A$2:$A$3000,$A2,'07_Pallet_Contents'!$D$2:$D$3000)) | Y8: =IF($A2="","",SUMIF('07_Pallet_Contents'!$A$2:$A$3000,$A2,'07_Pallet_Contents'!$I$2:$I$3000)) | Z8: =IF($A2="","",IF(COUNTIF('07_Pallet_Contents'!$A$2:$A$3000,$A2)>0,"Yes",""))
A9: OVERFLOW-SAMPLE-PO1007-CAT3-PAL008 | B9: WH-Z1-AisleA-Bay1-Level5 | C9: SAMPLE: Power Supplies | D9: =IF($C9="","",IFERROR(LOOKUP(2,1/('03_Warehouse_Movements'!$C$2:$C$500=$A9),'03_Warehouse_Movements'!$E$2:$E$500),$C9)) | E9: STANDARD | F9: SAMPLE: Monitors 24-40 | H9: =IF(AND($F9="TEMP",$G9>0,$M9<>""),$M9+$G9,"") | I9: PAL-0000009 | J9: SAMPLE-TECH | K9: 46052 | L9: B:OVERFLOW-<ClientLastName>-PO<PO>-<Category>-<Seq> | M9: =IF($C9="","",IFERROR(LOOKUP(2,1/('03_Warehouse_Movements'!$C$2:$C$500=$A9),'03_Warehouse_Movements'!$A$2:$A$500),"")) | N9: =IF($C9="","",IFERROR(LOOKUP(2,1/('03_Warehouse_Movements'!$C$2:$C$500=$A9),'03_Warehouse_Movements'!$H$2:$H$500),"")) | O9: =A9 | W9: =IF($A2="","",COUNTIF('07_Pallet_Contents'!$A$2:$A$3000,$A2)) | X9: =IF($A2="","",SUMIF('07_Pallet_Contents'!$A$2:$A$3000,$A2,'07_Pallet_Contents'!$D$2:$D$3000)) | Y9: =IF($A2="","",SUMIF('07_Pallet_Contents'!$A$2:$A$3000,$A2,'07_Pallet_Contents'!$I$2:$I$3000)) | Z9: =IF($A2="","",IF(COUNTIF('07_Pallet_Contents'!$A$2:$A$3000,$A2)>0,"Yes",""))
A10: WH-Z1-AisleA-Bay1-Level6 | C10: SAMPLE: Imaging Equipment | D10: =IF($C10="","",IFERROR(LOOKUP(2,1/('03_Warehouse_Movements'!$C$2:$C$500=$A10),'03_Warehouse_Movements'!$E$2:$E$500),$C10)) | E10: STANDARD | F10: SAMPLE: Monitors 24-40 | H10: =IF(AND($F10="TEMP",$G10>0,$M10<>""),$M10+$G10,"") | I10: PAL-0000010 | J10: SAMPLE-TECH | K10: 46052 | L10: B:OVERFLOW-<ClientLastName>-PO<PO>-<Category>-<Seq> | M10: =IF($C10="","",IFERROR(LOOKUP(2,1/('03_Warehouse_Movements'!$C$2:$C$500=$A10),'03_Warehouse_Movements'!$A$2:$A$500),"")) | N10: =IF($C10="","",IFERROR(LOOKUP(2,1/('03_Warehouse_Movements'!$C$2:$C$500=$A10),'03_Warehouse_Movements'!$H$2:$H$500),"")) | O10: =A10 | W10: =IF($A2="","",COUNTIF('07_Pallet_Contents'!$A$2:$A$3000,$A2)) | X10: =IF($A2="","",SUMIF('07_Pallet_Contents'!$A$2:$A$3000,$A2,'07_Pallet_Contents'!$D$2:$D$3000)) | Y10: =IF($A2="","",SUMIF('07_Pallet_Contents'!$A$2:$A$3000,$A2,'07_Pallet_Contents'!$I$2:$I$3000)) | Z10: =IF($A2="","",IF(COUNTIF('07_Pallet_Contents'!$A$2:$A$3000,$A2)>0,"Yes",""))
A11: WH-Z1-AisleA-Bay1-Level7 | C11: SAMPLE: Misc Hardware | D11: =IF($C11="","",IFERROR(LOOKUP(2,1/('03_Warehouse_Movements'!$C$2:$C$500=$A11),'03_Warehouse_Movements'!$E$2:$E$500),$C11)) | E11: STANDARD | F11: SAMPLE: Monitors 24-40 | H11: =IF(AND($F11="TEMP",$G11>0,$M11<>""),$M11+$G11,"") | I11: B | J11: SAMPLE-TECH | K11: 46052 | L11: B:OVERFLOW-<ClientLastName>-PO<PO>-<Category>-<Seq> | M11: =IF($C11="","",IFERROR(LOOKUP(2,1/('03_Warehouse_Movements'!$C$2:$C$500=$A11),'03_Warehouse_Movements'!$A$2:$A$500),"")) | N11: =IF($C11="","",IFERROR(LOOKUP(2,1/('03_Warehouse_Movements'!$C$2:$C$500=$A11),'03_Warehouse_Movements'!$H$2:$H$500),"")) | O11: =A11 | Q11: PAL-0000011 | W11: =IF($A2="","",COUNTIF('07_Pallet_Contents'!$A$2:$A$3000,$A2)) | X11: =IF($A2="","",SUMIF('07_Pallet_Contents'!$A$2:$A$3000,$A2,'07_Pallet_Contents'!$D$2:$D$3000)) | Y11: =IF($A2="","",SUMIF('07_Pallet_Contents'!$A$2:$A$3000,$A2,'07_Pallet_Contents'!$I$2:$I$3000)) | Z11: =IF($A2="","",IF(COUNTIF('07_Pallet_Contents'!$A$2:$A$3000,$A2)>0,"Yes",""))
A12: WH-Z1-AisleA-Bay1-Level8 | C12: SAMPLE: Dell Devices | D12: =IF($C12="","",IFERROR(LOOKUP(2,1/('03_Warehouse_Movements'!$C$2:$C$500=$A12),'03_Warehouse_Movements'!$E$2:$E$500),$C12)) | E12: STANDARD | F12: SAMPLE: Monitors 24-40 | H12: =IF(AND($F12="TEMP",$G12>0,$M12<>""),$M12+$G12,"") | I12: PAL-0000012 | J12: SAMPLE-TECH | K12: 46052 | L12: B:OVERFLOW-<ClientLastName>-PO<PO>-<Category>-<Seq> | M12: =IF($C12="","",IFERROR(LOOKUP(2,1/('03_Warehouse_Movements'!$C$2:$C$500=$A12),'03_Warehouse_Movements'!$A$2:$A$500),"")) | N12: =IF($C12="","",IFERROR(LOOKUP(2,1/('03_Warehouse_Movements'!$C$2:$C$500=$A12),'03_Warehouse_Movements'!$H$2:$H$500),"")) | O12: =A12 | W12: =IF($A2="","",COUNTIF('07_Pallet_Contents'!$A$2:$A$3000,$A2)) | X12: =IF($A2="","",SUMIF('07_Pallet_Contents'!$A$2:$A$3000,$A2,'07_Pallet_Contents'!$D$2:$D$3000)) | Y12: =IF($A2="","",SUMIF('07_Pallet_Contents'!$A$2:$A$3000,$A2,'07_Pallet_Contents'!$I$2:$I$3000)) | Z12: =IF($A2="","",IF(COUNTIF('07_Pallet_Contents'!$A$2:$A$3000,$A2)>0,"Yes",""))
A13: WH-Z1-AisleA-Bay1-Level9 | C13: PAL-0000013 | D13: =IF($C13="","",IFERROR(LOOKUP(2,1/('03_Warehouse_Movements'!$C$2:$C$500=$A13),'03_Warehouse_Movements'!$E$2:$E$500),$C13)) | E13: STANDARD | F13: SAMPLE: Monitors 24-40 | H13: =IF(AND($F13="TEMP",$G13>0,$M13<>""),$M13+$G13,"") | I13: SAMPLE: replace with real notes / serials / constraints | J13: SAMPLE-TECH | K13: 46052 | L13: B:OVERFLOW-<ClientLastName>-PO<PO>-<Category>-<Seq> | M13: =IF($C13="","",IFERROR(LOOKUP(2,1/('03_Warehouse_Movements'!$C$2:$C$500=$A13),'03_Warehouse_Movements'!$A$2:$A$500),"")) | N13: =IF($C13="","",IFERROR(LOOKUP(2,1/('03_Warehouse_Movements'!$C$2:$C$500=$A13),'03_Warehouse_Movements'!$H$2:$H$500),"")) | O13: =A13 | W13: =IF($A2="","",COUNTIF('07_Pallet_Contents'!$A$2:$A$3000,$A2)) | X13: =IF($A2="","",SUMIF('07_Pallet_Contents'!$A$2:$A$3000,$A2,'07_Pallet_Contents'!$D$2:$D$3000)) | Y13: =IF($A2="","",SUMIF('07_Pallet_Contents'!$A$2:$A$3000,$A2,'07_Pallet_Contents'!$I$2:$I$3000)) | Z13: =IF($A2="","",IF(COUNTIF('07_Pallet_Contents'!$A$2:$A$3000,$A2)>0,"Yes",""))
A14: WH-Z1-AisleA-Bay1-Level10 | C14: SAMPLE: Cables & Adapters | D14: =IF($C14="","",IFERROR(LOOKUP(2,1/('03_Warehouse_Movements'!$C$2:$C$500=$A14),'03_Warehouse_Movements'!$E$2:$E$500),$C14)) | E14: STANDARD | F14: PAL-0000008 | G14: 14 | H14: =IF(AND($F14="TEMP",$G14>0,$M14<>""),$M14+$G14,"") | I14: PAL-0000014 | J14: SAMPLE-TECH | K14: 46052 | L14: B:OVERFLOW-<ClientLastName>-PO<PO>-<Category>-<Seq> | M14: =IF($C14="","",IFERROR(LOOKUP(2,1/('03_Warehouse_Movements'!$C$2:$C$500=$A14),'03_Warehouse_Movements'!$A$2:$A$500),"")) | N14: =IF($C14="","",IFERROR(LOOKUP(2,1/('03_Warehouse_Movements'!$C$2:$C$500=$A14),'03_Warehouse_Movements'!$H$2:$H$500),"")) | O14: =A14 | W14: =IF($A2="","",COUNTIF('07_Pallet_Contents'!$A$2:$A$3000,$A2)) | X14: =IF($A2="","",SUMIF('07_Pallet_Contents'!$A$2:$A$3000,$A2,'07_Pallet_Contents'!$D$2:$D$3000)) | Y14: =IF($A2="","",SUMIF('07_Pallet_Contents'!$A$2:$A$3000,$A2,'07_Pallet_Contents'!$I$2:$I$3000)) | Z14: =IF($A2="","",IF(COUNTIF('07_Pallet_Contents'!$A$2:$A$3000,$A2)>0,"Yes",""))
A15: WH-Z1-AisleA-Bay1-Level11 | C15: SAMPLE: Racks & Rails | D15: =IF($C15="","",IFERROR(LOOKUP(2,1/('03_Warehouse_Movements'!$C$2:$C$500=$A15),'03_Warehouse_Movements'!$E$2:$E$500),$C15)) | E15: STANDARD | F15: SAMPLE: Monitors 24-40 | H15: =IF(AND($F15="TEMP",$G15>0,$M15<>""),$M15+$G15,"") | I15: PAL-0000015 | J15: SAMPLE-TECH | K15: 46052 | L15: B:OVERFLOW-<ClientLastName>-PO<PO>-<Category>-<Seq> | M15: =IF($C15="","",IFERROR(LOOKUP(2,1/('03_Warehouse_Movements'!$C$2:$C$500=$A15),'03_Warehouse_Movements'!$A$2:$A$500),"")) | N15: =IF($C15="","",IFERROR(LOOKUP(2,1/('03_Warehouse_Movements'!$C$2:$C$500=$A15),'03_Warehouse_Movements'!$H$2:$H$500),"")) | O15: =A15 | W15: =IF($A2="","",COUNTIF('07_Pallet_Contents'!$A$2:$A$3000,$A2)) | X15: =IF($A2="","",SUMIF('07_Pallet_Contents'!$A$2:$A$3000,$A2,'07_Pallet_Contents'!$D$2:$D$3000)) | Y15: =IF($A2="","",SUMIF('07_Pallet_Contents'!$A$2:$A$3000,$A2,'07_Pallet_Contents'!$I$2:$I$3000)) | Z15: =IF($A2="","",IF(COUNTIF('07_Pallet_Contents'!$A$2:$A$3000,$A2)>0,"Yes",""))
A16: OVERFLOW-SAMPLE-PO1014-CAT5-PAL015 | B16: WH-Z1-AisleA-Bay1-Level12 | C16: SAMPLE: Networking Gear | D16: =IF($C16="","",IFERROR(LOOKUP(2,1/('03_Warehouse_Movements'!$C$2:$C$500=$A16),'03_Warehouse_Movements'!$E$2:$E$500),$C16)) | E16: STANDARD | F16: SAMPLE: Monitors 24-40 | H16: =IF(AND($F16="TEMP",$G16>0,$M16<>""),$M16+$G16,"") | I16: PAL-0000016 | J16: SAMPLE-TECH | K16: 46052 | L16: B:OVERFLOW-<ClientLastName>-PO<PO>-<Category>-<Seq> | M16: =IF($C16="","",IFERROR(LOOKUP(2,1/('03_Warehouse_Movements'!$C$2:$C$500=$A16),'03_Warehouse_Movements'!$A$2:$A$500),"")) | N16: =IF($C16="","",IFERROR(LOOKUP(2,1/('03_Warehouse_Movements'!$C$2:$C$500=$A16),'03_Warehouse_Movements'!$H$2:$H$500),"")) | O16: =A16 | W16: =IF($A2="","",COUNTIF('07_Pallet_Contents'!$A$2:$A$3000,$A2)) | X16: =IF($A2="","",SUMIF('07_Pallet_Contents'!$A$2:$A$3000,$A2,'07_Pallet_Contents'!$D$2:$D$3000)) | Y16: =IF($A2="","",SUMIF('07_Pallet_Contents'!$A$2:$A$3000,$A2,'07_Pallet_Contents'!$I$2:$I$3000)) | Z16: =IF($A2="","",IF(COUNTIF('07_Pallet_Contents'!$A$2:$A$3000,$A2)>0,"Yes",""))
A17: WH-Z1-AisleA-Bay1-Level13 | C17: SAMPLE: Keyboards & Mice | D17: =IF($C17="","",IFERROR(LOOKUP(2,1/('03_Warehouse_Movements'!$C$2:$C$500=$A17),'03_Warehouse_Movements'!$E$2:$E$500),$C17)) | E17: STANDARD | F17: SAMPLE: Monitors 24-40 | H17: =IF(AND($F17="TEMP",$G17>0,$M17<>""),$M17+$G17,"") | I17: PAL-0000017 | J17: SAMPLE-TECH | K17: 46052 | L17: B:OVERFLOW-<ClientLastName>-PO<PO>-<Category>-<Seq> | M17: =IF($C17="","",IFERROR(LOOKUP(2,1/('03_Warehouse_Movements'!$C$2:$C$500=$A17),'03_Warehouse_Movements'!$A$2:$A$500),"")) | N17: =IF($C17="","",IFERROR(LOOKUP(2,1/('03_Warehouse_Movements'!$C$2:$C$500=$A17),'03_Warehouse_Movements'!$H$2:$H$500),"")) | O17: =A17 | W17: =IF($A2="","",COUNTIF('07_Pallet_Contents'!$A$2:$A$3000,$A2)) | X17: =IF($A2="","",SUMIF('07_Pallet_Contents'!$A$2:$A$3000,$A2,'07_Pallet_Contents'!$D$2:$D$3000)) | Y17: =IF($A2="","",SUMIF('07_Pallet_Contents'!$A$2:$A$3000,$A2,'07_Pallet_Contents'!$I$2:$I$3000)) | Z17: =IF($A2="","",IF(COUNTIF('07_Pallet_Contents'!$A$2:$A$3000,$A2)>0,"Yes",""))
A18: WH-Z1-AisleA-Bay1-Level14 | C18: SAMPLE: Spare Parts | D18: =IF($C18="","",IFERROR(LOOKUP(2,1/('03_Warehouse_Movements'!$C$2:$C$500=$A18),'03_Warehouse_Movements'!$E$2:$E$500),$C18)) | E18: STANDARD | F18: SAMPLE: Monitors 24-40 | H18: =IF(AND($F18="TEMP",$G18>0,$M18<>""),$M18+$G18,"") | I18: PAL-0000018 | J18: SAMPLE-TECH | K18: 46052 | L18: B:OVERFLOW-<ClientLastName>-PO<PO>-<Category>-<Seq> | M18: =IF($C18="","",IFERROR(LOOKUP(2,1/('03_Warehouse_Movements'!$C$2:$C$500=$A18),'03_Warehouse_Movements'!$A$2:$A$500),"")) | N18: =IF($C18="","",IFERROR(LOOKUP(2,1/('03_Warehouse_Movements'!$C$2:$C$500=$A18),'03_Warehouse_Movements'!$H$2:$H$500),"")) | O18: =A18 | W18: =IF($A2="","",COUNTIF('07_Pallet_Contents'!$A$2:$A$3000,$A2)) | X18: =IF($A2="","",SUMIF('07_Pallet_Contents'!$A$2:$A$3000,$A2,'07_Pallet_Contents'!$D$2:$D$3000)) | Y18: =IF($A2="","",SUMIF('07_Pallet_Contents'!$A$2:$A$3000,$A2,'07_Pallet_Contents'!$I$2:$I$3000)) | Z18: =IF($A2="","",IF(COUNTIF('07_Pallet_Contents'!$A$2:$A$3000,$A2)>0,"Yes",""))
A19: WH-Z1-AisleA-Bay1-Level15 | C19: PAL-0000019 | D19: =IF($C19="","",IFERROR(LOOKUP(2,1/('03_Warehouse_Movements'!$C$2:$C$500=$A19),'03_Warehouse_Movements'!$E$2:$E$500),$C19)) | E19: STANDARD | F19: SAMPLE: Monitors 24-40 | H19: =IF(AND($F19="TEMP",$G19>0,$M19<>""),$M19+$G19,"") | I19: PAL-0000009 | J19: SAMPLE-TECH | K19: 46052 | L19: B:OVERFLOW-<ClientLastName>-PO<PO>-<Category>-<Seq> | M19: =IF($C19="","",IFERROR(LOOKUP(2,1/('03_Warehouse_Movements'!$C$2:$C$500=$A19),'03_Warehouse_Movements'!$A$2:$A$500),"")) | N19: =IF($C19="","",IFERROR(LOOKUP(2,1/('03_Warehouse_Movements'!$C$2:$C$500=$A19),'03_Warehouse_Movements'!$H$2:$H$500),"")) | O19: =A19 | W19: =IF($A2="","",COUNTIF('07_Pallet_Contents'!$A$2:$A$3000,$A2)) | X19: =IF($A2="","",SUMIF('07_Pallet_Contents'!$A$2:$A$3000,$A2,'07_Pallet_Contents'!$D$2:$D$3000)) | Y19: =IF($A2="","",SUMIF('07_Pallet_Contents'!$A$2:$A$3000,$A2,'07_Pallet_Contents'!$I$2:$I$3000)) | Z19: =IF($A2="","",IF(COUNTIF('07_Pallet_Contents'!$A$2:$A$3000,$A2)>0,"Yes",""))
A20: WH-Z1-AisleA-Bay1-Level16 | C20: PAL-0000020 | D20: =IF($C20="","",IFERROR(LOOKUP(2,1/('03_Warehouse_Movements'!$C$2:$C$500=$A20),'03_Warehouse_Movements'!$E$2:$E$500),$C20)) | E20: STANDARD | F20: PAL-0000008 | G20: 14 | H20: =IF(AND($F20="TEMP",$G20>0,$M20<>""),$M20+$G20,"") | I20: PAL-0000010 | J20: SAMPLE-TECH | K20: 46052 | L20: B:OVERFLOW-<ClientLastName>-PO<PO>-<Category>-<Seq> | M20: =IF($C20="","",IFERROR(LOOKUP(2,1/('03_Warehouse_Movements'!$C$2:$C$500=$A20),'03_Warehouse_Movements'!$A$2:$A$500),"")) | N20: =IF($C20="","",IFERROR(LOOKUP(2,1/('03_Warehouse_Movements'!$C$2:$C$500=$A20),'03_Warehouse_Movements'!$H$2:$H$500),"")) | O20: =A20 | W20: =IF($A2="","",COUNTIF('07_Pallet_Contents'!$A$2:$A$3000,$A2)) | X20: =IF($A2="","",SUMIF('07_Pallet_Contents'!$A$2:$A$3000,$A2,'07_Pallet_Contents'!$D$2:$D$3000)) | Y20: =IF($A2="","",SUMIF('07_Pallet_Contents'!$A$2:$A$3000,$A2,'07_Pallet_Contents'!$I$2:$I$3000)) | Z20: =IF($A2="","",IF(COUNTIF('07_Pallet_Contents'!$A$2:$A$3000,$A2)>0,"Yes",""))
A21: WH-Z1-AisleA-Bay1-Level17 | C21: PAL-0000021 | D21: =IF($C21="","",IFERROR(LOOKUP(2,1/('03_Warehouse_Movements'!$C$2:$C$500=$A21),'03_Warehouse_Movements'!$E$2:$E$500),$C21)) | E21: STANDARD | F21: SAMPLE: Monitors 24-40 | H21: =IF(AND($F21="TEMP",$G21>0,$M21<>""),$M21+$G21,"") | I21: B | J21: SAMPLE-TECH | K21: 46052 | L21: B:OVERFLOW-<ClientLastName>-PO<PO>-<Category>-<Seq> | M21: =IF($C21="","",IFERROR(LOOKUP(2,1/('03_Warehouse_Movements'!$C$2:$C$500=$A21),'03_Warehouse_Movements'!$A$2:$A$500),"")) | N21: =IF($C21="","",IFERROR(LOOKUP(2,1/('03_Warehouse_Movements'!$C$2:$C$500=$A21),'03_Warehouse_Movements'!$H$2:$H$500),"")) | O21: =A21 | W21: =IF($A2="","",COUNTIF('07_Pallet_Contents'!$A$2:$A$3000,$A2)) | X21: =IF($A2="","",SUMIF('07_Pallet_Contents'!$A$2:$A$3000,$A2,'07_Pallet_Contents'!$D$2:$D$3000)) | Y21: =IF($A2="","",SUMIF('07_Pallet_Contents'!$A$2:$A$3000,$A2,'07_Pallet_Contents'!$I$2:$I$3000)) | Z21: =IF($A2="","",IF(COUNTIF('07_Pallet_Contents'!$A$2:$A$3000,$A2)>0,"Yes",""))
A22: WH-Z1-AisleA-Bay1-Level18 | C22: PAL-0000022 | D22: =IF($C22="","",IFERROR(LOOKUP(2,1/('03_Warehouse_Movements'!$C$2:$C$500=$A22),'03_Warehouse_Movements'!$E$2:$E$500),$C22)) | E22: STANDARD | F22: SAMPLE: Monitors 24-40 | H22: =IF(AND($F22="TEMP",$G22>0,$M22<>""),$M22+$G22,"") | I22: PAL-0000012 | J22: SAMPLE-TECH | K22: 46052 | L22: B:OVERFLOW-<ClientLastName>-PO<PO>-<Category>-<Seq> | M22: =IF($C22="","",IFERROR(LOOKUP(2,1/('03_Warehouse_Movements'!$C$2:$C$500=$A22),'03_Warehouse_Movements'!$A$2:$A$500),"")) | N22: =IF($C22="","",IFERROR(LOOKUP(2,1/('03_Warehouse_Movements'!$C$2:$C$500=$A22),'03_Warehouse_Movements'!$H$2:$H$500),"")) | O22: =A22 | W22: =IF($A2="","",COUNTIF('07_Pallet_Contents'!$A$2:$A$3000,$A2)) | X22: =IF($A2="","",SUMIF('07_Pallet_Contents'!$A$2:$A$3000,$A2,'07_Pallet_Contents'!$D$2:$D$3000)) | Y22: =IF($A2="","",SUMIF('07_Pallet_Contents'!$A$2:$A$3000,$A2,'07_Pallet_Contents'!$I$2:$I$3000)) | Z22: =IF($A2="","",IF(COUNTIF('07_Pallet_Contents'!$A$2:$A$3000,$A2)>0,"Yes",""))
A23: OVERFLOW-SAMPLE-PO1021-CAT2-PAL022 | B23: WH-Z1-AisleA-Bay1-Level19 | C23: PAL-0000023 | D23: =IF($C23="","",IFERROR(LOOKUP(2,1/('03_Warehouse_Movements'!$C$2:$C$500=$A23),'03_Warehouse_Movements'!$E$2:$E$500),$C23)) | E23: STANDARD | F23: SAMPLE: Monitors 24-40 | H23: =IF(AND($F23="TEMP",$G23>0,$M23<>""),$M23+$G23,"") | I23: SAMPLE: replace with real notes / serials / constraints | J23: SAMPLE-TECH | K23: 46052 | L23: B:OVERFLOW-<ClientLastName>-PO<PO>-<Category>-<Seq> | M23: =IF($C23="","",IFERROR(LOOKUP(2,1/('03_Warehouse_Movements'!$C$2:$C$500=$A23),'03_Warehouse_Movements'!$A$2:$A$500),"")) | N23: =IF($C23="","",IFERROR(LOOKUP(2,1/('03_Warehouse_Movements'!$C$2:$C$500=$A23),'03_Warehouse_Movements'!$H$2:$H$500),"")) | O23: =A23 | W23: =IF($A2="","",COUNTIF('07_Pallet_Contents'!$A$2:$A$3000,$A2)) | X23: =IF($A2="","",SUMIF('07_Pallet_Contents'!$A$2:$A$3000,$A2,'07_Pallet_Contents'!$D$2:$D$3000)) | Y23: =IF($A2="","",SUMIF('07_Pallet_Contents'!$A$2:$A$3000,$A2,'07_Pallet_Contents'!$I$2:$I$3000)) | Z23: =IF($A2="","",IF(COUNTIF('07_Pallet_Contents'!$A$2:$A$3000,$A2)>0,"Yes",""))
A24: WH-Z1-AisleA-Bay1-Level20 | C24: PAL-0000024 | D24: =IF($C24="","",IFERROR(LOOKUP(2,1/('03_Warehouse_Movements'!$C$2:$C$500=$A24),'03_Warehouse_Movements'!$E$2:$E$500),$C24)) | E24: STANDARD | F24: SAMPLE: Monitors 24-40 | H24: =IF(AND($F24="TEMP",$G24>0,$M24<>""),$M24+$G24,"") | I24: PAL-0000014 | J24: SAMPLE-TECH | K24: 46052 | L24: B:OVERFLOW-<ClientLastName>-PO<PO>-<Category>-<Seq> | M24: =IF($C24="","",IFERROR(LOOKUP(2,1/('03_Warehouse_Movements'!$C$2:$C$500=$A24),'03_Warehouse_Movements'!$A$2:$A$500),"")) | N24: =IF($C24="","",IFERROR(LOOKUP(2,1/('03_Warehouse_Movements'!$C$2:$C$500=$A24),'03_Warehouse_Movements'!$H$2:$H$500),"")) | O24: =A24 | W24: =IF($A2="","",COUNTIF('07_Pallet_Contents'!$A$2:$A$3000,$A2)) | X24: =IF($A2="","",SUMIF('07_Pallet_Contents'!$A$2:$A$3000,$A2,'07_Pallet_Contents'!$D$2:$D$3000)) | Y24: =IF($A2="","",SUMIF('07_Pallet_Contents'!$A$2:$A$3000,$A2,'07_Pallet_Contents'!$I$2:$I$3000)) | Z24: =IF($A2="","",IF(COUNTIF('07_Pallet_Contents'!$A$2:$A$3000,$A2)>0,"Yes",""))
A25: WH-Z1-AisleB-Bay1-Level1 | C25: PAL-0000025 | D25: =IF($C25="","",IFERROR(LOOKUP(2,1/('03_Warehouse_Movements'!$C$2:$C$500=$A25),'03_Warehouse_Movements'!$E$2:$E$500),$C25)) | E25: STANDARD | F25: SAMPLE: Monitors 24-40 | H25: =IF(AND($F25="TEMP",$G25>0,$M25<>""),$M25+$G25,"") | I25: PAL-0000015 | J25: SAMPLE-TECH | K25: 46052 | L25: B:OVERFLOW-<ClientLastName>-PO<PO>-<Category>-<Seq> | M25: =IF($C25="","",IFERROR(LOOKUP(2,1/('03_Warehouse_Movements'!$C$2:$C$500=$A25),'03_Warehouse_Movements'!$A$2:$A$500),"")) | N25: =IF($C25="","",IFERROR(LOOKUP(2,1/('03_Warehouse_Movements'!$C$2:$C$500=$A25),'03_Warehouse_Movements'!$H$2:$H$500),"")) | O25: =A25 | W25: =IF($A2="","",COUNTIF('07_Pallet_Contents'!$A$2:$A$3000,$A2)) | X25: =IF($A2="","",SUMIF('07_Pallet_Contents'!$A$2:$A$3000,$A2,'07_Pallet_Contents'!$D$2:$D$3000)) | Y25: =IF($A2="","",SUMIF('07_Pallet_Contents'!$A$2:$A$3000,$A2,'07_Pallet_Contents'!$I$2:$I$3000)) | Z25: =IF($A2="","",IF(COUNTIF('07_Pallet_Contents'!$A$2:$A$3000,$A2)>0,"Yes",""))
A26: WH-Z1-AisleB-Bay1-Level2 | C26: PAL-0000026 | D26: =IF($C26="","",IFERROR(LOOKUP(2,1/('03_Warehouse_Movements'!$C$2:$C$500=$A26),'03_Warehouse_Movements'!$E$2:$E$500),$C26)) | E26: STANDARD | F26: PAL-0000008 | G26: 14 | H26: =IF(AND($F26="TEMP",$G26>0,$M26<>""),$M26+$G26,"") | I26: PAL-0000016 | J26: SAMPLE-TECH | K26: 46052 | L26: B:OVERFLOW-<ClientLastName>-PO<PO>-<Category>-<Seq> | M26: =IF($C26="","",IFERROR(LOOKUP(2,1/('03_Warehouse_Movements'!$C$2:$C$500=$A26),'03_Warehouse_Movements'!$A$2:$A$500),"")) | N26: =IF($C26="","",IFERROR(LOOKUP(2,1/('03_Warehouse_Movements'!$C$2:$C$500=$A26),'03_Warehouse_Movements'!$H$2:$H$500),"")) | O26: =A26 | W26: =IF($A2="","",COUNTIF('07_Pallet_Contents'!$A$2:$A$3000,$A2)) | X26: =IF($A2="","",SUMIF('07_Pallet_Contents'!$A$2:$A$3000,$A2,'07_Pallet_Contents'!$D$2:$D$3000)) | Y26: =IF($A2="","",SUMIF('07_Pallet_Contents'!$A$2:$A$3000,$A2,'07_Pallet_Contents'!$I$2:$I$3000)) | Z26: =IF($A2="","",IF(COUNTIF('07_Pallet_Contents'!$A$2:$A$3000,$A2)>0,"Yes",""))
A27: WH-Z1-AisleB-Bay1-Level3 | C27: PAL-0000027 | D27: =IF($C27="","",IFERROR(LOOKUP(2,1/('03_Warehouse_Movements'!$C$2:$C$500=$A27),'03_Warehouse_Movements'!$E$2:$E$500),$C27)) | E27: STANDARD | F27: SAMPLE: Monitors 24-40 | H27: =IF(AND($F27="TEMP",$G27>0,$M27<>""),$M27+$G27,"") | I27: PAL-0000017 | J27: SAMPLE-TECH | K27: 46052 | L27: B:OVERFLOW-<ClientLastName>-PO<PO>-<Category>-<Seq> | M27: =IF($C27="","",IFERROR(LOOKUP(2,1/('03_Warehouse_Movements'!$C$2:$C$500=$A27),'03_Warehouse_Movements'!$A$2:$A$500),"")) | N27: =IF($C27="","",IFERROR(LOOKUP(2,1/('03_Warehouse_Movements'!$C$2:$C$500=$A27),'03_Warehouse_Movements'!$H$2:$H$500),"")) | O27: =A27 | W27: =IF($A2="","",COUNTIF('07_Pallet_Contents'!$A$2:$A$3000,$A2)) | X27: =IF($A2="","",SUMIF('07_Pallet_Contents'!$A$2:$A$3000,$A2,'07_Pallet_Contents'!$D$2:$D$3000)) | Y27: =IF($A2="","",SUMIF('07_Pallet_Contents'!$A$2:$A$3000,$A2,'07_Pallet_Contents'!$I$2:$I$3000)) | Z27: =IF($A2="","",IF(COUNTIF('07_Pallet_Contents'!$A$2:$A$3000,$A2)>0,"Yes",""))
A28: WH-Z1-AisleB-Bay1-Level4 | C28: PAL-0000028 | D28: =IF($C28="","",IFERROR(LOOKUP(2,1/('03_Warehouse_Movements'!$C$2:$C$500=$A28),'03_Warehouse_Movements'!$E$2:$E$500),$C28)) | E28: STANDARD | F28: SAMPLE: Monitors 24-40 | H28: =IF(AND($F28="TEMP",$G28>0,$M28<>""),$M28+$G28,"") | I28: PAL-0000018 | J28: SAMPLE-TECH | K28: 46052 | L28: B:OVERFLOW-<ClientLastName>-PO<PO>-<Category>-<Seq> | M28: =IF($C28="","",IFERROR(LOOKUP(2,1/('03_Warehouse_Movements'!$C$2:$C$500=$A28),'03_Warehouse_Movements'!$A$2:$A$500),"")) | N28: =IF($C28="","",IFERROR(LOOKUP(2,1/('03_Warehouse_Movements'!$C$2:$C$500=$A28),'03_Warehouse_Movements'!$H$2:$H$500),"")) | O28: =A28 | W28: =IF($A2="","",COUNTIF('07_Pallet_Contents'!$A$2:$A$3000,$A2)) | X28: =IF($A2="","",SUMIF('07_Pallet_Contents'!$A$2:$A$3000,$A2,'07_Pallet_Contents'!$D$2:$D$3000)) | Y28: =IF($A2="","",SUMIF('07_Pallet_Contents'!$A$2:$A$3000,$A2,'07_Pallet_Contents'!$I$2:$I$3000)) | Z28: =IF($A2="","",IF(COUNTIF('07_Pallet_Contents'!$A$2:$A$3000,$A2)>0,"Yes",""))
A29: WH-Z1-AisleB-Bay1-Level5 | C29: PAL-0000029 | D29: =IF($C29="","",IFERROR(LOOKUP(2,1/('03_Warehouse_Movements'!$C$2:$C$500=$A29),'03_Warehouse_Movements'!$E$2:$E$500),$C29)) | E29: STANDARD | F29: SAMPLE: Monitors 24-40 | H29: =IF(AND($F29="TEMP",$G29>0,$M29<>""),$M29+$G29,"") | I29: PAL-0000009 | J29: SAMPLE-TECH | K29: 46052 | L29: B:OVERFLOW-<ClientLastName>-PO<PO>-<Category>-<Seq> | M29: =IF($C29="","",IFERROR(LOOKUP(2,1/('03_Warehouse_Movements'!$C$2:$C$500=$A29),'03_Warehouse_Movements'!$A$2:$A$500),"")) | N29: =IF($C29="","",IFERROR(LOOKUP(2,1/('03_Warehouse_Movements'!$C$2:$C$500=$A29),'03_Warehouse_Movements'!$H$2:$H$500),"")) | O29: =A29 | W29: =IF($A2="","",COUNTIF('07_Pallet_Contents'!$A$2:$A$3000,$A2)) | X29: =IF($A2="","",SUMIF('07_Pallet_Contents'!$A$2:$A$3000,$A2,'07_Pallet_Contents'!$D$2:$D$3000)) | Y29: =IF($A2="","",SUMIF('07_Pallet_Contents'!$A$2:$A$3000,$A2,'07_Pallet_Contents'!$I$2:$I$3000)) | Z29: =IF($A2="","",IF(COUNTIF('07_Pallet_Contents'!$A$2:$A$3000,$A2)>0,"Yes",""))
A30: OVERFLOW-SAMPLE-PO1028-CAT4-PAL029 | B30: WH-Z1-AisleB-Bay1-Level6 | C30: PAL-0000030 | D30: =IF($C30="","",IFERROR(LOOKUP(2,1/('03_Warehouse_Movements'!$C$2:$C$500=$A30),'03_Warehouse_Movements'!$E$2:$E$500),$C30)) | E30: STANDARD | F30: SAMPLE: Monitors 24-40 | H30: =IF(AND($F30="TEMP",$G30>0,$M30<>""),$M30+$G30,"") | I30: PAL-0000010 | J30: SAMPLE-TECH | K30: 46052 | L30: B:OVERFLOW-<ClientLastName>-PO<PO>-<Category>-<Seq> | M30: =IF($C30="","",IFERROR(LOOKUP(2,1/('03_Warehouse_Movements'!$C$2:$C$500=$A30),'03_Warehouse_Movements'!$A$2:$A$500),"")) | N30: =IF($C30="","",IFERROR(LOOKUP(2,1/('03_Warehouse_Movements'!$C$2:$C$500=$A30),'03_Warehouse_Movements'!$H$2:$H$500),"")) | O30: =A30 | W30: =IF($A2="","",COUNTIF('07_Pallet_Contents'!$A$2:$A$3000,$A2)) | X30: =IF($A2="","",SUMIF('07_Pallet_Contents'!$A$2:$A$3000,$A2,'07_Pallet_Contents'!$D$2:$D$3000)) | Y30: =IF($A2="","",SUMIF('07_Pallet_Contents'!$A$2:$A$3000,$A2,'07_Pallet_Contents'!$I$2:$I$3000)) | Z30: =IF($A2="","",IF(COUNTIF('07_Pallet_Contents'!$A$2:$A$3000,$A2)>0,"Yes",""))
A31: WH-Z1-AisleB-Bay1-Level7 | C31: PAL-0000031 | D31: =IF($C31="","",IFERROR(LOOKUP(2,1/('03_Warehouse_Movements'!$C$2:$C$500=$A31),'03_Warehouse_Movements'!$E$2:$E$500),$C31)) | E31: STANDARD | F31: SAMPLE: Monitors 24-40 | H31: =IF(AND($F31="TEMP",$G31>0,$M31<>""),$M31+$G31,"") | I31: B | J31: SAMPLE-TECH | K31: 46052 | L31: B:OVERFLOW-<ClientLastName>-PO<PO>-<Category>-<Seq> | M31: =IF($C31="","",IFERROR(LOOKUP(2,1/('03_Warehouse_Movements'!$C$2:$C$500=$A31),'03_Warehouse_Movements'!$A$2:$A$500),"")) | N31: =IF($C31="","",IFERROR(LOOKUP(2,1/('03_Warehouse_Movements'!$C$2:$C$500=$A31),'03_Warehouse_Movements'!$H$2:$H$500),"")) | O31: =A31 | W31: =IF($A2="","",COUNTIF('07_Pallet_Contents'!$A$2:$A$3000,$A2)) | X31: =IF($A2="","",SUMIF('07_Pallet_Contents'!$A$2:$A$3000,$A2,'07_Pallet_Contents'!$D$2:$D$3000)) | Y31: =IF($A2="","",SUMIF('07_Pallet_Contents'!$A$2:$A$3000,$A2,'07_Pallet_Contents'!$I$2:$I$3000)) | Z31: =IF($A2="","",IF(COUNTIF('07_Pallet_Contents'!$A$2:$A$3000,$A2)>0,"Yes",""))
A32: WH-Z1-AisleB-Bay1-Level8 | C32: PAL-0000032 | D32: =IF($C32="","",IFERROR(LOOKUP(2,1/('03_Warehouse_Movements'!$C$2:$C$500=$A32),'03_Warehouse_Movements'!$E$2:$E$500),$C32)) | E32: STANDARD | F32: PAL-0000008 | G32: 14 | H32: =IF(AND($F32="TEMP",$G32>0,$M32<>""),$M32+$G32,"") | I32: PAL-0000012 | J32: SAMPLE-TECH | K32: 46052 | L32: B:OVERFLOW-<ClientLastName>-PO<PO>-<Category>-<Seq> | M32: =IF($C32="","",IFERROR(LOOKUP(2,1/('03_Warehouse_Movements'!$C$2:$C$500=$A32),'03_Warehouse_Movements'!$A$2:$A$500),"")) | N32: =IF($C32="","",IFERROR(LOOKUP(2,1/('03_Warehouse_Movements'!$C$2:$C$500=$A32),'03_Warehouse_Movements'!$H$2:$H$500),"")) | O32: =A32 | W32: =IF($A2="","",COUNTIF('07_Pallet_Contents'!$A$2:$A$3000,$A2)) | X32: =IF($A2="","",SUMIF('07_Pallet_Contents'!$A$2:$A$3000,$A2,'07_Pallet_Contents'!$D$2:$D$3000)) | Y32: =IF($A2="","",SUMIF('07_Pallet_Contents'!$A$2:$A$3000,$A2,'07_Pallet_Contents'!$I$2:$I$3000)) | Z32: =IF($A2="","",IF(COUNTIF('07_Pallet_Contents'!$A$2:$A$3000,$A2)>0,"Yes",""))
A33: WH-Z1-AisleB-Bay1-Level9 | C33: PAL-0000033 | D33: =IF($C33="","",IFERROR(LOOKUP(2,1/('03_Warehouse_Movements'!$C$2:$C$500=$A33),'03_Warehouse_Movements'!$E$2:$E$500),$C33)) | E33: STANDARD | F33: SAMPLE: Monitors 24-40 | H33: =IF(AND($F33="TEMP",$G33>0,$M33<>""),$M33+$G33,"") | I33: SAMPLE: replace with real notes / serials / constraints | J33: SAMPLE-TECH | K33: 46052 | L33: B:OVERFLOW-<ClientLastName>-PO<PO>-<Category>-<Seq> | M33: =IF($C33="","",IFERROR(LOOKUP(2,1/('03_Warehouse_Movements'!$C$2:$C$500=$A33),'03_Warehouse_Movements'!$A$2:$A$500),"")) | N33: =IF($C33="","",IFERROR(LOOKUP(2,1/('03_Warehouse_Movements'!$C$2:$C$500=$A33),'03_Warehouse_Movements'!$H$2:$H$500),"")) | O33: =A33 | W33: =IF($A2="","",COUNTIF('07_Pallet_Contents'!$A$2:$A$3000,$A2)) | X33: =IF($A2="","",SUMIF('07_Pallet_Contents'!$A$2:$A$3000,$A2,'07_Pallet_Contents'!$D$2:$D$3000)) | Y33: =IF($A2="","",SUMIF('07_Pallet_Contents'!$A$2:$A$3000,$A2,'07_Pallet_Contents'!$I$2:$I$3000)) | Z33: =IF($A2="","",IF(COUNTIF('07_Pallet_Contents'!$A$2:$A$3000,$A2)>0,"Yes",""))
A34: WH-Z1-AisleB-Bay1-Level10 | C34: PAL-0000034 | D34: =IF($C34="","",IFERROR(LOOKUP(2,1/('03_Warehouse_Movements'!$C$2:$C$500=$A34),'03_Warehouse_Movements'!$E$2:$E$500),$C34)) | E34: STANDARD | F34: SAMPLE: Monitors 24-40 | H34: =IF(AND($F34="TEMP",$G34>0,$M34<>""),$M34+$G34,"") | I34: PAL-0000014 | J34: SAMPLE-TECH | K34: 46052 | L34: B:OVERFLOW-<ClientLastName>-PO<PO>-<Category>-<Seq> | M34: =IF($C34="","",IFERROR(LOOKUP(2,1/('03_Warehouse_Movements'!$C$2:$C$500=$A34),'03_Warehouse_Movements'!$A$2:$A$500),"")) | N34: =IF($C34="","",IFERROR(LOOKUP(2,1/('03_Warehouse_Movements'!$C$2:$C$500=$A34),'03_Warehouse_Movements'!$H$2:$H$500),"")) | O34: =A34 | W34: =IF($A2="","",COUNTIF('07_Pallet_Contents'!$A$2:$A$3000,$A2)) | X34: =IF($A2="","",SUMIF('07_Pallet_Contents'!$A$2:$A$3000,$A2,'07_Pallet_Contents'!$D$2:$D$3000)) | Y34: =IF($A2="","",SUMIF('07_Pallet_Contents'!$A$2:$A$3000,$A2,'07_Pallet_Contents'!$I$2:$I$3000)) | Z34: =IF($A2="","",IF(COUNTIF('07_Pallet_Contents'!$A$2:$A$3000,$A2)>0,"Yes",""))
A35: WH-Z1-AisleB-Bay1-Level11 | C35: PAL-0000035 | D35: =IF($C35="","",IFERROR(LOOKUP(2,1/('03_Warehouse_Movements'!$C$2:$C$500=$A35),'03_Warehouse_Movements'!$E$2:$E$500),$C35)) | E35: STANDARD | F35: SAMPLE: Monitors 24-40 | H35: =IF(AND($F35="TEMP",$G35>0,$M35<>""),$M35+$G35,"") | I35: PAL-0000015 | J35: SAMPLE-TECH | K35: 46052 | L35: B:OVERFLOW-<ClientLastName>-PO<PO>-<Category>-<Seq> | M35: =IF($C35="","",IFERROR(LOOKUP(2,1/('03_Warehouse_Movements'!$C$2:$C$500=$A35),'03_Warehouse_Movements'!$A$2:$A$500),"")) | N35: =IF($C35="","",IFERROR(LOOKUP(2,1/('03_Warehouse_Movements'!$C$2:$C$500=$A35),'03_Warehouse_Movements'!$H$2:$H$500),"")) | O35: =A35 | W35: =IF($A2="","",COUNTIF('07_Pallet_Contents'!$A$2:$A$3000,$A2)) | X35: =IF($A2="","",SUMIF('07_Pallet_Contents'!$A$2:$A$3000,$A2,'07_Pallet_Contents'!$D$2:$D$3000)) | Y35: =IF($A2="","",SUMIF('07_Pallet_Contents'!$A$2:$A$3000,$A2,'07_Pallet_Contents'!$I$2:$I$3000)) | Z35: =IF($A2="","",IF(COUNTIF('07_Pallet_Contents'!$A$2:$A$3000,$A2)>0,"Yes",""))
A36: WH-Z1-AisleB-Bay1-Level12 | C36: PAL-0000036 | D36: =IF($C36="","",IFERROR(LOOKUP(2,1/('03_Warehouse_Movements'!$C$2:$C$500=$A36),'03_Warehouse_Movements'!$E$2:$E$500),$C36)) | E36: STANDARD | F36: SAMPLE: Monitors 24-40 | H36: =IF(AND($F36="TEMP",$G36>0,$M36<>""),$M36+$G36,"") | I36: PAL-0000016 | J36: SAMPLE-TECH | K36: 46052 | L36: B:OVERFLOW-<ClientLastName>-PO<PO>-<Category>-<Seq> | M36: =IF($C36="","",IFERROR(LOOKUP(2,1/('03_Warehouse_Movements'!$C$2:$C$500=$A36),'03_Warehouse_Movements'!$A$2:$A$500),"")) | N36: =IF($C36="","",IFERROR(LOOKUP(2,1/('03_Warehouse_Movements'!$C$2:$C$500=$A36),'03_Warehouse_Movements'!$H$2:$H$500),"")) | O36: =A36 | W36: =IF($A2="","",COUNTIF('07_Pallet_Contents'!$A$2:$A$3000,$A2)) | X36: =IF($A2="","",SUMIF('07_Pallet_Contents'!$A$2:$A$3000,$A2,'07_Pallet_Contents'!$D$2:$D$3000)) | Y36: =IF($A2="","",SUMIF('07_Pallet_Contents'!$A$2:$A$3000,$A2,'07_Pallet_Contents'!$I$2:$I$3000)) | Z36: =IF($A2="","",IF(COUNTIF('07_Pallet_Contents'!$A$2:$A$3000,$A2)>0,"Yes",""))
A37: OVERFLOW-SAMPLE-PO1035-CAT1-PAL036 | B37: WH-Z1-AisleB-Bay1-Level13 | C37: PAL-0000037 | D37: =IF($C37="","",IFERROR(LOOKUP(2,1/('03_Warehouse_Movements'!$C$2:$C$500=$A37),'03_Warehouse_Movements'!$E$2:$E$500),$C37)) | E37: STANDARD | F37: SAMPLE: Monitors 24-40 | H37: =IF(AND($F37="TEMP",$G37>0,$M37<>""),$M37+$G37,"") | I37: PAL-0000017 | J37: SAMPLE-TECH | K37: 46052 | L37: B:OVERFLOW-<ClientLastName>-PO<PO>-<Category>-<Seq> | M37: =IF($C37="","",IFERROR(LOOKUP(2,1/('03_Warehouse_Movements'!$C$2:$C$500=$A37),'03_Warehouse_Movements'!$A$2:$A$500),"")) | N37: =IF($C37="","",IFERROR(LOOKUP(2,1/('03_Warehouse_Movements'!$C$2:$C$500=$A37),'03_Warehouse_Movements'!$H$2:$H$500),"")) | O37: =A37 | W37: =IF($A2="","",COUNTIF('07_Pallet_Contents'!$A$2:$A$3000,$A2)) | X37: =IF($A2="","",SUMIF('07_Pallet_Contents'!$A$2:$A$3000,$A2,'07_Pallet_Contents'!$D$2:$D$3000)) | Y37: =IF($A2="","",SUMIF('07_Pallet_Contents'!$A$2:$A$3000,$A2,'07_Pallet_Contents'!$I$2:$I$3000)) | Z37: =IF($A2="","",IF(COUNTIF('07_Pallet_Contents'!$A$2:$A$3000,$A2)>0,"Yes",""))
A38: WH-Z1-AisleB-Bay1-Level14 | C38: PAL-0000038 | D38: =IF($C38="","",IFERROR(LOOKUP(2,1/('03_Warehouse_Movements'!$C$2:$C$500=$A38),'03_Warehouse_Movements'!$E$2:$E$500),$C38)) | E38: STANDARD | F38: PAL-0000008 | G38: 14 | H38: =IF(AND($F38="TEMP",$G38>0,$M38<>""),$M38+$G38,"") | I38: PAL-0000018 | J38: SAMPLE-TECH | K38: 46052 | L38: B:OVERFLOW-<ClientLastName>-PO<PO>-<Category>-<Seq> | M38: =IF($C38="","",IFERROR(LOOKUP(2,1/('03_Warehouse_Movements'!$C$2:$C$500=$A38),'03_Warehouse_Movements'!$A$2:$A$500),"")) | N38: =IF($C38="","",IFERROR(LOOKUP(2,1/('03_Warehouse_Movements'!$C$2:$C$500=$A38),'03_Warehouse_Movements'!$H$2:$H$500),"")) | O38: =A38 | W38: =IF($A2="","",COUNTIF('07_Pallet_Contents'!$A$2:$A$3000,$A2)) | X38: =IF($A2="","",SUMIF('07_Pallet_Contents'!$A$2:$A$3000,$A2,'07_Pallet_Contents'!$D$2:$D$3000)) | Y38: =IF($A2="","",SUMIF('07_Pallet_Contents'!$A$2:$A$3000,$A2,'07_Pallet_Contents'!$I$2:$I$3000)) | Z38: =IF($A2="","",IF(COUNTIF('07_Pallet_Contents'!$A$2:$A$3000,$A2)>0,"Yes",""))
A39: WH-Z1-AisleB-Bay1-Level15 | C39: PAL-0000039 | D39: =IF($C39="","",IFERROR(LOOKUP(2,1/('03_Warehouse_Movements'!$C$2:$C$500=$A39),'03_Warehouse_Movements'!$E$2:$E$500),$C39)) | E39: STANDARD | F39: SAMPLE: Monitors 24-40 | H39: =IF(AND($F39="TEMP",$G39>0,$M39<>""),$M39+$G39,"") | I39: PAL-0000009 | J39: SAMPLE-TECH | K39: 46052 | L39: B:OVERFLOW-<ClientLastName>-PO<PO>-<Category>-<Seq> | M39: =IF($C39="","",IFERROR(LOOKUP(2,1/('03_Warehouse_Movements'!$C$2:$C$500=$A39),'03_Warehouse_Movements'!$A$2:$A$500),"")) | N39: =IF($C39="","",IFERROR(LOOKUP(2,1/('03_Warehouse_Movements'!$C$2:$C$500=$A39),'03_Warehouse_Movements'!$H$2:$H$500),"")) | O39: =A39 | W39: =IF($A2="","",COUNTIF('07_Pallet_Contents'!$A$2:$A$3000,$A2)) | X39: =IF($A2="","",SUMIF('07_Pallet_Contents'!$A$2:$A$3000,$A2,'07_Pallet_Contents'!$D$2:$D$3000)) | Y39: =IF($A2="","",SUMIF('07_Pallet_Contents'!$A$2:$A$3000,$A2,'07_Pallet_Contents'!$I$2:$I$3000)) | Z39: =IF($A2="","",IF(COUNTIF('07_Pallet_Contents'!$A$2:$A$3000,$A2)>0,"Yes",""))
A40: WH-Z1-AisleB-Bay1-Level16 | C40: PAL-0000040 | D40: =IF($C40="","",IFERROR(LOOKUP(2,1/('03_Warehouse_Movements'!$C$2:$C$500=$A40),'03_Warehouse_Movements'!$E$2:$E$500),$C40)) | E40: STANDARD | F40: SAMPLE: Monitors 24-40 | H40: =IF(AND($F40="TEMP",$G40>0,$M40<>""),$M40+$G40,"") | I40: PAL-0000010 | J40: SAMPLE-TECH | K40: 46052 | L40: B:OVERFLOW-<ClientLastName>-PO<PO>-<Category>-<Seq> | M40: =IF($C40="","",IFERROR(LOOKUP(2,1/('03_Warehouse_Movements'!$C$2:$C$500=$A40),'03_Warehouse_Movements'!$A$2:$A$500),"")) | N40: =IF($C40="","",IFERROR(LOOKUP(2,1/('03_Warehouse_Movements'!$C$2:$C$500=$A40),'03_Warehouse_Movements'!$H$2:$H$500),"")) | O40: =A40 | W40: =IF($A2="","",COUNTIF('07_Pallet_Contents'!$A$2:$A$3000,$A2)) | X40: =IF($A2="","",SUMIF('07_Pallet_Contents'!$A$2:$A$3000,$A2,'07_Pallet_Contents'!$D$2:$D$3000)) | Y40: =IF($A2="","",SUMIF('07_Pallet_Contents'!$A$2:$A$3000,$A2,'07_Pallet_Contents'!$I$2:$I$3000)) | Z40: =IF($A2="","",IF(COUNTIF('07_Pallet_Contents'!$A$2:$A$3000,$A2)>0,"Yes",""))
...

Sheet 02_Warehouse_Locations
A1: Zone | B1: Aisle | C1: Position/Slot | D1: LocationType | E1: AccessRating(1-5) | F1: QR_Payload | G1: Expires (AUTO) | H1: DisplayLabel (AUTO) | I1: Notes | J1: AisleNum (AUTO) | K1: SlotNum (AUTO) | L1: LevelNum (AUTO) | M1: PrismNode (AUTO) | N1: GridCol (AUTO) | O1: GridRow (AUTO) | P1: GridNode (AUTO) | Q1: WH
A2: STAGED | B2: STAGE_IN | E2: Inbound staging | F2: 1 | G2: 0 | H2: =A2 | I2: WH-STAGE-OUT | J2: =IF($I2<>"",$I2,$A2) | K2: =IF($C2="","",IF(LEN($C2)=1,CODE(UPPER($C2))-64,IFERROR(VALUE(MID($C2,2,99)),""))) | L2: =IF($D2="","",IFERROR(VALUE($D2),"")) | M2: =IFERROR(VALUE(MID($A2,FIND("Level",$A2)+5,99)),IF($E2="AISLE_FLOOR",0,IF($E2="OVERFLOW",0,IF($E2="ENDCAP",0,"")))) | N2: =IF(AND($B2<>"",$C2<>"",ISNUMBER(--$D2)), $B2&": "&LEFT($C2,1)&TEXT(--$D2,"00"), IF($I2<>"",$I2,$A2)) | O2: =IF(AND($C2<>"",ISNUMBER(--$D2)),LEFT($C2,1),"") | P2: =IF(ISNUMBER(--$D2),--$D2,"") | Q2: =IF(AND($O2<>"",$P2<>""),$O2&TEXT($P2,"00"),"")
